[META]
version=2.0
spawnOnBlockType=2
spawnSunlight=True
spawnDarkness=False
spawnWater=False
spawnLava=False
underFill=True
randomRotation=True
dig=True
tree=True
branch=False
needsFoundation=True
rarity=1
collisionPercentage=1
spawnElevationMin=0
spawnElevationMax=256
spawnInBiome=Jungle
[DATA]
-2,-1,0:82
-2,0,0:82
-2,1,0:82
-2,-1,1:139
-2,0,1:139
-2,1,1:139
-2,-1,2:82
-2,0,2:82
-2,1,2:82
-2,-1,3:160.8
-2,0,3:160.8
-2,1,3:160.8
-2,-1,4:160.8
-2,0,4:160.8
-2,1,4:160.8
-2,-1,5:160.8
-2,0,5:160.8
-2,1,5:160.8
-2,-1,6:160.8
-2,0,6:160.8
-2,1,6:160.8
-2,-1,7:82
-2,0,7:82
-2,1,7:82
-1,-2,0:82
-1,-1,0:82
-1,0,0:82
-1,1,0:82
-1,2,0:82
-1,-2,1:139
-1,-1,1:159.9
-1,0,1:159.9
-1,1,1:159.9
-1,2,1:139
-1,-2,2:82
-1,-1,2:82
-1,0,2:82
-1,1,2:82
-1,2,2:82
-1,-2,3:160.8
-1,-1,3:160.8
-1,0,3:54.5
-1,1,3:160.8
-1,2,3:160.8
-1,-2,4:160.8
-1,-1,4:160.8
-1,0,4:160.5
-1,1,4:160.8
-1,2,4:160.8
-1,-2,5:160.8
-1,-1,5:160.8
-1,0,5:160.5
-1,1,5:160.8
-1,2,5:160.8
-1,-2,6:160.8
-1,-1,6:160.8
-1,0,6:160.5
-1,1,6:160.8
-1,2,6:160.8
-1,-2,7:82
-1,-1,7:82
-1,0,7:82
-1,1,7:82
-1,2,7:82
0,-2,0:82
0,-1,0:82
0,0,0:82
0,1,0:82
0,2,0:82
0,-2,1:139
0,-1,1:159.9
0,0,1:159.9
0,1,1:159.9
0,2,1:139
0,-2,2:82
0,-1,2:82
0,0,2:82
0,1,2:82
0,2,2:82
0,-2,3:160.8
0,-1,3:54.3
0,1,3:54.2
0,2,3:160.8
0,-2,4:160.8
0,-1,4:160.5
0,1,4:160.5
0,2,4:160.8
0,-2,5:160.8
0,-1,5:160.5
0,1,5:160.5
0,2,5:160.8
0,-2,6:160.8
0,-1,6:160.5
0,1,6:160.5
0,2,6:160.8
0,-2,7:82
0,-1,7:82
0,0,7:82
0,1,7:82
0,2,7:82
1,-2,0:82
1,-1,0:82
1,0,0:82
1,1,0:82
1,2,0:82
1,-2,1:139
1,-1,1:159.9
1,0,1:159.9
1,1,1:159.9
1,2,1:139
1,-2,2:82
1,-1,2:82
1,0,2:82
1,1,2:82
1,2,2:82
1,-2,3:160.8
1,-1,3:160.8
1,0,3:54.4
1,1,3:160.8
1,2,3:160.8
1,-2,4:160.8
1,-1,4:160.8
1,0,4:160.5
1,1,4:160.8
1,2,4:160.8
1,-2,5:160.8
1,-1,5:160.8
1,0,5:160.5
1,1,5:160.8
1,2,5:160.8
1,-2,6:160.8
1,-1,6:160.8
1,0,6:160.5
1,1,6:160.8
1,2,6:160.8
1,-2,7:82
1,-1,7:82
1,0,7:82
1,1,7:82
1,2,7:82
2,-1,0:82
2,0,0:82
2,1,0:82
2,-1,1:139
2,0,1:139
2,1,1:139
2,-1,2:82
2,0,2:82
2,1,2:82
2,-1,3:160.8
2,0,3:160.8
2,1,3:160.8
2,-1,4:160.8
2,0,4:160.8
2,1,4:160.8
2,-1,5:160.8
2,0,5:160.8
2,1,5:160.8
2,-1,6:160.8
2,0,6:160.8
2,1,6:160.8
2,-1,7:82
2,0,7:82
2,1,7:82
