[META]
version=2.0
spawnOnBlockType=2
spawnSunlight=True
spawnDarkness=False
spawnWater=False
spawnLava=False
underFill=True
randomRotation=True
dig=True
tree=True
branch=False
needsFoundation=True
rarity=1
collisionPercentage=1
spawnElevationMin=0
spawnElevationMax=256
spawnInBiome=Jungle
[DATA]
-46,6,53:95.5
-46,8,53:95.5
-46,9,53:95.5
-46,10,53:95.5
-46,7,54:95.5
-46,8,54:95.5
-46,9,54:95.5
-45,-9,51:95.5
-45,-6,51:95.5
-45,7,51:95.5
-45,9,51:95.5
-45,10,51:95.5
-45,7,52:95.5
-45,8,52:95.5
-45,-12,53:95.5
-45,4,53:95.5
-45,11,53:95.5
-45,-12,54:95.5
-45,-11,54:95.5
-45,-4,54:95.5
-45,11,54:95.5
-44,-10,49:95.5
-44,-9,49:95.5
-44,-8,49:95.5
-44,-6,49:95.5
-44,-5,49:95.5
-44,7,49:95.5
-44,8,49:95.5
-44,9,49:95.5
-44,10,49:95.5
-44,-10,50:95.5
-44,-9,50:95.5
-44,-7,50:95.5
-44,-6,50:95.5
-44,-5,50:95.5
-44,7,50:95.5
-44,9,50:95.5
-44,4,51:95.5
-44,-11,52:95.5
-44,14,53:95.5
-44,3,54:95.5
-44,15,54:95.5
-43,-9,47:95.5
-43,6,47:95.5
-43,9,47:95.5
-43,-9,48:95.5
-43,5,48:95.5
-43,9,48:95.5
-43,-11,49:95.5
-43,-4,49:95.5
-43,11,49:95.5
-43,-12,50:95.5
-43,-11,50:95.5
-43,4,50:95.5
-43,12,50:95.5
-43,-14,51:95.5
-43,13,51:95.5
-43,14,52:95.5
-43,2,53:95.5
-43,2,54:95.5
-43,16,54:95.5
-42,-10,45:95.5
-42,-8,45:95.5
-42,-6,45:95.5
-42,5,45:95.5
-42,8,45:95.5
-42,10,45:95.5
-42,-10,46:95.5
-42,-9,46:95.5
-42,-8,46:95.5
-42,12,47:95.5
-42,12,48:95.5
-42,13,49:95.5
-42,14,49:95.5
-42,15,49:95.5
-42,-15,50:95.5
-42,-3,50:95.5
-42,3,50:95.5
-42,15,50:95.5
-42,-2,51:95.5
-42,2,51:95.5
-42,16,51:95.5
-42,2,52:95.5
-42,1,53:95.5
-42,17,53:95.5
-42,-17,54:95.5
-42,-1,54:95.5
-42,1,54:95.5
-41,-10,43:95.5
-41,-8,43:95.5
-41,-6,43:95.5
-41,6,43:95.5
-41,7,43:95.5
-41,10,43:95.5
-41,-7,44:95.5
-41,6,44:95.5
-41,7,44:95.5
-41,12,45:95.5
-41,-12,46:95.5
-41,-11,46:95.5
-41,12,46:95.5
-41,-3,47:95.5
-41,13,47:95.5
-41,15,47:95.5
-41,-3,48:95.5
-41,13,48:95.5
-41,15,48:95.5
-41,-16,49:95.5
-41,1,51:95.5
-41,1,52:95.5
-41,0,53:95.5
-41,18,54:95.5
-41,-3,58:35.1
-41,3,58:35.1
-41,-3,59:85
-41,3,59:85
-41,-3,60:35.1
-41,3,60:35.1
-40,-2,26:159.9
-40,-1,26:159.9
-40,0,26:159.9
-40,1,26:159.9
-40,2,26:159.9
-40,-2,27:159.9
-40,-1,27:159.9
-40,0,27:159.9
-40,1,27:159.9
-40,2,27:159.9
-40,-2,28:159.9
-40,-1,28:159.9
-40,0,28:159.9
-40,1,28:159.9
-40,2,28:159.9
-40,-2,30:159.9
-40,-1,30:159.9
-40,0,30:159.9
-40,1,30:159.9
-40,2,30:159.9
-40,-2,31:159.9
-40,-1,31:159.9
-40,0,31:159.9
-40,1,31:159.9
-40,2,31:159.9
-40,-6,41:95.5
-40,-5,41:95.5
-40,10,41:95.5
-40,-6,42:95.5
-40,-5,42:95.5
-40,6,42:95.5
-40,8,42:95.5
-40,-4,43:95.5
-40,12,44:95.5
-40,-3,45:95.5
-40,14,45:95.5
-40,-15,46:95.5
-40,-2,47:95.5
-40,-16,48:95.5
-40,-2,48:95.5
-40,2,48:95.5
-40,-17,49:95.5
-40,-17,50:95.5
-40,-1,50:95.5
-40,18,52:95.5
-40,19,54:95.5
-40,-4,58:35.1
-40,4,58:35.1
-40,-4,59:85
-40,4,59:85
-40,-4,60:35.1
-40,-3,60:85
-40,3,60:85
-40,4,60:35.1
-40,-3,61:85
-40,3,61:85
-39,0,25:35.7
-39,-4,26:159.9
-39,-3,26:159.9
-39,-2,26:159.9
-39,-1,26:159.9
-39,0,26:159.9
-39,1,26:159.9
-39,2,26:159.9
-39,3,26:159.9
-39,4,26:159.9
-39,-4,27:159.9
-39,-3,27:159.9
-39,-2,27:159.9
-39,-1,27:159.9
-39,0,27:159.9
-39,1,27:159.9
-39,2,27:159.9
-39,3,27:159.9
-39,4,27:159.9
-39,-4,28:159.9
-39,-3,28:159.9
-39,-2,28:159.9
-39,-1,28:159.9
-39,0,28:159.9
-39,1,28:159.9
-39,2,28:159.9
-39,3,28:159.9
-39,4,28:159.9
-39,-2,29:82
-39,-1,29:82
-39,0,29:82
-39,1,29:82
-39,2,29:82
-39,-4,30:159.9
-39,-3,30:159.9
-39,-2,30:159.9
-39,-1,30:159.9
-39,0,30:159.9
-39,1,30:159.9
-39,2,30:159.9
-39,3,30:159.9
-39,4,30:159.9
-39,-4,31:159.9
-39,-3,31:159.9
-39,-2,31:159.9
-39,-1,31:159.9
-39,0,31:159.9
-39,1,31:159.9
-39,2,31:159.9
-39,3,31:159.9
-39,4,31:159.9
-39,-2,32:1
-39,-1,32:1
-39,0,32:1
-39,1,32:1
-39,2,32:1
-39,-2,33:1
-39,-1,33:1
-39,0,33:1
-39,1,33:1
-39,2,33:1
-39,-2,34:1
-39,-1,34:1
-39,0,34:1
-39,1,34:1
-39,2,34:1
-39,-2,35:1
-39,-1,35:1
-39,0,35:1
-39,1,35:1
-39,2,35:1
-39,-2,36:1
-39,-1,36:1
-39,0,36:1
-39,1,36:1
-39,2,36:1
-39,-2,37:1
-39,-1,37:1
-39,0,37:1
-39,1,37:1
-39,2,37:1
-39,-2,38:1
-39,-1,38:1
-39,0,38:1
-39,1,38:1
-39,2,38:1
-39,-10,39:95.5
-39,-9,39:95.5
-39,-8,39:95.5
-39,-7,39:95.5
-39,-6,39:95.5
-39,-5,39:95.5
-39,-2,39:1
-39,-1,39:1
-39,0,39:1
-39,1,39:1
-39,2,39:1
-39,6,39:95.5
-39,8,39:95.5
-39,9,39:95.5
-39,10,39:95.5
-39,-9,40:95.5
-39,-7,40:95.5
-39,-6,40:95.5
-39,-5,40:95.5
-39,-2,40:1
-39,-1,40:1
-39,0,40:1
-39,1,40:1
-39,2,40:1
-39,5,40:95.5
-39,6,40:95.5
-39,8,40:95.5
-39,9,40:95.5
-39,-12,41:95.5
-39,-11,41:95.5
-39,-4,41:95.5
-39,-2,41:1
-39,-1,41:1
-39,0,41:1
-39,1,41:1
-39,2,41:1
-39,-4,42:95.5
-39,-2,42:1
-39,-1,42:1
-39,0,42:1
-39,1,42:1
-39,2,42:1
-39,4,42:95.5
-39,-3,43:95.5
-39,-2,43:1
-39,-1,43:1
-39,0,43:1
-39,1,43:1
-39,2,43:1
-39,3,43:95.5
-39,14,43:95.5
-39,-3,44:95.5
-39,-2,44:1
-39,-1,44:1
-39,0,44:1
-39,1,44:1
-39,2,44:1
-39,3,44:95.5
-39,13,44:95.5
-39,-2,45:1
-39,-1,45:1
-39,0,45:1
-39,1,45:1
-39,2,45:1
-39,-2,46:1
-39,-1,46:1
-39,0,46:1
-39,1,46:1
-39,2,46:1
-39,-2,47:95.5
-39,2,47:95.5
-39,17,47:95.5
-39,2,48:95.5
-39,17,48:95.5
-39,-1,49:95.5
-39,1,49:95.5
-39,18,49:95.5
-39,-1,50:95.5
-39,1,50:95.5
-39,-20,53:95.5
-39,20,53:95.5
-39,-20,54:95.5
-39,20,54:95.5
-39,-5,58:35.1
-39,5,58:35.1
-39,-5,59:85
-39,5,59:85
-39,-5,60:35.1
-39,-4,60:85
-39,4,60:85
-39,5,60:35.1
-39,-4,61:85
-39,-3,61:35.1
-39,3,61:35.1
-39,4,61:85
-38,0,24:35.7
-38,-1,25:35.7
-38,0,25:35.7
-38,1,25:35.7
-38,-6,26:159.9
-38,-5,26:159.9
-38,-4,26:159.9
-38,-3,26:159.9
-38,-2,26:159.9
-38,-1,26:159.9
-38,0,26:159.9
-38,1,26:159.9
-38,2,26:159.9
-38,3,26:159.9
-38,4,26:159.9
-38,5,26:159.9
-38,6,26:159.9
-38,-6,27:159.9
-38,-5,27:159.9
-38,-4,27:159.9
-38,-3,27:159.9
-38,-2,27:159.9
-38,-1,27:159.9
-38,0,27:159.9
-38,1,27:159.9
-38,2,27:159.9
-38,3,27:159.9
-38,4,27:159.9
-38,5,27:159.9
-38,6,27:159.9
-38,-6,28:159.9
-38,-5,28:159.9
-38,-4,28:159.9
-38,-3,28:159.9
-38,-2,28:159.9
-38,-1,28:159.9
-38,0,28:159.9
-38,1,28:159.9
-38,2,28:159.9
-38,3,28:159.9
-38,4,28:159.9
-38,5,28:159.9
-38,6,28:159.9
-38,-4,29:82
-38,-3,29:82
-38,-2,29:82
-38,-1,29:82
-38,0,29:82
-38,1,29:82
-38,2,29:82
-38,3,29:82
-38,4,29:82
-38,-6,30:159.9
-38,-5,30:159.9
-38,-4,30:159.9
-38,-3,30:159.9
-38,-2,30:159.9
-38,-1,30:159.9
-38,0,30:159.9
-38,1,30:159.9
-38,2,30:159.9
-38,3,30:159.9
-38,4,30:159.9
-38,5,30:159.9
-38,6,30:159.9
-38,-6,31:159.9
-38,-5,31:159.9
-38,-4,31:159.9
-38,-3,31:159.9
-38,-2,31:159.9
-38,-1,31:159.9
-38,0,31:159.9
-38,1,31:159.9
-38,2,31:159.9
-38,3,31:159.9
-38,4,31:159.9
-38,5,31:159.9
-38,6,31:159.9
-38,-4,32:1
-38,-3,32:1
-38,-2,32:1
-38,-1,32:1
-38,0,32:1
-38,1,32:1
-38,2,32:1
-38,3,32:1
-38,4,32:1
-38,-4,33:1
-38,-3,33:1
-38,-2,33:1
-38,-1,33:1
-38,0,33:1
-38,1,33:1
-38,2,33:1
-38,3,33:1
-38,4,33:1
-38,-4,34:1
-38,-3,34:1
-38,-2,34:1
-38,-1,34:1
-38,0,34:1
-38,1,34:1
-38,2,34:1
-38,3,34:1
-38,4,34:1
-38,-4,35:1
-38,-3,35:1
-38,-2,35:1
-38,-1,35:1
-38,0,35:1
-38,1,35:1
-38,2,35:1
-38,3,35:1
-38,4,35:1
-38,-4,36:1
-38,-3,36:1
-38,-2,36:1
-38,-1,36:1
-38,0,36:1
-38,1,36:1
-38,2,36:1
-38,3,36:1
-38,4,36:1
-38,-10,37:95.5
-38,-9,37:95.5
-38,-8,37:95.5
-38,-7,37:95.5
-38,-6,37:95.5
-38,-5,37:95.5
-38,-4,37:1
-38,-3,37:1
-38,-2,37:1
-38,-1,37:1
-38,0,37:1
-38,1,37:1
-38,2,37:1
-38,3,37:1
-38,4,37:1
-38,5,37:95.5
-38,6,37:95.5
-38,7,37:95.5
-38,8,37:95.5
-38,9,37:95.5
-38,10,37:95.5
-38,-10,38:95.5
-38,-9,38:95.5
-38,-8,38:95.5
-38,-7,38:95.5
-38,-6,38:95.5
-38,-5,38:95.5
-38,-4,38:1
-38,-3,38:1
-38,-2,38:1
-38,-1,38:1
-38,0,38:1
-38,1,38:1
-38,2,38:1
-38,3,38:1
-38,4,38:1
-38,5,38:95.5
-38,6,38:95.5
-38,7,38:95.5
-38,8,38:95.5
-38,9,38:95.5
-38,10,38:95.5
-38,-11,39:95.5
-38,-4,39:1
-38,-3,39:1
-38,-2,39:1
-38,-1,39:1
-38,0,39:1
-38,1,39:1
-38,2,39:1
-38,3,39:1
-38,4,39:1
-38,-4,40:1
-38,-3,40:1
-38,-2,40:1
-38,-1,40:1
-38,0,40:1
-38,1,40:1
-38,2,40:1
-38,3,40:1
-38,4,40:1
-38,11,40:95.5
-38,-4,41:1
-38,-3,41:1
-38,-2,41:1
-38,-1,41:1
-38,0,41:1
-38,1,41:1
-38,2,41:1
-38,3,41:1
-38,4,41:1
-38,14,41:95.5
-38,-4,42:1
-38,-3,42:1
-38,-2,42:1
-38,-1,42:1
-38,0,42:1
-38,1,42:1
-38,2,42:1
-38,3,42:1
-38,4,42:1
-38,-4,43:1
-38,-3,43:1
-38,-2,43:1
-38,-1,43:1
-38,0,43:1
-38,1,43:1
-38,2,43:1
-38,3,43:1
-38,4,43:1
-38,-4,44:1
-38,-3,44:1
-38,-2,44:1
-38,-1,44:1
-38,0,44:1
-38,1,44:1
-38,2,44:1
-38,3,44:1
-38,4,44:1
-38,-4,45:1
-38,-3,45:1
-38,-2,45:1
-38,-1,45:1
-38,0,45:1
-38,1,45:1
-38,2,45:1
-38,3,45:1
-38,4,45:1
-38,-4,46:1
-38,-3,46:1
-38,-2,46:1
-38,-1,46:1
-38,0,46:1
-38,1,46:1
-38,2,46:1
-38,3,46:1
-38,4,46:1
-38,-18,47:95.5
-38,-2,47:1
-38,-1,47:1
-38,0,47:1
-38,1,47:1
-38,2,47:1
-38,18,47:95.5
-38,-18,48:95.5
-38,-2,48:1
-38,-1,48:1
-38,0,48:1
-38,1,48:1
-38,2,48:1
-38,-2,49:1
-38,-1,49:1
-38,0,49:1
-38,1,49:1
-38,2,49:1
-38,19,49:95.5
-38,-2,50:1
-38,-1,50:1
-38,0,50:1
-38,1,50:1
-38,2,50:1
-38,19,50:95.5
-38,-2,51:1
-38,-1,51:1
-38,0,51:1
-38,1,51:1
-38,2,51:1
-38,-2,52:1
-38,-1,52:1
-38,0,52:1
-38,1,52:1
-38,2,52:1
-38,-21,53:95.5
-38,-2,53:1
-38,-1,53:1
-38,0,53:1
-38,1,53:1
-38,2,53:1
-38,21,53:95.5
-38,-2,54:1
-38,-1,54:1
-38,0,54:1
-38,1,54:1
-38,2,54:1
-38,21,54:95.5
-38,-2,55:1
-38,-1,55:1
-38,0,55:1
-38,1,55:1
-38,2,55:1
-38,-2,56:1
-38,-1,56:1
-38,0,56:1
-38,1,56:1
-38,2,56:1
-38,-6,58:35.1
-38,6,58:35.1
-38,-6,59:85
-38,6,59:85
-38,-6,60:35.1
-38,-5,60:85
-38,5,60:85
-38,6,60:35.1
-38,-5,61:85
-38,-4,61:35.1
-38,-3,61:85
-38,3,61:85
-38,4,61:35.1
-38,5,61:85
-38,-3,62:85
-38,3,62:85
-37,-1,24:35.7
-37,0,24:35.7
-37,1,24:35.7
-37,-1,25:35.7
-37,0,25:35.7
-37,1,25:35.7
-37,-6,26:159.9
-37,-5,26:159.9
-37,-4,26:159.9
-37,-3,26:159.9
-37,-2,26:159.9
-37,-1,26:159.9
-37,0,26:159.9
-37,1,26:159.9
-37,2,26:159.9
-37,3,26:159.9
-37,4,26:159.9
-37,5,26:159.9
-37,6,26:159.9
-37,-6,27:159.9
-37,-5,27:159.9
-37,-4,27:159.9
-37,-3,27:159.9
-37,-2,27:159.9
-37,-1,27:159.9
-37,0,27:159.9
-37,1,27:159.9
-37,2,27:159.9
-37,3,27:159.9
-37,4,27:159.9
-37,5,27:159.9
-37,6,27:159.9
-37,-6,28:159.9
-37,-5,28:159.9
-37,-4,28:159.9
-37,-3,28:159.9
-37,-2,28:159.9
-37,-1,28:159.9
-37,0,28:159.9
-37,1,28:159.9
-37,2,28:159.9
-37,3,28:159.9
-37,4,28:159.9
-37,5,28:159.9
-37,6,28:159.9
-37,-5,29:82
-37,-4,29:82
-37,-3,29:82
-37,-2,29:82
-37,-1,29:82
-37,0,29:82
-37,1,29:82
-37,2,29:82
-37,3,29:82
-37,4,29:82
-37,5,29:82
-37,-6,30:159.9
-37,-5,30:159.9
-37,-4,30:159.9
-37,-3,30:159.9
-37,-2,30:159.9
-37,-1,30:159.9
-37,0,30:159.9
-37,1,30:159.9
-37,2,30:159.9
-37,3,30:159.9
-37,4,30:159.9
-37,5,30:159.9
-37,6,30:159.9
-37,-6,31:159.9
-37,-5,31:159.9
-37,-4,31:159.9
-37,-3,31:159.9
-37,-2,31:159.9
-37,-1,31:159.9
-37,0,31:159.9
-37,1,31:159.9
-37,2,31:159.9
-37,3,31:159.9
-37,4,31:159.9
-37,5,31:159.9
-37,6,31:159.9
-37,-5,32:1
-37,-4,32:1
-37,-3,32:1
-37,3,32:1
-37,4,32:1
-37,5,32:1
-37,-5,33:1
-37,-4,33:1
-37,-3,33:1
-37,3,33:1
-37,4,33:1
-37,5,33:1
-37,-5,34:1
-37,-4,34:1
-37,-3,34:1
-37,3,34:1
-37,4,34:1
-37,5,34:1
-37,-10,35:95.5
-37,-9,35:95.5
-37,-8,35:95.5
-37,-7,35:95.5
-37,-6,35:95.5
-37,-5,35:1
-37,-4,35:1
-37,-3,35:1
-37,3,35:1
-37,4,35:1
-37,5,35:1
-37,6,35:95.5
-37,7,35:95.5
-37,8,35:95.5
-37,9,35:95.5
-37,10,35:95.5
-37,-10,36:95.5
-37,-9,36:95.5
-37,-8,36:95.5
-37,-7,36:95.5
-37,-6,36:95.5
-37,-5,36:1
-37,-4,36:1
-37,-3,36:1
-37,3,36:1
-37,4,36:1
-37,5,36:1
-37,6,36:95.5
-37,7,36:95.5
-37,8,36:95.5
-37,9,36:95.5
-37,10,36:95.5
-37,-12,37:95.5
-37,-11,37:95.5
-37,-5,37:1
-37,-4,37:1
-37,-3,37:1
-37,3,37:1
-37,4,37:1
-37,5,37:1
-37,11,37:95.5
-37,12,37:95.5
-37,-12,38:95.5
-37,-11,38:95.5
-37,-5,38:1
-37,-4,38:1
-37,-3,38:1
-37,3,38:1
-37,4,38:1
-37,5,38:1
-37,11,38:95.5
-37,12,38:95.5
-37,-15,39:95.5
-37,-14,39:95.5
-37,-5,39:1
-37,-4,39:1
-37,-3,39:1
-37,3,39:1
-37,4,39:1
-37,5,39:1
-37,13,39:95.5
-37,-5,40:1
-37,-4,40:1
-37,-3,40:1
-37,3,40:1
-37,4,40:1
-37,5,40:1
-37,15,40:95.5
-37,-16,41:95.5
-37,-5,41:1
-37,-4,41:1
-37,-3,41:1
-37,3,41:1
-37,4,41:1
-37,5,41:1
-37,-5,42:1
-37,-4,42:1
-37,-3,42:1
-37,3,42:1
-37,4,42:1
-37,5,42:1
-37,-5,43:1
-37,-4,43:1
-37,-3,43:1
-37,3,43:1
-37,4,43:1
-37,5,43:1
-37,17,43:95.5
-37,-5,44:1
-37,-4,44:1
-37,-3,44:1
-37,3,44:1
-37,4,44:1
-37,5,44:1
-37,-18,45:95.5
-37,-5,45:1
-37,-4,45:1
-37,-3,45:1
-37,3,45:1
-37,4,45:1
-37,5,45:1
-37,-18,46:95.5
-37,-5,46:1
-37,-4,46:1
-37,-3,46:1
-37,3,46:1
-37,4,46:1
-37,5,46:1
-37,18,46:95.5
-37,-4,47:1
-37,-3,47:1
-37,3,47:1
-37,4,47:1
-37,19,47:95.5
-37,-4,48:1
-37,-3,48:1
-37,3,48:1
-37,4,48:1
-37,19,48:95.5
-37,-20,49:95.5
-37,-4,49:1
-37,-3,49:1
-37,3,49:1
-37,4,49:1
-37,20,49:95.5
-37,-4,50:1
-37,-3,50:1
-37,3,50:1
-37,4,50:1
-37,-21,51:95.5
-37,-4,51:1
-37,-3,51:1
-37,3,51:1
-37,4,51:1
-37,-4,52:1
-37,-3,52:1
-37,3,52:1
-37,4,52:1
-37,-4,53:1
-37,-3,53:1
-37,3,53:1
-37,4,53:1
-37,-4,54:1
-37,-3,54:1
-37,3,54:1
-37,4,54:1
-37,-4,55:1
-37,-3,55:1
-37,3,55:1
-37,4,55:1
-37,-4,56:1
-37,-3,56:1
-37,-2,56:1
-37,-1,56:1
-37,0,56:1
-37,1,56:1
-37,2,56:1
-37,3,56:1
-37,4,56:1
-37,-1,57:159.9
-37,0,57:159.9
-37,1,57:159.9
-37,-7,58:35.1
-37,7,58:35.1
-37,-7,59:85
-37,7,59:85
-37,-7,60:35.1
-37,-6,60:85
-37,6,60:85
-37,7,60:35.1
-37,-6,61:85
-37,-5,61:35.1
-37,-4,61:85
-37,4,61:85
-37,5,61:35.1
-37,6,61:85
-37,-4,62:85
-37,-3,62:85
-37,3,62:85
-37,4,62:85
-37,-3,63:35.1
-37,3,63:35.1
-37,0,69:156.4
-37,0,70:155.2
-37,-2,71:155
-37,-1,71:155
-37,0,71:155
-37,1,71:155
-37,2,71:155
-37,-2,84:125.4
-37,-1,84:125.4
-37,0,84:125.4
-37,1,84:125.4
-37,2,84:125.4
-37,-2,124:42
-37,-1,124:42
-37,0,124:42
-37,1,124:42
-37,2,124:42
-36,0,23:35.7
-36,-1,24:35.7
-36,0,24:35.7
-36,1,24:35.7
-36,0,25:35.7
-36,-7,26:159.9
-36,-6,26:159.9
-36,-5,26:159.9
-36,-4,26:159.9
-36,-3,26:159.9
-36,-2,26:159.9
-36,-1,26:159.9
-36,0,26:159.9
-36,1,26:159.9
-36,2,26:159.9
-36,3,26:159.9
-36,4,26:159.9
-36,5,26:159.9
-36,6,26:159.9
-36,7,26:159.9
-36,-7,27:159.9
-36,-6,27:159.9
-36,-5,27:159.9
-36,-4,27:159.9
-36,-3,27:159.9
-36,-2,27:159.9
-36,-1,27:159.9
-36,0,27:159.9
-36,1,27:159.9
-36,2,27:159.9
-36,3,27:159.9
-36,4,27:159.9
-36,5,27:159.9
-36,6,27:159.9
-36,7,27:159.9
-36,-7,28:159.9
-36,-6,28:159.9
-36,-5,28:159.9
-36,-4,28:159.9
-36,-3,28:159.9
-36,-2,28:159.9
-36,-1,28:159.9
-36,0,28:159.9
-36,1,28:159.9
-36,2,28:159.9
-36,3,28:159.9
-36,4,28:159.9
-36,5,28:159.9
-36,6,28:159.9
-36,7,28:159.9
-36,-6,29:82
-36,-5,29:82
-36,-4,29:82
-36,-3,29:82
-36,-2,29:82
-36,-1,29:82
-36,0,29:82
-36,1,29:82
-36,2,29:82
-36,3,29:82
-36,4,29:82
-36,5,29:82
-36,6,29:82
-36,-7,30:159.9
-36,-6,30:159.9
-36,-5,30:159.9
-36,-4,30:159.9
-36,-3,30:159.9
-36,-2,30:159.9
-36,-1,30:159.9
-36,0,30:159.9
-36,1,30:159.9
-36,2,30:159.9
-36,3,30:159.9
-36,4,30:159.9
-36,5,30:159.9
-36,6,30:159.9
-36,7,30:159.9
-36,-7,31:159.9
-36,-6,31:159.9
-36,-5,31:159.9
-36,-4,31:159.9
-36,-3,31:159.9
-36,-2,31:159.9
-36,-1,31:159.9
-36,0,31:159.9
-36,1,31:159.9
-36,2,31:159.9
-36,3,31:159.9
-36,4,31:159.9
-36,5,31:159.9
-36,6,31:159.9
-36,7,31:159.9
-36,-6,32:1
-36,-5,32:1
-36,5,32:1
-36,6,32:1
-36,-10,33:95.5
-36,-9,33:95.5
-36,-8,33:95.5
-36,-7,33:95.5
-36,-6,33:1
-36,-5,33:1
-36,5,33:1
-36,6,33:1
-36,7,33:95.5
-36,8,33:95.5
-36,9,33:95.5
-36,10,33:95.5
-36,-10,34:95.5
-36,-9,34:95.5
-36,-8,34:95.5
-36,-7,34:95.5
-36,-6,34:1
-36,-5,34:1
-36,5,34:1
-36,6,34:1
-36,7,34:95.5
-36,8,34:95.5
-36,9,34:95.5
-36,10,34:95.5
-36,-12,35:95.5
-36,-11,35:95.5
-36,-6,35:1
-36,-5,35:1
-36,5,35:1
-36,6,35:1
-36,11,35:95.5
-36,12,35:95.5
-36,-12,36:95.5
-36,-11,36:95.5
-36,-6,36:1
-36,-5,36:1
-36,5,36:1
-36,6,36:1
-36,11,36:95.5
-36,12,36:95.5
-36,-15,37:95.5
-36,-14,37:95.5
-36,-13,37:95.5
-36,-6,37:1
-36,-5,37:1
-36,5,37:1
-36,6,37:1
-36,13,37:95.5
-36,14,37:95.5
-36,15,37:95.5
-36,-15,38:95.5
-36,-14,38:95.5
-36,-13,38:95.5
-36,-6,38:1
-36,-5,38:1
-36,5,38:1
-36,6,38:1
-36,13,38:95.5
-36,14,38:95.5
-36,15,38:95.5
-36,-16,39:95.5
-36,-6,39:1
-36,-5,39:1
-36,5,39:1
-36,6,39:1
-36,-16,40:95.5
-36,-6,40:1
-36,-5,40:1
-36,5,40:1
-36,6,40:1
-36,-17,41:95.5
-36,-6,41:1
-36,-5,41:1
-36,5,41:1
-36,6,41:1
-36,-17,42:95.5
-36,-6,42:1
-36,-5,42:1
-36,5,42:1
-36,6,42:1
-36,17,42:95.5
-36,-18,43:95.5
-36,-6,43:1
-36,-5,43:1
-36,5,43:1
-36,6,43:1
-36,18,43:95.5
-36,-6,44:1
-36,-5,44:1
-36,5,44:1
-36,6,44:1
-36,18,44:95.5
-36,-6,45:1
-36,-5,45:1
-36,5,45:1
-36,6,45:1
-36,19,45:95.5
-36,-6,46:1
-36,-5,46:1
-36,5,46:1
-36,6,46:1
-36,19,46:95.5
-36,-20,47:95.5
-36,-5,47:1
-36,5,47:1
-36,20,47:95.5
-36,-5,48:1
-36,5,48:1
-36,20,48:95.5
-36,-19,49:20
-36,-18,49:35.7
-36,-5,49:1
-36,5,49:1
-36,18,49:35.7
-36,19,49:20
-36,-19,50:35.7
-36,-18,50:35.7
-36,-5,50:1
-36,5,50:1
-36,18,50:35.7
-36,19,50:35.7
-36,-20,51:95.5
-36,-19,51:35.7
-36,-18,51:35.7
-36,-5,51:1
-36,5,51:1
-36,18,51:35.7
-36,19,51:35.7
-36,20,51:95.5
-36,-20,52:95.5
-36,-19,52:35.7
-36,-18,52:35.7
-36,-5,52:1
-36,5,52:1
-36,18,52:35.7
-36,19,52:35.7
-36,-19,53:35.7
-36,-5,53:1
-36,5,53:1
-36,19,53:35.7
-36,-19,54:35.7
-36,-5,54:1
-36,5,54:1
-36,19,54:35.7
-36,21,54:95.5
-36,-5,55:1
-36,5,55:1
-36,-5,56:1
-36,-4,56:1
-36,-3,56:1
-36,-2,56:1
-36,-1,56:1
-36,0,56:1
-36,1,56:1
-36,2,56:1
-36,3,56:1
-36,4,56:1
-36,5,56:1
-36,-2,57:159.9
-36,-1,57:1
-36,0,57:1
-36,1,57:1
-36,2,57:159.9
-36,-8,58:35.1
-36,-1,58:1
-36,0,58:1
-36,1,58:1
-36,8,58:35.1
-36,-8,59:85
-36,-1,59:1
-36,0,59:1
-36,1,59:1
-36,8,59:85
-36,-8,60:35.1
-36,-7,60:85
-36,7,60:85
-36,8,60:35.1
-36,-7,61:85
-36,-6,61:35.1
-36,-5,61:85
-36,5,61:85
-36,6,61:35.1
-36,7,61:85
-36,-5,62:85
-36,-4,62:85
-36,4,62:85
-36,5,62:85
-36,-4,63:35.1
-36,4,63:35.1
-36,0,68:156.4
-36,0,69:155.2
-36,0,70:156.1
-36,-3,71:155
-36,3,71:155
-36,-3,84:125.4
-36,-2,84:126.4
-36,-1,84:126.4
-36,0,84:126.4
-36,1,84:126.4
-36,2,84:126.4
-36,3,84:125.4
-36,-2,123:42
-36,-1,123:42
-36,0,123:42
-36,1,123:42
-36,2,123:42
-36,-3,124:42
-36,3,124:42
-36,-2,125:42
-36,-1,125:42
-36,0,125:42
-36,1,125:42
-36,2,125:42
-36,-2,127:95.9
-36,-1,127:95.9
-36,0,127:95.9
-36,1,127:95.9
-36,2,127:95.9
-36,-2,128:95.9
-36,-1,128:95.9
-36,0,128:95.9
-36,1,128:95.9
-36,2,128:95.9
-36,-2,129:95.9
-36,-1,129:95.9
-36,0,129:95.9
-36,1,129:95.9
-36,2,129:95.9
-36,-2,130:95.9
-36,-1,130:95.9
-36,0,130:95.9
-36,1,130:95.9
-36,2,130:95.9
-35,-1,23:35.7
-35,0,23:35.7
-35,1,23:35.7
-35,-1,24:35.7
-35,0,24:35.7
-35,1,24:35.7
-35,-7,26:159.9
-35,-6,26:159.9
-35,-5,26:159.9
-35,-4,26:159.9
-35,-3,26:159.9
-35,-2,26:159.9
-35,-1,26:159.9
-35,0,26:159.9
-35,1,26:159.9
-35,2,26:159.9
-35,3,26:159.9
-35,4,26:159.9
-35,5,26:159.9
-35,6,26:159.9
-35,7,26:159.9
-35,-7,27:159.9
-35,-6,27:159.9
-35,-5,27:159.9
-35,-4,27:159.9
-35,-3,27:159.9
-35,-2,27:159.9
-35,-1,27:159.9
-35,0,27:159.9
-35,1,27:159.9
-35,2,27:159.9
-35,3,27:159.9
-35,4,27:159.9
-35,5,27:159.9
-35,6,27:159.9
-35,7,27:159.9
-35,-7,28:159.9
-35,-6,28:159.9
-35,-5,28:159.9
-35,-4,28:159.9
-35,-3,28:159.9
-35,-2,28:159.9
-35,-1,28:159.9
-35,0,28:159.9
-35,1,28:159.9
-35,2,28:159.9
-35,3,28:159.9
-35,4,28:159.9
-35,5,28:159.9
-35,6,28:159.9
-35,7,28:159.9
-35,-6,29:82
-35,-5,29:82
-35,-4,29:82
-35,-3,29:82
-35,-2,29:82
-35,-1,29:82
-35,0,29:82
-35,1,29:82
-35,2,29:82
-35,3,29:82
-35,4,29:82
-35,5,29:82
-35,6,29:82
-35,-7,30:159.9
-35,-6,30:159.9
-35,-5,30:159.9
-35,-4,30:159.9
-35,-3,30:159.9
-35,-2,30:159.9
-35,-1,30:159.9
-35,0,30:159.9
-35,1,30:159.9
-35,2,30:159.9
-35,3,30:159.9
-35,4,30:159.9
-35,5,30:159.9
-35,6,30:159.9
-35,7,30:159.9
-35,-10,31:95.5
-35,-9,31:95.5
-35,-8,31:95.5
-35,-7,31:159.9
-35,-6,31:159.9
-35,-5,31:159.9
-35,-4,31:159.9
-35,-3,31:159.9
-35,-2,31:159.9
-35,-1,31:159.9
-35,0,31:159.9
-35,1,31:159.9
-35,2,31:159.9
-35,3,31:159.9
-35,4,31:159.9
-35,5,31:159.9
-35,6,31:159.9
-35,7,31:159.9
-35,8,31:95.5
-35,9,31:95.5
-35,10,31:95.5
-35,-10,32:95.5
-35,-9,32:95.5
-35,-8,32:95.5
-35,-7,32:95.5
-35,-6,32:1
-35,-5,32:1
-35,5,32:1
-35,6,32:1
-35,7,32:95.5
-35,8,32:95.5
-35,9,32:95.5
-35,10,32:95.5
-35,-13,33:95.5
-35,-12,33:95.5
-35,-11,33:95.5
-35,-6,33:1
-35,-5,33:1
-35,5,33:1
-35,6,33:1
-35,11,33:95.5
-35,12,33:95.5
-35,13,33:95.5
-35,-13,34:95.5
-35,-12,34:95.5
-35,-11,34:95.5
-35,-6,34:1
-35,-5,34:1
-35,5,34:1
-35,6,34:1
-35,11,34:95.5
-35,12,34:95.5
-35,13,34:95.5
-35,-15,35:95.5
-35,-14,35:95.5
-35,-13,35:95.5
-35,-6,35:1
-35,-5,35:1
-35,5,35:1
-35,6,35:1
-35,13,35:95.5
-35,14,35:95.5
-35,15,35:95.5
-35,-15,36:95.5
-35,-14,36:95.5
-35,-13,36:95.5
-35,-6,36:1
-35,-5,36:1
-35,5,36:1
-35,6,36:1
-35,13,36:95.5
-35,14,36:95.5
-35,15,36:95.5
-35,-16,37:95.5
-35,-6,37:1
-35,-5,37:1
-35,5,37:1
-35,6,37:1
-35,16,37:95.5
-35,-16,38:95.5
-35,-6,38:1
-35,-5,38:1
-35,5,38:1
-35,6,38:1
-35,16,38:95.5
-35,-6,39:1
-35,-5,39:1
-35,5,39:1
-35,6,39:1
-35,-17,40:35.7
-35,-6,40:1
-35,-5,40:1
-35,5,40:1
-35,6,40:1
-35,17,40:35.7
-35,-17,41:35.7
-35,-6,41:1
-35,-5,41:1
-35,5,41:1
-35,6,41:1
-35,17,41:35.7
-35,-17,42:35.7
-35,-6,42:1
-35,-5,42:1
-35,5,42:1
-35,6,42:1
-35,17,42:35.7
-35,-18,43:35.7
-35,-17,43:35.7
-35,-6,43:1
-35,-5,43:1
-35,5,43:1
-35,6,43:1
-35,17,43:35.7
-35,18,43:35.7
-35,-18,44:35.7
-35,-17,44:35.7
-35,-6,44:1
-35,-5,44:1
-35,5,44:1
-35,6,44:1
-35,17,44:35.7
-35,18,44:35.7
-35,-18,45:35.7
-35,-17,45:35.7
-35,-6,45:1
-35,-5,45:1
-35,5,45:1
-35,6,45:1
-35,17,45:35.7
-35,18,45:35.7
-35,-18,46:35.7
-35,-17,46:35.7
-35,-6,46:1
-35,-5,46:1
-35,5,46:1
-35,6,46:1
-35,17,46:35.7
-35,18,46:35.7
-35,-19,47:95.5
-35,-18,47:35.7
-35,-17,47:35.7
-35,-5,47:1
-35,5,47:1
-35,17,47:35.7
-35,18,47:35.7
-35,19,47:95.5
-35,-18,48:35.7
-35,-17,48:35.7
-35,-5,48:1
-35,5,48:1
-35,17,48:35.7
-35,18,48:35.7
-35,19,48:95.5
-35,-19,49:35.7
-35,-18,49:35.7
-35,-5,49:1
-35,5,49:1
-35,18,49:35.7
-35,19,49:35.7
-35,-19,50:35.7
-35,-18,50:35.7
-35,-5,50:1
-35,5,50:1
-35,18,50:35.7
-35,19,50:35.7
-35,-19,51:35.7
-35,-18,51:35.7
-35,-5,51:1
-35,5,51:1
-35,18,51:35.7
-35,19,51:35.7
-35,-20,52:95.5
-35,-19,52:35.7
-35,-18,52:35.7
-35,-5,52:1
-35,5,52:1
-35,18,52:35.7
-35,19,52:35.7
-35,-20,53:95.5
-35,-5,53:1
-35,5,53:1
-35,-5,54:1
-35,5,54:1
-35,-5,55:1
-35,5,55:1
-35,-5,56:1
-35,-4,56:1
-35,-3,56:1
-35,-2,56:1
-35,-1,56:1
-35,0,56:1
-35,1,56:1
-35,2,56:1
-35,3,56:1
-35,4,56:1
-35,5,56:1
-35,-2,57:159.9
-35,-1,57:1
-35,0,57:159.9
-35,1,57:1
-35,2,57:159.9
-35,-9,58:35.1
-35,-1,58:1
-35,0,58:159.9
-35,1,58:1
-35,9,58:35.1
-35,-9,59:85
-35,-1,59:1
-35,0,59:159.9
-35,1,59:1
-35,9,59:85
-35,-9,60:35.1
-35,-8,60:85
-35,0,60:159.9
-35,8,60:85
-35,9,60:35.1
-35,-8,61:85
-35,-7,61:35.1
-35,-6,61:85
-35,6,61:85
-35,7,61:35.1
-35,8,61:85
-35,-6,62:85
-35,-5,62:85
-35,0,62:159.9
-35,5,62:85
-35,6,62:85
-35,-5,63:35.1
-35,0,63:159.9
-35,5,63:35.1
-35,-3,64:1.3
-35,-2,64:1.3
-35,2,64:1.3
-35,3,64:1.3
-35,0,68:155.2
-35,0,69:156.1
-35,-4,71:155
-35,4,71:155
-35,-4,84:125.4
-35,-3,84:126.4
-35,3,84:126.4
-35,4,84:125.4
-35,-1,105:42
-35,0,105:42
-35,1,105:42
-35,-3,123:42
-35,3,123:42
-35,-4,124:42
-35,4,124:42
-35,-3,125:42
-35,3,125:42
-35,-3,127:95.9
-35,-2,127:57
-35,-1,127:57
-35,0,127:57
-35,1,127:57
-35,2,127:57
-35,3,127:95.9
-35,-3,128:95.9
-35,-2,128:57
-35,-1,128:57
-35,0,128:57
-35,1,128:57
-35,2,128:57
-35,3,128:95.9
-35,-3,129:95.9
-35,-2,129:57
-35,-1,129:57
-35,0,129:57
-35,1,129:57
-35,2,129:57
-35,3,129:95.9
-35,-3,130:95.9
-35,-2,130:57
-35,-1,130:57
-35,0,130:57
-35,1,130:57
-35,2,130:57
-35,3,130:95.9
-34,0,22:35.7
-34,-1,23:35.7
-34,0,23:35.7
-34,1,23:35.7
-34,-5,24:159.9
-34,-4,24:159.9
-34,-3,24:159.9
-34,-2,24:159.9
-34,-1,24:159.9
-34,0,24:159.9
-34,1,24:159.9
-34,2,24:159.9
-34,3,24:159.9
-34,4,24:159.9
-34,5,24:159.9
-34,-5,25:159.9
-34,-4,25:159.9
-34,-3,25:159.9
-34,-2,25:159.9
-34,-1,25:159.9
-34,0,25:159.9
-34,1,25:159.9
-34,2,25:159.9
-34,3,25:159.9
-34,4,25:159.9
-34,5,25:159.9
-34,-8,26:159.9
-34,-7,26:159.9
-34,-6,26:159.9
-34,-5,26:159.9
-34,-4,26:159.9
-34,-3,26:159.9
-34,-2,26:159.9
-34,-1,26:159.9
-34,0,26:159.9
-34,1,26:159.9
-34,2,26:159.9
-34,3,26:159.9
-34,4,26:159.9
-34,5,26:159.9
-34,6,26:159.9
-34,7,26:159.9
-34,8,26:159.9
-34,-8,27:159.9
-34,-7,27:159.9
-34,-6,27:159.9
-34,-5,27:159.9
-34,-4,27:159.9
-34,-3,27:159.9
-34,-2,27:159.9
-34,-1,27:159.9
-34,0,27:159.9
-34,1,27:159.9
-34,2,27:159.9
-34,3,27:159.9
-34,4,27:159.9
-34,5,27:159.9
-34,6,27:159.9
-34,7,27:159.9
-34,8,27:159.9
-34,-8,28:159.9
-34,-7,28:159.9
-34,-6,28:159.9
-34,-5,28:159.9
-34,-4,28:159.9
-34,-3,28:159.9
-34,-2,28:159.9
-34,-1,28:159.9
-34,0,28:159.9
-34,1,28:159.9
-34,2,28:159.9
-34,3,28:159.9
-34,4,28:159.9
-34,5,28:159.9
-34,6,28:159.9
-34,7,28:159.9
-34,8,28:159.9
-34,-10,29:95.5
-34,-9,29:95.5
-34,-7,29:82
-34,-6,29:82
-34,-5,29:82
-34,-4,29:82
-34,-3,29:82
-34,-2,29:82
-34,-1,29:82
-34,0,29:82
-34,1,29:82
-34,2,29:82
-34,3,29:82
-34,4,29:82
-34,5,29:82
-34,6,29:82
-34,7,29:82
-34,9,29:95.5
-34,10,29:95.5
-34,-10,30:95.5
-34,-9,30:95.5
-34,-8,30:159.9
-34,-7,30:159.9
-34,-6,30:159.9
-34,-5,30:159.9
-34,-4,30:159.9
-34,-3,30:159.9
-34,-2,30:159.9
-34,-1,30:159.9
-34,0,30:159.9
-34,1,30:159.9
-34,2,30:159.9
-34,3,30:159.9
-34,4,30:159.9
-34,5,30:159.9
-34,6,30:159.9
-34,7,30:159.9
-34,8,30:159.9
-34,9,30:95.5
-34,10,30:95.5
-34,-15,31:35.7
-34,-12,31:95.5
-34,-11,31:95.5
-34,-8,31:159.9
-34,-7,31:159.9
-34,-6,31:159.9
-34,-5,31:159.9
-34,-4,31:159.9
-34,-3,31:159.9
-34,-2,31:159.9
-34,-1,31:159.9
-34,0,31:159.9
-34,1,31:159.9
-34,2,31:159.9
-34,3,31:159.9
-34,4,31:159.9
-34,5,31:159.9
-34,6,31:159.9
-34,7,31:159.9
-34,8,31:159.9
-34,11,31:95.5
-34,12,31:95.5
-34,15,31:35.7
-34,-15,32:35.7
-34,-12,32:95.5
-34,-11,32:95.5
-34,-7,32:1
-34,-6,32:1
-34,6,32:1
-34,7,32:1
-34,11,32:95.5
-34,12,32:95.5
-34,15,32:35.7
-34,-15,33:35.7
-34,-14,33:95.5
-34,-13,33:95.5
-34,-7,33:1
-34,-6,33:1
-34,6,33:1
-34,7,33:1
-34,13,33:95.5
-34,14,33:95.5
-34,15,33:35.7
-34,-16,34:35.7
-34,-15,34:35.7
-34,-14,34:95.5
-34,-13,34:95.5
-34,-7,34:1
-34,-6,34:1
-34,6,34:1
-34,7,34:1
-34,13,34:95.5
-34,14,34:95.5
-34,15,34:35.7
-34,16,34:35.7
-34,-16,35:35.7
-34,-7,35:1
-34,-6,35:1
-34,6,35:1
-34,7,35:1
-34,16,35:35.7
-34,-17,36:35.7
-34,-16,36:35.7
-34,-15,36:35.7
-34,-7,36:1
-34,-6,36:1
-34,6,36:1
-34,7,36:1
-34,15,36:35.7
-34,16,36:35.7
-34,17,36:35.7
-34,-17,37:35.7
-34,-16,37:35.7
-34,-15,37:35.7
-34,-7,37:1
-34,-6,37:1
-34,6,37:1
-34,7,37:1
-34,15,37:35.7
-34,16,37:35.7
-34,17,37:35.7
-34,-17,38:35.7
-34,-16,38:35.7
-34,-15,38:35.7
-34,-7,38:1
-34,-6,38:1
-34,6,38:1
-34,7,38:1
-34,15,38:35.7
-34,16,38:35.7
-34,17,38:35.7
-34,-17,39:35.7
-34,-16,39:35.7
-34,-7,39:1
-34,-6,39:1
-34,6,39:1
-34,7,39:1
-34,16,39:35.7
-34,17,39:35.7
-34,-18,40:35.7
-34,-17,40:35.7
-34,-16,40:35.7
-34,-15,40:35.7
-34,-7,40:1
-34,-6,40:1
-34,6,40:1
-34,7,40:1
-34,15,40:35.7
-34,16,40:35.7
-34,17,40:35.7
-34,18,40:35.7
-34,-18,41:35.7
-34,-17,41:35.7
-34,-16,41:35.7
-34,-7,41:1
-34,-6,41:1
-34,6,41:1
-34,7,41:1
-34,16,41:35.7
-34,17,41:35.7
-34,18,41:35.7
-34,-18,42:35.7
-34,-17,42:35.7
-34,-16,42:35.7
-34,-7,42:1
-34,-6,42:1
-34,6,42:1
-34,7,42:1
-34,16,42:35.7
-34,17,42:35.7
-34,18,42:35.7
-34,-18,43:35.7
-34,-17,43:35.7
-34,-16,43:35.7
-34,-7,43:1
-34,-6,43:1
-34,6,43:1
-34,7,43:1
-34,16,43:35.7
-34,17,43:35.7
-34,18,43:35.7
-34,-18,44:35.7
-34,-17,44:35.7
-34,-16,44:35.7
-34,-7,44:1
-34,-6,44:1
-34,6,44:1
-34,7,44:1
-34,16,44:35.7
-34,17,44:35.7
-34,18,44:35.7
-34,-18,45:35.7
-34,-17,45:35.7
-34,-7,45:1
-34,-6,45:1
-34,6,45:1
-34,7,45:1
-34,17,45:35.7
-34,18,45:35.7
-34,-18,46:35.7
-34,-17,46:35.7
-34,-7,46:1
-34,-6,46:1
-34,6,46:1
-34,7,46:1
-34,17,46:35.7
-34,18,46:35.7
-34,-18,47:35.7
-34,-17,47:35.7
-34,-6,47:1
-34,6,47:1
-34,17,47:35.7
-34,18,47:35.7
-34,-18,48:35.7
-34,-6,48:1
-34,6,48:1
-34,18,48:35.7
-34,19,48:95.5
-34,-19,49:95.5
-34,-6,49:1
-34,6,49:1
-34,-6,50:1
-34,6,50:1
-34,-6,51:1
-34,6,51:1
-34,-6,52:1
-34,6,52:1
-34,-6,53:1
-34,6,53:1
-34,-6,54:1
-34,6,54:1
-34,-6,55:1
-34,6,55:1
-34,-6,56:1
-34,-5,56:1
-34,-4,56:1
-34,-3,56:1
-34,-2,56:1
-34,-1,56:1
-34,0,56:1
-34,1,56:1
-34,2,56:1
-34,3,56:1
-34,4,56:1
-34,5,56:1
-34,6,56:1
-34,-4,57:159.9
-34,-3,57:159.9
-34,-2,57:159.9
-34,-1,57:1
-34,0,57:159.9
-34,1,57:1
-34,2,57:159.9
-34,3,57:159.9
-34,4,57:159.9
-34,-2,58:1
-34,-1,58:1
-34,0,58:159.9
-34,1,58:1
-34,2,58:1
-34,-2,59:1
-34,-1,59:1
-34,0,59:159.9
-34,1,59:1
-34,2,59:1
-34,-1,60:159.9
-34,0,60:159.9
-34,1,60:159.9
-34,0,61:7
-34,-1,62:159.9
-34,0,62:159.9
-34,1,62:159.9
-34,-2,63:1.3
-34,-1,63:159.9
-34,0,63:159.9
-34,1,63:159.9
-34,2,63:1.3
-34,-3,64:1.3
-34,-2,64:1.3
-34,2,64:1.3
-34,3,64:1.3
-34,0,68:155.3
-34,-5,71:155
-34,5,71:155
-34,0,81:19
-34,-1,82:19
-34,0,82:19
-34,1,82:19
-34,0,83:19
-34,-5,84:125.4
-34,-4,84:126.4
-34,4,84:126.4
-34,5,84:125.4
-34,0,102:42
-34,0,103:42
-34,-1,104:42
-34,0,104:42
-34,1,104:42
-34,-2,105:42
-34,-1,105:42
-34,1,105:42
-34,2,105:42
-34,-4,123:42
-34,4,123:42
-34,-5,124:42
-34,5,124:42
-34,-4,125:42
-34,4,125:42
-34,-4,127:95.9
-34,-3,127:57
-34,-2,127:57
-34,2,127:57
-34,3,127:57
-34,4,127:95.9
-34,-4,128:95.9
-34,-3,128:57
-34,-2,128:57
-34,2,128:57
-34,3,128:57
-34,4,128:95.9
-34,-4,129:95.9
-34,-3,129:57
-34,-2,129:57
-34,2,129:57
-34,3,129:57
-34,4,129:95.9
-34,-4,130:95.9
-34,-3,130:57
-34,-2,130:57
-34,2,130:57
-34,3,130:57
-34,4,130:95.9
-34,0,134:159.1
-34,-1,135:159.1
-34,0,135:159.1
-34,1,135:159.1
-34,0,136:159.1
-33,-1,22:35.7
-33,0,22:35.7
-33,1,22:35.7
-33,-1,23:35.7
-33,0,23:35.7
-33,1,23:35.7
-33,-10,24:159.9
-33,-9,24:159.9
-33,-8,24:159.9
-33,-7,24:159.9
-33,-6,24:159.9
-33,-5,24:159.9
-33,-4,24:159.9
-33,-3,24:159.9
-33,-2,24:159.9
-33,-1,24:159.9
-33,0,24:159.9
-33,1,24:159.9
-33,2,24:159.9
-33,3,24:159.9
-33,4,24:159.9
-33,5,24:159.9
-33,6,24:159.9
-33,7,24:159.9
-33,8,24:159.9
-33,9,24:159.9
-33,10,24:159.9
-33,-10,25:159.9
-33,-9,25:159.9
-33,-8,25:159.9
-33,-7,25:159.9
-33,-6,25:159.9
-33,-5,25:159.9
-33,-4,25:159.9
-33,-3,25:159.9
-33,-2,25:159.9
-33,-1,25:159.9
-33,0,25:159.9
-33,1,25:159.9
-33,2,25:159.9
-33,3,25:159.9
-33,4,25:159.9
-33,5,25:159.9
-33,6,25:159.9
-33,7,25:159.9
-33,8,25:159.9
-33,9,25:159.9
-33,10,25:159.9
-33,-14,26:35.7
-33,-10,26:95.5
-33,-9,26:95.5
-33,-8,26:159.9
-33,-7,26:159.9
-33,-6,26:159.9
-33,-5,26:159.9
-33,-4,26:159.9
-33,-3,26:159.9
-33,-2,26:159.9
-33,-1,26:159.9
-33,0,26:159.9
-33,1,26:159.9
-33,2,26:159.9
-33,3,26:159.9
-33,4,26:159.9
-33,5,26:159.9
-33,6,26:159.9
-33,7,26:159.9
-33,8,26:159.9
-33,9,26:95.5
-33,10,26:95.5
-33,14,26:35.7
-33,-14,27:35.7
-33,-10,27:95.5
-33,-9,27:95.5
-33,-8,27:159.9
-33,-7,27:159.9
-33,-6,27:159.9
-33,-5,27:159.9
-33,-4,27:159.9
-33,-3,27:159.9
-33,-2,27:159.9
-33,-1,27:159.9
-33,0,27:159.9
-33,1,27:159.9
-33,2,27:159.9
-33,3,27:159.9
-33,4,27:159.9
-33,5,27:159.9
-33,6,27:159.9
-33,7,27:159.9
-33,8,27:159.9
-33,9,27:95.5
-33,10,27:95.5
-33,14,27:35.7
-33,-14,28:35.7
-33,-10,28:95.5
-33,-9,28:95.5
-33,-8,28:159.9
-33,-7,28:159.9
-33,-6,28:159.9
-33,-5,28:159.9
-33,-4,28:159.9
-33,-3,28:159.9
-33,-2,28:159.9
-33,-1,28:159.9
-33,0,28:159.9
-33,1,28:159.9
-33,2,28:159.9
-33,3,28:159.9
-33,4,28:159.9
-33,5,28:159.9
-33,6,28:159.9
-33,7,28:159.9
-33,8,28:159.9
-33,9,28:95.5
-33,10,28:95.5
-33,14,28:35.7
-33,-16,29:35.7
-33,-15,29:35.7
-33,-14,29:35.7
-33,-12,29:95.5
-33,-11,29:95.5
-33,-7,29:82
-33,-6,29:82
-33,-5,29:82
-33,-4,29:82
-33,-3,29:82
-33,-2,29:82
-33,-1,29:82
-33,0,29:82
-33,1,29:82
-33,2,29:82
-33,3,29:82
-33,4,29:82
-33,5,29:82
-33,6,29:82
-33,7,29:82
-33,11,29:95.5
-33,12,29:95.5
-33,14,29:35.7
-33,15,29:35.7
-33,16,29:35.7
-33,-16,30:35.7
-33,-15,30:35.7
-33,-14,30:35.7
-33,-12,30:95.5
-33,-11,30:95.5
-33,-8,30:159.9
-33,-7,30:159.9
-33,-6,30:159.9
-33,-5,30:159.9
-33,-4,30:159.9
-33,-3,30:159.9
-33,-2,30:159.9
-33,-1,30:159.9
-33,0,30:159.9
-33,1,30:159.9
-33,2,30:159.9
-33,3,30:159.9
-33,4,30:159.9
-33,5,30:159.9
-33,6,30:159.9
-33,7,30:159.9
-33,8,30:159.9
-33,11,30:95.5
-33,12,30:95.5
-33,14,30:35.7
-33,15,30:35.7
-33,16,30:35.7
-33,-16,31:35.7
-33,-15,31:35.7
-33,-14,31:35.7
-33,-13,31:95.5
-33,-8,31:159.9
-33,-7,31:159.9
-33,-6,31:159.9
-33,-5,31:159.9
-33,-4,31:159.9
-33,-3,31:159.9
-33,-2,31:159.9
-33,-1,31:159.9
-33,0,31:159.9
-33,1,31:159.9
-33,2,31:159.9
-33,3,31:159.9
-33,4,31:159.9
-33,5,31:159.9
-33,6,31:159.9
-33,7,31:159.9
-33,8,31:159.9
-33,13,31:95.5
-33,14,31:35.7
-33,15,31:35.7
-33,16,31:35.7
-33,-16,32:35.7
-33,-14,32:35.7
-33,-13,32:95.5
-33,-7,32:1
-33,-6,32:1
-33,6,32:1
-33,7,32:1
-33,13,32:95.5
-33,14,32:35.7
-33,16,32:35.7
-33,-16,33:35.7
-33,-15,33:35.7
-33,-14,33:35.7
-33,-7,33:1
-33,-6,33:1
-33,6,33:1
-33,7,33:1
-33,14,33:35.7
-33,15,33:35.7
-33,16,33:35.7
-33,-17,34:35.7
-33,-16,34:35.7
-33,-15,34:35.7
-33,-14,34:35.7
-33,-7,34:1
-33,-6,34:1
-33,6,34:1
-33,7,34:1
-33,14,34:35.7
-33,15,34:35.7
-33,16,34:35.7
-33,17,34:35.7
-33,-17,35:35.7
-33,-16,35:35.7
-33,-15,35:35.7
-33,-14,35:35.7
-33,-7,35:1
-33,-6,35:1
-33,6,35:1
-33,7,35:1
-33,14,35:35.7
-33,15,35:35.7
-33,16,35:35.7
-33,17,35:35.7
-33,-17,36:35.7
-33,-16,36:35.7
-33,-15,36:35.7
-33,-14,36:35.7
-33,-7,36:1
-33,-6,36:1
-33,6,36:1
-33,7,36:1
-33,14,36:35.7
-33,15,36:35.7
-33,16,36:35.7
-33,17,36:35.7
-33,-17,37:35.7
-33,-15,37:35.7
-33,-7,37:1
-33,-6,37:1
-33,6,37:1
-33,7,37:1
-33,15,37:35.7
-33,17,37:35.7
-33,-17,38:35.7
-33,-16,38:35.7
-33,-15,38:35.7
-33,-7,38:1
-33,-6,38:1
-33,6,38:1
-33,7,38:1
-33,15,38:35.7
-33,16,38:35.7
-33,17,38:35.7
-33,-17,39:35.7
-33,-16,39:35.7
-33,-15,39:35.7
-33,-7,39:1
-33,-6,39:1
-33,6,39:1
-33,7,39:1
-33,15,39:35.7
-33,16,39:35.7
-33,17,39:35.7
-33,-17,40:35.7
-33,-16,40:35.7
-33,-15,40:35.7
-33,-7,40:1
-33,-6,40:1
-33,6,40:1
-33,7,40:1
-33,15,40:35.7
-33,16,40:35.7
-33,17,40:35.7
-33,-17,41:35.7
-33,-16,41:35.7
-33,-7,41:1
-33,-6,41:1
-33,6,41:1
-33,7,41:1
-33,16,41:35.7
-33,17,41:35.7
-33,-17,42:35.7
-33,-16,42:35.7
-33,-7,42:1
-33,-6,42:1
-33,6,42:1
-33,7,42:1
-33,16,42:35.7
-33,17,42:35.7
-33,-18,43:95.5
-33,-17,43:35.7
-33,-7,43:1
-33,-6,43:1
-33,6,43:1
-33,7,43:1
-33,17,43:35.7
-33,18,43:95.5
-33,-18,44:95.5
-33,-17,44:35.7
-33,-7,44:1
-33,-6,44:1
-33,6,44:1
-33,7,44:1
-33,17,44:35.7
-33,18,44:95.5
-33,-18,45:95.5
-33,-7,45:1
-33,-6,45:1
-33,6,45:1
-33,7,45:1
-33,18,45:95.5
-33,-7,46:1
-33,-6,46:1
-33,6,46:1
-33,7,46:1
-33,-19,47:95.5
-33,-6,47:1
-33,6,47:1
-33,19,47:95.5
-33,-6,48:1
-33,6,48:1
-33,-20,49:95.5
-33,-6,49:1
-33,6,49:1
-33,20,49:95.5
-33,-21,50:95.5
-33,-6,50:1
-33,6,50:1
-33,-6,51:1
-33,6,51:1
-33,-22,52:95.5
-33,-6,52:1
-33,6,52:1
-33,-22,53:95.5
-33,-6,53:1
-33,6,53:1
-33,-22,54:95.5
-33,-6,54:1
-33,6,54:1
-33,-6,55:1
-33,6,55:1
-33,-6,56:1
-33,-5,56:1
-33,-4,56:1
-33,-3,56:1
-33,-2,56:1
-33,-1,56:1
-33,0,56:1
-33,1,56:1
-33,2,56:1
-33,3,56:1
-33,4,56:1
-33,5,56:1
-33,6,56:1
-33,-5,57:159.9
-33,-4,57:1
-33,-3,57:1
-33,-2,57:1
-33,-1,57:159.9
-33,1,57:159.9
-33,2,57:1
-33,3,57:1
-33,4,57:1
-33,5,57:159.9
-33,-4,58:1
-33,-3,58:1
-33,-2,58:1
-33,-1,58:159.9
-33,1,58:159.9
-33,2,58:1
-33,3,58:1
-33,4,58:1
-33,-4,59:1
-33,-3,59:1
-33,-2,59:1
-33,-1,59:159.9
-33,1,59:159.9
-33,2,59:1
-33,3,59:1
-33,4,59:1
-33,-2,60:159.9
-33,-1,60:159.9
-33,1,60:159.9
-33,2,60:159.9
-33,-1,61:7
-33,1,61:7
-33,-2,62:159.9
-33,-1,62:159.9
-33,1,62:159.9
-33,2,62:159.9
-33,-2,63:159.9
-33,-1,63:159.9
-33,0,63:1
-33,1,63:159.9
-33,2,63:159.9
-33,-1,64:1
-33,0,64:1
-33,1,64:1
-33,-1,65:1
-33,0,65:1
-33,1,65:1
-33,0,66:156
-33,0,67:156.4
-33,0,68:156
-33,0,69:1
-33,0,70:1
-33,-5,71:155
-33,0,71:1
-33,5,71:155
-33,0,72:1
-33,0,73:1
-33,0,74:1
-33,0,75:1
-33,0,76:1
-33,0,77:1
-33,0,78:1
-33,-1,79:1
-33,0,79:1
-33,1,79:1
-33,0,80:1
-33,-1,81:19
-33,0,81:19
-33,1,81:19
-33,-2,82:19
-33,-1,82:19
-33,0,82:19
-33,1,82:19
-33,2,82:19
-33,-1,83:19
-33,0,83:19
-33,1,83:19
-33,-5,84:125.4
-33,-4,84:126.4
-33,-1,84:98
-33,0,84:98
-33,1,84:98
-33,4,84:126.4
-33,5,84:125.4
-33,-1,85:98
-33,0,85:98
-33,1,85:98
-33,-1,86:98
-33,0,86:98
-33,1,86:98
-33,-1,87:98
-33,0,87:98
-33,1,87:98
-33,-1,88:98
-33,0,88:98
-33,1,88:98
-33,-1,89:98
-33,0,89:98
-33,1,89:98
-33,-1,90:98
-33,0,90:98
-33,1,90:98
-33,-1,91:98
-33,0,91:98
-33,1,91:98
-33,-1,92:98
-33,0,92:98
-33,1,92:98
-33,-1,93:98
-33,0,93:98
-33,1,93:98
-33,-1,94:98
-33,0,94:98
-33,1,94:98
-33,-1,95:98
-33,0,95:98
-33,1,95:98
-33,-1,96:98
-33,0,96:98
-33,1,96:98
-33,-1,97:98
-33,0,97:98
-33,1,97:98
-33,-1,98:98
-33,0,98:98
-33,1,98:98
-33,-1,99:98
-33,0,99:98
-33,1,99:98
-33,-1,100:98
-33,0,100:98
-33,1,100:98
-33,-1,101:98
-33,0,101:98
-33,1,101:98
-33,-1,102:98
-33,0,102:98
-33,1,102:98
-33,-1,103:98
-33,0,103:98
-33,1,103:98
-33,-2,104:42
-33,-1,104:98
-33,0,104:98
-33,1,104:98
-33,2,104:42
-33,-3,105:42
-33,-2,105:42
-33,-1,105:98
-33,0,105:98
-33,1,105:98
-33,2,105:42
-33,3,105:42
-33,-1,106:98
-33,0,106:98
-33,1,106:98
-33,0,107:98
-33,0,108:98
-33,0,109:98
-33,0,110:98
-33,0,111:98
-33,0,112:98
-33,0,113:98
-33,0,114:98
-33,0,115:98
-33,0,116:98
-33,0,117:98
-33,0,118:98
-33,0,119:98
-33,0,120:98
-33,0,121:98
-33,0,122:98
-33,-4,123:42
-33,0,123:98
-33,4,123:42
-33,-5,124:42
-33,0,124:98
-33,5,124:42
-33,-4,125:42
-33,0,125:98
-33,4,125:42
-33,0,126:98
-33,-4,127:95.9
-33,-3,127:57
-33,0,127:98
-33,3,127:57
-33,4,127:95.9
-33,-4,128:95.9
-33,-3,128:57
-33,0,128:98
-33,3,128:57
-33,4,128:95.9
-33,-4,129:95.9
-33,-3,129:57
-33,0,129:98
-33,3,129:57
-33,4,129:95.9
-33,-4,130:95.9
-33,-3,130:57
-33,0,130:98
-33,3,130:57
-33,4,130:95.9
-33,0,131:98
-33,0,132:98
-33,0,133:98
-33,-1,134:159.1
-33,0,134:159.1
-33,1,134:159.1
-33,-2,135:159.1
-33,2,135:159.1
-33,-1,136:159.1
-33,0,136:159.1
-33,1,136:159.1
-32,0,21:35.7
-32,-1,22:35.7
-32,0,22:35.7
-32,1,22:35.7
-32,-13,24:159.9
-32,-12,24:159.9
-32,-11,24:159.9
-32,-10,24:159.9
-32,-9,24:159.9
-32,-8,24:159.9
-32,-7,24:159.9
-32,-6,24:159.9
-32,-5,24:159.9
-32,-4,24:159.9
-32,-3,24:159.9
-32,-2,24:159.9
-32,-1,24:159.9
-32,0,24:159.9
-32,1,24:159.9
-32,2,24:159.9
-32,3,24:159.9
-32,4,24:159.9
-32,5,24:159.9
-32,6,24:159.9
-32,7,24:159.9
-32,8,24:159.9
-32,9,24:159.9
-32,10,24:159.9
-32,11,24:159.9
-32,12,24:159.9
-32,13,24:159.9
-32,-13,25:159.9
-32,-12,25:159.9
-32,-11,25:159.9
-32,-10,25:159.9
-32,-9,25:159.9
-32,-8,25:159.9
-32,-7,25:159.9
-32,-6,25:159.9
-32,-5,25:159.9
-32,-4,25:159.9
-32,-3,25:159.9
-32,-2,25:159.9
-32,-1,25:159.9
-32,0,25:159.9
-32,1,25:159.9
-32,2,25:159.9
-32,3,25:159.9
-32,4,25:159.9
-32,5,25:159.9
-32,6,25:159.9
-32,7,25:159.9
-32,8,25:159.9
-32,9,25:159.9
-32,10,25:159.9
-32,11,25:159.9
-32,12,25:159.9
-32,13,25:159.9
-32,-15,26:35.7
-32,-14,26:35.7
-32,-13,26:35.7
-32,-12,26:95.5
-32,-11,26:95.5
-32,-8,26:159.9
-32,-7,26:159.9
-32,-6,26:159.9
-32,-5,26:159.9
-32,-4,26:159.9
-32,-3,26:159.9
-32,-2,26:159.9
-32,-1,26:159.9
-32,0,26:159.9
-32,1,26:159.9
-32,2,26:159.9
-32,3,26:159.9
-32,4,26:159.9
-32,5,26:159.9
-32,6,26:159.9
-32,7,26:159.9
-32,8,26:159.9
-32,11,26:95.5
-32,12,26:95.5
-32,13,26:35.7
-32,14,26:35.7
-32,15,26:35.7
-32,-15,27:35.7
-32,-13,27:35.7
-32,-12,27:95.5
-32,-11,27:95.5
-32,-8,27:159.9
-32,-7,27:159.9
-32,-6,27:159.9
-32,-5,27:159.9
-32,-4,27:159.9
-32,-3,27:159.9
-32,-2,27:159.9
-32,-1,27:159.9
-32,0,27:159.9
-32,1,27:159.9
-32,2,27:159.9
-32,3,27:159.9
-32,4,27:159.9
-32,5,27:159.9
-32,6,27:159.9
-32,7,27:159.9
-32,8,27:159.9
-32,11,27:95.5
-32,12,27:95.5
-32,13,27:35.7
-32,15,27:35.7
-32,-15,28:35.7
-32,-14,28:35.7
-32,-13,28:35.7
-32,-12,28:95.5
-32,-11,28:95.5
-32,-8,28:159.9
-32,-7,28:159.9
-32,-6,28:159.9
-32,-5,28:159.9
-32,-4,28:159.9
-32,-3,28:159.9
-32,-2,28:159.9
-32,-1,28:159.9
-32,0,28:159.9
-32,1,28:159.9
-32,2,28:159.9
-32,3,28:159.9
-32,4,28:159.9
-32,5,28:159.9
-32,6,28:159.9
-32,7,28:159.9
-32,8,28:159.9
-32,11,28:95.5
-32,12,28:95.5
-32,13,28:35.7
-32,14,28:35.7
-32,15,28:35.7
-32,-16,29:35.7
-32,-15,29:35.7
-32,-14,29:35.7
-32,-13,29:35.7
-32,-7,29:82
-32,-6,29:82
-32,-5,29:82
-32,-4,29:82
-32,-3,29:82
-32,-2,29:82
-32,-1,29:82
-32,0,29:82
-32,1,29:82
-32,2,29:82
-32,3,29:82
-32,4,29:82
-32,5,29:82
-32,6,29:82
-32,7,29:82
-32,13,29:35.7
-32,14,29:35.7
-32,15,29:35.7
-32,16,29:35.7
-32,-16,30:35.7
-32,-13,30:35.7
-32,-8,30:159.9
-32,-7,30:159.9
-32,-6,30:159.9
-32,-5,30:159.9
-32,-4,30:159.9
-32,-3,30:159.9
-32,-2,30:159.9
-32,-1,30:159.9
-32,0,30:159.9
-32,1,30:159.9
-32,2,30:159.9
-32,3,30:159.9
-32,4,30:159.9
-32,5,30:159.9
-32,6,30:159.9
-32,7,30:159.9
-32,8,30:159.9
-32,13,30:35.7
-32,16,30:35.7
-32,-17,31:35.7
-32,-16,31:35.7
-32,-13,31:35.7
-32,-8,31:159.9
-32,-7,31:159.9
-32,-6,31:159.9
-32,-5,31:159.9
-32,-4,31:159.9
-32,-3,31:159.9
-32,-2,31:159.9
-32,-1,31:159.9
-32,0,31:159.9
-32,1,31:159.9
-32,2,31:159.9
-32,3,31:159.9
-32,4,31:159.9
-32,5,31:159.9
-32,6,31:159.9
-32,7,31:159.9
-32,8,31:159.9
-32,13,31:35.7
-32,16,31:35.7
-32,17,31:35.7
-32,-17,32:35.7
-32,-14,32:35.7
-32,-13,32:35.7
-32,-7,32:1
-32,-6,32:1
-32,6,32:1
-32,7,32:1
-32,13,32:35.7
-32,14,32:35.7
-32,17,32:35.7
-32,-17,33:35.7
-32,-16,33:35.7
-32,-15,33:35.7
-32,-14,33:35.7
-32,-6,33:95.14
-32,6,33:95.14
-32,14,33:35.7
-32,15,33:35.7
-32,16,33:35.7
-32,17,33:35.7
-32,-17,34:35.7
-32,-16,34:35.7
-32,-15,34:35.7
-32,-14,34:35.7
-32,-6,34:95.14
-32,6,34:95.14
-32,14,34:35.7
-32,15,34:35.7
-32,16,34:35.7
-32,17,34:35.7
-32,-16,35:35.7
-32,-15,35:35.7
-32,-6,35:95.14
-32,6,35:95.14
-32,15,35:35.7
-32,16,35:35.7
-32,-17,36:35.7
-32,-16,36:35.7
-32,-15,36:35.7
-32,-6,36:95.14
-32,6,36:95.14
-32,15,36:35.7
-32,16,36:35.7
-32,17,36:35.7
-32,-17,37:35.7
-32,-16,37:35.7
-32,-15,37:35.7
-32,-6,37:95.14
-32,6,37:95.14
-32,15,37:35.7
-32,16,37:35.7
-32,17,37:35.7
-32,-17,38:95.5
-32,-16,38:35.7
-32,-15,38:35.7
-32,-6,38:95.14
-32,6,38:95.14
-32,15,38:35.7
-32,16,38:35.7
-32,17,38:95.5
-32,-17,39:95.5
-32,-16,39:35.7
-32,-6,39:95.14
-32,-1,39:156.6
-32,0,39:42
-32,1,39:156.7
-32,6,39:95.14
-32,16,39:35.7
-32,17,39:95.5
-32,-18,40:95.5
-32,-17,40:35.7
-32,-16,40:35.7
-32,-7,40:95.14
-32,-6,40:95.14
-32,-1,40:42
-32,1,40:42
-32,6,40:95.14
-32,7,40:95.14
-32,16,40:35.7
-32,17,40:35.7
-32,18,40:95.5
-32,-18,41:95.5
-32,-7,41:95.14
-32,-6,41:95.14
-32,-1,41:42
-32,1,41:42
-32,6,41:95.14
-32,7,41:95.14
-32,-18,42:95.5
-32,-7,42:95.14
-32,-6,42:95.14
-32,-1,42:42
-32,1,42:42
-32,6,42:95.14
-32,7,42:95.14
-32,-7,43:95.14
-32,-6,43:95.14
-32,-1,43:42
-32,1,43:42
-32,6,43:95.14
-32,7,43:95.14
-32,-7,44:95.14
-32,-6,44:95.14
-32,-1,44:156.2
-32,0,44:42
-32,1,44:156.3
-32,6,44:95.14
-32,7,44:95.14
-32,-7,45:95.14
-32,-6,45:95.14
-32,6,45:95.14
-32,7,45:95.14
-32,-7,46:95.14
-32,-6,46:95.14
-32,6,46:95.14
-32,7,46:95.14
-32,20,46:95.5
-32,-6,47:1
-32,6,47:1
-32,-6,48:1
-32,6,48:1
-32,-21,49:95.5
-32,-6,49:1
-32,6,49:1
-32,21,49:95.5
-32,-22,50:95.5
-32,-6,50:1
-32,6,50:1
-32,22,50:95.5
-32,-6,51:1
-32,6,51:1
-32,-6,52:1
-32,6,52:1
-32,-6,53:1
-32,6,53:1
-32,-6,54:1
-32,6,54:1
-32,-6,55:1
-32,6,55:1
-32,-6,56:1
-32,-5,56:1
-32,-4,56:1
-32,-3,56:1
-32,-2,56:1
-32,-1,56:1
-32,0,56:95.5
-32,1,56:1
-32,2,56:1
-32,3,56:1
-32,4,56:1
-32,5,56:1
-32,6,56:1
-32,-5,57:159.9
-32,-4,57:1
-32,-3,57:159.9
-32,-2,57:159.9
-32,2,57:159.9
-32,3,57:159.9
-32,4,57:1
-32,5,57:159.9
-32,-4,58:1
-32,-3,58:159.9
-32,-2,58:159.9
-32,2,58:159.9
-32,3,58:159.9
-32,4,58:1
-32,-4,59:1
-32,-3,59:159.9
-32,-2,59:159.9
-32,2,59:159.9
-32,3,59:159.9
-32,4,59:1
-32,-3,60:159.9
-32,-2,60:159.9
-32,2,60:159.9
-32,3,60:159.9
-32,-2,61:7
-32,2,61:7
-32,-3,62:159.9
-32,-2,62:159.9
-32,2,62:159.9
-32,3,62:159.9
-32,-3,63:159.9
-32,-2,63:159.9
-32,-1,63:1
-32,0,63:1
-32,1,63:1
-32,2,63:159.9
-32,3,63:159.9
-32,-1,64:1
-32,0,64:1
-32,1,64:1
-32,-1,65:1
-32,0,65:1
-32,1,65:1
-32,-1,66:156.2
-32,0,66:155.2
-32,1,66:156.3
-32,-1,67:156.6
-32,0,67:155.2
-32,1,67:156.7
-32,-4,68:156.6
-32,-3,68:155.2
-32,-2,68:155.3
-32,-1,68:155.3
-32,0,68:155.2
-32,1,68:156.3
-32,2,68:155.3
-32,3,68:155.2
-32,4,68:156.7
-32,-5,69:156.6
-32,-4,69:155.2
-32,-3,69:156.3
-32,-1,69:1
-32,0,69:1
-32,1,69:1
-32,3,69:156.2
-32,4,69:155.2
-32,5,69:156.7
-32,-5,70:155.2
-32,-4,70:156.3
-32,-1,70:1
-32,0,70:1
-32,1,70:1
-32,4,70:156.2
-32,5,70:155.2
-32,-5,71:155
-32,-1,71:1
-32,0,71:1
-32,1,71:1
-32,5,71:155
-32,-1,72:1
-32,0,72:1
-32,1,72:1
-32,-1,73:1
-32,0,73:1
-32,1,73:1
-32,-1,74:1
-32,0,74:1
-32,1,74:1
-32,-1,75:1
-32,0,75:1
-32,1,75:1
-32,-1,76:1
-32,0,76:1
-32,1,76:1
-32,-1,77:1
-32,0,77:1
-32,1,77:1
-32,-1,78:1
-32,0,78:1
-32,1,78:1
-32,-1,79:1
-32,0,79:1
-32,1,79:1
-32,-1,80:1
-32,0,80:1
-32,1,80:1
-32,-2,81:19
-32,-1,81:19
-32,0,81:19
-32,1,81:19
-32,2,81:19
-32,-2,82:19
-32,-1,82:19
-32,0,82:19
-32,1,82:19
-32,2,82:19
-32,-2,83:19
-32,-1,83:19
-32,0,83:19
-32,1,83:19
-32,2,83:19
-32,-5,84:125.4
-32,-4,84:126.4
-32,-1,84:98
-32,0,84:98
-32,1,84:98
-32,4,84:126.4
-32,5,84:125.4
-32,-1,85:98
-32,0,85:98
-32,1,85:98
-32,-1,86:98
-32,0,86:98
-32,1,86:98
-32,-1,87:98
-32,0,87:98
-32,1,87:98
-32,-1,88:98
-32,0,88:98
-32,1,88:98
-32,-1,89:98
-32,0,89:98
-32,1,89:98
-32,-1,90:98
-32,0,90:98
-32,1,90:98
-32,-1,91:98
-32,0,91:98
-32,1,91:98
-32,-1,92:98
-32,0,92:98
-32,1,92:98
-32,-1,93:98
-32,0,93:98
-32,1,93:98
-32,-1,94:98
-32,0,94:98
-32,1,94:98
-32,-1,95:98
-32,0,95:98
-32,1,95:98
-32,-1,96:98
-32,0,96:98
-32,1,96:98
-32,-1,97:98
-32,0,97:98
-32,1,97:98
-32,-1,98:98
-32,0,98:98
-32,1,98:98
-32,-1,99:98
-32,0,99:98
-32,1,99:98
-32,-1,100:98
-32,0,100:98
-32,1,100:98
-32,-1,101:98
-32,0,101:98
-32,1,101:98
-32,-2,102:42
-32,-1,102:98
-32,0,102:98
-32,1,102:98
-32,2,102:42
-32,-2,103:42
-32,-1,103:98
-32,0,103:98
-32,1,103:98
-32,2,103:42
-32,-2,104:42
-32,-1,104:98
-32,0,104:98
-32,1,104:98
-32,2,104:42
-32,-3,105:42
-32,-1,105:98
-32,0,105:98
-32,1,105:98
-32,3,105:42
-32,-1,106:98
-32,0,106:98
-32,1,106:98
-32,-1,107:98
-32,0,107:98
-32,1,107:98
-32,-1,108:98
-32,0,108:98
-32,1,108:98
-32,-1,109:98
-32,0,109:98
-32,1,109:98
-32,-1,110:98
-32,0,110:98
-32,1,110:98
-32,-1,111:98
-32,0,111:98
-32,1,111:98
-32,-1,112:98
-32,0,112:98
-32,1,112:98
-32,-1,113:98
-32,0,113:98
-32,1,113:98
-32,-1,114:98
-32,0,114:98
-32,1,114:98
-32,-1,115:98
-32,0,115:98
-32,1,115:98
-32,-1,116:98
-32,0,116:98
-32,1,116:98
-32,-1,117:98
-32,0,117:98
-32,1,117:98
-32,-1,118:98
-32,0,118:98
-32,1,118:98
-32,-1,119:98
-32,0,119:98
-32,1,119:98
-32,-1,120:98
-32,0,120:98
-32,1,120:98
-32,-1,121:98
-32,0,121:98
-32,1,121:98
-32,-1,122:98
-32,0,122:98
-32,1,122:98
-32,-4,123:42
-32,-1,123:98
-32,0,123:98
-32,1,123:98
-32,4,123:42
-32,-5,124:42
-32,-1,124:98
-32,0,124:98
-32,1,124:98
-32,5,124:42
-32,-4,125:42
-32,-1,125:98
-32,0,125:98
-32,1,125:98
-32,4,125:42
-32,-1,126:98
-32,0,126:98
-32,1,126:98
-32,-4,127:95.9
-32,-3,127:57
-32,-1,127:98
-32,0,127:98
-32,1,127:98
-32,3,127:57
-32,4,127:95.9
-32,-4,128:95.9
-32,-3,128:57
-32,-1,128:98
-32,0,128:98
-32,1,128:98
-32,3,128:57
-32,4,128:95.9
-32,-4,129:95.9
-32,-3,129:57
-32,-1,129:98
-32,0,129:98
-32,1,129:98
-32,3,129:57
-32,4,129:95.9
-32,-4,130:95.9
-32,-3,130:57
-32,-1,130:98
-32,0,130:98
-32,1,130:98
-32,3,130:57
-32,4,130:95.9
-32,-1,131:98
-32,0,131:98
-32,1,131:98
-32,-1,132:98
-32,0,132:98
-32,1,132:98
-32,-1,133:98
-32,0,133:98
-32,1,133:98
-32,-2,134:159.1
-32,-1,134:159.1
-32,0,134:159.1
-32,1,134:159.1
-32,2,134:159.1
-32,-2,135:159.1
-32,0,135:159.1
-32,2,135:159.1
-32,-2,136:159.1
-32,-1,136:159.1
-32,0,136:159.1
-32,1,136:159.1
-32,2,136:159.1
-32,0,137:98
-32,0,138:139
-32,0,139:85
-32,0,140:85
-32,0,141:113
-31,-1,21:35.7
-31,0,21:35.7
-31,1,21:35.7
-31,-1,22:35.7
-31,0,22:35.7
-31,1,22:35.7
-31,-15,24:159.9
-31,-14,24:159.9
-31,-13,24:159.9
-31,-12,24:159.9
-31,-11,24:159.9
-31,-10,24:159.9
-31,-9,24:159.9
-31,-8,24:159.9
-31,-7,24:159.9
-31,-6,24:159.9
-31,-5,24:159.9
-31,-4,24:159.9
-31,-3,24:159.9
-31,-2,24:159.9
-31,-1,24:159.9
-31,0,24:159.9
-31,1,24:159.9
-31,2,24:159.9
-31,3,24:159.9
-31,4,24:159.9
-31,5,24:159.9
-31,6,24:159.9
-31,7,24:159.9
-31,8,24:159.9
-31,9,24:159.9
-31,10,24:159.9
-31,11,24:159.9
-31,12,24:159.9
-31,13,24:159.9
-31,14,24:159.9
-31,15,24:159.9
-31,-15,25:159.9
-31,-14,25:159.9
-31,-13,25:159.9
-31,-12,25:159.9
-31,-11,25:159.9
-31,-10,25:159.9
-31,-9,25:159.9
-31,-8,25:159.9
-31,-7,25:159.9
-31,-6,25:159.9
-31,-5,25:159.9
-31,-4,25:159.9
-31,-3,25:159.9
-31,-2,25:159.9
-31,-1,25:159.9
-31,0,25:159.9
-31,1,25:159.9
-31,2,25:159.9
-31,3,25:159.9
-31,4,25:159.9
-31,5,25:159.9
-31,6,25:159.9
-31,7,25:159.9
-31,8,25:159.9
-31,9,25:159.9
-31,10,25:159.9
-31,11,25:159.9
-31,12,25:159.9
-31,13,25:159.9
-31,14,25:159.9
-31,15,25:159.9
-31,-16,26:35.7
-31,-15,26:35.7
-31,-14,26:35.7
-31,-13,26:35.7
-31,-12,26:35.7
-31,-8,26:159.9
-31,-7,26:159.9
-31,-6,26:159.9
-31,-5,26:159.9
-31,-4,26:159.9
-31,-3,26:159.9
-31,-2,26:159.9
-31,-1,26:159.9
-31,0,26:159.9
-31,1,26:159.9
-31,2,26:159.9
-31,3,26:159.9
-31,4,26:159.9
-31,5,26:159.9
-31,6,26:159.9
-31,7,26:159.9
-31,8,26:159.9
-31,12,26:35.7
-31,13,26:35.7
-31,14,26:35.7
-31,15,26:35.7
-31,16,26:35.7
-31,-16,27:35.7
-31,-12,27:35.7
-31,-8,27:159.9
-31,-7,27:159.9
-31,-6,27:159.9
-31,-5,27:159.9
-31,-4,27:159.9
-31,-3,27:159.9
-31,-2,27:159.9
-31,-1,27:159.9
-31,0,27:159.9
-31,1,27:159.9
-31,2,27:159.9
-31,3,27:159.9
-31,4,27:159.9
-31,5,27:159.9
-31,6,27:159.9
-31,7,27:159.9
-31,8,27:159.9
-31,12,27:35.7
-31,16,27:35.7
-31,-16,28:35.7
-31,-15,28:35.7
-31,-14,28:35.7
-31,-13,28:35.7
-31,-12,28:35.7
-31,-8,28:159.9
-31,-7,28:159.9
-31,-6,28:159.9
-31,-5,28:159.9
-31,-4,28:159.9
-31,-3,28:159.9
-31,-2,28:159.9
-31,-1,28:159.9
-31,0,28:159.9
-31,1,28:159.9
-31,2,28:159.9
-31,3,28:159.9
-31,4,28:159.9
-31,5,28:159.9
-31,6,28:159.9
-31,7,28:159.9
-31,8,28:159.9
-31,12,28:35.7
-31,13,28:35.7
-31,14,28:35.7
-31,15,28:35.7
-31,16,28:35.7
-31,-16,29:35.7
-31,-15,29:35.7
-31,-14,29:35.7
-31,-13,29:35.7
-31,-7,29:82
-31,-6,29:82
-31,-5,29:82
-31,-4,29:82
-31,-3,29:82
-31,-2,29:82
-31,-1,29:82
-31,0,29:82
-31,1,29:82
-31,2,29:82
-31,3,29:82
-31,4,29:82
-31,5,29:82
-31,6,29:82
-31,7,29:82
-31,13,29:35.7
-31,14,29:35.7
-31,15,29:35.7
-31,16,29:35.7
-31,-16,30:35.7
-31,-14,30:35.7
-31,-8,30:159.9
-31,-7,30:159.9
-31,-6,30:159.9
-31,-5,30:159.9
-31,-4,30:159.9
-31,-3,30:159.9
-31,-2,30:159.9
-31,-1,30:159.9
-31,0,30:159.9
-31,1,30:159.9
-31,2,30:159.9
-31,3,30:159.9
-31,4,30:159.9
-31,5,30:159.9
-31,6,30:159.9
-31,7,30:159.9
-31,8,30:159.9
-31,14,30:35.7
-31,16,30:35.7
-31,-16,31:35.7
-31,-14,31:35.7
-31,-8,31:159.9
-31,-7,31:159.9
-31,-6,31:159.9
-31,-5,31:159.9
-31,-4,31:159.9
-31,-3,31:159.9
-31,-2,31:159.9
-31,-1,31:159.9
-31,0,31:159.9
-31,1,31:159.9
-31,2,31:159.9
-31,3,31:159.9
-31,4,31:159.9
-31,5,31:159.9
-31,6,31:159.9
-31,7,31:159.9
-31,8,31:159.9
-31,14,31:35.7
-31,16,31:35.7
-31,-16,32:35.7
-31,-15,32:35.7
-31,-14,32:35.7
-31,-7,32:1
-31,-6,32:1
-31,6,32:1
-31,7,32:1
-31,14,32:35.7
-31,15,32:35.7
-31,16,32:35.7
-31,-16,33:35.7
-31,-15,33:35.7
-31,-14,33:35.7
-31,-6,33:95.14
-31,6,33:95.14
-31,14,33:35.7
-31,15,33:35.7
-31,16,33:35.7
-31,-16,34:35.7
-31,-15,34:35.7
-31,-6,34:95.14
-31,6,34:95.14
-31,15,34:35.7
-31,16,34:35.7
-31,-17,35:95.5
-31,-16,35:35.7
-31,-6,35:95.14
-31,6,35:95.14
-31,16,35:35.7
-31,17,35:95.5
-31,-17,36:95.5
-31,-16,36:35.7
-31,-6,36:95.14
-31,6,36:95.14
-31,16,36:35.7
-31,17,36:95.5
-31,-17,37:95.5
-31,-6,37:95.14
-31,6,37:95.14
-31,17,37:95.5
-31,-18,38:95.5
-31,-6,38:95.14
-31,6,38:95.14
-31,18,38:95.5
-31,-18,39:95.5
-31,-6,39:95.14
-31,6,39:95.14
-31,18,39:95.5
-31,-19,40:95.5
-31,-7,40:95.14
-31,-6,40:95.14
-31,6,40:95.14
-31,7,40:95.14
-31,-19,41:95.5
-31,-7,41:95.14
-31,-6,41:95.14
-31,6,41:95.14
-31,7,41:95.14
-31,19,41:95.5
-31,-19,42:95.5
-31,-7,42:95.14
-31,-6,42:95.14
-31,6,42:95.14
-31,7,42:95.14
-31,19,42:95.5
-31,-20,43:95.5
-31,-7,43:95.14
-31,-6,43:95.14
-31,6,43:95.14
-31,7,43:95.14
-31,-7,44:95.14
-31,-6,44:95.14
-31,6,44:95.14
-31,7,44:95.14
-31,-7,45:95.14
-31,-6,45:95.14
-31,6,45:95.14
-31,7,45:95.14
-31,-21,46:95.5
-31,-7,46:95.14
-31,-6,46:95.14
-31,6,46:95.14
-31,7,46:95.14
-31,-6,47:1
-31,6,47:1
-31,-6,48:1
-31,6,48:1
-31,-6,49:1
-31,6,49:1
-31,22,49:95.5
-31,-6,50:1
-31,6,50:1
-31,-23,51:95.5
-31,-6,51:1
-31,6,51:1
-31,-6,52:1
-31,6,52:1
-31,24,52:95.5
-31,-6,53:1
-31,6,53:1
-31,-6,54:1
-31,6,54:1
-31,24,54:95.5
-31,-6,55:1
-31,6,55:1
-31,-6,56:1
-31,-5,56:1
-31,-4,56:1
-31,-3,56:1
-31,-2,56:1
-31,-1,56:1
-31,0,56:1
-31,1,56:1
-31,2,56:1
-31,3,56:1
-31,4,56:1
-31,5,56:1
-31,6,56:1
-31,-5,57:159.9
-31,-4,57:1
-31,-3,57:1
-31,-2,57:1
-31,-1,57:159.9
-31,1,57:159.9
-31,2,57:1
-31,3,57:1
-31,4,57:1
-31,5,57:159.9
-31,-4,58:1
-31,-3,58:1
-31,-2,58:1
-31,-1,58:159.9
-31,1,58:159.9
-31,2,58:1
-31,3,58:1
-31,4,58:1
-31,-4,59:1
-31,-3,59:1
-31,-2,59:1
-31,-1,59:159.9
-31,1,59:159.9
-31,2,59:1
-31,3,59:1
-31,4,59:1
-31,-2,60:159.9
-31,-1,60:159.9
-31,1,60:159.9
-31,2,60:159.9
-31,-1,61:7
-31,1,61:7
-31,-2,62:159.9
-31,-1,62:159.9
-31,1,62:159.9
-31,2,62:159.9
-31,-2,63:159.9
-31,-1,63:159.9
-31,0,63:1
-31,1,63:159.9
-31,2,63:159.9
-31,-1,64:1
-31,0,64:1
-31,1,64:1
-31,-1,65:1
-31,0,65:1
-31,1,65:1
-31,0,66:156.1
-31,0,67:156.5
-31,0,68:156.1
-31,0,69:1
-31,0,70:1
-31,-5,71:155
-31,0,71:1
-31,5,71:155
-31,0,72:1
-31,0,73:1
-31,0,74:1
-31,0,75:1
-31,0,76:1
-31,0,77:1
-31,0,78:1
-31,-1,79:1
-31,0,79:1
-31,1,79:1
-31,0,80:1
-31,-1,81:19
-31,0,81:19
-31,1,81:19
-31,-2,82:19
-31,-1,82:19
-31,0,82:19
-31,1,82:19
-31,2,82:19
-31,-1,83:19
-31,0,83:19
-31,1,83:19
-31,-5,84:125.4
-31,-4,84:126.4
-31,-1,84:98
-31,0,84:98
-31,1,84:98
-31,4,84:126.4
-31,5,84:125.4
-31,-1,85:98
-31,0,85:98
-31,1,85:98
-31,-1,86:98
-31,0,86:98
-31,1,86:98
-31,-1,87:98
-31,0,87:98
-31,1,87:98
-31,-1,88:98
-31,0,88:98
-31,1,88:98
-31,-1,89:98
-31,0,89:98
-31,1,89:98
-31,-1,90:98
-31,0,90:98
-31,1,90:98
-31,-1,91:98
-31,0,91:98
-31,1,91:98
-31,-1,92:98
-31,0,92:98
-31,1,92:98
-31,-1,93:98
-31,0,93:98
-31,1,93:98
-31,-1,94:98
-31,0,94:98
-31,1,94:98
-31,-1,95:98
-31,0,95:98
-31,1,95:98
-31,-1,96:98
-31,0,96:98
-31,1,96:98
-31,-1,97:98
-31,0,97:98
-31,1,97:98
-31,-1,98:98
-31,0,98:98
-31,1,98:98
-31,-1,99:98
-31,0,99:98
-31,1,99:98
-31,-1,100:98
-31,0,100:98
-31,1,100:98
-31,-1,101:98
-31,0,101:98
-31,1,101:98
-31,-1,102:98
-31,0,102:98
-31,1,102:98
-31,-1,103:98
-31,0,103:98
-31,1,103:98
-31,-2,104:42
-31,-1,104:98
-31,0,104:98
-31,1,104:98
-31,2,104:42
-31,-3,105:42
-31,-2,105:42
-31,-1,105:98
-31,0,105:98
-31,1,105:98
-31,2,105:42
-31,3,105:42
-31,-1,106:98
-31,0,106:98
-31,1,106:98
-31,0,107:98
-31,0,108:98
-31,0,109:98
-31,0,110:98
-31,0,111:98
-31,0,112:98
-31,0,113:98
-31,0,114:98
-31,0,115:98
-31,0,116:98
-31,0,117:98
-31,0,118:98
-31,0,119:98
-31,0,120:98
-31,0,121:98
-31,0,122:98
-31,-4,123:42
-31,0,123:98
-31,4,123:42
-31,-5,124:42
-31,0,124:98
-31,5,124:42
-31,-4,125:42
-31,0,125:98
-31,4,125:42
-31,0,126:98
-31,-4,127:95.9
-31,-3,127:57
-31,0,127:98
-31,3,127:57
-31,4,127:95.9
-31,-4,128:95.9
-31,-3,128:57
-31,0,128:98
-31,3,128:57
-31,4,128:95.9
-31,-4,129:95.9
-31,-3,129:57
-31,0,129:98
-31,3,129:57
-31,4,129:95.9
-31,-4,130:95.9
-31,-3,130:57
-31,0,130:98
-31,3,130:57
-31,4,130:95.9
-31,0,131:98
-31,0,132:98
-31,0,133:98
-31,-1,134:159.1
-31,0,134:159.1
-31,1,134:159.1
-31,-2,135:159.1
-31,2,135:159.1
-31,-1,136:159.1
-31,0,136:159.1
-31,1,136:159.1
-30,0,20:35.7
-30,-1,21:35.7
-30,0,21:35.7
-30,1,21:35.7
-30,-17,24:159.9
-30,-16,24:159.9
-30,-15,24:159.9
-30,-14,24:159.9
-30,-13,24:159.9
-30,-12,24:159.9
-30,-11,24:159.9
-30,-10,24:159.9
-30,-9,24:159.9
-30,-8,24:159.9
-30,-7,24:159.9
-30,-6,24:159.9
-30,-5,24:159.9
-30,-4,24:159.9
-30,-3,24:159.9
-30,-2,24:159.9
-30,-1,24:159.9
-30,0,24:159.9
-30,1,24:159.9
-30,2,24:159.9
-30,3,24:159.9
-30,4,24:159.9
-30,5,24:159.9
-30,6,24:159.9
-30,7,24:159.9
-30,8,24:159.9
-30,9,24:159.9
-30,10,24:159.9
-30,11,24:159.9
-30,12,24:159.9
-30,13,24:159.9
-30,14,24:159.9
-30,15,24:159.9
-30,16,24:159.9
-30,17,24:159.9
-30,-17,25:159.9
-30,-16,25:159.9
-30,-15,25:159.9
-30,-14,25:159.9
-30,-13,25:159.9
-30,-12,25:159.9
-30,-11,25:159.9
-30,-10,25:159.9
-30,-9,25:159.9
-30,-8,25:159.9
-30,-7,25:159.9
-30,-6,25:159.9
-30,-5,25:159.9
-30,-4,25:159.9
-30,-3,25:159.9
-30,-2,25:159.9
-30,-1,25:159.9
-30,0,25:159.9
-30,1,25:159.9
-30,2,25:159.9
-30,3,25:159.9
-30,4,25:159.9
-30,5,25:159.9
-30,6,25:159.9
-30,7,25:159.9
-30,8,25:159.9
-30,9,25:159.9
-30,10,25:159.9
-30,11,25:159.9
-30,12,25:159.9
-30,13,25:159.9
-30,14,25:159.9
-30,15,25:159.9
-30,16,25:159.9
-30,17,25:159.9
-30,-15,26:35.7
-30,-14,26:35.7
-30,-13,26:35.7
-30,-8,26:159.9
-30,-7,26:159.9
-30,-6,26:159.9
-30,-5,26:159.9
-30,-4,26:159.9
-30,-3,26:159.9
-30,-2,26:159.9
-30,-1,26:159.9
-30,0,26:159.9
-30,1,26:159.9
-30,2,26:159.9
-30,3,26:159.9
-30,4,26:159.9
-30,5,26:159.9
-30,6,26:159.9
-30,7,26:159.9
-30,8,26:159.9
-30,13,26:35.7
-30,14,26:35.7
-30,15,26:35.7
-30,-15,27:35.7
-30,-13,27:35.7
-30,-8,27:159.9
-30,-7,27:159.9
-30,-6,27:159.9
-30,-5,27:159.9
-30,-4,27:159.9
-30,-3,27:159.9
-30,-2,27:159.9
-30,-1,27:159.9
-30,0,27:159.9
-30,1,27:159.9
-30,2,27:159.9
-30,3,27:159.9
-30,4,27:159.9
-30,5,27:159.9
-30,6,27:159.9
-30,7,27:159.9
-30,8,27:159.9
-30,13,27:35.7
-30,15,27:35.7
-30,-15,28:35.7
-30,-14,28:35.7
-30,-13,28:35.7
-30,-8,28:159.9
-30,-7,28:159.9
-30,-6,28:159.9
-30,-5,28:159.9
-30,-4,28:159.9
-30,-3,28:159.9
-30,-2,28:159.9
-30,-1,28:159.9
-30,0,28:159.9
-30,1,28:159.9
-30,2,28:159.9
-30,3,28:159.9
-30,4,28:159.9
-30,5,28:159.9
-30,6,28:159.9
-30,7,28:159.9
-30,8,28:159.9
-30,13,28:35.7
-30,14,28:35.7
-30,15,28:35.7
-30,-16,29:95.5
-30,-15,29:35.7
-30,-14,29:35.7
-30,-7,29:82
-30,-6,29:82
-30,-5,29:82
-30,-4,29:82
-30,-3,29:82
-30,-2,29:82
-30,-1,29:82
-30,0,29:82
-30,1,29:82
-30,2,29:82
-30,3,29:82
-30,4,29:82
-30,5,29:82
-30,6,29:82
-30,7,29:82
-30,14,29:35.7
-30,15,29:35.7
-30,16,29:95.5
-30,-16,30:95.5
-30,-15,30:35.7
-30,-8,30:159.9
-30,-7,30:159.9
-30,-6,30:159.9
-30,-5,30:159.9
-30,-4,30:159.9
-30,-3,30:159.9
-30,-2,30:159.9
-30,-1,30:159.9
-30,0,30:159.9
-30,1,30:159.9
-30,2,30:159.9
-30,3,30:159.9
-30,4,30:159.9
-30,5,30:159.9
-30,6,30:159.9
-30,7,30:159.9
-30,8,30:159.9
-30,15,30:35.7
-30,16,30:95.5
-30,-16,31:95.5
-30,-15,31:35.7
-30,-8,31:159.9
-30,-7,31:159.9
-30,-6,31:159.9
-30,-5,31:159.9
-30,-4,31:159.9
-30,-3,31:159.9
-30,-2,31:159.9
-30,-1,31:159.9
-30,0,31:159.9
-30,1,31:159.9
-30,2,31:159.9
-30,3,31:159.9
-30,4,31:159.9
-30,5,31:159.9
-30,6,31:159.9
-30,7,31:159.9
-30,8,31:159.9
-30,15,31:35.7
-30,16,31:95.5
-30,-17,32:95.5
-30,-15,32:35.7
-30,-7,32:1
-30,-6,32:1
-30,6,32:1
-30,7,32:1
-30,15,32:35.7
-30,17,32:95.5
-30,-17,33:95.5
-30,-6,33:95.14
-30,6,33:95.14
-30,17,33:95.5
-30,-17,34:95.5
-30,-6,34:95.14
-30,6,34:95.14
-30,17,34:95.5
-30,-18,35:95.5
-30,-6,35:95.14
-30,6,35:95.14
-30,18,35:95.5
-30,-18,36:95.5
-30,-6,36:95.14
-30,6,36:95.14
-30,18,36:95.5
-30,-18,37:95.5
-30,-6,37:95.14
-30,6,37:95.14
-30,18,37:95.5
-30,-19,38:95.5
-30,-6,38:95.14
-30,6,38:95.14
-30,19,38:95.5
-30,-19,39:95.5
-30,-6,39:95.14
-30,6,39:95.14
-30,-20,40:95.5
-30,-7,40:95.14
-30,-6,40:95.14
-30,6,40:95.14
-30,7,40:95.14
-30,-20,41:95.5
-30,-7,41:95.14
-30,-6,41:95.14
-30,6,41:95.14
-30,7,41:95.14
-30,-7,42:95.14
-30,-6,42:95.14
-30,6,42:95.14
-30,7,42:95.14
-30,-7,43:95.14
-30,-6,43:95.14
-30,6,43:95.14
-30,7,43:95.14
-30,-7,44:95.14
-30,-6,44:95.14
-30,6,44:95.14
-30,7,44:95.14
-30,-7,45:95.14
-30,-6,45:95.14
-30,6,45:95.14
-30,7,45:95.14
-30,-7,46:95.14
-30,-6,46:95.14
-30,6,46:95.14
-30,7,46:95.14
-30,-6,47:1
-30,6,47:1
-30,-6,48:1
-30,6,48:1
-30,-6,49:1
-30,6,49:1
-30,23,49:95.5
-30,-6,50:1
-30,6,50:1
-30,24,50:95.5
-30,-6,51:1
-30,6,51:1
-30,-6,52:1
-30,6,52:1
-30,-6,53:1
-30,6,53:1
-30,-6,54:1
-30,6,54:1
-30,-6,55:1
-30,6,55:1
-30,-6,56:1
-30,-5,56:1
-30,-4,56:1
-30,-3,56:1
-30,-2,56:1
-30,-1,56:1
-30,0,56:1
-30,1,56:1
-30,2,56:1
-30,3,56:1
-30,4,56:1
-30,5,56:1
-30,6,56:1
-30,-4,57:159.9
-30,-3,57:159.9
-30,-2,57:159.9
-30,-1,57:1
-30,0,57:159.9
-30,1,57:1
-30,2,57:159.9
-30,3,57:159.9
-30,4,57:159.9
-30,-2,58:1
-30,-1,58:1
-30,0,58:159.9
-30,1,58:1
-30,2,58:1
-30,-2,59:1
-30,-1,59:1
-30,0,59:159.9
-30,1,59:1
-30,2,59:1
-30,-1,60:159.9
-30,0,60:159.9
-30,1,60:159.9
-30,0,61:7
-30,-1,62:159.9
-30,0,62:159.9
-30,1,62:159.9
-30,-2,63:1.3
-30,-1,63:159.9
-30,0,63:159.9
-30,1,63:159.9
-30,2,63:1.3
-30,-3,64:1.3
-30,-2,64:1.3
-30,2,64:1.3
-30,3,64:1.3
-30,0,68:155.3
-30,-5,71:155
-30,5,71:155
-30,0,81:19
-30,-1,82:19
-30,0,82:19
-30,1,82:19
-30,0,83:19
-30,-5,84:125.4
-30,-4,84:126.4
-30,4,84:126.4
-30,5,84:125.4
-30,0,102:42
-30,0,103:42
-30,-1,104:42
-30,0,104:42
-30,1,104:42
-30,-2,105:42
-30,-1,105:42
-30,1,105:42
-30,2,105:42
-30,-4,123:42
-30,4,123:42
-30,-5,124:42
-30,5,124:42
-30,-4,125:42
-30,4,125:42
-30,-4,127:95.9
-30,-3,127:57
-30,-2,127:57
-30,2,127:57
-30,3,127:57
-30,4,127:95.9
-30,-4,128:95.9
-30,-3,128:57
-30,-2,128:57
-30,2,128:57
-30,3,128:57
-30,4,128:95.9
-30,-4,129:95.9
-30,-3,129:57
-30,-2,129:57
-30,2,129:57
-30,3,129:57
-30,4,129:95.9
-30,-4,130:95.9
-30,-3,130:57
-30,-2,130:57
-30,2,130:57
-30,3,130:57
-30,4,130:95.9
-30,0,134:159.1
-30,-1,135:159.1
-30,0,135:159.1
-30,1,135:159.1
-30,0,136:159.1
-29,-5,3:159.9
-29,-4,3:159.9
-29,-3,3:159.9
-29,-2,3:159.9
-29,-1,3:159.9
-29,0,3:159.9
-29,1,3:159.9
-29,2,3:159.9
-29,3,3:159.9
-29,4,3:159.9
-29,5,3:159.9
-29,-5,4:159.9
-29,-4,4:159.9
-29,-3,4:159.9
-29,-2,4:159.9
-29,-1,4:159.9
-29,0,4:159.9
-29,1,4:159.9
-29,2,4:159.9
-29,3,4:159.9
-29,4,4:159.9
-29,5,4:159.9
-29,-5,8:159.9
-29,-4,8:159.9
-29,-3,8:159.9
-29,-2,8:159.9
-29,-1,8:159.9
-29,0,8:159.9
-29,1,8:159.9
-29,2,8:159.9
-29,3,8:159.9
-29,4,8:159.9
-29,5,8:159.9
-29,-5,9:159.9
-29,-4,9:159.9
-29,-3,9:159.9
-29,-2,9:159.9
-29,-1,9:159.9
-29,0,9:159.9
-29,1,9:159.9
-29,2,9:159.9
-29,3,9:159.9
-29,4,9:159.9
-29,5,9:159.9
-29,-5,10:159.9
-29,-4,10:159.9
-29,-3,10:159.9
-29,-2,10:159.9
-29,-1,10:159.9
-29,0,10:159.9
-29,1,10:159.9
-29,2,10:159.9
-29,3,10:159.9
-29,4,10:159.9
-29,5,10:159.9
-29,-5,11:159.9
-29,4,11:159.9
-29,5,11:159.9
-29,-5,14:82
-29,-4,14:82
-29,3,14:82
-29,4,14:82
-29,5,14:82
-29,-5,15:82
-29,-4,15:82
-29,-3,15:82
-29,3,15:82
-29,4,15:82
-29,5,15:82
-29,-5,16:82
-29,-4,16:82
-29,-3,16:82
-29,-2,16:82
-29,2,16:82
-29,3,16:82
-29,4,16:82
-29,5,16:82
-29,-5,17:82
-29,-4,17:82
-29,-3,17:82
-29,-2,17:82
-29,-1,17:82
-29,1,17:82
-29,2,17:82
-29,3,17:82
-29,4,17:82
-29,5,17:82
-29,-5,18:82
-29,-4,18:82
-29,-3,18:82
-29,-2,18:82
-29,-1,18:82
-29,0,18:82
-29,1,18:82
-29,2,18:82
-29,3,18:82
-29,4,18:82
-29,5,18:82
-29,-5,19:82
-29,-4,19:82
-29,-3,19:82
-29,-2,19:82
-29,-1,19:82
-29,0,19:82
-29,1,19:82
-29,2,19:82
-29,3,19:82
-29,4,19:82
-29,5,19:82
-29,-5,20:82
-29,-4,20:82
-29,-3,20:82
-29,-2,20:82
-29,-1,20:82
-29,0,20:35.7
-29,1,20:82
-29,2,20:82
-29,3,20:82
-29,4,20:82
-29,5,20:82
-29,-5,21:82
-29,-4,21:82
-29,-3,21:82
-29,-2,21:82
-29,-1,21:82
-29,0,21:35.7
-29,1,21:82
-29,2,21:82
-29,3,21:82
-29,4,21:82
-29,5,21:82
-29,-5,22:82
-29,-4,22:82
-29,-3,22:82
-29,-2,22:82
-29,-1,22:82
-29,0,22:82
-29,1,22:82
-29,2,22:82
-29,3,22:82
-29,4,22:82
-29,5,22:82
-29,-5,23:82
-29,-4,23:82
-29,-3,23:82
-29,-2,23:82
-29,-1,23:82
-29,0,23:82
-29,1,23:82
-29,2,23:82
-29,3,23:82
-29,4,23:82
-29,5,23:82
-29,-18,24:159.9
-29,-17,24:159.9
-29,-16,24:159.9
-29,-15,24:159.9
-29,-14,24:159.9
-29,-13,24:159.9
-29,-12,24:159.9
-29,-11,24:159.9
-29,-10,24:159.9
-29,-9,24:159.9
-29,-8,24:159.9
-29,-7,24:159.9
-29,-6,24:159.9
-29,-5,24:159.9
-29,-4,24:159.9
-29,-3,24:159.9
-29,-2,24:159.9
-29,-1,24:159.9
-29,0,24:159.9
-29,1,24:159.9
-29,2,24:159.9
-29,3,24:159.9
-29,4,24:159.9
-29,5,24:159.9
-29,6,24:159.9
-29,7,24:159.9
-29,8,24:159.9
-29,9,24:159.9
-29,10,24:159.9
-29,11,24:159.9
-29,12,24:159.9
-29,13,24:159.9
-29,14,24:159.9
-29,15,24:159.9
-29,16,24:159.9
-29,17,24:159.9
-29,18,24:159.9
-29,-18,25:159.9
-29,-17,25:159.9
-29,-16,25:159.9
-29,-15,25:159.9
-29,-14,25:159.9
-29,-13,25:159.9
-29,-12,25:159.9
-29,-11,25:159.9
-29,-10,25:159.9
-29,-9,25:159.9
-29,-8,25:159.9
-29,-7,25:159.9
-29,-6,25:159.9
-29,-5,25:159.9
-29,-4,25:159.9
-29,-3,25:159.9
-29,-2,25:159.9
-29,-1,25:159.9
-29,0,25:159.9
-29,1,25:159.9
-29,2,25:159.9
-29,3,25:159.9
-29,4,25:159.9
-29,5,25:159.9
-29,6,25:159.9
-29,7,25:159.9
-29,8,25:159.9
-29,9,25:159.9
-29,10,25:159.9
-29,11,25:159.9
-29,12,25:159.9
-29,13,25:159.9
-29,14,25:159.9
-29,15,25:159.9
-29,16,25:159.9
-29,17,25:159.9
-29,18,25:159.9
-29,-16,26:95.5
-29,-14,26:35.7
-29,-7,26:159.9
-29,-6,26:159.9
-29,-5,26:159.9
-29,-4,26:159.9
-29,-3,26:159.9
-29,-2,26:159.9
-29,-1,26:159.9
-29,0,26:159.9
-29,1,26:159.9
-29,2,26:159.9
-29,3,26:159.9
-29,4,26:159.9
-29,5,26:159.9
-29,6,26:159.9
-29,7,26:159.9
-29,14,26:35.7
-29,16,26:95.5
-29,-16,27:95.5
-29,-14,27:35.7
-29,-7,27:159.9
-29,-6,27:159.9
-29,-5,27:159.9
-29,-4,27:159.9
-29,-3,27:159.9
-29,-2,27:159.9
-29,-1,27:159.9
-29,0,27:159.9
-29,1,27:159.9
-29,2,27:159.9
-29,3,27:159.9
-29,4,27:159.9
-29,5,27:159.9
-29,6,27:159.9
-29,7,27:159.9
-29,14,27:35.7
-29,16,27:95.5
-29,-16,28:95.5
-29,-14,28:35.7
-29,-7,28:159.9
-29,-6,28:159.9
-29,-5,28:159.9
-29,-4,28:159.9
-29,-3,28:159.9
-29,-2,28:159.9
-29,-1,28:159.9
-29,0,28:159.9
-29,1,28:159.9
-29,2,28:159.9
-29,3,28:159.9
-29,4,28:159.9
-29,5,28:159.9
-29,6,28:159.9
-29,7,28:159.9
-29,14,28:35.7
-29,16,28:95.5
-29,-17,29:95.5
-29,-6,29:82
-29,-5,29:82
-29,-4,29:82
-29,-3,29:82
-29,-2,29:82
-29,-1,29:82
-29,0,29:82
-29,1,29:82
-29,2,29:82
-29,3,29:82
-29,4,29:82
-29,5,29:82
-29,6,29:82
-29,17,29:95.5
-29,-17,30:95.5
-29,-7,30:159.9
-29,-6,30:159.9
-29,-5,30:159.9
-29,-4,30:159.9
-29,-3,30:159.9
-29,-2,30:159.9
-29,-1,30:159.9
-29,0,30:159.9
-29,1,30:159.9
-29,2,30:159.9
-29,3,30:159.9
-29,4,30:159.9
-29,5,30:159.9
-29,6,30:159.9
-29,7,30:159.9
-29,17,30:95.5
-29,-17,31:95.5
-29,-7,31:159.9
-29,-6,31:159.9
-29,-5,31:159.9
-29,-4,31:159.9
-29,-3,31:159.9
-29,-2,31:159.9
-29,-1,31:159.9
-29,0,31:159.9
-29,1,31:159.9
-29,2,31:159.9
-29,3,31:159.9
-29,4,31:159.9
-29,5,31:159.9
-29,6,31:159.9
-29,7,31:159.9
-29,17,31:95.5
-29,-18,32:95.5
-29,-6,32:1
-29,-5,32:1
-29,5,32:1
-29,6,32:1
-29,18,32:95.5
-29,-18,33:95.5
-29,-5,33:95.14
-29,5,33:95.14
-29,18,33:95.5
-29,-18,34:95.5
-29,-5,34:95.14
-29,5,34:95.14
-29,18,34:95.5
-29,-19,35:95.5
-29,-5,35:95.14
-29,5,35:95.14
-29,19,35:95.5
-29,-19,36:95.5
-29,-5,36:95.14
-29,5,36:95.14
-29,19,36:95.5
-29,-19,37:95.5
-29,-5,37:95.14
-29,5,37:95.14
-29,19,37:95.5
-29,-20,38:95.5
-29,-5,38:95.14
-29,5,38:95.14
-29,20,38:95.5
-29,-20,39:95.5
-29,-5,39:95.14
-29,5,39:95.14
-29,-21,40:95.5
-29,-6,40:95.14
-29,-5,40:95.14
-29,5,40:95.14
-29,6,40:95.14
-29,21,40:95.5
-29,-6,41:95.14
-29,-5,41:95.14
-29,5,41:95.14
-29,6,41:95.14
-29,21,41:95.5
-29,-6,42:95.14
-29,-5,42:95.14
-29,5,42:95.14
-29,6,42:95.14
-29,21,42:95.5
-29,-22,43:95.5
-29,-6,43:95.14
-29,-5,43:95.14
-29,5,43:95.14
-29,6,43:95.14
-29,-6,44:95.14
-29,-5,44:95.14
-29,5,44:95.14
-29,6,44:95.14
-29,-6,45:95.14
-29,-5,45:95.14
-29,5,45:95.14
-29,6,45:95.14
-29,-6,46:95.14
-29,-5,46:95.14
-29,5,46:95.14
-29,6,46:95.14
-29,-5,47:1
-29,5,47:1
-29,23,47:95.5
-29,-5,48:1
-29,5,48:1
-29,-5,49:1
-29,5,49:1
-29,24,49:95.5
-29,-5,50:1
-29,5,50:1
-29,25,50:95.5
-29,-5,51:1
-29,5,51:1
-29,25,51:95.5
-29,-26,52:95.5
-29,-5,52:1
-29,5,52:1
-29,-5,53:1
-29,5,53:1
-29,26,53:95.5
-29,-26,54:95.5
-29,-5,54:1
-29,5,54:1
-29,-5,55:1
-29,5,55:1
-29,-5,56:1
-29,-4,56:1
-29,-3,56:1
-29,-2,56:1
-29,-1,56:1
-29,0,56:1
-29,1,56:1
-29,2,56:1
-29,3,56:1
-29,4,56:1
-29,5,56:1
-29,-2,57:159.9
-29,-1,57:1
-29,0,57:159.9
-29,1,57:1
-29,2,57:159.9
-29,-9,58:35.1
-29,-1,58:1
-29,0,58:159.9
-29,1,58:1
-29,9,58:35.1
-29,-9,59:85
-29,-1,59:1
-29,0,59:159.9
-29,1,59:1
-29,9,59:85
-29,-9,60:35.1
-29,-8,60:85
-29,0,60:159.9
-29,8,60:85
-29,9,60:35.1
-29,-8,61:85
-29,-7,61:35.1
-29,-6,61:85
-29,6,61:85
-29,7,61:35.1
-29,8,61:85
-29,-6,62:85
-29,-5,62:85
-29,0,62:159.9
-29,5,62:85
-29,6,62:85
-29,-5,63:35.1
-29,0,63:159.9
-29,5,63:35.1
-29,-3,64:1.3
-29,-2,64:1.3
-29,2,64:1.3
-29,3,64:1.3
-29,0,68:155.2
-29,0,69:156
-29,-4,71:155
-29,4,71:155
-29,-4,84:125.4
-29,-3,84:126.4
-29,3,84:126.4
-29,4,84:125.4
-29,-1,105:42
-29,0,105:42
-29,1,105:42
-29,-3,123:42
-29,3,123:42
-29,-4,124:42
-29,4,124:42
-29,-3,125:42
-29,3,125:42
-29,-3,127:95.9
-29,-2,127:57
-29,-1,127:57
-29,0,127:57
-29,1,127:57
-29,2,127:57
-29,3,127:95.9
-29,-3,128:95.9
-29,-2,128:57
-29,-1,128:57
-29,0,128:57
-29,1,128:57
-29,2,128:57
-29,3,128:95.9
-29,-3,129:95.9
-29,-2,129:57
-29,-1,129:57
-29,0,129:57
-29,1,129:57
-29,2,129:57
-29,3,129:95.9
-29,-3,130:95.9
-29,-2,130:57
-29,-1,130:57
-29,0,130:57
-29,1,130:57
-29,2,130:57
-29,3,130:95.9
-28,-9,3:159.9
-28,-8,3:159.9
-28,-7,3:159.9
-28,-6,3:159.9
-28,-5,3:159.9
-28,-4,3:159.9
-28,-3,3:159.9
-28,-2,3:159.9
-28,-1,3:159.9
-28,0,3:159.9
-28,1,3:159.9
-28,2,3:159.9
-28,3,3:159.9
-28,4,3:159.9
-28,5,3:159.9
-28,6,3:159.9
-28,7,3:159.9
-28,8,3:159.9
-28,9,3:159.9
-28,-9,4:159.9
-28,-8,4:159.9
-28,-7,4:159.9
-28,-6,4:159.9
-28,-5,4:159.9
-28,-4,4:159.9
-28,-3,4:159.9
-28,-2,4:159.9
-28,-1,4:159.9
-28,0,4:159.9
-28,1,4:159.9
-28,2,4:159.9
-28,3,4:159.9
-28,4,4:159.9
-28,5,4:159.9
-28,6,4:159.9
-28,7,4:159.9
-28,8,4:159.9
-28,9,4:159.9
-28,-5,5:42
-28,-4,5:42
-28,-3,5:42
-28,-2,5:42
-28,-1,5:42
-28,0,5:42
-28,1,5:42
-28,2,5:42
-28,3,5:42
-28,4,5:42
-28,5,5:42
-28,-5,6:42
-28,-4,6:42
-28,-3,6:42
-28,-2,6:42
-28,-1,6:42
-28,0,6:42
-28,1,6:42
-28,2,6:42
-28,3,6:42
-28,4,6:42
-28,5,6:42
-28,-5,7:42
-28,-4,7:42
-28,-3,7:42
-28,-2,7:42
-28,-1,7:42
-28,0,7:42
-28,1,7:42
-28,2,7:42
-28,3,7:42
-28,4,7:42
-28,5,7:42
-28,-9,8:159.9
-28,-8,8:159.9
-28,-7,8:159.9
-28,-6,8:159.9
-28,-5,8:159.9
-28,-4,8:159.9
-28,-3,8:159.9
-28,-2,8:159.9
-28,-1,8:159.9
-28,0,8:159.9
-28,1,8:159.9
-28,2,8:159.9
-28,3,8:159.9
-28,4,8:159.9
-28,5,8:159.9
-28,6,8:159.9
-28,7,8:159.9
-28,8,8:159.9
-28,9,8:159.9
-28,-9,9:159.9
-28,-8,9:159.9
-28,-7,9:159.9
-28,-6,9:159.9
-28,-5,9:159.9
-28,-4,9:159.9
-28,-3,9:159.9
-28,-2,9:159.9
-28,-1,9:159.9
-28,0,9:159.9
-28,1,9:159.9
-28,2,9:159.9
-28,3,9:159.9
-28,4,9:159.9
-28,5,9:159.9
-28,6,9:159.9
-28,7,9:159.9
-28,8,9:159.9
-28,9,9:159.9
-28,-9,10:159.9
-28,-8,10:159.9
-28,-7,10:159.9
-28,-6,10:159.9
-28,-5,10:159.9
-28,-4,10:159.9
-28,-3,10:159.9
-28,-2,10:159.9
-28,-1,10:159.9
-28,0,10:159.9
-28,1,10:159.9
-28,2,10:159.9
-28,3,10:159.9
-28,4,10:159.9
-28,5,10:159.9
-28,6,10:159.9
-28,7,10:159.9
-28,8,10:159.9
-28,9,10:159.9
-28,-9,11:159.9
-28,-8,11:159.9
-28,-7,11:159.9
-28,-6,11:159.9
-28,-5,11:159.9
-28,-4,11:159.9
-28,-3,11:33.5
-28,-2,11:33.5
-28,-1,11:33.5
-28,0,11:33.5
-28,1,11:33.5
-28,2,11:33.5
-28,3,11:33.5
-28,4,11:159.9
-28,5,11:159.9
-28,6,11:159.9
-28,7,11:159.9
-28,8,11:159.9
-28,9,11:159.9
-28,-5,12:159.9
-28,-4,12:159.9
-28,-3,12:33.5
-28,-2,12:33.5
-28,-1,12:33.5
-28,0,12:33.5
-28,1,12:33.5
-28,2,12:33.5
-28,3,12:33.5
-28,4,12:159.9
-28,5,12:159.9
-28,-5,13:159.9
-28,-4,13:159.9
-28,-3,13:33.5
-28,-2,13:33.5
-28,-1,13:33.5
-28,0,13:33.5
-28,1,13:33.5
-28,2,13:33.5
-28,3,13:33.5
-28,4,13:159.9
-28,5,13:159.9
-28,-9,14:82
-28,-8,14:82
-28,-7,14:82
-28,-6,14:82
-28,-4,14:42
-28,-3,14:42
-28,-2,14:33.5
-28,-1,14:33.5
-28,0,14:33.5
-28,1,14:33.5
-28,2,14:33.5
-28,3,14:42
-28,4,14:42
-28,6,14:82
-28,7,14:82
-28,8,14:82
-28,9,14:82
-28,-9,15:82
-28,-8,15:82
-28,-7,15:82
-28,-6,15:82
-28,-4,15:42
-28,-3,15:42
-28,-2,15:33.5
-28,-1,15:33.5
-28,0,15:33.5
-28,1,15:33.5
-28,2,15:33.5
-28,3,15:42
-28,4,15:42
-28,6,15:82
-28,7,15:82
-28,8,15:82
-28,9,15:82
-28,-9,16:82
-28,-8,16:82
-28,-7,16:82
-28,-6,16:82
-28,-4,16:42
-28,-3,16:42
-28,-2,16:33.5
-28,-1,16:33.5
-28,0,16:33.5
-28,1,16:33.5
-28,2,16:33.5
-28,3,16:42
-28,4,16:42
-28,6,16:82
-28,7,16:82
-28,8,16:82
-28,9,16:82
-28,-9,17:82
-28,-8,17:82
-28,-7,17:82
-28,-6,17:82
-28,-4,17:42
-28,-3,17:42
-28,-2,17:42
-28,-1,17:33.5
-28,0,17:33.5
-28,1,17:33.5
-28,2,17:42
-28,3,17:42
-28,4,17:42
-28,6,17:82
-28,7,17:82
-28,8,17:82
-28,9,17:82
-28,-9,18:82
-28,-8,18:82
-28,-7,18:82
-28,-6,18:82
-28,-3,18:42
-28,-2,18:42
-28,-1,18:42
-28,0,18:42
-28,1,18:42
-28,2,18:42
-28,3,18:42
-28,6,18:82
-28,7,18:82
-28,8,18:82
-28,9,18:82
-28,-9,19:82
-28,-8,19:82
-28,-7,19:82
-28,-6,19:82
-28,-2,19:42
-28,-1,19:42
-28,0,19:42
-28,1,19:42
-28,2,19:42
-28,6,19:82
-28,7,19:82
-28,8,19:82
-28,9,19:82
-28,-9,20:82
-28,-8,20:82
-28,-7,20:82
-28,-6,20:82
-28,6,20:82
-28,7,20:82
-28,8,20:82
-28,9,20:82
-28,-9,21:82
-28,-8,21:82
-28,-7,21:82
-28,-6,21:82
-28,0,21:35.7
-28,6,21:82
-28,7,21:82
-28,8,21:82
-28,9,21:82
-28,-9,22:82
-28,-8,22:82
-28,-7,22:82
-28,-6,22:82
-28,-1,22:35.7
-28,0,22:35.7
-28,1,22:35.7
-28,6,22:82
-28,7,22:82
-28,8,22:82
-28,9,22:82
-28,-9,23:82
-28,-8,23:82
-28,-7,23:82
-28,-6,23:82
-28,-1,23:35.7
-28,0,23:35.7
-28,1,23:35.7
-28,6,23:82
-28,7,23:82
-28,8,23:82
-28,9,23:82
-28,-20,24:159.9
-28,-19,24:159.9
-28,-18,24:159.9
-28,-17,24:159.9
-28,-16,24:159.9
-28,-15,24:159.9
-28,-14,24:159.9
-28,-13,24:159.9
-28,-12,24:159.9
-28,-11,24:159.9
-28,-10,24:159.9
-28,-9,24:159.9
-28,-8,24:159.9
-28,-7,24:159.9
-28,-6,24:159.9
-28,-5,24:159.9
-28,-4,24:159.9
-28,-3,24:159.9
-28,-2,24:159.9
-28,-1,24:159.9
-28,0,24:35.7
-28,1,24:159.9
-28,2,24:159.9
-28,3,24:159.9
-28,4,24:159.9
-28,5,24:159.9
-28,6,24:159.9
-28,7,24:159.9
-28,8,24:159.9
-28,9,24:159.9
-28,10,24:159.9
-28,11,24:159.9
-28,12,24:159.9
-28,13,24:159.9
-28,14,24:159.9
-28,15,24:159.9
-28,16,24:159.9
-28,17,24:159.9
-28,18,24:159.9
-28,19,24:159.9
-28,20,24:159.9
-28,-20,25:159.9
-28,-19,25:159.9
-28,-18,25:159.9
-28,-17,25:159.9
-28,-16,25:159.9
-28,-15,25:159.9
-28,-14,25:159.9
-28,-13,25:159.9
-28,-12,25:159.9
-28,-11,25:159.9
-28,-10,25:159.9
-28,-9,25:159.9
-28,-8,25:159.9
-28,-7,25:159.9
-28,-6,25:159.9
-28,-5,25:159.9
-28,-4,25:159.9
-28,-3,25:159.9
-28,-2,25:159.9
-28,-1,25:159.9
-28,0,25:159.9
-28,1,25:159.9
-28,2,25:159.9
-28,3,25:159.9
-28,4,25:159.9
-28,5,25:159.9
-28,6,25:159.9
-28,7,25:159.9
-28,8,25:159.9
-28,9,25:159.9
-28,10,25:159.9
-28,11,25:159.9
-28,12,25:159.9
-28,13,25:159.9
-28,14,25:159.9
-28,15,25:159.9
-28,16,25:159.9
-28,17,25:159.9
-28,18,25:159.9
-28,19,25:159.9
-28,20,25:159.9
-28,-17,26:95.5
-28,-7,26:159.9
-28,-6,26:159.9
-28,-5,26:159.9
-28,-4,26:159.9
-28,-3,26:159.9
-28,-2,26:159.9
-28,-1,26:159.9
-28,0,26:159.9
-28,1,26:159.9
-28,2,26:159.9
-28,3,26:159.9
-28,4,26:159.9
-28,5,26:159.9
-28,6,26:159.9
-28,7,26:159.9
-28,17,26:95.5
-28,-17,27:95.5
-28,-7,27:159.9
-28,-6,27:159.9
-28,-5,27:159.9
-28,-4,27:159.9
-28,-3,27:159.9
-28,-2,27:159.9
-28,-1,27:159.9
-28,0,27:159.9
-28,1,27:159.9
-28,2,27:159.9
-28,3,27:159.9
-28,4,27:159.9
-28,5,27:159.9
-28,6,27:159.9
-28,7,27:159.9
-28,17,27:95.5
-28,-17,28:95.5
-28,-7,28:159.9
-28,-6,28:159.9
-28,-5,28:159.9
-28,-4,28:159.9
-28,-3,28:159.9
-28,-2,28:159.9
-28,-1,28:159.9
-28,0,28:159.9
-28,1,28:159.9
-28,2,28:159.9
-28,3,28:159.9
-28,4,28:159.9
-28,5,28:159.9
-28,6,28:159.9
-28,7,28:159.9
-28,17,28:95.5
-28,-18,29:95.5
-28,-6,29:82
-28,-5,29:82
-28,-4,29:82
-28,-3,29:82
-28,-2,29:82
-28,-1,29:82
-28,0,29:82
-28,1,29:82
-28,2,29:82
-28,3,29:82
-28,4,29:82
-28,5,29:82
-28,6,29:82
-28,18,29:95.5
-28,-18,30:95.5
-28,-7,30:159.9
-28,-6,30:159.9
-28,-5,30:159.9
-28,-4,30:159.9
-28,-3,30:159.9
-28,-2,30:159.9
-28,-1,30:159.9
-28,0,30:159.9
-28,1,30:159.9
-28,2,30:159.9
-28,3,30:159.9
-28,4,30:159.9
-28,5,30:159.9
-28,6,30:159.9
-28,7,30:159.9
-28,18,30:95.5
-28,-18,31:95.5
-28,-7,31:159.9
-28,-6,31:159.9
-28,-5,31:159.9
-28,-4,31:159.9
-28,-3,31:159.9
-28,-2,31:159.9
-28,-1,31:159.9
-28,0,31:159.9
-28,1,31:159.9
-28,2,31:159.9
-28,3,31:159.9
-28,4,31:159.9
-28,5,31:159.9
-28,6,31:159.9
-28,7,31:159.9
-28,18,31:95.5
-28,-19,32:95.5
-28,-6,32:1
-28,-5,32:1
-28,5,32:1
-28,6,32:1
-28,19,32:95.5
-28,-19,33:95.5
-28,-5,33:95.14
-28,5,33:95.14
-28,19,33:95.5
-28,-19,34:95.5
-28,-5,34:95.14
-28,5,34:95.14
-28,19,34:95.5
-28,-20,35:95.5
-28,-5,35:95.14
-28,5,35:95.14
-28,20,35:95.5
-28,-20,36:95.5
-28,-5,36:95.14
-28,5,36:95.14
-28,20,36:95.5
-28,-20,37:95.5
-28,-5,37:95.14
-28,5,37:95.14
-28,20,37:95.5
-28,-21,38:95.5
-28,-5,38:95.14
-28,5,38:95.14
-28,21,38:95.5
-28,-21,39:95.5
-28,-5,39:95.14
-28,5,39:95.14
-28,21,39:95.5
-28,-22,40:95.5
-28,-6,40:95.14
-28,-5,40:95.14
-28,5,40:95.14
-28,6,40:95.14
-28,-22,41:95.5
-28,-6,41:95.14
-28,-5,41:95.14
-28,5,41:95.14
-28,6,41:95.14
-28,22,41:95.5
-28,-6,42:95.14
-28,-5,42:95.14
-28,5,42:95.14
-28,6,42:95.14
-28,22,42:95.5
-28,-23,43:95.5
-28,-6,43:95.14
-28,-5,43:95.14
-28,5,43:95.14
-28,6,43:95.14
-28,-23,44:95.5
-28,-6,44:95.14
-28,-5,44:95.14
-28,5,44:95.14
-28,6,44:95.14
-28,-6,45:95.14
-28,-5,45:95.14
-28,5,45:95.14
-28,6,45:95.14
-28,-24,46:95.5
-28,-6,46:95.14
-28,-5,46:95.14
-28,5,46:95.14
-28,6,46:95.14
-28,-6,47:159.9
-28,-5,47:159.9
-28,-4,47:159.9
-28,5,47:1
-28,-6,48:159.9
-28,-5,48:159.9
-28,-4,48:159.9
-28,5,48:1
-28,-6,49:159.9
-28,-5,49:159.9
-28,-4,49:159.9
-28,5,49:1
-28,26,49:95.5
-28,-6,50:159.9
-28,-5,50:159.9
-28,-4,50:159.9
-28,5,50:1
-28,-26,51:95.5
-28,-6,51:159.9
-28,-5,51:159.9
-28,-4,51:159.9
-28,5,51:1
-28,26,51:95.5
-28,-27,52:95.5
-28,-6,52:159.9
-28,-5,52:159.9
-28,-4,52:159.9
-28,5,52:1
-28,-27,53:95.5
-28,-6,53:159.9
-28,-5,53:159.9
-28,-4,53:159.9
-28,5,53:1
-28,-27,54:95.5
-28,-6,54:159.9
-28,-5,54:159.9
-28,-4,54:159.9
-28,5,54:1
-28,-6,55:159.9
-28,-5,55:159.9
-28,-4,55:159.9
-28,5,55:1
-28,-6,56:159.9
-28,-5,56:159.9
-28,-4,56:159.9
-28,-3,56:1
-28,-2,56:1
-28,-1,56:1
-28,0,56:1
-28,1,56:1
-28,2,56:1
-28,3,56:1
-28,4,56:1
-28,5,56:1
-28,-2,57:159.9
-28,-1,57:1
-28,0,57:1
-28,1,57:1
-28,2,57:159.9
-28,-8,58:35.1
-28,-1,58:1
-28,0,58:1
-28,1,58:1
-28,8,58:35.1
-28,-8,59:85
-28,-1,59:1
-28,0,59:1
-28,1,59:1
-28,8,59:85
-28,-8,60:35.1
-28,-7,60:85
-28,7,60:85
-28,8,60:35.1
-28,-7,61:85
-28,-6,61:35.1
-28,-5,61:85
-28,5,61:85
-28,6,61:35.1
-28,7,61:85
-28,-5,62:85
-28,-4,62:85
-28,4,62:85
-28,5,62:85
-28,-4,63:35.1
-28,4,63:35.1
-28,0,68:156.5
-28,0,69:155.2
-28,0,70:156
-28,-3,71:155
-28,3,71:155
-28,-3,84:125.4
-28,-2,84:126.4
-28,-1,84:126.4
-28,0,84:126.4
-28,1,84:126.4
-28,2,84:126.4
-28,3,84:125.4
-28,-2,123:42
-28,-1,123:42
-28,0,123:42
-28,1,123:42
-28,2,123:42
-28,-3,124:42
-28,3,124:42
-28,-2,125:42
-28,-1,125:42
-28,0,125:42
-28,1,125:42
-28,2,125:42
-28,-2,127:95.9
-28,-1,127:95.9
-28,0,127:95.9
-28,1,127:95.9
-28,2,127:95.9
-28,-2,128:95.9
-28,-1,128:95.9
-28,0,128:95.9
-28,1,128:95.9
-28,2,128:95.9
-28,-2,129:95.9
-28,-1,129:95.9
-28,0,129:95.9
-28,1,129:95.9
-28,2,129:95.9
-28,-2,130:95.9
-28,-1,130:95.9
-28,0,130:95.9
-28,1,130:95.9
-28,2,130:95.9
-27,-12,3:159.9
-27,-11,3:159.9
-27,-10,3:159.9
-27,-9,3:159.9
-27,-8,3:159.9
-27,-7,3:159.9
-27,-6,3:159.9
-27,-5,3:159.9
-27,-4,3:159.9
-27,-3,3:159.9
-27,-2,3:159.9
-27,-1,3:159.9
-27,0,3:159.9
-27,1,3:159.9
-27,2,3:159.9
-27,3,3:159.9
-27,4,3:159.9
-27,5,3:159.9
-27,6,3:159.9
-27,7,3:159.9
-27,8,3:159.9
-27,9,3:159.9
-27,10,3:159.9
-27,11,3:159.9
-27,12,3:159.9
-27,-12,4:159.9
-27,-11,4:159.9
-27,-10,4:159.9
-27,-9,4:159.9
-27,-8,4:159.9
-27,-7,4:159.9
-27,-6,4:159.9
-27,-5,4:159.9
-27,-4,4:159.9
-27,-3,4:159.9
-27,-2,4:159.9
-27,-1,4:159.9
-27,0,4:159.9
-27,1,4:159.9
-27,2,4:159.9
-27,3,4:159.9
-27,4,4:159.9
-27,5,4:159.9
-27,6,4:159.9
-27,7,4:159.9
-27,8,4:159.9
-27,9,4:159.9
-27,10,4:159.9
-27,11,4:159.9
-27,12,4:159.9
-27,-9,5:42
-27,-8,5:42
-27,-7,5:42
-27,-6,5:42
-27,-5,5:42
-27,-4,5:42
-27,-3,5:42
-27,-2,5:42
-27,-1,5:42
-27,0,5:42
-27,1,5:42
-27,2,5:42
-27,3,5:42
-27,4,5:42
-27,5,5:42
-27,6,5:42
-27,7,5:42
-27,8,5:42
-27,9,5:42
-27,-9,6:42
-27,-8,6:42
-27,-7,6:42
-27,-6,6:42
-27,-5,6:42
-27,-4,6:42
-27,-3,6:42
-27,-2,6:42
-27,-1,6:42
-27,0,6:42
-27,1,6:42
-27,2,6:42
-27,3,6:42
-27,4,6:42
-27,5,6:42
-27,6,6:42
-27,7,6:42
-27,8,6:42
-27,9,6:42
-27,-9,7:42
-27,-8,7:42
-27,-7,7:42
-27,-6,7:42
-27,-5,7:42
-27,-4,7:42
-27,-3,7:42
-27,-2,7:42
-27,-1,7:42
-27,0,7:42
-27,1,7:42
-27,2,7:42
-27,3,7:42
-27,4,7:42
-27,5,7:42
-27,6,7:42
-27,7,7:42
-27,8,7:42
-27,9,7:42
-27,-12,8:159.9
-27,-11,8:159.9
-27,-10,8:159.9
-27,-9,8:159.9
-27,-8,8:159.9
-27,-7,8:159.9
-27,-6,8:159.9
-27,-5,8:159.9
-27,-4,8:159.9
-27,-3,8:159.9
-27,-2,8:159.9
-27,-1,8:159.9
-27,0,8:159.9
-27,1,8:159.9
-27,2,8:159.9
-27,3,8:159.9
-27,4,8:159.9
-27,5,8:159.9
-27,6,8:159.9
-27,7,8:159.9
-27,8,8:159.9
-27,9,8:159.9
-27,10,8:159.9
-27,11,8:159.9
-27,12,8:159.9
-27,-12,9:159.9
-27,-11,9:159.9
-27,-10,9:159.9
-27,-9,9:159.9
-27,-8,9:159.9
-27,-7,9:159.9
-27,-6,9:159.9
-27,-5,9:159.9
-27,-4,9:159.9
-27,-3,9:159.9
-27,-2,9:159.9
-27,-1,9:159.9
-27,0,9:159.9
-27,1,9:159.9
-27,2,9:159.9
-27,3,9:159.9
-27,4,9:159.9
-27,5,9:159.9
-27,6,9:159.9
-27,7,9:159.9
-27,8,9:159.9
-27,9,9:159.9
-27,10,9:159.9
-27,11,9:159.9
-27,12,9:159.9
-27,-12,10:159.9
-27,-11,10:159.9
-27,-10,10:159.9
-27,-9,10:159.9
-27,-8,10:159.9
-27,-7,10:159.9
-27,-6,10:159.9
-27,-5,10:159.9
-27,-4,10:159.9
-27,-3,10:159.9
-27,-2,10:159.9
-27,-1,10:159.9
-27,0,10:159.9
-27,1,10:159.9
-27,2,10:159.9
-27,3,10:159.9
-27,4,10:159.9
-27,5,10:159.9
-27,6,10:159.9
-27,7,10:159.9
-27,8,10:159.9
-27,9,10:159.9
-27,10,10:159.9
-27,11,10:159.9
-27,12,10:159.9
-27,-12,11:159.9
-27,-11,11:159.9
-27,-10,11:159.9
-27,-9,11:159.9
-27,-8,11:159.9
-27,-7,11:159.9
-27,-6,11:159.9
-27,-4,11:42
-27,-3,11:42
-27,3,11:42
-27,4,11:42
-27,6,11:159.9
-27,7,11:159.9
-27,8,11:159.9
-27,9,11:159.9
-27,10,11:159.9
-27,11,11:159.9
-27,12,11:159.9
-27,-9,12:159.9
-27,-8,12:159.9
-27,-7,12:159.9
-27,-6,12:159.9
-27,-4,12:42
-27,-3,12:42
-27,3,12:42
-27,4,12:42
-27,6,12:159.9
-27,7,12:159.9
-27,8,12:159.9
-27,9,12:159.9
-27,-9,13:159.9
-27,-8,13:159.9
-27,-7,13:159.9
-27,-6,13:159.9
-27,-4,13:42
-27,-3,13:42
-27,3,13:42
-27,4,13:42
-27,6,13:159.9
-27,7,13:159.9
-27,8,13:159.9
-27,9,13:159.9
-27,-12,14:82
-27,-11,14:82
-27,-10,14:82
-27,-4,14:42
-27,-3,14:42
-27,3,14:42
-27,4,14:42
-27,10,14:82
-27,11,14:82
-27,12,14:82
-27,-12,15:82
-27,-11,15:82
-27,-10,15:82
-27,-4,15:42
-27,-3,15:42
-27,3,15:42
-27,4,15:42
-27,10,15:82
-27,11,15:82
-27,12,15:82
-27,-12,16:82
-27,-11,16:82
-27,-10,16:82
-27,-4,16:42
-27,-3,16:42
-27,3,16:42
-27,4,16:42
-27,10,16:82
-27,11,16:82
-27,12,16:82
-27,-12,17:82
-27,-11,17:82
-27,-10,17:82
-27,-4,17:42
-27,-3,17:42
-27,-2,17:42
-27,2,17:42
-27,3,17:42
-27,4,17:42
-27,10,17:82
-27,11,17:82
-27,12,17:82
-27,-12,18:82
-27,-11,18:82
-27,-10,18:82
-27,-3,18:42
-27,-2,18:42
-27,-1,18:42
-27,0,18:42
-27,1,18:42
-27,2,18:42
-27,3,18:42
-27,10,18:82
-27,11,18:82
-27,12,18:82
-27,-12,19:82
-27,-11,19:82
-27,-10,19:82
-27,-2,19:42
-27,-1,19:42
-27,0,19:42
-27,1,19:42
-27,2,19:42
-27,10,19:82
-27,11,19:82
-27,12,19:82
-27,-12,20:82
-27,-11,20:82
-27,-10,20:82
-27,10,20:82
-27,11,20:82
-27,12,20:82
-27,-12,21:82
-27,-11,21:82
-27,-10,21:82
-27,10,21:82
-27,11,21:82
-27,12,21:82
-27,-12,22:82
-27,-11,22:82
-27,-10,22:82
-27,0,22:35.7
-27,10,22:82
-27,11,22:82
-27,12,22:82
-27,-12,23:82
-27,-11,23:82
-27,-10,23:82
-27,-1,23:35.7
-27,0,23:35.7
-27,1,23:35.7
-27,10,23:82
-27,11,23:82
-27,12,23:82
-27,-21,24:159.9
-27,-20,24:159.9
-27,-19,24:159.9
-27,-18,24:159.9
-27,-17,24:159.9
-27,-16,24:159.9
-27,-15,24:159.9
-27,-14,24:159.9
-27,-13,24:159.9
-27,-12,24:159.9
-27,-11,24:159.9
-27,-10,24:159.9
-27,-9,24:159.9
-27,-8,24:159.9
-27,-7,24:159.9
-27,-6,24:159.9
-27,-1,24:35.7
-27,0,24:35.7
-27,1,24:35.7
-27,6,24:159.9
-27,7,24:159.9
-27,8,24:159.9
-27,9,24:159.9
-27,10,24:159.9
-27,11,24:159.9
-27,12,24:159.9
-27,13,24:159.9
-27,14,24:159.9
-27,15,24:159.9
-27,16,24:159.9
-27,17,24:159.9
-27,18,24:159.9
-27,19,24:159.9
-27,20,24:159.9
-27,21,24:159.9
-27,-21,25:159.9
-27,-20,25:159.9
-27,-19,25:159.9
-27,-18,25:159.9
-27,-17,25:159.9
-27,-16,25:159.9
-27,-15,25:159.9
-27,-14,25:159.9
-27,-13,25:159.9
-27,-12,25:159.9
-27,-11,25:159.9
-27,-10,25:159.9
-27,-9,25:159.9
-27,-8,25:159.9
-27,-7,25:159.9
-27,-6,25:159.9
-27,0,25:35.7
-27,6,25:159.9
-27,7,25:159.9
-27,8,25:159.9
-27,9,25:159.9
-27,10,25:159.9
-27,11,25:159.9
-27,12,25:159.9
-27,13,25:159.9
-27,14,25:159.9
-27,15,25:159.9
-27,16,25:159.9
-27,17,25:159.9
-27,18,25:159.9
-27,19,25:159.9
-27,20,25:159.9
-27,21,25:159.9
-27,-18,26:95.5
-27,-6,26:159.9
-27,-5,26:159.9
-27,-4,26:159.9
-27,-3,26:159.9
-27,-2,26:159.9
-27,-1,26:159.9
-27,0,26:159.9
-27,1,26:159.9
-27,2,26:159.9
-27,3,26:159.9
-27,4,26:159.9
-27,5,26:159.9
-27,6,26:159.9
-27,18,26:95.5
-27,-18,27:95.5
-27,-6,27:159.9
-27,-5,27:159.9
-27,-4,27:159.9
-27,-3,27:159.9
-27,-2,27:159.9
-27,-1,27:159.9
-27,0,27:159.9
-27,1,27:159.9
-27,2,27:159.9
-27,3,27:159.9
-27,4,27:159.9
-27,5,27:159.9
-27,6,27:159.9
-27,18,27:95.5
-27,-18,28:95.5
-27,-6,28:159.9
-27,-5,28:159.9
-27,-4,28:159.9
-27,-3,28:159.9
-27,-2,28:159.9
-27,-1,28:159.9
-27,0,28:159.9
-27,1,28:159.9
-27,2,28:159.9
-27,3,28:159.9
-27,4,28:159.9
-27,5,28:159.9
-27,6,28:159.9
-27,18,28:95.5
-27,-19,29:95.5
-27,-5,29:82
-27,-4,29:82
-27,-3,29:82
-27,-2,29:82
-27,-1,29:82
-27,0,29:82
-27,1,29:82
-27,2,29:82
-27,3,29:82
-27,4,29:82
-27,5,29:82
-27,19,29:95.5
-27,-19,30:95.5
-27,-6,30:159.9
-27,-5,30:159.9
-27,-4,30:159.9
-27,-3,30:159.9
-27,-2,30:159.9
-27,-1,30:159.9
-27,0,30:159.9
-27,1,30:159.9
-27,2,30:159.9
-27,3,30:159.9
-27,4,30:159.9
-27,5,30:159.9
-27,6,30:159.9
-27,19,30:95.5
-27,-19,31:95.5
-27,-6,31:159.9
-27,-5,31:159.9
-27,-4,31:159.9
-27,-3,31:159.9
-27,-2,31:159.9
-27,-1,31:159.9
-27,0,31:159.9
-27,1,31:159.9
-27,2,31:159.9
-27,3,31:159.9
-27,4,31:159.9
-27,5,31:159.9
-27,6,31:159.9
-27,19,31:95.5
-27,-20,32:95.5
-27,-5,32:1
-27,-4,32:1
-27,-3,32:1
-27,3,32:1
-27,4,32:1
-27,5,32:1
-27,20,32:95.5
-27,-20,33:95.5
-27,-4,33:95.14
-27,-3,33:95.14
-27,3,33:95.14
-27,4,33:95.14
-27,20,33:95.5
-27,-20,34:95.5
-27,-4,34:95.14
-27,-3,34:95.14
-27,3,34:95.14
-27,4,34:95.14
-27,20,34:95.5
-27,-21,35:95.5
-27,-4,35:95.14
-27,-3,35:95.14
-27,3,35:95.14
-27,4,35:95.14
-27,21,35:95.5
-27,-21,36:95.5
-27,-4,36:95.14
-27,-3,36:95.14
-27,3,36:95.14
-27,4,36:95.14
-27,21,36:95.5
-27,-21,37:95.5
-27,-4,37:95.14
-27,-3,37:95.14
-27,3,37:95.14
-27,4,37:95.14
-27,21,37:95.5
-27,-22,38:95.5
-27,-4,38:95.14
-27,-3,38:95.14
-27,3,38:95.14
-27,4,38:95.14
-27,22,38:95.5
-27,-22,39:95.5
-27,-4,39:95.14
-27,-3,39:95.14
-27,3,39:95.14
-27,4,39:95.14
-27,22,39:95.5
-27,-23,40:95.5
-27,-5,40:95.14
-27,-4,40:95.14
-27,-3,40:95.14
-27,3,40:95.14
-27,4,40:95.14
-27,5,40:95.14
-27,23,40:95.5
-27,-23,41:95.5
-27,-5,41:95.14
-27,-4,41:95.14
-27,-3,41:95.14
-27,3,41:95.14
-27,4,41:95.14
-27,5,41:95.14
-27,23,41:95.5
-27,-23,42:95.5
-27,-5,42:95.14
-27,-4,42:95.14
-27,-3,42:95.14
-27,3,42:95.14
-27,4,42:95.14
-27,5,42:95.14
-27,23,42:95.5
-27,-24,43:95.5
-27,-5,43:95.14
-27,-4,43:95.14
-27,-3,43:95.14
-27,3,43:95.14
-27,4,43:95.14
-27,5,43:95.14
-27,24,43:95.5
-27,-24,44:95.5
-27,-5,44:95.14
-27,-4,44:95.14
-27,-3,44:95.14
-27,3,44:95.14
-27,4,44:95.14
-27,5,44:95.14
-27,-24,45:95.5
-27,-5,45:95.14
-27,-4,45:95.14
-27,-3,45:95.14
-27,3,45:95.14
-27,4,45:95.14
-27,5,45:95.14
-27,-25,46:95.5
-27,-5,46:95.14
-27,-4,46:95.14
-27,-3,46:95.14
-27,3,46:95.14
-27,4,46:95.14
-27,5,46:95.14
-27,25,46:95.5
-27,-6,47:159.9
-27,-5,47:159.9
-27,-4,47:159.9
-27,-3,47:1
-27,3,47:1
-27,4,47:1
-27,5,47:159.9
-27,6,47:159.9
-27,25,47:95.5
-27,-6,48:159.9
-27,-5,48:159.9
-27,-4,48:159.9
-27,-3,48:1
-27,3,48:1
-27,4,48:1
-27,5,48:159.9
-27,6,48:159.9
-27,-26,49:95.5
-27,-6,49:159.9
-27,-5,49:159.9
-27,-4,49:159.9
-27,-3,49:1
-27,3,49:1
-27,4,49:1
-27,5,49:159.9
-27,6,49:159.9
-27,26,49:95.5
-27,-27,50:95.5
-27,-6,50:159.9
-27,-5,50:159.9
-27,-4,50:159.9
-27,-3,50:1
-27,3,50:1
-27,4,50:1
-27,5,50:159.9
-27,6,50:159.9
-27,-27,51:95.5
-27,-6,51:159.9
-27,-5,51:159.9
-27,-4,51:159.9
-27,-3,51:1
-27,3,51:1
-27,4,51:1
-27,5,51:159.9
-27,6,51:159.9
-27,27,51:95.5
-27,-28,52:95.5
-27,-6,52:159.9
-27,-5,52:159.9
-27,-4,52:159.9
-27,-3,52:1
-27,3,52:1
-27,4,52:1
-27,5,52:159.9
-27,6,52:159.9
-27,28,52:95.5
-27,-28,53:95.5
-27,-6,53:159.9
-27,-5,53:159.9
-27,-4,53:159.9
-27,-3,53:1
-27,3,53:1
-27,4,53:1
-27,5,53:159.9
-27,6,53:159.9
-27,28,53:95.5
-27,-28,54:95.5
-27,-6,54:159.9
-27,-5,54:159.9
-27,-4,54:159.9
-27,-3,54:1
-27,3,54:1
-27,4,54:1
-27,5,54:159.9
-27,6,54:159.9
-27,28,54:95.5
-27,-6,55:159.9
-27,-5,55:159.9
-27,-4,55:159.9
-27,-3,55:1
-27,3,55:1
-27,4,55:1
-27,5,55:159.9
-27,6,55:159.9
-27,-6,56:159.9
-27,-5,56:159.9
-27,-4,56:159.9
-27,-3,56:1
-27,-2,56:1
-27,-1,56:1
-27,0,56:1
-27,1,56:1
-27,2,56:1
-27,3,56:1
-27,4,56:1
-27,5,56:159.9
-27,6,56:159.9
-27,-1,57:159.9
-27,0,57:159.9
-27,1,57:159.9
-27,-7,58:35.1
-27,7,58:35.1
-27,-7,59:85
-27,7,59:85
-27,-7,60:35.1
-27,-6,60:85
-27,6,60:85
-27,7,60:35.1
-27,-6,61:85
-27,-5,61:35.1
-27,-4,61:85
-27,4,61:85
-27,5,61:35.1
-27,6,61:85
-27,-4,62:85
-27,-3,62:85
-27,3,62:85
-27,4,62:85
-27,-3,63:35.1
-27,3,63:35.1
-27,0,69:156.5
-27,0,70:155.2
-27,-2,71:155
-27,-1,71:155
-27,0,71:155
-27,1,71:155
-27,2,71:155
-27,-2,84:125.4
-27,-1,84:125.4
-27,0,84:125.4
-27,1,84:125.4
-27,2,84:125.4
-27,-2,124:42
-27,-1,124:42
-27,0,124:42
-27,1,124:42
-27,2,124:42
-26,-14,3:159.9
-26,-13,3:159.9
-26,-12,3:159.9
-26,-11,3:159.9
-26,-10,3:159.9
-26,-9,3:159.9
-26,-8,3:159.9
-26,-7,3:159.9
-26,-6,3:159.9
-26,-5,3:159.9
-26,-4,3:159.9
-26,-3,3:159.9
-26,-2,3:159.9
-26,-1,3:159.9
-26,0,3:159.9
-26,1,3:159.9
-26,2,3:159.9
-26,3,3:159.9
-26,4,3:159.9
-26,5,3:159.9
-26,6,3:159.9
-26,7,3:159.9
-26,8,3:159.9
-26,9,3:159.9
-26,10,3:159.9
-26,11,3:159.9
-26,12,3:159.9
-26,13,3:159.9
-26,14,3:159.9
-26,-14,4:159.9
-26,-13,4:159.9
-26,-12,4:159.9
-26,-11,4:159.9
-26,-10,4:159.9
-26,-9,4:159.9
-26,-8,4:159.9
-26,-7,4:159.9
-26,-6,4:159.9
-26,-5,4:159.9
-26,-4,4:159.9
-26,-3,4:159.9
-26,-2,4:159.9
-26,-1,4:159.9
-26,0,4:159.9
-26,1,4:159.9
-26,2,4:159.9
-26,3,4:159.9
-26,4,4:159.9
-26,5,4:159.9
-26,6,4:159.9
-26,7,4:159.9
-26,8,4:159.9
-26,9,4:159.9
-26,10,4:159.9
-26,11,4:159.9
-26,12,4:159.9
-26,13,4:159.9
-26,14,4:159.9
-26,-11,5:42
-26,-10,5:42
-26,-9,5:42
-26,-8,5:42
-26,-7,5:42
-26,-6,5:42
-26,-5,5:42
-26,-4,5:42
-26,-3,5:42
-26,-2,5:42
-26,-1,5:42
-26,0,5:42
-26,1,5:42
-26,2,5:42
-26,3,5:42
-26,4,5:42
-26,5,5:42
-26,6,5:42
-26,7,5:42
-26,8,5:42
-26,9,5:42
-26,10,5:42
-26,11,5:42
-26,-11,6:42
-26,-10,6:42
-26,-9,6:42
-26,-8,6:42
-26,-7,6:42
-26,-6,6:42
-26,-5,6:42
-26,-4,6:42
-26,-3,6:42
-26,-2,6:42
-26,-1,6:42
-26,0,6:42
-26,1,6:42
-26,2,6:42
-26,3,6:42
-26,4,6:42
-26,5,6:42
-26,6,6:42
-26,7,6:42
-26,8,6:42
-26,9,6:42
-26,10,6:42
-26,11,6:42
-26,-11,7:42
-26,-10,7:42
-26,-9,7:42
-26,-8,7:42
-26,-7,7:42
-26,-6,7:42
-26,-5,7:42
-26,-4,7:42
-26,-3,7:42
-26,-2,7:42
-26,-1,7:42
-26,0,7:42
-26,1,7:42
-26,2,7:42
-26,3,7:42
-26,4,7:42
-26,5,7:42
-26,6,7:42
-26,7,7:42
-26,8,7:42
-26,9,7:42
-26,10,7:42
-26,11,7:42
-26,-14,8:159.9
-26,-13,8:159.9
-26,-12,8:159.9
-26,-11,8:159.9
-26,-10,8:159.9
-26,-9,8:159.9
-26,-8,8:159.9
-26,-7,8:159.9
-26,-6,8:159.9
-26,-5,8:159.9
-26,-4,8:159.9
-26,-3,8:159.9
-26,-2,8:159.9
-26,-1,8:159.9
-26,0,8:159.9
-26,1,8:159.9
-26,2,8:159.9
-26,3,8:159.9
-26,4,8:159.9
-26,5,8:159.9
-26,6,8:159.9
-26,7,8:159.9
-26,8,8:159.9
-26,9,8:159.9
-26,10,8:159.9
-26,11,8:159.9
-26,12,8:159.9
-26,13,8:159.9
-26,14,8:159.9
-26,-14,9:159.9
-26,-13,9:159.9
-26,-12,9:159.9
-26,-11,9:159.9
-26,-10,9:159.9
-26,-9,9:159.9
-26,-8,9:159.9
-26,-7,9:159.9
-26,-6,9:159.9
-26,-5,9:159.9
-26,-4,9:159.9
-26,-3,9:159.9
-26,-2,9:159.9
-26,-1,9:159.9
-26,0,9:159.9
-26,1,9:159.9
-26,2,9:159.9
-26,3,9:159.9
-26,4,9:159.9
-26,5,9:159.9
-26,6,9:159.9
-26,7,9:159.9
-26,8,9:159.9
-26,9,9:159.9
-26,10,9:159.9
-26,11,9:159.9
-26,12,9:159.9
-26,13,9:159.9
-26,14,9:159.9
-26,-14,10:159.9
-26,-13,10:159.9
-26,-12,10:159.9
-26,-11,10:159.9
-26,-10,10:159.9
-26,-9,10:159.9
-26,-8,10:159.9
-26,-7,10:159.9
-26,-6,10:159.9
-26,-5,10:159.9
-26,-4,10:159.9
-26,-3,10:159.9
-26,-2,10:159.9
-26,-1,10:159.9
-26,0,10:159.9
-26,1,10:159.9
-26,2,10:159.9
-26,3,10:159.9
-26,4,10:159.9
-26,5,10:159.9
-26,6,10:159.9
-26,7,10:159.9
-26,8,10:159.9
-26,9,10:159.9
-26,10,10:159.9
-26,11,10:159.9
-26,12,10:159.9
-26,13,10:159.9
-26,14,10:159.9
-26,-14,11:159.9
-26,-13,11:159.9
-26,-11,11:159.9
-26,-10,11:159.9
-26,10,11:159.9
-26,11,11:159.9
-26,13,11:159.9
-26,14,11:159.9
-26,-11,12:159.9
-26,-10,12:159.9
-26,10,12:159.9
-26,11,12:159.9
-26,-12,13:159.9
-26,-11,13:159.9
-26,-10,13:159.9
-26,10,13:159.9
-26,11,13:159.9
-26,12,13:159.9
-26,-14,14:82
-26,-13,14:82
-26,13,14:82
-26,14,14:82
-26,-14,15:82
-26,-13,15:82
-26,13,15:82
-26,14,15:82
-26,-14,16:82
-26,-13,16:82
-26,13,16:82
-26,14,16:82
-26,-14,17:82
-26,-13,17:82
-26,13,17:82
-26,14,17:82
-26,-14,18:82
-26,-13,18:82
-26,13,18:82
-26,14,18:82
-26,-14,19:82
-26,-13,19:82
-26,13,19:82
-26,14,19:82
-26,-14,20:82
-26,-13,20:82
-26,13,20:82
-26,14,20:82
-26,-14,21:82
-26,-13,21:82
-26,13,21:82
-26,14,21:82
-26,-14,22:82
-26,-13,22:82
-26,13,22:82
-26,14,22:82
-26,-14,23:82
-26,-13,23:82
-26,0,23:35.7
-26,13,23:82
-26,14,23:82
-26,-23,24:159.9
-26,-22,24:159.9
-26,-21,24:159.9
-26,-20,24:159.9
-26,-19,24:159.9
-26,-18,24:159.9
-26,-17,24:159.9
-26,-16,24:159.9
-26,-15,24:159.9
-26,-14,24:159.9
-26,-13,24:159.9
-26,-12,24:159.9
-26,-11,24:159.9
-26,-10,24:159.9
-26,-1,24:35.7
-26,0,24:35.7
-26,1,24:35.7
-26,10,24:159.9
-26,11,24:159.9
-26,12,24:159.9
-26,13,24:159.9
-26,14,24:159.9
-26,15,24:159.9
-26,16,24:159.9
-26,17,24:159.9
-26,18,24:159.9
-26,19,24:159.9
-26,20,24:159.9
-26,21,24:159.9
-26,22,24:159.9
-26,23,24:159.9
-26,-23,25:159.9
-26,-22,25:159.9
-26,-21,25:159.9
-26,-20,25:159.9
-26,-19,25:159.9
-26,-18,25:159.9
-26,-17,25:159.9
-26,-16,25:159.9
-26,-15,25:159.9
-26,-14,25:159.9
-26,-13,25:159.9
-26,-12,25:159.9
-26,-11,25:159.9
-26,-10,25:159.9
-26,-1,25:35.7
-26,1,25:35.7
-26,10,25:159.9
-26,11,25:159.9
-26,12,25:159.9
-26,13,25:159.9
-26,14,25:159.9
-26,15,25:159.9
-26,16,25:159.9
-26,17,25:159.9
-26,18,25:159.9
-26,19,25:159.9
-26,20,25:159.9
-26,21,25:159.9
-26,22,25:159.9
-26,23,25:159.9
-26,-19,26:95.5
-26,-6,26:159.9
-26,-5,26:159.9
-26,-4,26:159.9
-26,-3,26:159.9
-26,-2,26:159.9
-26,-1,26:159.9
-26,0,26:159.9
-26,1,26:159.9
-26,2,26:159.9
-26,3,26:159.9
-26,4,26:159.9
-26,5,26:159.9
-26,6,26:159.9
-26,19,26:95.5
-26,-19,27:95.5
-26,-6,27:159.9
-26,-5,27:159.9
-26,-4,27:159.9
-26,-3,27:159.9
-26,-2,27:159.9
-26,-1,27:159.9
-26,0,27:159.9
-26,1,27:159.9
-26,2,27:159.9
-26,3,27:159.9
-26,4,27:159.9
-26,5,27:159.9
-26,6,27:159.9
-26,19,27:95.5
-26,-19,28:95.5
-26,-6,28:159.9
-26,-5,28:159.9
-26,-4,28:159.9
-26,-3,28:159.9
-26,-2,28:159.9
-26,-1,28:159.9
-26,0,28:159.9
-26,1,28:159.9
-26,2,28:159.9
-26,3,28:159.9
-26,4,28:159.9
-26,5,28:159.9
-26,6,28:159.9
-26,19,28:95.5
-26,-20,29:95.5
-26,-4,29:82
-26,-3,29:82
-26,-2,29:82
-26,-1,29:82
-26,0,29:82
-26,1,29:82
-26,2,29:82
-26,3,29:82
-26,4,29:82
-26,20,29:95.5
-26,-20,30:95.5
-26,-6,30:159.9
-26,-5,30:159.9
-26,-4,30:159.9
-26,-3,30:159.9
-26,-2,30:159.9
-26,-1,30:159.9
-26,0,30:159.9
-26,1,30:159.9
-26,2,30:159.9
-26,3,30:159.9
-26,4,30:159.9
-26,5,30:159.9
-26,6,30:159.9
-26,20,30:95.5
-26,-20,31:95.5
-26,-6,31:159.9
-26,-5,31:159.9
-26,-4,31:159.9
-26,-3,31:159.9
-26,-2,31:159.9
-26,-1,31:159.9
-26,0,31:159.9
-26,1,31:159.9
-26,2,31:159.9
-26,3,31:159.9
-26,4,31:159.9
-26,5,31:159.9
-26,6,31:159.9
-26,20,31:95.5
-26,-21,32:95.5
-26,-4,32:1
-26,-3,32:1
-26,-2,32:1
-26,-1,32:1
-26,0,32:1
-26,1,32:1
-26,2,32:1
-26,3,32:1
-26,4,32:1
-26,21,32:95.5
-26,-21,33:95.5
-26,-2,33:95.14
-26,-1,33:95.14
-26,0,33:95.14
-26,1,33:95.14
-26,2,33:95.14
-26,21,33:95.5
-26,-21,34:95.5
-26,-2,34:95.14
-26,-1,34:95.14
-26,0,34:95.14
-26,1,34:95.14
-26,2,34:95.14
-26,21,34:95.5
-26,-22,35:95.5
-26,-2,35:95.14
-26,-1,35:95.14
-26,0,35:95.14
-26,1,35:95.14
-26,2,35:95.14
-26,22,35:95.5
-26,-22,36:95.5
-26,-2,36:95.14
-26,-1,36:95.14
-26,0,36:95.14
-26,1,36:95.14
-26,2,36:95.14
-26,22,36:95.5
-26,-22,37:95.5
-26,-2,37:95.14
-26,-1,37:95.14
-26,0,37:95.14
-26,1,37:95.14
-26,2,37:95.14
-26,22,37:95.5
-26,-23,38:95.5
-26,-2,38:95.14
-26,-1,38:95.14
-26,0,38:95.14
-26,1,38:95.14
-26,2,38:95.14
-26,23,38:95.5
-26,-23,39:95.5
-26,-2,39:95.14
-26,-1,39:95.14
-26,0,39:95.14
-26,1,39:95.14
-26,2,39:95.14
-26,23,39:95.5
-26,-24,40:95.5
-26,-4,40:95.14
-26,-3,40:95.14
-26,-2,40:95.14
-26,-1,40:95.14
-26,0,40:95.14
-26,1,40:95.14
-26,2,40:95.14
-26,4,40:95.14
-26,24,40:95.5
-26,-24,41:95.5
-26,-4,41:95.14
-26,-3,41:95.14
-26,-2,41:95.14
-26,-1,41:95.14
-26,0,41:95.14
-26,1,41:95.14
-26,2,41:95.14
-26,3,41:95.14
-26,4,41:95.14
-26,24,41:95.5
-26,-24,42:95.5
-26,-4,42:95.14
-26,-3,42:95.14
-26,-2,42:95.14
-26,-1,42:95.14
-26,0,42:95.14
-26,1,42:95.14
-26,2,42:95.14
-26,3,42:95.14
-26,4,42:95.14
-26,24,42:95.5
-26,-25,43:95.5
-26,-4,43:95.14
-26,-3,43:95.14
-26,-2,43:95.14
-26,-1,43:95.14
-26,0,43:95.14
-26,1,43:95.14
-26,2,43:95.14
-26,3,43:95.14
-26,4,43:95.14
-26,25,43:95.5
-26,-25,44:95.5
-26,-4,44:95.14
-26,-3,44:95.14
-26,-2,44:95.14
-26,-1,44:95.14
-26,0,44:95.14
-26,1,44:95.14
-26,2,44:95.14
-26,3,44:95.14
-26,4,44:95.14
-26,-25,45:95.5
-26,-4,45:95.14
-26,-3,45:95.14
-26,-2,45:95.14
-26,-1,45:95.14
-26,0,45:95.14
-26,1,45:95.14
-26,2,45:95.14
-26,3,45:95.14
-26,4,45:95.14
-26,-26,46:95.5
-26,-4,46:95.14
-26,-3,46:95.14
-26,-2,46:95.14
-26,-1,46:95.14
-26,0,46:95.14
-26,1,46:95.14
-26,2,46:95.14
-26,3,46:95.14
-26,4,46:95.14
-26,-26,47:35.7
-26,-6,47:159.9
-26,-5,47:159.9
-26,-4,47:159.9
-26,-2,47:1
-26,-1,47:1
-26,0,47:1
-26,1,47:1
-26,2,47:1
-26,5,47:159.9
-26,6,47:159.9
-26,26,47:35.7
-26,-26,48:35.7
-26,-6,48:159.9
-26,-5,48:159.9
-26,-4,48:159.9
-26,-2,48:1
-26,-1,48:1
-26,0,48:1
-26,1,48:1
-26,2,48:1
-26,5,48:159.9
-26,6,48:159.9
-26,26,48:35.7
-26,-27,49:35.7
-26,-26,49:35.7
-26,-6,49:159.9
-26,-5,49:159.9
-26,-4,49:159.9
-26,-2,49:1
-26,-1,49:1
-26,0,49:1
-26,1,49:1
-26,2,49:1
-26,5,49:159.9
-26,6,49:159.9
-26,26,49:35.7
-26,27,49:35.7
-26,-27,50:35.7
-26,-26,50:35.7
-26,-6,50:159.9
-26,-5,50:159.9
-26,-4,50:159.9
-26,-2,50:1
-26,-1,50:1
-26,0,50:1
-26,1,50:1
-26,2,50:1
-26,5,50:159.9
-26,6,50:159.9
-26,26,50:35.7
-26,27,50:35.7
-26,28,50:95.5
-26,-28,51:95.5
-26,-27,51:35.7
-26,-26,51:35.7
-26,-6,51:159.9
-26,-5,51:159.9
-26,-4,51:159.9
-26,-2,51:1
-26,-1,51:1
-26,0,51:1
-26,1,51:1
-26,2,51:1
-26,5,51:159.9
-26,6,51:159.9
-26,26,51:35.7
-26,27,51:35.7
-26,28,51:95.5
-26,-27,52:35.7
-26,-26,52:35.7
-26,-6,52:159.9
-26,-5,52:159.9
-26,-4,52:159.9
-26,-2,52:1
-26,-1,52:1
-26,0,52:1
-26,1,52:1
-26,2,52:1
-26,5,52:159.9
-26,6,52:159.9
-26,26,52:35.7
-26,27,52:35.7
-26,29,52:95.5
-26,-27,53:35.7
-26,-6,53:159.9
-26,-5,53:159.9
-26,-4,53:159.9
-26,-2,53:1
-26,-1,53:1
-26,0,53:1
-26,1,53:1
-26,2,53:1
-26,5,53:159.9
-26,6,53:159.9
-26,27,53:35.7
-26,29,53:95.5
-26,-27,54:35.7
-26,-6,54:159.9
-26,-5,54:159.9
-26,-4,54:159.9
-26,-2,54:1
-26,-1,54:1
-26,0,54:1
-26,1,54:1
-26,2,54:1
-26,5,54:159.9
-26,6,54:159.9
-26,27,54:35.7
-26,29,54:95.5
-26,-6,55:159.9
-26,-5,55:159.9
-26,-4,55:159.9
-26,-2,55:1
-26,-1,55:1
-26,0,55:1
-26,1,55:1
-26,2,55:1
-26,5,55:159.9
-26,6,55:159.9
-26,-6,56:159.9
-26,-5,56:159.9
-26,-4,56:159.9
-26,-2,56:1
-26,-1,56:1
-26,0,56:1
-26,1,56:1
-26,2,56:1
-26,5,56:159.9
-26,6,56:159.9
-26,-6,58:35.1
-26,6,58:35.1
-26,-6,59:85
-26,6,59:85
-26,-6,60:35.1
-26,-5,60:85
-26,5,60:85
-26,6,60:35.1
-26,-5,61:85
-26,-4,61:35.1
-26,-3,61:85
-26,3,61:85
-26,4,61:35.1
-26,5,61:85
-26,-3,62:85
-26,3,62:85
-25,-15,3:159.9
-25,-14,3:159.9
-25,-13,3:159.9
-25,-12,3:159.9
-25,-11,3:159.9
-25,-10,3:159.9
-25,-9,3:159.9
-25,-8,3:159.9
-25,-7,3:159.9
-25,-6,3:159.9
-25,-5,3:159.9
-25,-4,3:159.9
-25,-3,3:159.9
-25,-2,3:159.9
-25,-1,3:159.9
-25,0,3:159.9
-25,1,3:159.9
-25,2,3:159.9
-25,3,3:159.9
-25,4,3:159.9
-25,5,3:159.9
-25,6,3:159.9
-25,7,3:159.9
-25,8,3:159.9
-25,9,3:159.9
-25,10,3:159.9
-25,11,3:159.9
-25,12,3:159.9
-25,13,3:159.9
-25,14,3:159.9
-25,15,3:159.9
-25,-15,4:159.9
-25,-14,4:159.9
-25,-13,4:159.9
-25,-12,4:159.9
-25,-11,4:159.9
-25,-10,4:159.9
-25,-9,4:159.9
-25,-8,4:159.9
-25,-7,4:159.9
-25,-6,4:159.9
-25,-5,4:159.9
-25,-4,4:159.9
-25,-3,4:159.9
-25,-2,4:159.9
-25,-1,4:159.9
-25,0,4:159.9
-25,1,4:159.9
-25,2,4:159.9
-25,3,4:159.9
-25,4,4:159.9
-25,5,4:159.9
-25,6,4:159.9
-25,7,4:159.9
-25,8,4:159.9
-25,9,4:159.9
-25,10,4:159.9
-25,11,4:159.9
-25,12,4:159.9
-25,13,4:159.9
-25,14,4:159.9
-25,15,4:159.9
-25,-13,5:42
-25,-12,5:42
-25,-11,5:42
-25,-10,5:42
-25,-9,5:42
-25,-8,5:42
-25,-7,5:42
-25,-6,5:42
-25,-5,5:42
-25,-4,5:42
-25,-3,5:42
-25,-2,5:42
-25,-1,5:42
-25,0,5:42
-25,1,5:42
-25,2,5:42
-25,3,5:42
-25,4,5:42
-25,5,5:42
-25,6,5:42
-25,7,5:42
-25,8,5:42
-25,9,5:42
-25,10,5:42
-25,11,5:42
-25,12,5:42
-25,13,5:42
-25,-13,6:42
-25,-12,6:42
-25,-11,6:42
-25,-10,6:42
-25,-9,6:42
-25,-8,6:42
-25,-7,6:42
-25,-6,6:42
-25,-5,6:42
-25,-4,6:42
-25,-3,6:42
-25,-2,6:42
-25,-1,6:42
-25,0,6:42
-25,1,6:42
-25,2,6:42
-25,3,6:42
-25,4,6:42
-25,5,6:42
-25,6,6:42
-25,7,6:42
-25,8,6:42
-25,9,6:42
-25,10,6:42
-25,11,6:42
-25,12,6:42
-25,13,6:42
-25,-13,7:42
-25,-12,7:42
-25,-11,7:42
-25,-10,7:42
-25,-9,7:42
-25,-8,7:42
-25,-7,7:42
-25,-6,7:42
-25,-5,7:42
-25,-4,7:42
-25,-3,7:42
-25,-2,7:42
-25,-1,7:42
-25,0,7:42
-25,1,7:42
-25,2,7:42
-25,3,7:42
-25,4,7:42
-25,5,7:42
-25,6,7:42
-25,7,7:42
-25,8,7:42
-25,9,7:42
-25,10,7:42
-25,11,7:42
-25,12,7:42
-25,13,7:42
-25,-15,8:159.9
-25,-14,8:159.9
-25,-13,8:159.9
-25,-12,8:159.9
-25,-11,8:159.9
-25,-10,8:159.9
-25,-9,8:159.9
-25,-8,8:159.9
-25,-7,8:159.9
-25,-6,8:159.9
-25,-5,8:159.9
-25,-4,8:159.9
-25,-3,8:159.9
-25,-2,8:159.9
-25,-1,8:159.9
-25,0,8:159.9
-25,1,8:159.9
-25,2,8:159.9
-25,3,8:159.9
-25,4,8:159.9
-25,5,8:159.9
-25,6,8:159.9
-25,7,8:159.9
-25,8,8:159.9
-25,9,8:159.9
-25,10,8:159.9
-25,11,8:159.9
-25,12,8:159.9
-25,13,8:159.9
-25,14,8:159.9
-25,15,8:159.9
-25,-15,9:159.9
-25,-14,9:159.9
