[META]
version=2.0
spawnOnBlockType=2
spawnSunlight=True
spawnDarkness=False
spawnWater=False
spawnLava=False
underFill=True
randomRotation=True
dig=True
tree=True
branch=False
needsFoundation=True
rarity=1
collisionPercentage=1
spawnElevationMin=0
spawnElevationMax=256
spawnInBiome=Jungle
[DATA]
-40,-4,1:1
-40,-3,1:1
-40,-2,1:1
-40,-1,1:1
-40,0,1:1
-40,-4,2:1
-40,-3,2:1
-40,-2,2:1
-40,-1,2:1
-40,0,2:1
-40,-4,3:1
-40,-3,3:1
-40,-2,3:1
-40,-1,3:1
-40,0,3:1
-39,-5,1:1
-39,-4,1:1
-39,-3,1:1
-39,-2,1:1
-39,-1,1:1
-39,0,1:1
-39,1,1:1
-39,-5,2:1
-39,-4,2:1
-39,-3,2:1
-39,-2,2:1
-39,-1,2:1
-39,0,2:1
-39,1,2:1
-39,-5,3:1
-39,-4,3:1
-39,-3,3:1
-39,-2,3:1
-39,-1,3:1
-39,0,3:1
-39,1,3:1
-38,-5,1:1
-38,-4,1:1
-38,-3,1:1
-38,-2,1:1
-38,-1,1:1
-38,0,1:1
-38,1,1:1
-38,-5,2:1
-38,-4,2:1
-38,-3,2:1
-38,-2,2:1
-38,-1,2:1
-38,0,2:1
-38,1,2:1
-38,-5,3:1
-38,-4,3:1
-38,-3,3:1
-38,-2,3:1
-38,-1,3:1
-38,0,3:1
-38,1,3:1
-37,-18,1:1
-37,-17,1:1
-37,-16,1:1
-37,-15,1:1
-37,-6,1:1
-37,-5,1:1
-37,-4,1:1
-37,-3,1:1
-37,-2,1:1
-37,-1,1:1
-37,0,1:1
-37,1,1:1
-37,2,1:1
-37,11,1:1
-37,12,1:1
-37,13,1:1
-37,14,1:1
-37,-18,2:1
-37,-17,2:1
-37,-16,2:1
-37,-15,2:1
-37,-6,2:1
-37,-5,2:1
-37,-4,2:1
-37,-3,2:1
-37,-2,2:1
-37,-1,2:1
-37,0,2:1
-37,1,2:1
-37,2,2:1
-37,11,2:1
-37,12,2:1
-37,13,2:1
-37,14,2:1
-37,-18,3:1
-37,-17,3:1
-37,-16,3:1
-37,-15,3:1
-37,-6,3:1
-37,-5,3:1
-37,-4,3:1
-37,-3,3:1
-37,-2,3:1
-37,-1,3:1
-37,0,3:1
-37,1,3:1
-37,2,3:1
-37,11,3:1
-37,12,3:1
-37,13,3:1
-37,14,3:1
-36,-20,1:1
-36,-19,1:1
-36,-18,1:1
-36,-17,1:1
-36,-16,1:1
-36,-15,1:1
-36,-6,1:1
-36,-5,1:1
-36,-4,1:1
-36,-3,1:1
-36,-2,1:1
-36,-1,1:1
-36,0,1:1
-36,1,1:1
-36,2,1:1
-36,11,1:1
-36,12,1:1
-36,13,1:1
-36,14,1:1
-36,15,1:1
-36,16,1:1
-36,-20,2:1
-36,-19,2:1
-36,-18,2:1
-36,-17,2:1
-36,-16,2:1
-36,-15,2:1
-36,-6,2:1
-36,-5,2:1
-36,-4,2:1
-36,-3,2:1
-36,-2,2:1
-36,-1,2:1
-36,0,2:1
-36,1,2:1
-36,2,2:1
-36,11,2:1
-36,12,2:1
-36,13,2:1
-36,14,2:1
-36,15,2:1
-36,16,2:1
-36,-20,3:1
-36,-19,3:1
-36,-18,3:1
-36,-17,3:1
-36,-16,3:1
-36,-15,3:1
-36,-6,3:1
-36,-5,3:1
-36,-4,3:1
-36,-3,3:1
-36,-2,3:1
-36,-1,3:1
-36,0,3:1
-36,1,3:1
-36,2,3:1
-36,11,3:1
-36,12,3:1
-36,13,3:1
-36,14,3:1
-36,15,3:1
-36,16,3:1
-35,-20,1:1
-35,-19,1:1
-35,-18,1:1
-35,-17,1:1
-35,-16,1:1
-35,-15,1:1
-35,-14,1:1
-35,-13,1:1
-35,-6,1:1
-35,-5,1:1
-35,-4,1:1
-35,-3,1:1
-35,-2,1:1
-35,-1,1:1
-35,0,1:1
-35,1,1:1
-35,2,1:1
-35,9,1:1
-35,10,1:1
-35,11,1:1
-35,12,1:1
-35,13,1:1
-35,14,1:1
-35,15,1:1
-35,16,1:1
-35,-20,2:1
-35,-19,2:1
-35,-18,2:1
-35,-17,2:1
-35,-16,2:1
-35,-15,2:1
-35,-14,2:1
-35,-13,2:1
-35,-6,2:1
-35,-5,2:1
-35,-4,2:1
-35,-3,2:1
-35,-2,2:1
-35,-1,2:1
-35,0,2:1
-35,1,2:1
-35,2,2:1
-35,9,2:1
-35,10,2:1
-35,11,2:1
-35,12,2:1
-35,13,2:1
-35,14,2:1
-35,15,2:1
-35,16,2:1
-35,-20,3:1
-35,-19,3:1
-35,-18,3:1
-35,-17,3:1
-35,-16,3:1
-35,-15,3:1
-35,-14,3:1
-35,-13,3:1
-35,-6,3:1
-35,-5,3:1
-35,-4,3:1
-35,-3,3:1
-35,-2,3:1
-35,-1,3:1
-35,0,3:1
-35,1,3:1
-35,2,3:1
-35,9,3:1
-35,10,3:1
-35,11,3:1
-35,12,3:1
-35,13,3:1
-35,14,3:1
-35,15,3:1
-35,16,3:1
-34,-20,1:1
-34,-19,1:1
-34,-18,1:1
-34,-17,1:1
-34,-16,1:1
-34,-15,1:1
-34,-14,1:1
-34,-13,1:1
-34,-6,1:1
-34,-5,1:1
-34,-4,1:1
-34,-3,1:1
-34,-2,1:1
-34,-1,1:1
-34,0,1:1
-34,1,1:1
-34,2,1:1
-34,9,1:1
-34,10,1:1
-34,11,1:1
-34,12,1:1
-34,13,1:1
-34,14,1:1
-34,15,1:1
-34,16,1:1
-34,-20,2:1
-34,-19,2:1
-34,-18,2:1
-34,-17,2:1
-34,-16,2:1
-34,-15,2:1
-34,-14,2:1
-34,-13,2:1
-34,-6,2:1
-34,-5,2:1
-34,-4,2:1
-34,-3,2:1
-34,-2,2:1
-34,-1,2:1
-34,0,2:1
-34,1,2:1
-34,2,2:1
-34,9,2:1
-34,10,2:1
-34,11,2:1
-34,12,2:1
-34,13,2:1
-34,14,2:1
-34,15,2:1
-34,16,2:1
-34,-20,3:1
-34,-19,3:1
-34,-18,3:1
-34,-17,3:1
-34,-16,3:1
-34,-15,3:1
-34,-14,3:1
-34,-13,3:1
-34,-6,3:1
-34,-5,3:1
-34,-4,3:1
-34,-3,3:1
-34,-2,3:1
-34,-1,3:1
-34,0,3:1
-34,1,3:1
-34,2,3:1
-34,9,3:1
-34,10,3:1
-34,11,3:1
-34,12,3:1
-34,13,3:1
-34,14,3:1
-34,15,3:1
-34,16,3:1
-33,-20,1:1
-33,-19,1:1
-33,-18,1:1
-33,-17,1:1
-33,-16,1:1
-33,-15,1:1
-33,-14,1:1
-33,-13,1:1
-33,-12,1:1
-33,-7,1:1
-33,-6,1:1
-33,-5,1:1
-33,-4,1:1
-33,-3,1:1
-33,-2,1:1
-33,-1,1:1
-33,0,1:1
-33,1,1:1
-33,2,1:1
-33,3,1:1
-33,8,1:1
-33,9,1:1
-33,10,1:1
-33,11,1:1
-33,12,1:1
-33,13,1:1
-33,14,1:1
-33,15,1:1
-33,16,1:1
-33,-20,2:1
-33,-19,2:1
-33,-18,2:1
-33,-17,2:1
-33,-16,2:1
-33,-15,2:1
-33,-14,2:1
-33,-13,2:1
-33,-12,2:1
-33,-7,2:1
-33,-6,2:1
-33,-5,2:1
-33,-4,2:1
-33,-3,2:1
-33,-2,2:1
-33,-1,2:1
-33,0,2:1
-33,1,2:1
-33,2,2:1
-33,3,2:1
-33,8,2:1
-33,9,2:1
-33,10,2:1
-33,11,2:1
-33,12,2:1
-33,13,2:1
-33,14,2:1
-33,15,2:1
-33,16,2:1
-33,-20,3:1
-33,-19,3:1
-33,-18,3:1
-33,-17,3:1
-33,-16,3:1
-33,-15,3:1
-33,-14,3:1
-33,-13,3:1
-33,-12,3:1
-33,-7,3:1
-33,-6,3:1
-33,-5,3:1
-33,-4,3:1
-33,-3,3:1
-33,-2,3:1
-33,-1,3:1
-33,0,3:1
-33,1,3:1
-33,2,3:1
-33,3,3:1
-33,8,3:1
-33,9,3:1
-33,10,3:1
-33,11,3:1
-33,12,3:1
-33,13,3:1
-33,14,3:1
-33,15,3:1
-33,16,3:1
-32,-21,1:1
-32,-20,1:1
-32,-19,1:1
-32,-18,1:1
-32,-17,1:1
-32,-16,1:1
-32,-15,1:1
-32,-14,1:1
-32,-13,1:1
-32,-12,1:1
-32,-11,1:1
-32,-7,1:1
-32,-6,1:1
-32,-5,1:1
-32,-4,1:1
-32,-3,1:1
-32,-2,1:1
-32,-1,1:1
-32,0,1:1
-32,1,1:1
-32,2,1:1
-32,3,1:1
-32,7,1:1
-32,8,1:1
-32,9,1:1
-32,10,1:1
-32,11,1:1
-32,12,1:1
-32,13,1:1
-32,14,1:1
-32,15,1:1
-32,16,1:1
-32,17,1:1
-32,-21,2:1
-32,-20,2:1
-32,-19,2:1
-32,-18,2:1
-32,-17,2:1
-32,-16,2:1
-32,-15,2:1
-32,-14,2:1
-32,-13,2:1
-32,-12,2:1
-32,-11,2:1
-32,-7,2:1
-32,-6,2:1
-32,-5,2:1
-32,-4,2:1
-32,-3,2:1
-32,-2,2:1
-32,-1,2:1
-32,0,2:1
-32,1,2:1
-32,2,2:1
-32,3,2:1
-32,7,2:1
-32,8,2:1
-32,9,2:1
-32,10,2:1
-32,11,2:1
-32,12,2:1
-32,13,2:1
-32,14,2:1
-32,15,2:1
-32,16,2:1
-32,17,2:1
-32,-21,3:1
-32,-20,3:1
-32,-19,3:1
-32,-18,3:1
-32,-17,3:1
-32,-16,3:1
-32,-15,3:1
-32,-14,3:1
-32,-13,3:1
-32,-12,3:1
-32,-11,3:1
-32,-10,3:1
-32,-9,3:1
-32,-7,3:1
-32,-6,3:1
-32,-5,3:1
-32,-4,3:1
-32,-3,3:1
-32,-2,3:1
-32,-1,3:1
-32,0,3:1
-32,1,3:1
-32,2,3:1
-32,3,3:1
-32,6,3:1
-32,7,3:1
-32,8,3:1
-32,9,3:1
-32,10,3:1
-32,11,3:1
-32,12,3:1
-32,13,3:1
-32,14,3:1
-32,15,3:1
-32,16,3:1
-32,17,3:1
-31,-20,1:1
-31,-19,1:1
-31,-18,1:1
-31,-17,1:1
-31,-16,1:1
-31,-15,1:1
-31,-14,1:1
-31,-13,1:1
-31,-12,1:1
-31,-11,1:1
-31,-10,1:1
-31,-7,1:1
-31,-6,1:1
-31,-5,1:1
-31,-4,1:1
-31,-3,1:1
-31,-2,1:1
-31,-1,1:1
-31,0,1:1
-31,1,1:1
-31,2,1:1
-31,3,1:1
-31,6,1:1
-31,7,1:1
-31,8,1:1
-31,9,1:1
-31,10,1:1
-31,11,1:1
-31,12,1:1
-31,13,1:1
-31,14,1:1
-31,15,1:1
-31,16,1:1
-31,-20,2:1
-31,-19,2:1
-31,-18,2:1
-31,-17,2:1
-31,-16,2:1
-31,-15,2:1
-31,-14,2:1
-31,-13,2:1
-31,-12,2:1
-31,-11,2:1
-31,-10,2:1
-31,-7,2:1
-31,-6,2:1
-31,-5,2:1
-31,-4,2:1
-31,-3,2:1
-31,-2,2:1
-31,-1,2:1
-31,0,2:1
-31,1,2:1
-31,2,2:1
-31,3,2:1
-31,6,2:1
-31,7,2:1
-31,8,2:1
-31,9,2:1
-31,10,2:1
-31,11,2:1
-31,12,2:1
-31,13,2:1
-31,14,2:1
-31,15,2:1
-31,16,2:1
-31,-20,3:1
-31,-19,3:1
-31,-18,3:1
-31,-17,3:1
-31,-16,3:1
-31,-15,3:1
-31,-14,3:1
-31,-13,3:1
-31,-12,3:1
-31,-11,3:1
-31,-10,3:1
-31,-9,3:1
-31,-7,3:1
-31,-6,3:1
-31,-5,3:1
-31,-4,3:1
-31,-3,3:1
-31,-2,3:1
-31,-1,3:1
-31,0,3:1
-31,1,3:1
-31,2,3:1
-31,3,3:1
-31,6,3:1
-31,7,3:1
-31,8,3:1
-31,9,3:1
-31,10,3:1
-31,11,3:1
-31,12,3:1
-31,13,3:1
-31,14,3:1
-31,15,3:1
-31,16,3:1
-30,-20,1:1
-30,-19,1:1
-30,-18,1:1
-30,-17,1:1
-30,-16,1:1
-30,-15,1:1
-30,-14,1:1
-30,-13,1:1
-30,-12,1:1
-30,-11,1:1
-30,-10,1:1
-30,-7,1:1
-30,-6,1:1
-30,-5,1:1
-30,-4,1:1
-30,-3,1:1
-30,-2,1:1
-30,-1,1:1
-30,0,1:1
-30,1,1:1
-30,2,1:1
-30,3,1:1
-30,6,1:1
-30,7,1:1
-30,8,1:1
-30,9,1:1
-30,10,1:1
-30,11,1:1
-30,12,1:1
-30,13,1:1
-30,14,1:1
-30,15,1:1
-30,16,1:1
-30,-20,2:1
-30,-19,2:1
-30,-18,2:1
-30,-17,2:1
-30,-16,2:1
-30,-15,2:1
-30,-14,2:1
-30,-13,2:1
-30,-12,2:1
-30,-11,2:1
-30,-10,2:1
-30,-7,2:1
-30,-6,2:1
-30,-5,2:1
-30,-4,2:1
-30,-3,2:1
-30,-2,2:1
-30,-1,2:1
-30,0,2:1
-30,1,2:1
-30,2,2:1
-30,3,2:1
-30,6,2:1
-30,7,2:1
-30,8,2:1
-30,9,2:1
-30,10,2:1
-30,11,2:1
-30,12,2:1
-30,13,2:1
-30,14,2:1
-30,15,2:1
-30,16,2:1
-30,-20,3:1
-30,-19,3:1
-30,-18,3:1
-30,-17,3:1
-30,-16,3:1
-30,-15,3:1
-30,-14,3:1
-30,-13,3:1
-30,-12,3:1
-30,-11,3:1
-30,-10,3:1
-30,-9,3:1
-30,-7,3:1
-30,-6,3:1
-30,-5,3:1
-30,-4,3:1
-30,-3,3:1
-30,-2,3:1
-30,-1,3:1
-30,0,3:1
-30,1,3:1
-30,2,3:1
-30,3,3:1
-30,6,3:1
-30,7,3:1
-30,8,3:1
-30,9,3:1
-30,10,3:1
-30,11,3:1
-30,12,3:1
-30,13,3:1
-30,14,3:1
-30,15,3:1
-30,16,3:1
-29,-29,1:1
-29,-19,1:1
-29,-18,1:1
-29,-17,1:1
-29,-16,1:1
-29,-15,1:1
-29,-14,1:1
-29,-13,1:1
-29,-12,1:1
-29,-11,1:1
-29,-10,1:1
-29,-9,1:1
-29,-8,1:1
-29,-7,1:1
-29,-6,1:1
-29,-5,1:1
-29,-4,1:1
-29,-3,1:1
-29,-2,1:1
-29,-1,1:1
-29,0,1:1
-29,1,1:1
-29,2,1:1
-29,3,1:1
-29,4,1:1
-29,5,1:1
-29,6,1:1
-29,7,1:1
-29,8,1:1
-29,9,1:1
-29,10,1:1
-29,11,1:1
-29,12,1:1
-29,13,1:1
-29,14,1:1
-29,15,1:1
-29,-29,2:1
-29,-19,2:1
-29,-18,2:1
-29,-17,2:1
-29,-16,2:1
-29,-15,2:1
-29,-14,2:1
-29,-13,2:1
-29,-12,2:1
-29,-11,2:1
-29,-10,2:1
-29,-9,2:1
-29,-8,2:1
-29,-7,2:1
-29,-6,2:1
-29,-5,2:1
-29,-4,2:1
-29,-3,2:1
-29,-2,2:1
-29,-1,2:1
-29,0,2:1
-29,1,2:1
-29,2,2:1
-29,3,2:1
-29,4,2:1
-29,5,2:1
-29,6,2:1
-29,7,2:1
-29,8,2:1
-29,9,2:1
-29,10,2:1
-29,11,2:1
-29,12,2:1
-29,13,2:1
-29,14,2:1
-29,15,2:1
-29,-29,3:1
-29,-19,3:1
-29,-18,3:1
-29,-17,3:1
-29,-16,3:1
-29,-15,3:1
-29,-14,3:1
-29,-13,3:1
-29,-12,3:1
-29,-11,3:1
-29,-10,3:1
-29,-9,3:1
-29,-8,3:1
-29,-7,3:1
-29,-6,3:1
-29,-5,3:1
-29,-4,3:1
-29,-3,3:1
-29,-2,3:1
-29,-1,3:1
-29,0,3:1
-29,1,3:1
-29,2,3:1
-29,3,3:1
-29,4,3:1
-29,5,3:1
-29,6,3:1
-29,7,3:1
-29,8,3:1
-29,9,3:1
-29,10,3:1
-29,11,3:1
-29,12,3:1
-29,13,3:1
-29,14,3:1
-29,15,3:1
-29,-11,4:35.7
-29,-10,4:35.7
-29,6,4:35.7
-29,7,4:35.7
-29,-11,5:35.7
-29,7,5:35.7
-28,-31,1:1
-28,-30,1:1
-28,-29,1:1
-28,-28,1:1
-28,-27,1:1
-28,-20,1:1
-28,-19,1:1
-28,-18,1:1
-28,-17,1:1
-28,-16,1:1
-28,-15,1:1
-28,-14,1:1
-28,-13,1:1
-28,-12,1:1
-28,-11,1:1
-28,-10,1:1
-28,-9,1:1
-28,-8,1:1
-28,-7,1:1
-28,-6,1:1
-28,-5,1:1
-28,-4,1:1
-28,-3,1:1
-28,-2,1:1
-28,-1,1:1
-28,0,1:1
-28,1,1:1
-28,2,1:1
-28,3,1:1
-28,4,1:1
-28,5,1:1
-28,6,1:1
-28,7,1:1
-28,8,1:1
-28,9,1:1
-28,10,1:1
-28,11,1:1
-28,12,1:1
-28,13,1:1
-28,14,1:1
-28,15,1:1
-28,16,1:1
-28,23,1:1
-28,24,1:1
-28,25,1:1
-28,26,1:1
-28,27,1:1
-28,-31,2:1
-28,-30,2:1
-28,-29,2:1
-28,-28,2:1
-28,-27,2:1
-28,-20,2:1
-28,-19,2:1
-28,-18,2:1
-28,-17,2:1
-28,-16,2:1
-28,-15,2:1
-28,-14,2:1
-28,-13,2:1
-28,-12,2:1
-28,-11,2:1
-28,-10,2:1
-28,-9,2:1
-28,-8,2:1
-28,-7,2:1
-28,-6,2:1
-28,-5,2:1
-28,-4,2:1
-28,-3,2:1
-28,-2,2:1
-28,-1,2:1
-28,0,2:1
-28,1,2:1
-28,2,2:1
-28,3,2:1
-28,4,2:1
-28,5,2:1
-28,6,2:1
-28,7,2:1
-28,8,2:1
-28,9,2:1
-28,10,2:1
-28,11,2:1
-28,12,2:1
-28,13,2:1
-28,14,2:1
-28,15,2:1
-28,16,2:1
-28,23,2:1
-28,24,2:1
-28,25,2:1
-28,26,2:1
-28,27,2:1
-28,-31,3:1
-28,-30,3:1
-28,-29,3:1
-28,-28,3:1
-28,-27,3:1
-28,-20,3:1
-28,-19,3:1
-28,-18,3:1
-28,-17,3:1
-28,-16,3:1
-28,-15,3:1
-28,-14,3:1
-28,-13,3:1
-28,-12,3:1
-28,-11,3:1
-28,-10,3:1
-28,-9,3:1
-28,-8,3:1
-28,-7,3:1
-28,-6,3:1
-28,-5,3:1
-28,-4,3:1
-28,-3,3:1
-28,-2,3:1
-28,-1,3:1
-28,0,3:1
-28,1,3:1
-28,2,3:1
-28,3,3:1
-28,4,3:1
-28,5,3:1
-28,6,3:1
-28,7,3:1
-28,8,3:1
-28,9,3:1
-28,10,3:1
-28,11,3:1
-28,12,3:1
-28,13,3:1
-28,14,3:1
-28,15,3:1
-28,16,3:1
-28,23,3:1
-28,24,3:1
-28,25,3:1
-28,26,3:1
-28,27,3:1
-28,-12,4:35.7
-28,-11,4:35.7
-28,-10,4:35.7
-28,-9,4:35.7
-28,5,4:35.7
-28,6,4:35.7
-28,7,4:35.7
-28,8,4:35.7
-28,-11,5:35.7
-28,-10,5:35.7
-28,6,5:35.7
-28,7,5:35.7
-27,-32,1:1
-27,-31,1:1
-27,-30,1:1
-27,-29,1:1
-27,-28,1:1
-27,-27,1:1
-27,-26,1:1
-27,-20,1:1
-27,-19,1:1
-27,-18,1:1
-27,-17,1:1
-27,-16,1:1
-27,-15,1:1
-27,-14,1:1
-27,-13,1:1
-27,-12,1:1
-27,-11,1:1
-27,-10,1:1
-27,-9,1:1
-27,-8,1:1
-27,-7,1:1
-27,-6,1:1
-27,-5,1:1
-27,-4,1:1
-27,-3,1:1
-27,-2,1:1
-27,-1,1:1
-27,0,1:1
-27,1,1:1
-27,2,1:1
-27,3,1:1
-27,4,1:1
-27,5,1:1
-27,6,1:1
-27,7,1:1
-27,8,1:1
-27,9,1:1
-27,10,1:1
-27,11,1:1
-27,12,1:1
-27,13,1:1
-27,14,1:1
-27,15,1:1
-27,16,1:1
-27,22,1:1
-27,23,1:1
-27,24,1:1
-27,25,1:1
-27,26,1:1
-27,27,1:1
-27,28,1:1
-27,-32,2:1
-27,-31,2:1
-27,-30,2:1
-27,-29,2:1
-27,-28,2:1
-27,-27,2:1
-27,-26,2:1
-27,-20,2:1
-27,-19,2:1
-27,-18,2:1
-27,-17,2:1
-27,-16,2:1
-27,-15,2:1
-27,-14,2:1
-27,-13,2:1
-27,-12,2:1
-27,-11,2:1
-27,-10,2:1
-27,-9,2:1
-27,-8,2:1
-27,-7,2:1
-27,-6,2:1
-27,-5,2:1
-27,-4,2:1
-27,-3,2:1
-27,-2,2:1
-27,-1,2:1
-27,0,2:1
-27,1,2:1
-27,2,2:1
-27,3,2:1
-27,4,2:1
-27,5,2:1
-27,6,2:1
-27,7,2:1
-27,8,2:1
-27,9,2:1
-27,10,2:1
-27,11,2:1
-27,12,2:1
-27,13,2:1
-27,14,2:1
-27,15,2:1
-27,16,2:1
-27,22,2:1
-27,23,2:1
-27,24,2:1
-27,25,2:1
-27,26,2:1
-27,27,2:1
-27,28,2:1
-27,-32,3:1
-27,-31,3:1
-27,-30,3:1
-27,-29,3:1
-27,-28,3:1
-27,-27,3:1
-27,-26,3:1
-27,-20,3:1
-27,-19,3:1
-27,-18,3:1
-27,-17,3:1
-27,-16,3:1
-27,-15,3:1
-27,-14,3:1
-27,-13,3:1
-27,-12,3:1
-27,-11,3:1
-27,-10,3:1
-27,-9,3:1
-27,-8,3:1
-27,-7,3:1
-27,-6,3:1
-27,-5,3:1
-27,-4,3:1
-27,-3,3:1
-27,-2,3:1
-27,-1,3:1
-27,0,3:1
-27,1,3:1
-27,2,3:1
-27,3,3:1
-27,4,3:1
-27,5,3:1
-27,6,3:1
-27,7,3:1
-27,8,3:1
-27,9,3:1
-27,10,3:1
-27,11,3:1
-27,12,3:1
-27,13,3:1
-27,14,3:1
-27,15,3:1
-27,16,3:1
-27,22,3:1
-27,23,3:1
-27,24,3:1
-27,25,3:1
-27,26,3:1
-27,27,3:1
-27,28,3:1
-27,-13,4:35.7
-27,-12,4:35.7
-27,-11,4:35.7
-27,-10,4:35.7
-27,-9,4:35.7
-27,5,4:35.7
-27,6,4:35.7
-27,7,4:35.7
-27,8,4:35.7
-27,9,4:35.7
-27,-12,5:35.7
-27,-11,5:35.7
-27,-10,5:35.7
-27,6,5:35.7
-27,7,5:35.7
-27,8,5:35.7
-26,-33,1:1
-26,-32,1:1
-26,-31,1:1
-26,-30,1:1
-26,-29,1:1
-26,-28,1:1
-26,-27,1:1
-26,-26,1:1
-26,-25,1:1
-26,-23,1:1
-26,-19,1:1
-26,-18,1:1
-26,-17,1:1
-26,-16,1:1
-26,-15,1:1
-26,-14,1:1
-26,-13,1:1
-26,-12,1:1
-26,-11,1:1
-26,-10,1:1
-26,-9,1:1
-26,-8,1:1
-26,-7,1:1
-26,-6,1:1
-26,-5,1:1
-26,-4,1:1
-26,-3,1:1
-26,-2,1:1
-26,-1,1:1
-26,0,1:1
-26,1,1:1
-26,2,1:1
-26,3,1:1
-26,4,1:1
-26,5,1:1
-26,6,1:1
-26,7,1:1
-26,8,1:1
-26,9,1:1
-26,10,1:1
-26,11,1:1
-26,12,1:1
-26,13,1:1
-26,14,1:1
-26,15,1:1
-26,19,1:1
-26,21,1:1
-26,22,1:1
-26,23,1:1
-26,24,1:1
-26,25,1:1
-26,26,1:1
-26,27,1:1
-26,28,1:1
-26,29,1:1
-26,-33,2:1
-26,-32,2:1
-26,-31,2:1
-26,-30,2:1
-26,-29,2:1
-26,-28,2:1
-26,-27,2:1
-26,-26,2:1
-26,-25,2:1
-26,-23,2:1
-26,-19,2:1
-26,-18,2:1
-26,-17,2:1
-26,-16,2:1
-26,-15,2:1
-26,-14,2:1
-26,-13,2:1
-26,-12,2:1
-26,-11,2:1
-26,-10,2:1
-26,-9,2:1
-26,-8,2:1
-26,-7,2:1
-26,-6,2:1
-26,-5,2:1
-26,-4,2:1
-26,-3,2:1
-26,-2,2:1
-26,-1,2:1
-26,0,2:1
-26,1,2:1
-26,2,2:1
-26,3,2:1
-26,4,2:1
-26,5,2:1
-26,6,2:1
-26,7,2:1
-26,8,2:1
-26,9,2:1
-26,10,2:1
-26,11,2:1
-26,12,2:1
-26,13,2:1
-26,14,2:1
-26,15,2:1
-26,19,2:1
-26,21,2:1
-26,22,2:1
-26,23,2:1
-26,24,2:1
-26,25,2:1
-26,26,2:1
-26,27,2:1
-26,28,2:1
-26,29,2:1
-26,-33,3:1
-26,-32,3:1
-26,-31,3:1
-26,-30,3:1
-26,-29,3:1
-26,-28,3:1
-26,-27,3:1
-26,-26,3:1
-26,-25,3:1
-26,-23,3:1
-26,-19,3:1
-26,-18,3:1
-26,-17,3:1
-26,-16,3:1
-26,-15,3:1
-26,-14,3:1
-26,-13,3:1
-26,-12,3:1
-26,-11,3:1
-26,-10,3:1
-26,-9,3:1
-26,-8,3:1
-26,-7,3:1
-26,-6,3:1
-26,-5,3:1
-26,-4,3:1
-26,-3,3:1
-26,-2,3:1
-26,-1,3:1
-26,0,3:1
-26,1,3:1
-26,2,3:1
-26,3,3:1
-26,4,3:1
-26,5,3:1
-26,6,3:1
-26,7,3:1
-26,8,3:1
-26,9,3:1
-26,10,3:1
-26,11,3:1
-26,12,3:1
-26,13,3:1
-26,14,3:1
-26,15,3:1
-26,19,3:1
-26,21,3:1
-26,22,3:1
-26,23,3:1
-26,24,3:1
-26,25,3:1
-26,26,3:1
-26,27,3:1
-26,28,3:1
-26,29,3:1
-26,-13,4:35.7
-26,-12,4:35.7
-26,-11,4:35.7
-26,-10,4:35.7
-26,-9,4:35.7
-26,5,4:35.7
-26,6,4:35.7
-26,7,4:35.7
-26,8,4:35.7
-26,9,4:35.7
-26,-12,5:35.7
-26,-11,5:35.7
-26,-10,5:35.7
-26,6,5:35.7
-26,7,5:35.7
-26,8,5:35.7
-25,-33,1:1
-25,-32,1:1
-25,-31,1:1
-25,-30,1:1
-25,-29,1:1
-25,-28,1:1
-25,-27,1:1
-25,-26,1:1
-25,-25,1:1
-25,-24,1:1
-25,-23,1:1
-25,-22,1:1
-25,-19,1:1
-25,-18,1:1
-25,-17,1:1
-25,-16,1:1
-25,-15,1:1
-25,-14,1:1
-25,-13,1:1
-25,-12,1:1
-25,-11,1:1
-25,-10,1:1
-25,-9,1:1
-25,-8,1:1
-25,-7,1:172
-25,-6,1:172
-25,-5,1:172
-25,-4,1:172
-25,-3,1:172
-25,-2,1:172
-25,-1,1:172
-25,0,1:172
-25,1,1:172
-25,2,1:172
-25,3,1:172
-25,4,1:1
-25,5,1:1
-25,6,1:1
-25,7,1:1
-25,8,1:1
-25,9,1:1
-25,10,1:1
-25,11,1:1
-25,12,1:1
-25,13,1:1
-25,14,1:1
-25,15,1:1
-25,18,1:1
-25,19,1:1
-25,20,1:1
-25,21,1:1
-25,22,1:1
-25,23,1:1
-25,24,1:1
-25,25,1:1
-25,26,1:1
-25,27,1:1
-25,28,1:1
-25,29,1:1
-25,-33,2:1
-25,-32,2:1
-25,-31,2:1
-25,-30,2:1
-25,-29,2:1
-25,-28,2:1
-25,-27,2:1
-25,-26,2:1
-25,-25,2:1
-25,-24,2:1
-25,-23,2:1
-25,-22,2:1
-25,-19,2:1
-25,-18,2:1
-25,-17,2:1
-25,-16,2:1
-25,-15,2:1
-25,-14,2:1
-25,-13,2:1
-25,-12,2:1
-25,-11,2:1
-25,-10,2:1
-25,-9,2:1
-25,-8,2:1
-25,-7,2:95.12
-25,-6,2:95.12
-25,-5,2:95.12
-25,-4,2:95.12
-25,-3,2:95.12
-25,-2,2:95.12
-25,-1,2:95.12
-25,0,2:95.12
-25,1,2:95.12
-25,2,2:95.12
-25,3,2:95.12
-25,4,2:1
-25,5,2:1
-25,6,2:1
-25,7,2:1
-25,8,2:1
-25,9,2:1
-25,10,2:1
-25,11,2:1
-25,12,2:1
-25,13,2:1
-25,14,2:1
-25,15,2:1
-25,18,2:1
-25,19,2:1
-25,20,2:1
-25,21,2:1
-25,22,2:1
-25,23,2:1
-25,24,2:1
-25,25,2:1
-25,26,2:1
-25,27,2:1
-25,28,2:1
-25,29,2:1
-25,-33,3:1
-25,-32,3:1
-25,-31,3:1
-25,-30,3:1
-25,-29,3:1
-25,-28,3:1
-25,-27,3:1
-25,-26,3:1
-25,-25,3:1
-25,-24,3:1
-25,-23,3:1
-25,-22,3:1
-25,-19,3:1
-25,-18,3:1
-25,-17,3:1
-25,-16,3:1
-25,-15,3:1
-25,-14,3:1
-25,-13,3:1
-25,-12,3:1
-25,-11,3:1
-25,-10,3:1
-25,-9,3:1
-25,-8,3:1
-25,4,3:1
-25,5,3:1
-25,6,3:1
-25,7,3:1
-25,8,3:1
-25,9,3:1
-25,10,3:1
-25,11,3:1
-25,12,3:1
-25,13,3:1
-25,14,3:1
-25,15,3:1
-25,18,3:1
-25,19,3:1
-25,20,3:1
-25,21,3:1
-25,22,3:1
-25,23,3:1
-25,24,3:1
-25,25,3:1
-25,26,3:1
-25,27,3:1
-25,28,3:1
-25,29,3:1
-25,-11,4:35.7
-25,-10,4:35.7
-25,-9,4:35.7
-25,5,4:35.7
-25,6,4:35.7
-25,7,4:35.7
-25,-10,5:35.7
-25,6,5:35.7
-24,-33,1:1
-24,-32,1:1
-24,-31,1:1
-24,-30,1:1
-24,-29,1:1
-24,-28,1:1
-24,-27,1:1
-24,-26,1:1
-24,-25,1:1
-24,-24,1:1
-24,-23,1:1
-24,-22,1:1
-24,-21,1:1
-24,-20,1:1
-24,-19,1:1
-24,-18,1:1
-24,-17,1:1
-24,-16,1:1
-24,-15,1:1
-24,-14,1:1
-24,-13,1:1
-24,-12,1:1
-24,-11,1:1
-24,-10,1:172
-24,-9,1:172
-24,-8,1:172
-24,-7,1:172
-24,-6,1:172
-24,-5,1:172
-24,-4,1:172
-24,-3,1:172
-24,-2,1:172
-24,-1,1:172
-24,0,1:172
-24,1,1:172
-24,2,1:172
-24,3,1:172
-24,4,1:172
-24,5,1:172
-24,6,1:172
-24,7,1:1
-24,8,1:1
-24,9,1:1
-24,10,1:1
-24,11,1:1
-24,12,1:1
-24,13,1:1
-24,14,1:1
-24,15,1:1
-24,16,1:1
-24,17,1:1
-24,18,1:1
-24,19,1:1
-24,20,1:1
-24,21,1:1
-24,22,1:1
-24,23,1:1
-24,24,1:1
-24,25,1:1
-24,26,1:1
-24,27,1:1
-24,28,1:1
-24,29,1:1
-24,-33,2:1
-24,-32,2:1
-24,-31,2:1
-24,-30,2:1
-24,-29,2:1
-24,-28,2:1
-24,-27,2:1
-24,-26,2:1
-24,-25,2:1
-24,-24,2:1
-24,-23,2:1
-24,-22,2:1
-24,-21,2:1
-24,-20,2:1
-24,-19,2:1
-24,-18,2:1
-24,-17,2:1
-24,-16,2:1
-24,-15,2:1
-24,-14,2:1
-24,-13,2:1
-24,-12,2:1
-24,-11,2:1
-24,-10,2:95.12
-24,-9,2:95.12
-24,-8,2:95.12
-24,-7,2:95.12
-24,-6,2:95.12
-24,-5,2:95.12
-24,-4,2:95.12
-24,-3,2:95.12
-24,-2,2:95.12
-24,-1,2:95.12
-24,0,2:95.12
-24,1,2:95.12
-24,2,2:95.12
-24,3,2:95.12
-24,4,2:95.12
-24,5,2:95.12
-24,6,2:95.12
-24,7,2:1
-24,8,2:1
-24,9,2:1
-24,10,2:1
-24,11,2:1
-24,12,2:1
-24,13,2:1
-24,14,2:1
-24,15,2:1
-24,16,2:1
-24,17,2:1
-24,18,2:1
-24,19,2:1
-24,20,2:1
-24,21,2:1
-24,22,2:1
-24,23,2:1
-24,24,2:1
-24,25,2:1
-24,26,2:1
-24,27,2:1
-24,28,2:1
-24,29,2:1
-24,-33,3:1
-24,-32,3:1
-24,-31,3:1
-24,-30,3:1
-24,-29,3:1
-24,-28,3:1
-24,-27,3:1
-24,-26,3:1
-24,-25,3:1
-24,-24,3:1
-24,-23,3:1
-24,-22,3:1
-24,-21,3:1
-24,-20,3:1
-24,-19,3:1
-24,-18,3:1
-24,-17,3:1
-24,-16,3:1
-24,-15,3:1
-24,-14,3:1
-24,-13,3:1
-24,-12,3:1
-24,-11,3:1
-24,-10,3:35.7
-24,-9,3:35.7
-24,5,3:35.7
-24,6,3:35.7
-24,7,3:1
-24,8,3:1
-24,9,3:1
-24,10,3:1
-24,11,3:1
-24,12,3:1
-24,13,3:1
-24,14,3:1
-24,15,3:1
-24,16,3:1
-24,17,3:1
-24,18,3:1
-24,19,3:1
-24,20,3:1
-24,21,3:1
-24,22,3:1
-24,23,3:1
-24,24,3:1
-24,25,3:1
-24,26,3:1
-24,27,3:1
-24,28,3:1
-24,29,3:1
-24,-11,4:35.7
-24,-10,4:35.7
-24,6,4:35.7
-24,7,4:35.7
-23,-32,1:1
-23,-31,1:1
-23,-30,1:1
-23,-29,1:1
-23,-28,1:1
-23,-27,1:1
-23,-26,1:1
-23,-25,1:1
-23,-24,1:1
-23,-23,1:1
-23,-22,1:1
-23,-21,1:1
-23,-20,1:1
-23,-19,1:1
-23,-18,1:1
-23,-17,1:1
-23,-16,1:1
-23,-15,1:1
-23,-14,1:1
-23,-13,1:172
-23,-12,1:172
-23,-11,1:172
-23,-10,1:172
-23,-9,1:172
-23,-8,1:172
-23,-7,1:172
-23,-6,1:172
-23,-5,1:172
-23,-4,1:172
-23,-3,1:172
-23,-2,1:172
-23,-1,1:172
-23,0,1:172
-23,1,1:172
-23,2,1:172
-23,3,1:172
-23,4,1:172
-23,5,1:172
-23,6,1:172
-23,7,1:172
-23,8,1:172
-23,9,1:172
-23,10,1:1
-23,11,1:1
-23,12,1:1
-23,13,1:1
-23,14,1:1
-23,15,1:1
-23,16,1:1
-23,17,1:1
-23,18,1:1
-23,19,1:1
-23,20,1:1
-23,21,1:1
-23,22,1:1
-23,23,1:1
-23,24,1:1
-23,25,1:1
-23,26,1:1
-23,27,1:1
-23,28,1:1
-23,-32,2:1
-23,-31,2:1
-23,-30,2:1
-23,-29,2:1
-23,-28,2:1
-23,-27,2:1
-23,-26,2:1
-23,-25,2:1
-23,-24,2:1
-23,-23,2:1
-23,-22,2:1
-23,-21,2:1
-23,-20,2:1
-23,-19,2:1
-23,-18,2:1
-23,-17,2:1
-23,-16,2:1
-23,-15,2:1
-23,-14,2:1
-23,-13,2:95.12
-23,-12,2:95.12
-23,-11,2:95.12
-23,-10,2:95.12
-23,-9,2:95.12
-23,-8,2:95.12
-23,-7,2:95.12
-23,-6,2:95.12
-23,-5,2:95.12
-23,-4,2:95.12
-23,-3,2:95.12
-23,-2,2:95.12
-23,-1,2:95.12
-23,0,2:95.12
-23,1,2:95.12
-23,2,2:95.12
-23,3,2:95.12
-23,4,2:95.12
-23,5,2:95.12
-23,6,2:95.12
-23,7,2:95.12
-23,8,2:95.12
-23,9,2:95.12
-23,10,2:1
-23,11,2:1
-23,12,2:1
-23,13,2:1
-23,14,2:1
-23,15,2:1
-23,16,2:1
-23,17,2:1
-23,18,2:1
-23,19,2:1
-23,20,2:1
-23,21,2:1
-23,22,2:1
-23,23,2:1
-23,24,2:1
-23,25,2:1
-23,26,2:1
-23,27,2:1
-23,28,2:1
-23,-32,3:1
-23,-31,3:1
-23,-30,3:1
-23,-29,3:1
-23,-28,3:1
-23,-27,3:1
-23,-26,3:1
-23,-25,3:1
-23,-24,3:1
-23,-23,3:1
-23,-22,3:1
-23,-21,3:1
-23,-20,3:1
-23,-19,3:1
-23,-18,3:1
-23,-17,3:1
-23,-16,3:1
-23,-15,3:1
-23,-14,3:1
-23,-11,3:35.7
-23,-9,3:35.7
-23,5,3:35.7
-23,7,3:35.7
-23,10,3:1
-23,11,3:1
-23,12,3:1
-23,13,3:1
-23,14,3:1
-23,15,3:1
-23,16,3:1
-23,17,3:1
-23,18,3:1
-23,19,3:1
-23,20,3:1
-23,21,3:1
-23,22,3:1
-23,23,3:1
-23,24,3:1
-23,25,3:1
-23,26,3:1
-23,27,3:1
-23,28,3:1
-22,-32,1:1
-22,-31,1:1
-22,-30,1:1
-22,-29,1:1
-22,-28,1:1
-22,-27,1:1
-22,-26,1:1
-22,-25,1:1
-22,-24,1:1
-22,-23,1:1
-22,-22,1:1
-22,-21,1:1
-22,-20,1:1
-22,-19,1:1
-22,-18,1:1
-22,-17,1:1
-22,-16,1:1
-22,-15,1:1
-22,-14,1:172
-22,-13,1:172
-22,-12,1:172
-22,-11,1:172
-22,-10,1:172
-22,-9,1:172
-22,-8,1:172
-22,-7,1:172
-22,-6,1:172
-22,-5,1:172
-22,-4,1:172
-22,-3,1:172
-22,-2,1:172
-22,-1,1:172
-22,0,1:172
-22,1,1:172
-22,2,1:172
-22,3,1:172
-22,4,1:172
-22,5,1:172
-22,6,1:172
-22,7,1:172
-22,8,1:172
-22,9,1:172
-22,10,1:172
-22,11,1:1
-22,12,1:1
-22,13,1:1
-22,14,1:1
-22,15,1:1
-22,16,1:1
-22,17,1:1
-22,18,1:1
-22,19,1:1
-22,20,1:1
-22,21,1:1
-22,22,1:1
-22,23,1:1
-22,24,1:1
-22,25,1:1
-22,26,1:1
-22,27,1:1
-22,28,1:1
-22,-32,2:1
-22,-31,2:1
-22,-30,2:1
-22,-29,2:1
-22,-28,2:1
-22,-27,2:1
-22,-26,2:1
-22,-25,2:1
-22,-24,2:1
-22,-23,2:1
-22,-22,2:1
-22,-21,2:1
-22,-20,2:1
-22,-19,2:1
-22,-18,2:1
-22,-17,2:1
-22,-16,2:1
-22,-15,2:1
-22,-14,2:95.12
-22,-13,2:95.12
-22,-12,2:95.12
-22,-11,2:95.12
-22,-10,2:95.12
-22,-9,2:95.12
-22,-8,2:95.12
-22,-7,2:95.12
-22,-6,2:95.12
-22,-5,2:95.12
-22,-4,2:95.12
-22,-3,2:95.12
-22,-2,2:95.12
-22,-1,2:95.12
-22,0,2:95.12
-22,1,2:95.12
-22,2,2:95.12
-22,3,2:95.12
-22,4,2:95.12
-22,5,2:95.12
-22,6,2:95.12
-22,7,2:95.12
-22,8,2:95.12
-22,9,2:95.12
-22,10,2:95.12
-22,11,2:1
-22,12,2:1
-22,13,2:1
-22,14,2:1
-22,15,2:1
-22,16,2:1
-22,17,2:1
-22,18,2:1
-22,19,2:1
-22,20,2:1
-22,21,2:1
-22,22,2:1
-22,23,2:1
-22,24,2:1
-22,25,2:1
-22,26,2:1
-22,27,2:1
-22,28,2:1
-22,-32,3:1
-22,-31,3:1
-22,-30,3:1
-22,-29,3:1
-22,-28,3:1
-22,-27,3:1
-22,-26,3:1
-22,-25,3:1
-22,-24,3:1
-22,-23,3:1
-22,-22,3:1
-22,-21,3:1
-22,-20,3:1
-22,-19,3:1
-22,-18,3:1
-22,-17,3:1
-22,-16,3:1
-22,-15,3:1
-22,11,3:1
-22,12,3:1
-22,13,3:1
-22,14,3:1
-22,15,3:1
-22,16,3:1
-22,17,3:1
-22,18,3:1
-22,19,3:1
-22,20,3:1
-22,21,3:1
-22,22,3:1
-22,23,3:1
-22,24,3:1
-22,25,3:1
-22,26,3:1
-22,27,3:1
-22,28,3:1
-21,-32,1:1
-21,-31,1:1
-21,-30,1:1
-21,-29,1:1
-21,-28,1:1
-21,-27,1:1
-21,-26,1:1
-21,-25,1:1
-21,-24,1:1
-21,-23,1:1
-21,-22,1:1
-21,-21,1:1
-21,-20,1:1
-21,-19,1:1
-21,-18,1:1
-21,-17,1:1
-21,-16,1:172
-21,-15,1:172
-21,-14,1:172
-21,-13,1:172
-21,-12,1:172
-21,-11,1:172
-21,-10,1:172
-21,-9,1:172
-21,-8,1:172
-21,-7,1:172
-21,-6,1:172
-21,-5,1:172
-21,-4,1:172
-21,-3,1:172
-21,-2,1:172
-21,-1,1:172
-21,0,1:172
-21,1,1:172
-21,2,1:172
-21,3,1:172
-21,4,1:172
-21,5,1:172
-21,6,1:172
-21,7,1:172
-21,8,1:172
-21,9,1:172
-21,10,1:172
-21,11,1:172
-21,12,1:172
-21,13,1:1
-21,14,1:1
-21,15,1:1
-21,16,1:1
-21,17,1:1
-21,18,1:1
-21,19,1:1
-21,20,1:1
-21,21,1:1
-21,22,1:1
-21,23,1:1
-21,24,1:1
-21,25,1:1
-21,26,1:1
-21,27,1:1
-21,28,1:1
-21,-32,2:1
-21,-31,2:1
-21,-30,2:1
-21,-29,2:1
-21,-28,2:1
-21,-27,2:1
-21,-26,2:1
-21,-25,2:1
-21,-24,2:1
-21,-23,2:1
-21,-22,2:1
-21,-21,2:1
-21,-20,2:1
-21,-19,2:1
-21,-18,2:1
-21,-17,2:1
-21,-16,2:95.12
-21,-15,2:95.12
-21,-14,2:95.12
-21,-13,2:95.12
-21,-12,2:95.12
-21,-11,2:95.12
-21,-10,2:95.12
-21,-9,2:95.12
-21,-8,2:95.12
-21,-7,2:95.12
-21,-6,2:95.12
-21,-5,2:95.12
-21,-4,2:95.12
-21,-3,2:95.12
-21,-2,2:95.12
-21,-1,2:95.12
-21,0,2:95.12
-21,1,2:95.12
-21,2,2:95.12
-21,3,2:95.12
-21,4,2:95.12
-21,5,2:95.12
-21,6,2:95.12
-21,7,2:95.12
-21,8,2:95.12
-21,9,2:95.12
-21,10,2:95.12
-21,11,2:95.12
-21,12,2:95.12
-21,13,2:1
-21,14,2:1
-21,15,2:1
-21,16,2:1
-21,17,2:1
-21,18,2:1
-21,19,2:1
-21,20,2:1
-21,21,2:1
-21,22,2:1
-21,23,2:1
-21,24,2:1
-21,25,2:1
-21,26,2:1
-21,27,2:1
-21,28,2:1
-21,-32,3:1
-21,-31,3:1
-21,-30,3:1
-21,-29,3:1
-21,-28,3:1
-21,-27,3:1
-21,-26,3:1
-21,-25,3:1
-21,-24,3:1
-21,-23,3:1
-21,-22,3:1
-21,-21,3:1
-21,-20,3:1
-21,-19,3:1
-21,-18,3:1
-21,-17,3:1
-21,13,3:1
-21,14,3:1
-21,15,3:1
-21,16,3:1
-21,17,3:1
-21,18,3:1
-21,19,3:1
-21,20,3:1
-21,21,3:1
-21,22,3:1
-21,23,3:1
-21,24,3:1
-21,25,3:1
-21,26,3:1
-21,27,3:1
-21,28,3:1
-20,-30,1:1
-20,-29,1:1
-20,-28,1:1
-20,-27,1:1
-20,-26,1:1
-20,-25,1:1
-20,-24,1:1
-20,-23,1:1
-20,-22,1:1
-20,-21,1:1
-20,-20,1:1
-20,-19,1:1
-20,-18,1:1
-20,-17,1:172
-20,-16,1:172
-20,-15,1:172
-20,-14,1:172
-20,-13,1:172
-20,-12,1:172
-20,-11,1:172
-20,-10,1:172
-20,-9,1:172
-20,-8,1:172
-20,-7,1:172
-20,-6,1:172
-20,-5,1:172
-20,-4,1:172
-20,-3,1:172
-20,-2,1:172
-20,-1,1:172
-20,0,1:172
-20,1,1:172
-20,2,1:172
-20,3,1:172
-20,4,1:172
-20,5,1:172
-20,6,1:172
-20,7,1:172
-20,8,1:172
-20,9,1:172
-20,10,1:172
-20,11,1:172
-20,12,1:172
-20,13,1:172
-20,14,1:1
-20,15,1:1
-20,16,1:1
-20,17,1:1
-20,18,1:1
-20,19,1:1
-20,20,1:1
-20,21,1:1
-20,22,1:1
-20,23,1:1
-20,24,1:1
-20,25,1:1
-20,26,1:1
-20,-30,2:1
-20,-29,2:1
-20,-28,2:1
-20,-27,2:1
-20,-26,2:1
-20,-25,2:1
-20,-24,2:1
-20,-23,2:1
-20,-22,2:1
-20,-21,2:1
-20,-20,2:1
-20,-19,2:1
-20,-18,2:1
-20,-17,2:95.12
-20,-16,2:95.12
-20,-15,2:95.12
-20,-14,2:95.12
-20,-13,2:95.12
-20,-12,2:95.12
-20,-11,2:95.12
-20,-10,2:95.12
-20,-9,2:95.12
-20,-8,2:95.12
-20,-7,2:95.12
-20,-6,2:95.12
-20,-5,2:95.12
-20,-4,2:95.12
-20,-3,2:95.12
-20,-2,2:95.12
-20,-1,2:95.12
-20,0,2:95.12
-20,1,2:95.12
-20,2,2:95.12
-20,3,2:95.12
-20,4,2:95.12
-20,5,2:95.12
-20,6,2:95.12
-20,7,2:95.12
-20,8,2:95.12
-20,9,2:95.12
-20,10,2:95.12
-20,11,2:95.12
-20,12,2:95.12
-20,13,2:95.12
-20,14,2:1
-20,15,2:1
-20,16,2:1
-20,17,2:1
-20,18,2:1
-20,19,2:1
-20,20,2:1
-20,21,2:1
-20,22,2:1
-20,23,2:1
-20,24,2:1
-20,25,2:1
-20,26,2:1
-20,-30,3:1
-20,-29,3:1
-20,-28,3:1
-20,-27,3:1
-20,-26,3:1
-20,-25,3:1
-20,-24,3:1
-20,-23,3:1
-20,-22,3:1
-20,-21,3:1
-20,-20,3:1
-20,-19,3:1
-20,-18,3:1
-20,14,3:1
-20,15,3:1
-20,16,3:1
-20,17,3:1
-20,18,3:1
-20,19,3:1
-20,20,3:1
-20,21,3:1
-20,22,3:1
-20,23,3:1
-20,24,3:1
-20,25,3:1
-20,26,3:1
-19,-29,1:1
-19,-28,1:1
-19,-27,1:1
-19,-26,1:1
-19,-25,1:1
-19,-24,1:1
-19,-23,1:1
-19,-22,1:1
-19,-21,1:1
-19,-20,1:1
-19,-19,1:172
-19,-18,1:172
-19,-17,1:172
-19,-16,1:172
-19,-15,1:172
-19,-14,1:172
-19,-13,1:172
-19,-12,1:172
-19,-11,1:172
-19,-10,1:172
-19,-9,1:172
-19,-8,1:172
-19,-7,1:172
-19,-6,1:172
-19,-5,1:172
-19,-4,1:172
-19,-3,1:172
-19,-2,1:172
-19,-1,1:172
-19,0,1:172
-19,1,1:172
-19,2,1:172
-19,3,1:172
-19,4,1:172
-19,5,1:172
-19,6,1:172
-19,7,1:172
-19,8,1:172
-19,9,1:172
-19,10,1:172
-19,11,1:172
-19,12,1:172
-19,13,1:172
-19,14,1:172
-19,15,1:172
-19,16,1:1
-19,17,1:1
-19,18,1:1
-19,19,1:1
-19,20,1:1
-19,21,1:1
-19,22,1:1
-19,23,1:1
-19,24,1:1
-19,25,1:1
-19,-29,2:1
-19,-28,2:1
-19,-27,2:1
-19,-26,2:1
-19,-25,2:1
-19,-24,2:1
-19,-23,2:1
-19,-22,2:1
-19,-21,2:1
-19,-20,2:1
-19,-19,2:95.12
-19,-18,2:95.12
-19,-17,2:95.12
-19,-16,2:95.12
-19,-15,2:95.12
-19,-14,2:95.12
-19,-13,2:95.12
-19,-12,2:95.12
-19,-11,2:95.12
-19,-10,2:95.12
-19,-9,2:95.12
-19,-8,2:95.12
-19,-7,2:95.12
-19,-6,2:95.12
-19,-5,2:95.12
-19,-4,2:95.12
-19,-3,2:95.12
-19,-2,2:95.12
-19,-1,2:95.12
-19,0,2:95.12
-19,1,2:95.12
-19,2,2:95.12
-19,3,2:95.12
-19,4,2:95.12
-19,5,2:95.12
-19,6,2:95.12
-19,7,2:95.12
-19,8,2:95.12
-19,9,2:95.12
-19,10,2:95.12
-19,11,2:95.12
-19,12,2:95.12
-19,13,2:95.12
-19,14,2:95.12
-19,15,2:95.12
-19,16,2:1
-19,17,2:1
-19,18,2:1
-19,19,2:1
-19,20,2:1
-19,21,2:1
-19,22,2:1
-19,23,2:1
-19,24,2:1
-19,25,2:1
-19,-29,3:1
-19,-28,3:1
-19,-27,3:1
-19,-26,3:1
-19,-25,3:1
-19,-24,3:1
-19,-23,3:1
-19,-22,3:1
-19,-21,3:1
-19,-20,3:1
-19,16,3:1
-19,17,3:1
-19,18,3:1
-19,19,3:1
-19,20,3:1
-19,21,3:1
-19,22,3:1
-19,23,3:1
-19,24,3:1
-19,25,3:1
-19,-24,4:35.7
-19,20,4:35.7
-18,-30,1:1
-18,-29,1:1
-18,-28,1:1
-18,-27,1:1
-18,-26,1:1
-18,-25,1:1
-18,-24,1:1
-18,-23,1:1
-18,-22,1:1
-18,-21,1:1
-18,-20,1:172
-18,-19,1:172
-18,-18,1:172
-18,-17,1:172
-18,-16,1:172
-18,-15,1:172
-18,-14,1:172
-18,-13,1:172
-18,-12,1:172
-18,-11,1:172
-18,-10,1:172
-18,-9,1:172
-18,-8,1:172
-18,-7,1:172
-18,-6,1:172
-18,-5,1:172
-18,-4,1:172
-18,-3,1:172
-18,-2,1:172
-18,-1,1:172
-18,0,1:172
-18,1,1:172
-18,2,1:172
-18,3,1:172
-18,4,1:172
-18,5,1:172
-18,6,1:172
-18,7,1:172
-18,8,1:172
-18,9,1:172
-18,10,1:172
-18,11,1:172
-18,12,1:172
-18,13,1:172
-18,14,1:172
-18,15,1:172
-18,16,1:172
-18,17,1:1
-18,18,1:1
-18,19,1:1
-18,20,1:1
-18,21,1:1
-18,22,1:1
-18,23,1:1
-18,24,1:1
-18,25,1:1
-18,26,1:1
-18,-30,2:1
-18,-29,2:1
-18,-28,2:1
-18,-27,2:1
-18,-26,2:1
-18,-25,2:1
-18,-24,2:1
-18,-23,2:1
-18,-22,2:1
-18,-21,2:1
-18,-20,2:95.12
-18,-19,2:95.12
-18,-18,2:95.12
-18,-17,2:95.12
-18,-16,2:95.12
-18,-15,2:95.12
-18,-14,2:95.12
-18,-13,2:95.12
-18,-12,2:95.12
-18,-11,2:95.12
-18,-10,2:95.12
-18,-9,2:95.12
-18,-8,2:95.12
-18,-7,2:95.12
-18,-6,2:95.12
-18,-5,2:95.12
-18,-4,2:95.12
-18,-3,2:95.12
-18,-2,2:95.12
-18,-1,2:95.12
-18,0,2:95.12
-18,1,2:95.12
-18,2,2:95.12
-18,3,2:95.12
-18,4,2:95.12
-18,5,2:95.12
-18,6,2:95.12
-18,7,2:95.12
-18,8,2:95.12
-18,9,2:95.12
-18,10,2:95.12
-18,11,2:95.12
-18,12,2:95.12
-18,13,2:95.12
-18,14,2:95.12
-18,15,2:95.12
-18,16,2:95.12
-18,17,2:1
-18,18,2:1
-18,19,2:1
-18,20,2:1
-18,21,2:1
-18,22,2:1
-18,23,2:1
-18,24,2:1
-18,25,2:1
-18,26,2:1
-18,-30,3:1
-18,-29,3:1
-18,-28,3:1
-18,-27,3:1
-18,-26,3:1
-18,-25,3:1
-18,-24,3:1
-18,-23,3:1
-18,-22,3:1
-18,-21,3:1
-18,17,3:1
-18,18,3:1
-18,19,3:1
-18,20,3:1
-18,21,3:1
-18,22,3:1
-18,23,3:1
-18,24,3:1
-18,25,3:1
-18,26,3:1
-18,-26,4:35.7
-18,-25,4:35.7
-18,-24,4:35.7
-18,-23,4:35.7
-18,19,4:35.7
-18,20,4:35.7
-18,21,4:35.7
-18,22,4:35.7
-18,-26,5:35.7
-18,-25,5:35.7
-18,21,5:35.7
-18,22,5:35.7
-17,-29,1:1
-17,-28,1:1
-17,-27,1:1
-17,-26,1:1
-17,-25,1:1
-17,-24,1:1
-17,-23,1:1
-17,-22,1:1
-17,-21,1:172
-17,-20,1:172
-17,-19,1:172
-17,-18,1:172
-17,-17,1:172
-17,-16,1:172
-17,-15,1:172
-17,-14,1:172
-17,-13,1:172
-17,-12,1:172
-17,-11,1:172
-17,-10,1:172
-17,-9,1:172
-17,-8,1:172
-17,-7,1:172
-17,-6,1:172
-17,-5,1:172
-17,-4,1:172
-17,-3,1:172
-17,-2,1:172
-17,-1,1:172
-17,0,1:172
-17,1,1:172
-17,2,1:172
-17,3,1:172
-17,4,1:172
-17,5,1:172
-17,6,1:172
-17,7,1:172
-17,8,1:172
-17,9,1:172
-17,10,1:172
-17,11,1:172
-17,12,1:172
-17,13,1:172
-17,14,1:172
-17,15,1:172
-17,16,1:172
-17,17,1:172
-17,18,1:1
-17,19,1:1
-17,20,1:1
-17,21,1:1
-17,22,1:1
-17,23,1:1
-17,24,1:1
-17,25,1:1
-17,-29,2:1
-17,-28,2:1
-17,-27,2:1
-17,-26,2:1
-17,-25,2:1
-17,-24,2:1
-17,-23,2:1
-17,-22,2:1
-17,-21,2:95.12
-17,-20,2:95.12
-17,-19,2:95.12
-17,-18,2:95.12
-17,-17,2:95.12
-17,-16,2:95.12
-17,-15,2:95.12
-17,-14,2:95.12
-17,-13,2:95.12
-17,-12,2:95.12
-17,-11,2:95.12
-17,-10,2:95.12
-17,-9,2:95.12
-17,-8,2:95.12
-17,-7,2:95.12
-17,-6,2:95.12
-17,-5,2:95.12
-17,-4,2:95.12
-17,-3,2:95.12
-17,-2,2:95.12
-17,-1,2:95.12
-17,0,2:95.12
-17,1,2:95.12
-17,2,2:95.12
-17,3,2:95.12
-17,4,2:95.12
-17,5,2:95.12
-17,6,2:95.12
-17,7,2:95.12
-17,8,2:95.12
-17,9,2:95.12
-17,10,2:95.12
-17,11,2:95.12
-17,12,2:95.12
-17,13,2:95.12
-17,14,2:95.12
-17,15,2:95.12
-17,16,2:95.12
-17,17,2:95.12
-17,18,2:1
-17,19,2:1
-17,20,2:1
-17,21,2:1
-17,22,2:1
-17,23,2:1
-17,24,2:1
-17,25,2:1
-17,-29,3:1
-17,-28,3:1
-17,-27,3:1
-17,-26,3:1
-17,-25,3:1
-17,-24,3:1
-17,-23,3:1
-17,-22,3:1
-17,-8,3:159.1
-17,4,3:159.1
-17,18,3:1
-17,19,3:1
-17,20,3:1
-17,21,3:1
-17,22,3:1
-17,23,3:1
-17,24,3:1
-17,25,3:1
-17,26,3:1
-17,-27,4:35.7
-17,-26,4:35.7
-17,-25,4:35.7
-17,-24,4:35.7
-17,-23,4:35.7
-17,19,4:35.7
-17,20,4:35.7
-17,21,4:35.7
-17,22,4:35.7
-17,23,4:35.7
-17,-26,5:35.7
-17,-25,5:35.7
-17,-24,5:35.7
-17,20,5:35.7
-17,21,5:35.7
-17,22,5:35.7
-16,-27,1:1
-16,-26,1:1
-16,-25,1:1
-16,-24,1:1
-16,-23,1:1
-16,-22,1:1
-16,-21,1:172
-16,-20,1:172
-16,-19,1:172
-16,-18,1:172
-16,-17,1:172
-16,-16,1:172
-16,-15,1:172
-16,-14,1:172
-16,-13,1:172
-16,-12,1:172
-16,-11,1:172
-16,-10,1:172
-16,-9,1:172
-16,-8,1:172
-16,-7,1:172
-16,-6,1:172
-16,-5,1:172
-16,-4,1:172
-16,-3,1:172
-16,-2,1:172
-16,-1,1:172
-16,0,1:172
-16,1,1:172
-16,2,1:172
-16,3,1:172
-16,4,1:172
-16,5,1:172
-16,6,1:172
-16,7,1:172
-16,8,1:172
-16,9,1:172
-16,10,1:172
-16,11,1:172
-16,12,1:172
-16,13,1:172
-16,14,1:172
-16,15,1:172
-16,16,1:172
-16,17,1:172
-16,18,1:1
-16,19,1:1
-16,20,1:1
-16,21,1:1
-16,22,1:1
-16,23,1:1
-16,-27,2:1
-16,-26,2:1
-16,-25,2:1
-16,-24,2:1
-16,-23,2:1
-16,-22,2:1
-16,-21,2:95.12
-16,-20,2:95.12
-16,-19,2:95.12
-16,-18,2:95.12
-16,-17,2:95.12
-16,-16,2:95.12
-16,-15,2:95.12
-16,-14,2:95.12
-16,-13,2:95.12
-16,-12,2:95.12
-16,-11,2:95.12
-16,-10,2:95.12
-16,-9,2:95.12
-16,-8,2:95.12
-16,-7,2:95.12
-16,-6,2:95.12
-16,-5,2:95.12
-16,-4,2:95.12
-16,-3,2:95.12
-16,-2,2:95.12
-16,-1,2:95.12
-16,0,2:95.12
-16,1,2:95.12
-16,2,2:95.12
-16,3,2:95.12
-16,4,2:95.12
-16,5,2:95.12
-16,6,2:95.12
-16,7,2:95.12
-16,8,2:95.12
-16,9,2:95.12
-16,10,2:95.12
-16,11,2:95.12
-16,12,2:95.12
-16,13,2:95.12
-16,14,2:95.12
-16,15,2:95.12
-16,16,2:95.12
-16,17,2:95.12
-16,18,2:1
-16,19,2:1
-16,20,2:1
-16,21,2:1
-16,22,2:1
-16,23,2:1
-16,-28,3:1
-16,-27,3:1
-16,-26,3:1
-16,-25,3:1
-16,-24,3:1
-16,-23,3:1
-16,-22,3:1
-16,-8,3:159.1
-16,4,3:159.1
-16,18,3:1
-16,19,3:1
-16,20,3:1
-16,21,3:1
-16,22,3:1
-16,23,3:1
-16,24,3:1
-16,25,3:1
-16,-26,4:35.7
-16,-25,4:35.7
-16,-24,4:35.7
-16,-23,4:35.7
-16,-22,4:35.7
-16,18,4:35.7
-16,19,4:35.7
-16,20,4:35.7
-16,21,4:35.7
-16,22,4:35.7
-16,-26,5:35.7
-16,-25,5:35.7
-16,-24,5:35.7
-16,20,5:35.7
-16,21,5:35.7
-16,22,5:35.7
-15,-38,1:1
-15,-37,1:1
-15,-36,1:1
-15,-35,1:1
-15,-34,1:1
-15,-32,1:1
-15,-31,1:1
-15,-28,1:1
-15,-27,1:1
-15,-26,1:1
-15,-25,1:1
-15,-24,1:1
-15,-23,1:1
-15,-22,1:172
-15,-21,1:172
-15,-20,1:172
-15,-19,1:172
-15,-18,1:172
-15,-17,1:172
-15,-16,1:172
-15,-15,1:172
-15,-14,1:172
-15,-13,1:172
-15,-12,1:172
-15,-11,1:172
-15,-10,1:172
-15,-9,1:172
-15,-8,1:172
-15,-7,1:172
-15,-6,1:172
-15,-5,1:172
-15,-4,1:172
-15,-3,1:172
-15,-2,1:172
-15,-1,1:172
-15,0,1:172
-15,1,1:172
-15,2,1:172
-15,3,1:172
-15,4,1:172
-15,5,1:172
-15,6,1:172
-15,7,1:172
-15,8,1:172
-15,9,1:172
-15,10,1:172
-15,11,1:172
-15,12,1:172
-15,13,1:172
-15,14,1:172
-15,15,1:172
-15,16,1:172
-15,17,1:172
-15,18,1:172
-15,19,1:1
-15,20,1:1
-15,21,1:1
-15,22,1:1
-15,23,1:1
-15,24,1:1
-15,27,1:1
-15,28,1:1
-15,30,1:1
-15,31,1:1
-15,32,1:1
-15,33,1:1
-15,34,1:1
-15,-38,2:1
-15,-37,2:1
-15,-36,2:1
-15,-35,2:1
-15,-34,2:1
-15,-32,2:1
-15,-31,2:1
-15,-28,2:1
-15,-27,2:1
-15,-26,2:1
-15,-25,2:1
-15,-24,2:1
-15,-23,2:1
-15,-22,2:95.12
-15,-21,2:95.12
-15,-20,2:95.12
-15,-19,2:95.12
-15,-18,2:95.12
-15,-17,2:95.12
-15,-16,2:95.12
-15,-15,2:95.12
-15,-14,2:95.12
-15,-13,2:95.12
-15,-12,2:95.12
-15,-11,2:95.12
-15,-10,2:95.12
-15,-9,2:95.12
-15,-8,2:95.12
-15,-7,2:95.12
-15,-6,2:95.12
-15,-5,2:95.12
-15,-4,2:95.12
-15,-3,2:95.12
-15,-2,2:95.12
-15,-1,2:95.12
-15,0,2:95.12
-15,1,2:95.12
-15,2,2:95.12
-15,3,2:95.12
-15,4,2:95.12
-15,5,2:95.12
-15,6,2:95.12
-15,7,2:95.12
-15,8,2:95.12
-15,9,2:95.12
-15,10,2:95.12
-15,11,2:95.12
-15,12,2:95.12
-15,13,2:95.12
-15,14,2:95.12
-15,15,2:95.12
-15,16,2:95.12
-15,17,2:95.12
-15,18,2:95.12
-15,19,2:1
-15,20,2:1
-15,21,2:1
-15,22,2:1
-15,23,2:1
-15,24,2:1
-15,27,2:1
-15,28,2:1
-15,30,2:1
-15,31,2:1
-15,32,2:1
-15,33,2:1
-15,34,2:1
-15,-38,3:1
-15,-37,3:1
-15,-36,3:1
-15,-35,3:1
-15,-34,3:1
-15,-32,3:1
-15,-31,3:1
-15,-28,3:1
-15,-27,3:1
-15,-26,3:1
-15,-25,3:1
-15,-24,3:1
-15,-23,3:1
-15,-22,3:35.7
-15,-7,3:159.1
-15,-6,3:159.1
-15,2,3:159.1
-15,3,3:159.1
-15,18,3:35.7
-15,19,3:1
-15,20,3:1
-15,21,3:1
-15,22,3:1
-15,23,3:1
-15,24,3:1
-15,27,3:1
-15,28,3:1
-15,30,3:1
-15,31,3:1
-15,32,3:1
-15,33,3:1
-15,34,3:1
-15,-26,4:35.7
-15,-25,4:35.7
-15,-24,4:35.7
-15,-23,4:35.7
-15,-22,4:35.7
-15,18,4:35.7
-15,19,4:35.7
-15,20,4:35.7
-15,21,4:35.7
-15,22,4:35.7
-15,-23,5:35.7
-15,19,5:35.7
-14,-40,1:1
-14,-39,1:1
-14,-38,1:1
-14,-37,1:1
-14,-36,1:1
-14,-35,1:1
-14,-34,1:1
-14,-33,1:1
-14,-32,1:1
-14,-31,1:1
-14,-30,1:1
-14,-29,1:1
-14,-28,1:1
-14,-27,1:1
-14,-26,1:1
-14,-25,1:1
-14,-24,1:1
-14,-23,1:172
-14,-22,1:172
-14,-21,1:172
-14,-20,1:172
-14,-19,1:172
-14,-18,1:172
-14,-17,1:172
-14,-16,1:172
-14,-15,1:172
-14,-14,1:172
-14,-13,1:172
-14,-12,1:172
-14,-11,1:172
-14,-10,1:172
-14,-9,1:172
-14,-8,1:172
-14,-7,1:172
-14,-6,1:172
-14,-5,1:172
-14,-4,1:172
-14,-3,1:172
-14,-2,1:172
-14,-1,1:172
-14,0,1:172
-14,1,1:172
-14,2,1:172
-14,3,1:172
-14,4,1:172
-14,5,1:172
-14,6,1:172
-14,7,1:172
-14,8,1:172
-14,9,1:172
-14,10,1:172
-14,11,1:172
-14,12,1:172
-14,13,1:172
-14,14,1:172
-14,15,1:172
-14,16,1:172
-14,17,1:172
-14,18,1:172
-14,19,1:172
-14,20,1:1
-14,21,1:1
-14,22,1:1
-14,23,1:1
-14,24,1:1
-14,25,1:1
-14,26,1:1
-14,27,1:1
-14,28,1:1
-14,29,1:1
-14,30,1:1
-14,31,1:1
-14,32,1:1
-14,33,1:1
-14,34,1:1
-14,35,1:1
-14,36,1:1
-14,-40,2:1
-14,-39,2:1
-14,-38,2:1
-14,-37,2:1
-14,-36,2:1
-14,-35,2:1
-14,-34,2:1
-14,-33,2:1
-14,-32,2:1
-14,-31,2:1
-14,-30,2:1
-14,-29,2:1
-14,-28,2:1
-14,-27,2:1
-14,-26,2:1
-14,-25,2:1
-14,-24,2:1
-14,-23,2:95.12
-14,-22,2:95.12
-14,-21,2:95.12
-14,-20,2:95.12
-14,-19,2:95.12
-14,-18,2:95.12
-14,-17,2:95.12
-14,-16,2:95.12
-14,-15,2:95.12
-14,-14,2:95.12
-14,-13,2:95.12
-14,-12,2:95.12
-14,-11,2:95.12
-14,-10,2:95.12
-14,-9,2:95.12
-14,-8,2:95.12
-14,-7,2:95.12
-14,-6,2:95.12
-14,-5,2:95.12
-14,-4,2:95.12
-14,-3,2:95.12
-14,-2,2:95.12
-14,-1,2:95.12
-14,0,2:95.12
-14,1,2:95.12
-14,2,2:95.12
-14,3,2:95.12
-14,4,2:95.12
-14,5,2:95.12
-14,6,2:95.12
-14,7,2:95.12
-14,8,2:95.12
-14,9,2:95.12
-14,10,2:95.12
-14,11,2:95.12
-14,12,2:95.12
-14,13,2:95.12
-14,14,2:95.12
-14,15,2:95.12
-14,16,2:95.12
-14,17,2:95.12
-14,18,2:95.12
-14,19,2:95.12
-14,20,2:1
-14,21,2:1
-14,22,2:1
-14,23,2:1
-14,24,2:1
-14,25,2:1
-14,26,2:1
-14,27,2:1
-14,28,2:1
-14,29,2:1
-14,30,2:1
-14,31,2:1
-14,32,2:1
-14,33,2:1
-14,34,2:1
-14,35,2:1
-14,36,2:1
-14,-40,3:1
-14,-39,3:1
-14,-38,3:1
-14,-37,3:1
-14,-36,3:1
-14,-35,3:1
-14,-34,3:1
-14,-33,3:1
-14,-32,3:1
-14,-31,3:1
-14,-30,3:1
-14,-29,3:1
-14,-28,3:1
-14,-27,3:1
-14,-26,3:1
-14,-25,3:1
-14,-24,3:1
-14,-23,3:35.7
-14,-22,3:35.7
-14,-21,3:35.7
-14,-8,3:159.1
-14,-7,3:159.1
-14,-6,3:159.1
-14,2,3:159.1
-14,3,3:159.1
-14,4,3:159.1
-14,17,3:35.7
-14,18,3:35.7
-14,19,3:35.7
-14,20,3:1
-14,21,3:1
-14,22,3:1
-14,23,3:1
-14,24,3:1
-14,25,3:1
-14,26,3:1
-14,27,3:1
-14,28,3:1
-14,29,3:1
-14,30,3:1
-14,31,3:1
-14,32,3:1
-14,33,3:1
-14,34,3:1
-14,35,3:1
-14,36,3:1
-13,-40,1:1
-13,-39,1:1
-13,-38,1:1
-13,-37,1:1
-13,-36,1:1
-13,-35,1:1
-13,-34,1:1
-13,-33,1:1
-13,-32,1:1
-13,-31,1:1
-13,-30,1:1
-13,-29,1:1
-13,-28,1:1
-13,-27,1:1
-13,-26,1:1
-13,-25,1:1
-13,-24,1:1
-13,-23,1:172
-13,-22,1:172
-13,-21,1:172
-13,-20,1:172
-13,-19,1:172
-13,-18,1:172
-13,-17,1:172
-13,-16,1:172
-13,-15,1:172
-13,-14,1:172
-13,-13,1:172
-13,-12,1:172
-13,-11,1:172
-13,-10,1:172
-13,-9,1:172
-13,-8,1:172
-13,-7,1:172
-13,-6,1:172
-13,-5,1:172
-13,-4,1:172
-13,-3,1:172
-13,-2,1:172
-13,-1,1:172
-13,0,1:172
-13,1,1:172
-13,2,1:172
-13,3,1:172
-13,4,1:172
-13,5,1:172
-13,6,1:172
-13,7,1:172
-13,8,1:172
-13,9,1:172
-13,10,1:172
-13,11,1:172
-13,12,1:172
-13,13,1:172
-13,14,1:172
-13,15,1:172
-13,16,1:172
-13,17,1:172
-13,18,1:172
-13,19,1:172
-13,20,1:1
-13,21,1:1
-13,22,1:1
-13,23,1:1
-13,24,1:1
-13,25,1:1
-13,26,1:1
-13,27,1:1
-13,28,1:1
-13,29,1:1
-13,30,1:1
-13,31,1:1
-13,32,1:1
-13,33,1:1
-13,34,1:1
-13,35,1:1
-13,36,1:1
-13,-40,2:1
-13,-39,2:1
-13,-38,2:1
-13,-37,2:1
-13,-36,2:1
-13,-35,2:1
-13,-34,2:1
-13,-33,2:1
-13,-32,2:1
-13,-31,2:1
-13,-30,2:1
-13,-29,2:1
-13,-28,2:1
-13,-27,2:1
-13,-26,2:1
-13,-25,2:1
-13,-24,2:1
-13,-23,2:95.12
-13,-22,2:95.12
-13,-21,2:95.12
-13,-20,2:95.12
-13,-19,2:95.12
-13,-18,2:95.12
-13,-17,2:95.12
-13,-16,2:95.12
-13,-15,2:95.12
-13,-14,2:95.12
-13,-13,2:95.12
-13,-12,2:95.12
-13,-11,2:95.12
-13,-10,2:95.12
-13,-9,2:95.12
-13,-8,2:95.12
-13,-7,2:95.12
-13,-6,2:95.12
-13,-5,2:95.12
-13,-4,2:95.12
-13,-3,2:95.12
-13,-2,2:95.12
-13,-1,2:95.12
-13,0,2:95.12
-13,1,2:95.12
-13,2,2:95.12
-13,3,2:95.12
-13,4,2:95.12
-13,5,2:95.12
-13,6,2:95.12
-13,7,2:95.12
-13,8,2:95.12
-13,9,2:95.12
-13,10,2:95.12
-13,11,2:95.12
-13,12,2:95.12
-13,13,2:95.12
-13,14,2:95.12
-13,15,2:95.12
-13,16,2:95.12
-13,17,2:95.12
-13,18,2:95.12
-13,19,2:95.12
-13,20,2:1
-13,21,2:1
-13,22,2:1
-13,23,2:1
-13,24,2:1
-13,25,2:1
-13,26,2:1
-13,27,2:1
-13,28,2:1
-13,29,2:1
-13,30,2:1
-13,31,2:1
-13,32,2:1
-13,33,2:1
-13,34,2:1
-13,35,2:1
-13,36,2:1
-13,-40,3:1
-13,-39,3:1
-13,-38,3:1
-13,-37,3:1
-13,-36,3:1
-13,-35,3:1
-13,-34,3:1
-13,-33,3:1
-13,-32,3:1
-13,-31,3:1
-13,-30,3:1
-13,-29,3:1
-13,-28,3:1
-13,-27,3:1
-13,-26,3:1
-13,-25,3:1
-13,-24,3:1
-13,-8,3:159.1
-13,-7,3:159.1
-13,-6,3:159.1
-13,2,3:159.1
-13,3,3:159.1
-13,4,3:159.1
-13,20,3:1
-13,21,3:1
-13,22,3:1
-13,23,3:1
-13,24,3:1
-13,25,3:1
-13,26,3:1
-13,27,3:1
-13,28,3:1
-13,29,3:1
-13,30,3:1
-13,31,3:1
-13,32,3:1
-13,33,3:1
-13,34,3:1
-13,35,3:1
-13,36,3:1
-12,-40,1:1
-12,-39,1:1
-12,-38,1:1
-12,-37,1:1
-12,-36,1:1
-12,-35,1:1
-12,-34,1:1
-12,-33,1:1
-12,-32,1:1
-12,-31,1:1
-12,-30,1:1
-12,-29,1:1
-12,-28,1:1
-12,-27,1:1
-12,-26,1:1
-12,-25,1:1
-12,-24,1:172
-12,-23,1:172
-12,-22,1:172
-12,-21,1:172
-12,-20,1:172
-12,-19,1:172
-12,-18,1:172
-12,-17,1:172
-12,-16,1:172
-12,-15,1:172
-12,-14,1:172
-12,-13,1:172
-12,-12,1:172
-12,-11,1:172
-12,-10,1:172
-12,-9,1:172
-12,-8,1:172
-12,-7,1:172
-12,-6,1:172
-12,-5,1:172
-12,-4,1:172
-12,-3,1:172
-12,-2,1:172
-12,-1,1:172
-12,0,1:172
-12,1,1:172
-12,2,1:172
-12,3,1:172
-12,4,1:172
-12,5,1:172
-12,6,1:172
-12,7,1:172
-12,8,1:172
-12,9,1:172
-12,10,1:172
-12,11,1:172
-12,12,1:172
-12,13,1:172
-12,14,1:172
-12,15,1:172
-12,16,1:172
-12,17,1:172
-12,18,1:172
-12,19,1:172
-12,20,1:172
-12,21,1:1
-12,22,1:1
-12,23,1:1
-12,24,1:1
-12,25,1:1
-12,26,1:1
-12,27,1:1
-12,28,1:1
-12,29,1:1
-12,30,1:1
-12,31,1:1
-12,32,1:1
-12,33,1:1
-12,34,1:1
-12,35,1:1
-12,36,1:1
-12,-40,2:1
-12,-39,2:1
-12,-38,2:1
-12,-37,2:1
-12,-36,2:1
-12,-35,2:1
-12,-34,2:1
-12,-33,2:1
-12,-32,2:1
-12,-31,2:1
-12,-30,2:1
-12,-29,2:1
-12,-28,2:1
-12,-27,2:1
-12,-26,2:1
-12,-25,2:1
-12,-24,2:95.12
-12,-23,2:95.12
-12,-22,2:95.12
-12,-21,2:95.12
-12,-20,2:95.12
-12,-19,2:95.12
-12,-18,2:95.12
-12,-17,2:95.12
-12,-16,2:95.12
-12,-15,2:95.12
-12,-14,2:95.12
-12,-13,2:95.12
-12,-12,2:95.12
-12,-11,2:95.12
-12,-10,2:95.12
-12,-9,2:95.12
-12,-8,2:95.12
-12,-7,2:95.12
-12,-6,2:95.12
-12,-5,2:95.12
-12,-4,2:95.12
-12,-3,2:95.12
-12,-2,2:95.12
-12,-1,2:95.12
-12,0,2:95.12
-12,1,2:95.12
-12,2,2:95.12
-12,3,2:95.12
-12,4,2:95.12
-12,5,2:95.12
-12,6,2:95.12
-12,7,2:95.12
-12,8,2:95.12
-12,9,2:95.12
-12,10,2:95.12
-12,11,2:95.12
-12,12,2:95.12
-12,13,2:95.12
-12,14,2:95.12
-12,15,2:95.12
-12,16,2:95.12
-12,17,2:95.12
-12,18,2:95.12
-12,19,2:95.12
-12,20,2:95.12
-12,21,2:1
-12,22,2:1
-12,23,2:1
-12,24,2:1
-12,25,2:1
-12,26,2:1
-12,27,2:1
-12,28,2:1
-12,29,2:1
-12,30,2:1
-12,31,2:1
-12,32,2:1
-12,33,2:1
-12,34,2:1
-12,35,2:1
-12,36,2:1
-12,-40,3:1
-12,-39,3:1
-12,-38,3:1
-12,-37,3:1
-12,-36,3:1
-12,-35,3:1
-12,-34,3:1
-12,-33,3:1
-12,-32,3:1
-12,-31,3:1
-12,-30,3:1
-12,-29,3:1
-12,-28,3:1
-12,-27,3:1
-12,-26,3:1
-12,-25,3:1
-12,-7,3:159.1
-12,-6,3:159.1
-12,-5,3:159.1
-12,-4,3:159.1
-12,0,3:159.1
-12,1,3:159.1
-12,2,3:159.1
-12,3,3:159.1
-12,21,3:1
-12,22,3:1
-12,23,3:1
-12,24,3:1
-12,25,3:1
-12,26,3:1
-12,27,3:1
-12,28,3:1
-12,29,3:1
-12,30,3:1
-12,31,3:1
-12,32,3:1
-12,33,3:1
-12,34,3:1
-12,35,3:1
-12,36,3:1
-11,-41,1:1
-11,-40,1:1
-11,-39,1:1
-11,-38,1:1
-11,-37,1:1
-11,-36,1:1
-11,-35,1:1
-11,-34,1:1
-11,-33,1:1
-11,-32,1:1
-11,-31,1:1
-11,-30,1:1
-11,-29,1:1
-11,-28,1:1
-11,-27,1:1
-11,-26,1:1
-11,-25,1:172
-11,-24,1:172
-11,-23,1:172
-11,-22,1:172
-11,-21,1:172
-11,-20,1:172
-11,-19,1:172
-11,-18,1:172
-11,-17,1:172
-11,-16,1:172
-11,-15,1:172
-11,-14,1:172
-11,-13,1:172
-11,-12,1:172
-11,-11,1:172
-11,-10,1:172
-11,-9,1:172
-11,-8,1:172
-11,-7,1:172
-11,-6,1:172
-11,-5,1:172
-11,-4,1:172
-11,-3,1:172
-11,-2,1:172
-11,-1,1:172
-11,0,1:172
-11,1,1:172
-11,2,1:172
-11,3,1:172
-11,4,1:172
-11,5,1:172
-11,6,1:172
-11,7,1:172
-11,8,1:172
-11,9,1:172
-11,10,1:172
-11,11,1:172
-11,12,1:172
-11,13,1:172
-11,14,1:172
-11,15,1:172
-11,16,1:172
-11,17,1:172
-11,18,1:172
-11,19,1:172
-11,20,1:172
-11,21,1:172
-11,22,1:1
-11,23,1:1
-11,24,1:1
-11,25,1:1
-11,26,1:1
-11,27,1:1
-11,28,1:1
-11,29,1:1
-11,30,1:1
-11,31,1:1
-11,32,1:1
-11,33,1:1
-11,34,1:1
-11,35,1:1
-11,36,1:1
-11,37,1:1
-11,-41,2:1
-11,-40,2:1
-11,-39,2:1
-11,-38,2:1
-11,-37,2:1
-11,-36,2:1
-11,-35,2:1
-11,-34,2:1
-11,-33,2:1
-11,-32,2:1
-11,-31,2:1
-11,-30,2:1
-11,-29,2:1
-11,-28,2:1
-11,-27,2:1
-11,-26,2:1
-11,-25,2:95.12
-11,-24,2:95.12
-11,-23,2:95.12
-11,-22,2:95.12
-11,-21,2:95.12
-11,-20,2:95.12
-11,-19,2:95.12
-11,-18,2:95.12
-11,-17,2:95.12
-11,-16,2:95.12
-11,-15,2:95.12
-11,-14,2:95.12
-11,-13,2:95.12
-11,-12,2:95.12
-11,-11,2:95.12
-11,-10,2:95.12
-11,-9,2:95.12
-11,-8,2:95.12
-11,-7,2:95.12
-11,-6,2:95.12
-11,-5,2:95.12
-11,-4,2:95.12
-11,-3,2:95.12
-11,-2,2:95.12
-11,-1,2:95.12
-11,0,2:95.12
-11,1,2:95.12
-11,2,2:95.12
-11,3,2:95.12
-11,4,2:95.12
-11,5,2:95.12
-11,6,2:95.12
-11,7,2:95.12
-11,8,2:95.12
-11,9,2:95.12
-11,10,2:95.12
-11,11,2:95.12
-11,12,2:95.12
-11,13,2:95.12
-11,14,2:95.12
-11,15,2:95.12
-11,16,2:95.12
-11,17,2:95.12
-11,18,2:95.12
-11,19,2:95.12
-11,20,2:95.12
-11,21,2:95.12
-11,22,2:1
-11,23,2:1
-11,24,2:1
-11,25,2:1
-11,26,2:1
-11,27,2:1
-11,28,2:1
-11,29,2:1
-11,30,2:1
-11,31,2:1
-11,32,2:1
-11,33,2:1
-11,34,2:1
-11,35,2:1
-11,36,2:1
-11,37,2:1
-11,-41,3:1
-11,-40,3:1
-11,-39,3:1
-11,-38,3:1
-11,-37,3:1
-11,-36,3:1
-11,-35,3:1
-11,-34,3:1
-11,-33,3:1
-11,-32,3:1
-11,-31,3:1
-11,-30,3:1
-11,-29,3:1
-11,-28,3:1
-11,-27,3:1
-11,-26,3:1
-11,-8,3:159.1
-11,-7,3:159.1
-11,-6,3:159.1
-11,-5,3:159.1
-11,-4,3:159.1
-11,-2,3:159.1
-11,0,3:159.1
-11,1,3:159.1
-11,2,3:159.1
-11,3,3:159.1
-11,4,3:159.1
-11,22,3:1
-11,23,3:1
-11,24,3:1
-11,25,3:1
-11,26,3:1
-11,27,3:1
-11,28,3:1
-11,29,3:1
-11,30,3:1
-11,31,3:1
-11,32,3:1
-11,33,3:1
-11,34,3:1
-11,35,3:1
-11,36,3:1
-11,37,3:1
-10,-40,1:1
-10,-39,1:1
-10,-38,1:1
-10,-37,1:1
-10,-36,1:1
-10,-35,1:1
-10,-34,1:1
-10,-33,1:1
-10,-32,1:1
-10,-31,1:1
-10,-30,1:1
-10,-29,1:1
-10,-28,1:1
-10,-27,1:1
-10,-26,1:1
-10,-25,1:172
-10,-24,1:172
-10,-23,1:172
-10,-22,1:172
-10,-21,1:172
-10,-20,1:172
-10,-19,1:172
-10,-18,1:172
-10,-17,1:172
-10,-16,1:172
-10,-15,1:172
-10,-14,1:172
-10,-13,1:172
-10,-12,1:172
-10,-11,1:172
-10,-10,1:172
-10,-9,1:172
-10,-8,1:172
-10,-7,1:172
-10,-6,1:172
-10,-5,1:172
-10,-4,1:172
-10,-3,1:172
-10,-2,1:172
-10,-1,1:172
-10,0,1:172
-10,1,1:172
-10,2,1:172
-10,3,1:172
-10,4,1:172
-10,5,1:172
-10,6,1:172
-10,7,1:172
-10,8,1:172
-10,9,1:172
-10,10,1:172
-10,11,1:172
-10,12,1:172
-10,13,1:172
-10,14,1:172
-10,15,1:172
-10,16,1:172
-10,17,1:172
-10,18,1:172
-10,19,1:172
-10,20,1:172
-10,21,1:172
-10,22,1:1
-10,23,1:1
-10,24,1:1
-10,25,1:1
-10,26,1:1
-10,27,1:1
-10,28,1:1
-10,29,1:1
-10,30,1:1
-10,31,1:1
-10,32,1:1
-10,33,1:1
-10,34,1:1
-10,35,1:1
-10,36,1:1
-10,-40,2:1
-10,-39,2:1
-10,-38,2:1
-10,-37,2:1
-10,-36,2:1
-10,-35,2:1
-10,-34,2:1
-10,-33,2:1
-10,-32,2:1
-10,-31,2:1
-10,-30,2:1
-10,-29,2:1
-10,-28,2:1
-10,-27,2:1
-10,-26,2:1
-10,-25,2:95.12
-10,-24,2:95.12
-10,-23,2:95.12
-10,-22,2:95.12
-10,-21,2:95.12
-10,-20,2:95.12
-10,-19,2:95.12
-10,-18,2:95.12
-10,-17,2:95.12
-10,-16,2:95.12
-10,-15,2:95.12
-10,-14,2:95.12
-10,-13,2:95.12
-10,-12,2:95.12
-10,-11,2:95.12
-10,-10,2:95.12
-10,-9,2:95.12
-10,-8,2:95.12
-10,-7,2:95.12
-10,-6,2:95.12
-10,-5,2:95.12
-10,-4,2:95.12
-10,-3,2:95.12
-10,-2,2:95.12
-10,-1,2:95.12
-10,0,2:95.12
-10,1,2:95.12
-10,2,2:95.12
-10,3,2:95.12
-10,4,2:95.12
-10,5,2:95.12
-10,6,2:95.12
-10,7,2:95.12
-10,8,2:95.12
-10,9,2:95.12
-10,10,2:95.12
-10,11,2:95.12
-10,12,2:95.12
-10,13,2:95.12
-10,14,2:95.12
-10,15,2:95.12
-10,16,2:95.12
-10,17,2:95.12
-10,18,2:95.12
-10,19,2:95.12
-10,20,2:95.12
-10,21,2:95.12
-10,22,2:1
-10,23,2:1
-10,24,2:1
-10,25,2:1
-10,26,2:1
-10,27,2:1
-10,28,2:1
-10,29,2:1
-10,30,2:1
-10,31,2:1
-10,32,2:1
-10,33,2:1
-10,34,2:1
-10,35,2:1
-10,36,2:1
-10,-40,3:1
-10,-39,3:1
-10,-38,3:1
-10,-37,3:1
-10,-36,3:1
-10,-35,3:1
-10,-34,3:1
-10,-33,3:1
-10,-32,3:1
-10,-31,3:1
-10,-30,3:1
-10,-29,3:1
-10,-28,3:1
-10,-27,3:1
-10,-26,3:1
-10,-8,3:159.1
-10,-7,3:159.1
-10,-6,3:159.1
-10,-5,3:159.1
-10,-4,3:159.1
-10,-3,3:159.1
-10,-2,3:159.1
-10,-1,3:159.1
-10,0,3:159.1
-10,1,3:159.1
-10,2,3:159.1
-10,3,3:159.1
-10,4,3:159.1
-10,22,3:1
-10,23,3:1
-10,24,3:1
-10,25,3:1
-10,26,3:1
-10,27,3:1
-10,28,3:1
-10,29,3:1
-10,30,3:1
-10,31,3:1
-10,32,3:1
-10,33,3:1
-10,34,3:1
-10,35,3:1
-10,36,3:1
-9,-40,1:1
-9,-39,1:1
-9,-38,1:1
-9,-37,1:1
-9,-36,1:1
-9,-35,1:1
-9,-34,1:1
-9,-33,1:1
-9,-32,1:1
-9,-31,1:1
-9,-30,1:1
-9,-29,1:1
-9,-28,1:1
-9,-27,1:1
-9,-26,1:1
-9,-25,1:172
-9,-24,1:172
-9,-23,1:172
-9,-22,1:172
-9,-21,1:172
-9,-20,1:172
-9,-19,1:172
-9,-18,1:172
-9,-17,1:172
-9,-16,1:172
-9,-15,1:172
-9,-14,1:172
-9,-13,1:172
-9,-12,1:172
-9,-11,1:172
-9,-10,1:172
-9,-9,1:172
-9,-8,1:172
-9,-7,1:172
-9,-6,1:172
-9,-5,1:172
-9,-4,1:172
-9,-3,1:172
-9,-2,1:172
-9,-1,1:172
-9,0,1:172
-9,1,1:172
-9,2,1:172
-9,3,1:172
-9,4,1:172
-9,5,1:172
-9,6,1:172
-9,7,1:172
-9,8,1:172
-9,9,1:172
-9,10,1:172
-9,11,1:172
-9,12,1:172
-9,13,1:172
-9,14,1:172
-9,15,1:172
-9,16,1:172
-9,17,1:172
-9,18,1:172
-9,19,1:172
-9,20,1:172
-9,21,1:172
-9,22,1:1
-9,23,1:1
-9,24,1:1
-9,25,1:1
-9,26,1:1
-9,27,1:1
-9,28,1:1
-9,29,1:1
-9,30,1:1
-9,31,1:1
-9,32,1:1
-9,33,1:1
-9,34,1:1
-9,35,1:1
-9,36,1:1
-9,-40,2:1
-9,-39,2:1
-9,-38,2:1
-9,-37,2:1
-9,-36,2:1
-9,-35,2:1
-9,-34,2:1
-9,-33,2:1
-9,-32,2:1
-9,-31,2:1
-9,-30,2:1
-9,-29,2:1
-9,-28,2:1
-9,-27,2:1
-9,-26,2:1
-9,-25,2:95.12
-9,-24,2:95.12
-9,-23,2:95.12
-9,-22,2:95.12
-9,-21,2:95.12
-9,-20,2:95.12
-9,-19,2:95.12
-9,-18,2:95.12
-9,-17,2:95.12
-9,-16,2:95.12
-9,-15,2:95.12
-9,-14,2:95.12
-9,-13,2:95.12
-9,-12,2:95.12
-9,-11,2:95.12
-9,-10,2:95.12
-9,-9,2:95.12
-9,-8,2:95.12
-9,-7,2:95.12
-9,-6,2:95.12
-9,-5,2:95.12
-9,-4,2:95.12
-9,-3,2:95.12
-9,-2,2:95.12
-9,-1,2:95.12
-9,0,2:95.12
-9,1,2:95.12
-9,2,2:95.12
-9,3,2:95.12
-9,4,2:95.12
-9,5,2:95.12
-9,6,2:95.12
-9,7,2:95.12
-9,8,2:95.12
-9,9,2:95.12
-9,10,2:95.12
-9,11,2:95.12
-9,12,2:95.12
-9,13,2:95.12
-9,14,2:95.12
-9,15,2:95.12
-9,16,2:95.12
-9,17,2:95.12
-9,18,2:95.12
-9,19,2:95.12
-9,20,2:95.12
-9,21,2:95.12
-9,22,2:1
-9,23,2:1
-9,24,2:1
-9,25,2:1
-9,26,2:1
-9,27,2:1
-9,28,2:1
-9,29,2:1
-9,30,2:1
-9,31,2:1
-9,32,2:1
-9,33,2:1
-9,34,2:1
-9,35,2:1
-9,36,2:1
-9,-40,3:1
-9,-39,3:1
-9,-38,3:1
-9,-37,3:1
-9,-36,3:1
-9,-35,3:1
-9,-34,3:1
-9,-33,3:1
-9,-32,3:1
-9,-31,3:1
-9,-30,3:1
-9,-29,3:1
-9,-28,3:1
-9,-27,3:1
-9,-26,3:1
-9,-18,3:159.1
-9,-17,3:159.1
-9,-7,3:159.1
-9,-6,3:159.1
-9,-5,3:159.1
-9,-4,3:159.1
-9,-3,3:159.1
-9,-2,3:159.1
-9,-1,3:159.1
-9,0,3:159.1
-9,1,3:159.1
-9,2,3:159.1
-9,3,3:159.1
-9,13,3:159.1
-9,14,3:159.1
-9,22,3:1
-9,23,3:1
-9,24,3:1
-9,25,3:1
-9,26,3:1
-9,27,3:1
-9,28,3:1
-9,29,3:1
-9,30,3:1
-9,31,3:1
-9,32,3:1
-9,33,3:1
-9,34,3:1
-9,35,3:1
-9,36,3:1
-8,-38,1:1
-8,-37,1:1
-8,-36,1:1
-8,-35,1:1
-8,-34,1:1
-8,-33,1:1
-8,-32,1:1
-8,-31,1:1
-8,-30,1:1
-8,-29,1:1
-8,-28,1:1
-8,-27,1:1
-8,-26,1:172
-8,-25,1:172
-8,-24,1:172
-8,-23,1:172
-8,-22,1:172
-8,-21,1:172
-8,-20,1:172
-8,-19,1:172
-8,-18,1:172
-8,-17,1:172
-8,-16,1:172
-8,-15,1:172
-8,-14,1:172
-8,-13,1:172
-8,-12,1:172
-8,-11,1:172
-8,-10,1:172
-8,-9,1:172
-8,-8,1:172
-8,-7,1:172
-8,-6,1:172
-8,-5,1:172
-8,-4,1:172
-8,-3,1:172
-8,-2,1:172
-8,-1,1:172
-8,0,1:172
-8,1,1:172
-8,2,1:172
-8,3,1:172
-8,4,1:172
-8,5,1:172
-8,6,1:172
-8,7,1:172
-8,8,1:172
-8,9,1:172
-8,10,1:172
-8,11,1:172
-8,12,1:172
-8,13,1:172
-8,14,1:172
-8,15,1:172
-8,16,1:172
-8,17,1:172
-8,18,1:172
-8,19,1:172
-8,20,1:172
-8,21,1:172
-8,22,1:172
-8,23,1:1
-8,24,1:1
-8,25,1:1
-8,26,1:1
-8,27,1:1
-8,28,1:1
-8,29,1:1
-8,30,1:1
-8,31,1:1
-8,32,1:1
-8,33,1:1
-8,34,1:1
-8,-38,2:1
-8,-37,2:1
-8,-36,2:1
-8,-35,2:1
-8,-34,2:1
-8,-33,2:1
-8,-32,2:1
-8,-31,2:1
-8,-30,2:1
-8,-29,2:1
-8,-28,2:1
-8,-27,2:1
-8,-26,2:95.12
-8,-25,2:95.12
-8,-24,2:95.12
-8,-23,2:95.12
-8,-22,2:95.12
-8,-21,2:95.12
-8,-20,2:95.12
-8,-19,2:95.12
-8,-18,2:95.12
-8,-17,2:95.12
-8,-16,2:95.12
-8,-15,2:95.12
-8,-14,2:95.12
-8,-13,2:95.12
-8,-12,2:95.12
-8,-11,2:95.12
-8,-10,2:95.12
-8,-9,2:95.12
-8,-8,2:95.12
-8,-7,2:95.12
-8,-6,2:95.12
-8,-5,2:95.12
-8,-4,2:95.12
-8,-3,2:95.12
-8,-2,2:95.12
-8,-1,2:95.12
-8,0,2:95.12
-8,1,2:95.12
-8,2,2:95.12
-8,3,2:95.12
-8,4,2:95.12
-8,5,2:95.12
-8,6,2:95.12
-8,7,2:95.12
-8,8,2:95.12
-8,9,2:95.12
-8,10,2:95.12
-8,11,2:95.12
-8,12,2:95.12
-8,13,2:95.12
-8,14,2:95.12
-8,15,2:95.12
-8,16,2:95.12
-8,17,2:95.12
-8,18,2:95.12
-8,19,2:95.12
-8,20,2:95.12
-8,21,2:95.12
-8,22,2:95.12
-8,23,2:1
-8,24,2:1
-8,25,2:1
-8,26,2:1
-8,27,2:1
-8,28,2:1
-8,29,2:1
-8,30,2:1
-8,31,2:1
-8,32,2:1
-8,33,2:1
-8,34,2:1
-8,-38,3:1
-8,-37,3:1
-8,-36,3:1
-8,-35,3:1
-8,-34,3:1
-8,-33,3:1
-8,-32,3:1
-8,-31,3:1
-8,-30,3:1
-8,-29,3:1
-8,-28,3:1
-8,-27,3:1
-8,-16,3:159.1
-8,-15,3:159.1
-8,-14,3:159.1
-8,-13,3:159.1
-8,-11,3:159.1
-8,-9,3:159.1
-8,-8,3:159.1
-8,-7,3:159.1
-8,-6,3:159.1
-8,-5,3:159.1
-8,-4,3:159.1
-8,-3,3:159.1
-8,-2,3:159.1
-8,-1,3:159.1
-8,0,3:159.1
-8,1,3:159.1
-8,2,3:159.1
-8,3,3:159.1
-8,4,3:159.1
-8,5,3:159.1
-8,7,3:159.1
-8,9,3:159.1
-8,10,3:159.1
-8,11,3:159.1
-8,12,3:159.1
-8,23,3:1
-8,24,3:1
-8,25,3:1
-8,26,3:1
-8,27,3:1
-8,28,3:1
-8,29,3:1
-8,30,3:1
-8,31,3:1
-8,32,3:1
-8,33,3:1
-8,34,3:1
-7,-38,1:1
-7,-37,1:1
-7,-36,1:1
-7,-35,1:1
-7,-34,1:1
-7,-33,1:1
-7,-32,1:1
-7,-31,1:1
-7,-30,1:1
-7,-29,1:1
-7,-28,1:1
-7,-27,1:1
-7,-26,1:172
-7,-25,1:172
-7,-24,1:172
-7,-23,1:172
-7,-22,1:172
-7,-21,1:172
-7,-20,1:172
-7,-19,1:172
-7,-18,1:172
-7,-17,1:172
-7,-16,1:172
-7,-15,1:172
-7,-14,1:172
-7,-13,1:172
-7,-12,1:172
-7,-11,1:172
-7,-10,1:172
-7,-9,1:172
-7,-8,1:172
-7,-7,1:172
-7,-6,1:172
-7,-5,1:172
-7,-4,1:172
-7,-3,1:172
-7,-2,1:172
-7,-1,1:172
-7,0,1:172
-7,1,1:172
-7,2,1:172
-7,3,1:172
-7,4,1:172
-7,5,1:172
-7,6,1:172
-7,7,1:172
-7,8,1:172
-7,9,1:172
-7,10,1:172
-7,11,1:172
-7,12,1:172
-7,13,1:172
-7,14,1:172
-7,15,1:172
-7,16,1:172
-7,17,1:172
-7,18,1:172
-7,19,1:172
-7,20,1:172
-7,21,1:172
-7,22,1:172
-7,23,1:1
-7,24,1:1
-7,25,1:1
-7,26,1:1
-7,27,1:1
-7,28,1:1
-7,29,1:1
-7,30,1:1
-7,31,1:1
-7,32,1:1
-7,33,1:1
-7,34,1:1
-7,-38,2:1
-7,-37,2:1
-7,-36,2:1
-7,-35,2:1
-7,-34,2:1
-7,-33,2:1
-7,-32,2:1
-7,-31,2:1
-7,-30,2:1
-7,-29,2:1
-7,-28,2:1
-7,-27,2:1
-7,-26,2:95.12
-7,-25,2:95.12
-7,-24,2:95.12
-7,-23,2:95.12
-7,-22,2:95.12
-7,-21,2:95.12
-7,-20,2:95.12
-7,-19,2:95.12
-7,-18,2:95.12
-7,-17,2:95.12
-7,-16,2:95.12
-7,-15,2:95.12
-7,-14,2:95.12
-7,-13,2:95.12
-7,-12,2:95.12
-7,-11,2:95.12
-7,-10,2:95.12
-7,-9,2:95.12
-7,-8,2:95.12
-7,-7,2:95.12
-7,-6,2:95.12
-7,-5,2:95.12
-7,-4,2:95.12
-7,-3,2:95.12
-7,-2,2:95.12
-7,-1,2:95.12
-7,0,2:95.12
-7,1,2:95.12
-7,2,2:95.12
-7,3,2:95.12
-7,4,2:95.12
-7,5,2:95.12
-7,6,2:95.12
-7,7,2:95.12
-7,8,2:95.12
-7,9,2:95.12
-7,10,2:95.12
-7,11,2:95.12
-7,12,2:95.12
-7,13,2:95.12
-7,14,2:95.12
-7,15,2:95.12
-7,16,2:95.12
-7,17,2:95.12
-7,18,2:95.12
-7,19,2:95.12
-7,20,2:95.12
-7,21,2:95.12
-7,22,2:95.12
-7,23,2:1
-7,24,2:1
-7,25,2:1
-7,26,2:1
-7,27,2:1
-7,28,2:1
-7,29,2:1
-7,30,2:1
-7,31,2:1
-7,32,2:1
-7,33,2:1
-7,34,2:1
-7,-38,3:1
-7,-37,3:1
-7,-36,3:1
-7,-35,3:1
-7,-34,3:1
-7,-33,3:1
-7,-32,3:1
-7,-31,3:1
-7,-30,3:1
-7,-29,3:1
-7,-28,3:1
-7,-27,3:1
-7,-15,3:159.1
-7,-14,3:159.1
-7,-13,3:159.1
-7,-12,3:159.1
-7,-11,3:159.1
-7,-10,3:159.1
-7,-9,3:159.1
-7,-8,3:159.1
-7,-7,3:159.1
-7,-6,3:159.1
-7,-5,3:159.1
-7,-4,3:159.1
-7,-3,3:159.1
-7,-2,3:159.1
-7,-1,3:159.1
-7,0,3:159.1
-7,1,3:159.1
-7,2,3:159.1
-7,3,3:159.1
-7,4,3:159.1
-7,5,3:159.1
-7,6,3:159.1
-7,7,3:159.1
-7,8,3:159.1
-7,9,3:159.1
-7,10,3:159.1
-7,11,3:159.1
-7,23,3:1
-7,24,3:1
-7,25,3:1
-7,26,3:1
-7,27,3:1
-7,28,3:1
-7,29,3:1
-7,30,3:1
-7,31,3:1
-7,32,3:1
-7,33,3:1
-7,34,3:1
-6,-35,1:1
-6,-34,1:1
-6,-33,1:1
-6,-32,1:1
-6,-31,1:1
-6,-30,1:1
-6,-29,1:1
-6,-28,1:1
-6,-27,1:1
-6,-26,1:172
-6,-25,1:172
-6,-24,1:172
-6,-23,1:172
-6,-22,1:172
-6,-21,1:172
-6,-20,1:172
-6,-19,1:172
-6,-18,1:172
-6,-17,1:172
-6,-16,1:172
-6,-15,1:172
-6,-14,1:172
-6,-13,1:172
-6,-12,1:172
-6,-11,1:172
-6,-10,1:172
-6,-9,1:172
-6,-8,1:172
-6,-7,1:172
-6,-6,1:172
-6,-5,1:172
-6,-4,1:172
-6,-3,1:172
-6,-2,1:172
-6,-1,1:172
-6,0,1:172
-6,1,1:172
-6,2,1:172
-6,3,1:172
-6,4,1:172
-6,5,1:172
-6,6,1:172
-6,7,1:172
-6,8,1:172
-6,9,1:172
-6,10,1:172
-6,11,1:172
-6,12,1:172
-6,13,1:172
-6,14,1:172
-6,15,1:172
-6,16,1:172
-6,17,1:172
-6,18,1:172
-6,19,1:172
-6,20,1:172
-6,21,1:172
-6,22,1:172
-6,23,1:1
-6,24,1:1
-6,25,1:1
-6,26,1:1
-6,27,1:1
-6,28,1:1
-6,29,1:1
-6,30,1:1
-6,31,1:1
-6,-35,2:1
-6,-34,2:1
-6,-33,2:1
-6,-32,2:1
-6,-31,2:1
-6,-30,2:1
-6,-29,2:1
-6,-28,2:1
-6,-27,2:1
-6,-26,2:95.12
-6,-25,2:95.12
-6,-24,2:95.12
-6,-23,2:95.12
-6,-22,2:95.12
-6,-21,2:95.12
-6,-20,2:95.12
-6,-19,2:95.12
-6,-18,2:95.12
-6,-17,2:95.12
-6,-16,2:95.12
-6,-15,2:95.12
-6,-14,2:95.12
-6,-13,2:95.12
-6,-12,2:95.12
-6,-11,2:95.12
-6,-10,2:95.12
-6,-9,2:95.12
-6,-8,2:95.12
-6,-7,2:95.12
-6,-6,2:95.12
-6,-5,2:95.12
-6,-4,2:95.12
-6,-3,2:95.12
-6,-2,2:95.12
-6,-1,2:95.12
-6,0,2:95.12
-6,1,2:95.12
-6,2,2:95.12
-6,3,2:95.12
-6,4,2:95.12
-6,5,2:95.12
-6,6,2:95.12
-6,7,2:95.12
-6,8,2:95.12
-6,9,2:95.12
-6,10,2:95.12
-6,11,2:95.12
-6,12,2:95.12
-6,13,2:95.12
-6,14,2:95.12
-6,15,2:95.12
-6,16,2:95.12
-6,17,2:95.12
-6,18,2:95.12
-6,19,2:95.12
-6,20,2:95.12
-6,21,2:95.12
-6,22,2:95.12
-6,23,2:1
-6,24,2:1
-6,25,2:1
-6,26,2:1
-6,27,2:1
-6,28,2:1
-6,29,2:1
-6,30,2:1
-6,31,2:1
-6,-35,3:1
-6,-34,3:1
-6,-33,3:1
-6,-32,3:1
-6,-31,3:1
-6,-30,3:1
-6,-29,3:1
-6,-28,3:1
-6,-27,3:1
-6,-15,3:159.1
-6,-14,3:159.1
-6,-13,3:159.1
-6,-12,3:159.1
-6,-11,3:159.1
-6,-10,3:159.1
-6,-9,3:159.1
-6,-8,3:159.1
-6,-7,3:159.1
-6,-6,3:159.1
-6,-5,3:159.1
-6,-4,3:159.1
-6,-3,3:159.1
-6,-2,3:159.1
-6,-1,3:159.1
-6,0,3:159.1
-6,1,3:159.1
-6,2,3:159.1
-6,3,3:159.1
-6,4,3:159.1
-6,5,3:159.1
-6,6,3:159.1
-6,7,3:159.1
-6,8,3:159.1
-6,9,3:159.1
-6,10,3:159.1
-6,11,3:159.1
-6,23,3:1
-6,24,3:1
-6,25,3:1
-6,26,3:1
-6,27,3:1
-6,28,3:1
-6,29,3:1
-6,30,3:1
-6,31,3:1
-5,-35,1:1
-5,-34,1:1
-5,-33,1:1
-5,-32,1:1
-5,-31,1:1
-5,-30,1:1
-5,-29,1:1
-5,-28,1:1
-5,-27,1:172
-5,-26,1:172
-5,-25,1:172
-5,-24,1:172
-5,-23,1:172
-5,-22,1:172
-5,-21,1:172
-5,-20,1:172
-5,-19,1:172
-5,-18,1:172
-5,-17,1:172
-5,-16,1:172
-5,-15,1:172
-5,-14,1:172
-5,-13,1:172
-5,-12,1:172
-5,-11,1:172
-5,-10,1:172
-5,-9,1:172
-5,-8,1:172
-5,-7,1:172
-5,-6,1:172
-5,-5,1:172
-5,-4,1:172
-5,-3,1:172
-5,-2,1:172
-5,-1,1:172
-5,0,1:172
-5,1,1:172
-5,2,1:172
-5,3,1:172
-5,4,1:172
-5,5,1:172
-5,6,1:172
-5,7,1:172
-5,8,1:172
-5,9,1:172
-5,10,1:172
-5,11,1:172
-5,12,1:172
-5,13,1:172
-5,14,1:172
-5,15,1:172
-5,16,1:172
-5,17,1:172
-5,18,1:172
-5,19,1:172
-5,20,1:172
-5,21,1:172
-5,22,1:172
-5,23,1:172
-5,24,1:1
-5,25,1:1
-5,26,1:1
-5,27,1:1
-5,28,1:1
-5,29,1:1
-5,30,1:1
-5,31,1:1
-5,-35,2:1
-5,-34,2:1
-5,-33,2:1
-5,-32,2:1
-5,-31,2:1
-5,-30,2:1
-5,-29,2:1
-5,-28,2:1
-5,-27,2:95.12
-5,-26,2:95.12
-5,-25,2:95.12
-5,-24,2:95.12
-5,-23,2:95.12
-5,-22,2:95.12
-5,-21,2:95.12
-5,-20,2:95.12
-5,-19,2:95.12
-5,-18,2:95.12
-5,-17,2:95.12
-5,-16,2:95.12
-5,-15,2:95.12
-5,-14,2:95.12
-5,-13,2:95.12
-5,-12,2:95.12
-5,-11,2:95.12
-5,-10,2:95.12
-5,-9,2:95.12
-5,-8,2:95.12
-5,-7,2:95.12
-5,-6,2:95.12
-5,-5,2:95.12
-5,-4,2:95.12
-5,-3,2:95.12
-5,-2,2:95.12
-5,-1,2:95.12
-5,0,2:95.12
-5,1,2:95.12
-5,2,2:95.12
-5,3,2:95.12
-5,4,2:95.12
-5,5,2:95.12
-5,6,2:95.12
-5,7,2:95.12
-5,8,2:95.12
-5,9,2:95.12
-5,10,2:95.12
-5,11,2:95.12
-5,12,2:95.12
-5,13,2:95.12
-5,14,2:95.12
-5,15,2:95.12
-5,16,2:95.12
-5,17,2:95.12
-5,18,2:95.12
-5,19,2:95.12
-5,20,2:95.12
-5,21,2:95.12
-5,22,2:95.12
-5,23,2:95.12
-5,24,2:1
-5,25,2:1
-5,26,2:1
-5,27,2:1
-5,28,2:1
-5,29,2:1
-5,30,2:1
-5,31,2:1
-5,-35,3:1
-5,-34,3:1
-5,-33,3:1
-5,-32,3:1
-5,-31,3:1
-5,-30,3:1
-5,-29,3:1
-5,-28,3:1
-5,-13,3:159.1
-5,-12,3:159.1
-5,-11,3:159.1
-5,-10,3:159.1
-5,-9,3:159.1
-5,-8,3:159.1
-5,-7,3:159.1
-5,-6,3:159.1
-5,-5,3:159.1
-5,-4,3:159.1
-5,-3,3:159.1
-5,-2,3:159.1
-5,-1,3:159.1
-5,0,3:159.1
-5,1,3:159.1
-5,2,3:159.1
-5,3,3:159.1
-5,4,3:159.1
-5,5,3:159.1
-5,6,3:159.1
-5,7,3:159.1
-5,8,3:159.1
-5,9,3:159.1
-5,24,3:1
-5,25,3:1
-5,26,3:1
-5,27,3:1
-5,28,3:1
-5,29,3:1
-5,30,3:1
-5,31,3:1
-5,-4,4:109
-5,-3,4:109
-5,-2,4:109.4
-5,-1,4:109
-5,0,4:109
-4,-32,1:1
-4,-31,1:1
-4,-30,1:1
-4,-29,1:1
-4,-28,1:1
-4,-27,1:172
-4,-26,1:172
-4,-25,1:172
-4,-24,1:172
-4,-23,1:172
-4,-22,1:172
-4,-21,1:172
-4,-20,1:172
-4,-19,1:172
-4,-18,1:172
-4,-17,1:172
-4,-16,1:172
-4,-15,1:172
-4,-14,1:172
-4,-13,1:172
-4,-12,1:172
-4,-11,1:172
-4,-10,1:172
-4,-9,1:172
-4,-8,1:172
-4,-7,1:172
-4,-6,1:172
-4,-5,1:172
-4,-4,1:172
-4,-3,1:172
-4,-2,1:172
-4,-1,1:172
-4,0,1:172
-4,1,1:172
-4,2,1:172
-4,3,1:172
-4,4,1:172
-4,5,1:172
-4,6,1:172
-4,7,1:172
-4,8,1:172
-4,9,1:172
-4,10,1:172
-4,11,1:172
-4,12,1:172
-4,13,1:172
-4,14,1:172
-4,15,1:172
-4,16,1:172
-4,17,1:172
-4,18,1:172
-4,19,1:172
-4,20,1:172
-4,21,1:172
-4,22,1:172
-4,23,1:172
-4,24,1:1
-4,25,1:1
-4,26,1:1
-4,27,1:1
-4,28,1:1
-4,-32,2:1
-4,-31,2:1
-4,-30,2:1
-4,-29,2:1
-4,-28,2:1
-4,-27,2:95.12
-4,-26,2:95.12
-4,-25,2:95.12
-4,-24,2:95.12
-4,-23,2:95.12
-4,-22,2:95.12
-4,-21,2:95.12
-4,-20,2:95.12
-4,-19,2:95.12
-4,-18,2:95.12
-4,-17,2:95.12
-4,-16,2:95.12
-4,-15,2:95.12
-4,-14,2:95.12
-4,-13,2:95.12
-4,-12,2:95.12
-4,-11,2:95.12
-4,-10,2:95.12
-4,-9,2:95.12
-4,-8,2:95.12
-4,-7,2:95.12
-4,-6,2:95.12
-4,-5,2:95.12
-4,-4,2:95.12
-4,-3,2:95.12
-4,-2,2:95.12
-4,-1,2:95.12
-4,0,2:95.12
-4,1,2:95.12
-4,2,2:95.12
-4,3,2:95.12
-4,4,2:95.12
-4,5,2:95.12
-4,6,2:95.12
-4,7,2:95.12
-4,8,2:95.12
-4,9,2:95.12
-4,10,2:95.12
-4,11,2:95.12
-4,12,2:95.12
-4,13,2:95.12
-4,14,2:95.12
-4,15,2:95.12
-4,16,2:95.12
-4,17,2:95.12
-4,18,2:95.12
-4,19,2:95.12
-4,20,2:95.12
-4,21,2:95.12
-4,22,2:95.12
-4,23,2:95.12
-4,24,2:1
-4,25,2:1
-4,26,2:1
-4,27,2:1
-4,28,2:1
-4,-32,3:1
-4,-31,3:1
-4,-30,3:1
-4,-29,3:1
-4,-28,3:1
-4,-13,3:159.1
-4,-12,3:159.1
-4,-11,3:159.1
-4,-10,3:159.1
-4,-9,3:159.1
-4,-8,3:159.1
-4,-7,3:159.1
-4,-6,3:159.1
-4,-5,3:159.1
-4,-4,3:159.1
-4,-3,3:159.1
-4,-2,3:159.1
-4,-1,3:159.1
-4,0,3:159.1
-4,1,3:159.1
-4,2,3:159.1
-4,3,3:159.1
-4,4,3:159.1
-4,5,3:159.1
-4,6,3:159.1
-4,7,3:159.1
-4,8,3:159.1
-4,9,3:159.1
-4,24,3:1
-4,25,3:1
-4,26,3:1
-4,27,3:1
-4,28,3:1
-4,-5,4:109.2
-4,-4,4:173
-4,-3,4:109.4
-4,-2,4:109.5
-4,-1,4:109.4
-4,0,4:173
-4,1,4:109.3
-3,-32,1:1
-3,-31,1:1
-3,-30,1:1
-3,-29,1:1
-3,-28,1:1
-3,-27,1:172
-3,-26,1:172
-3,-25,1:172
-3,-24,1:172
-3,-23,1:172
-3,-22,1:172
-3,-21,1:172
-3,-20,1:172
-3,-19,1:172
-3,-18,1:172
-3,-17,1:172
-3,-16,1:172
-3,-15,1:172
-3,-14,1:172
-3,-13,1:172
-3,-12,1:172
-3,-11,1:172
-3,-10,1:172
-3,-9,1:172
-3,-8,1:172
-3,-7,1:172
-3,-6,1:172
-3,-5,1:172
-3,-4,1:172
-3,-3,1:172
-3,-2,1:172
-3,-1,1:172
-3,0,1:172
-3,1,1:172
-3,2,1:172
-3,3,1:172
-3,4,1:172
-3,5,1:172
-3,6,1:172
-3,7,1:172
-3,8,1:172
-3,9,1:172
-3,10,1:172
-3,11,1:172
-3,12,1:172
-3,13,1:172
-3,14,1:172
-3,15,1:172
-3,16,1:172
-3,17,1:172
-3,18,1:172
-3,19,1:172
-3,20,1:172
-3,21,1:172
-3,22,1:172
-3,23,1:172
-3,24,1:1
-3,25,1:1
-3,26,1:1
-3,27,1:1
-3,28,1:1
-3,-32,2:1
-3,-31,2:1
-3,-30,2:1
-3,-29,2:1
-3,-28,2:1
-3,-27,2:95.12
-3,-26,2:95.12
-3,-25,2:95.12
-3,-24,2:95.12
-3,-23,2:95.12
-3,-22,2:95.12
-3,-21,2:95.12
-3,-20,2:95.12
-3,-19,2:95.12
-3,-18,2:95.12
-3,-17,2:95.12
-3,-16,2:95.12
-3,-15,2:95.12
-3,-14,2:95.12
-3,-13,2:95.12
-3,-12,2:95.12
-3,-11,2:95.12
-3,-10,2:95.12
-3,-9,2:95.12
-3,-8,2:95.12
-3,-7,2:95.12
-3,-6,2:95.12
-3,-5,2:95.12
-3,-4,2:95.12
-3,-3,2:95.12
-3,-2,2:95.12
-3,-1,2:95.12
-3,0,2:95.12
-3,1,2:95.12
-3,2,2:95.12
-3,3,2:95.12
-3,4,2:95.12
-3,5,2:95.12
-3,6,2:95.12
-3,7,2:95.12
-3,8,2:95.12
-3,9,2:95.12
-3,10,2:95.12
-3,11,2:95.12
-3,12,2:95.12
-3,13,2:95.12
-3,14,2:95.12
-3,15,2:95.12
-3,16,2:95.12
-3,17,2:95.12
-3,18,2:95.12
-3,19,2:95.12
-3,20,2:95.12
-3,21,2:95.12
-3,22,2:95.12
-3,23,2:95.12
-3,24,2:1
-3,25,2:1
-3,26,2:1
-3,27,2:1
-3,28,2:1
-3,-35,3:1
-3,-34,3:1
-3,-33,3:1
-3,-32,3:1
-3,-31,3:1
-3,-30,3:1
-3,-29,3:1
-3,-28,3:1
-3,-12,3:159.1
-3,-11,3:159.1
-3,-10,3:159.1
-3,-9,3:159.1
-3,-8,3:159.1
-3,-7,3:159.1
-3,-6,3:159.1
-3,-5,3:159.1
-3,-4,3:159.1
-3,-3,3:159.1
-3,-2,3:159.1
-3,-1,3:159.1
-3,0,3:159.1
-3,1,3:159.1
-3,2,3:159.1
-3,3,3:159.1
-3,4,3:159.1
-3,5,3:159.1
-3,6,3:159.1
-3,7,3:159.1
-3,8,3:159.1
-3,24,3:1
-3,25,3:1
-3,26,3:1
-3,27,3:1
-3,28,3:1
-3,-6,4:109
-3,-5,4:173
-3,-4,4:173
-3,-3,4:173
-3,-2,4:109.4
-3,-1,4:173
-3,0,4:173
-3,1,4:173
-3,2,4:109
-2,-35,1:1
-2,-34,1:1
-2,-33,1:1
-2,-32,1:1
-2,-31,1:1
-2,-30,1:1
-2,-29,1:1
-2,-28,1:1
-2,-27,1:172
-2,-26,1:172
-2,-25,1:172
-2,-24,1:172
-2,-23,1:172
-2,-22,1:172
-2,-21,1:172
-2,-20,1:172
-2,-19,1:172
-2,-18,1:172
-2,-17,1:172
-2,-16,1:172
-2,-15,1:172
-2,-14,1:172
-2,-13,1:172
-2,-12,1:172
-2,-11,1:172
-2,-10,1:172
-2,-9,1:172
-2,-8,1:172
-2,-7,1:172
-2,-6,1:172
-2,-5,1:172
-2,-4,1:172
-2,-3,1:172
-2,-2,1:172
-2,-1,1:172
-2,0,1:172
-2,1,1:172
-2,2,1:172
-2,3,1:172
-2,4,1:172
-2,5,1:172
-2,6,1:172
-2,7,1:172
-2,8,1:172
-2,9,1:172
-2,10,1:172
-2,11,1:172
-2,12,1:172
-2,13,1:172
-2,14,1:172
-2,15,1:172
-2,16,1:172
-2,17,1:172
-2,18,1:172
-2,19,1:172
-2,20,1:172
-2,21,1:172
-2,22,1:172
-2,23,1:172
-2,24,1:1
-2,25,1:1
-2,26,1:1
-2,27,1:1
-2,28,1:1
-2,29,1:1
-2,30,1:1
-2,31,1:1
-2,-35,2:1
-2,-34,2:1
-2,-33,2:1
-2,-32,2:1
-2,-31,2:1
-2,-30,2:1
-2,-29,2:1
-2,-28,2:1
-2,-27,2:95.12
-2,-26,2:95.12
-2,-25,2:95.12
-2,-24,2:95.12
-2,-23,2:95.12
-2,-22,2:95.12
-2,-21,2:95.12
-2,-20,2:95.12
-2,-19,2:95.12
-2,-18,2:95.12
-2,-17,2:95.12
-2,-16,2:95.12
-2,-15,2:95.12
-2,-14,2:95.12
-2,-13,2:95.12
-2,-12,2:95.12
-2,-11,2:95.12
-2,-10,2:95.12
-2,-9,2:95.12
-2,-8,2:95.12
-2,-7,2:95.12
-2,-6,2:95.12
-2,-5,2:95.12
-2,-4,2:95.12
-2,-3,2:95.12
-2,-2,2:95.12
-2,-1,2:95.12
-2,0,2:95.12
-2,1,2:95.12
-2,2,2:95.12
-2,3,2:95.12
-2,4,2:95.12
-2,5,2:95.12
-2,6,2:95.12
-2,7,2:95.12
-2,8,2:95.12
-2,9,2:95.12
-2,10,2:95.12
-2,11,2:95.12
-2,12,2:95.12
-2,13,2:95.12
-2,14,2:95.12
-2,15,2:95.12
-2,16,2:95.12
-2,17,2:95.12
-2,18,2:95.12
-2,19,2:95.12
-2,20,2:95.12
-2,21,2:95.12
-2,22,2:95.12
-2,23,2:95.12
-2,24,2:1
-2,25,2:1
-2,26,2:1
-2,27,2:1
-2,28,2:1
-2,29,2:1
-2,30,2:1
-2,31,2:1
-2,-35,3:1
-2,-34,3:1
-2,-33,3:1
-2,-32,3:1
-2,-31,3:1
-2,-30,3:1
-2,-29,3:1
-2,-28,3:1
-2,-12,3:159.1
-2,-11,3:159.1
-2,-10,3:159.1
-2,-9,3:159.1
-2,-8,3:159.1
-2,-7,3:159.1
-2,-6,3:159.1
-2,-5,3:159.1
-2,-4,3:159.1
-2,-3,3:159.1
-2,-2,3:159.1
-2,-1,3:159.1
-2,0,3:159.1
-2,1,3:159.1
-2,2,3:159.1
-2,3,3:159.1
-2,4,3:159.1
-2,5,3:159.1
-2,6,3:159.1
-2,7,3:159.1
-2,8,3:159.1
-2,9,3:159.1
-2,24,3:1
-2,25,3:1
-2,26,3:1
-2,27,3:1
-2,28,3:1
-2,29,3:1
-2,30,3:1
-2,31,3:1
-2,-31,4:35.7
-2,-30,4:35.7
-2,-7,4:109.2
-2,-6,4:173
-2,-5,4:173
-2,-4,4:173
-2,-3,4:173
-2,-2,4:173
-2,-1,4:173
-2,0,4:173
-2,1,4:173
-2,2,4:173
-2,3,4:109.3
-2,26,4:35.7
-2,27,4:35.7
-2,-3,5:54.4
-2,-1,5:54.4
-1,-35,1:1
-1,-34,1:1
-1,-33,1:1
-1,-32,1:1
-1,-31,1:1
-1,-30,1:1
-1,-29,1:1
-1,-28,1:1
-1,-27,1:172
-1,-26,1:172
-1,-25,1:172
-1,-24,1:172
-1,-23,1:172
-1,-22,1:172
-1,-21,1:172
-1,-20,1:172
-1,-19,1:172
-1,-18,1:172
-1,-17,1:172
-1,-16,1:172
-1,-15,1:172
-1,-14,1:172
-1,-13,1:172
-1,-12,1:172
-1,-11,1:172
-1,-10,1:172
-1,-9,1:172
-1,-8,1:172
-1,-7,1:172
-1,-6,1:172
-1,-5,1:172
-1,-4,1:172
-1,-3,1:172
-1,-2,1:172
-1,-1,1:172
-1,0,1:172
-1,1,1:172
-1,2,1:172
-1,3,1:172
-1,4,1:172
-1,5,1:172
-1,6,1:172
-1,7,1:172
-1,8,1:172
-1,9,1:172
-1,10,1:172
-1,11,1:172
-1,12,1:172
-1,13,1:172
-1,14,1:172
-1,15,1:172
-1,16,1:172
-1,17,1:172
-1,18,1:172
-1,19,1:172
-1,20,1:172
-1,21,1:172
-1,22,1:172
-1,23,1:172
-1,24,1:1
-1,25,1:1
-1,26,1:1
-1,27,1:1
-1,28,1:1
-1,29,1:1
-1,30,1:1
-1,31,1:1
-1,-35,2:1
-1,-34,2:1
-1,-33,2:1
-1,-32,2:1
-1,-31,2:1
-1,-30,2:1
-1,-29,2:1
-1,-28,2:1
-1,-27,2:95.12
-1,-26,2:95.12
-1,-25,2:95.12
-1,-24,2:95.12
-1,-23,2:95.12
-1,-22,2:95.12
-1,-21,2:95.12
-1,-20,2:95.12
-1,-19,2:95.12
-1,-18,2:95.12
-1,-17,2:95.12
-1,-16,2:95.12
-1,-15,2:95.12
-1,-14,2:95.12
-1,-13,2:95.12
-1,-12,2:95.12
-1,-11,2:95.12
-1,-10,2:95.12
-1,-9,2:95.12
-1,-8,2:95.12
-1,-7,2:95.12
-1,-6,2:95.12
-1,-5,2:95.12
-1,-4,2:95.12
-1,-3,2:95.12
-1,-2,2:95.12
-1,-1,2:95.12
-1,0,2:95.12
-1,1,2:95.12
-1,2,2:95.12
-1,3,2:95.12
-1,4,2:95.12
-1,5,2:95.12
-1,6,2:95.12
-1,7,2:95.12
-1,8,2:95.12
-1,9,2:95.12
-1,10,2:95.12
-1,11,2:95.12
-1,12,2:95.12
-1,13,2:95.12
-1,14,2:95.12
-1,15,2:95.12
-1,16,2:95.12
-1,17,2:95.12
-1,18,2:95.12
-1,19,2:95.12
-1,20,2:95.12
-1,21,2:95.12
-1,22,2:95.12
-1,23,2:95.12
-1,24,2:1
-1,25,2:1
-1,26,2:1
-1,27,2:1
-1,28,2:1
-1,29,2:1
-1,30,2:1
-1,31,2:1
-1,-35,3:1
-1,-34,3:1
-1,-33,3:1
-1,-32,3:1
-1,-31,3:1
-1,-30,3:1
-1,-29,3:1
-1,-28,3:1
-1,-27,3:35.7
-1,-12,3:159.1
-1,-11,3:159.1
-1,-10,3:159.1
-1,-9,3:159.1
-1,-8,3:159.1
-1,-7,3:159.1
-1,-6,3:159.1
-1,-5,3:159.1
-1,-4,3:159.1
-1,-3,3:159.1
-1,-2,3:159.1
-1,-1,3:159.1
-1,0,3:159.1
-1,1,3:159.1
-1,2,3:159.1
-1,3,3:159.1
-1,4,3:159.1
-1,5,3:159.1
-1,6,3:159.1
-1,7,3:159.1
-1,8,3:159.1
-1,23,3:35.7
-1,24,3:1
-1,25,3:1
-1,26,3:1
-1,27,3:1
-1,28,3:1
-1,29,3:1
-1,30,3:1
-1,31,3:1
-1,-32,4:35.7
-1,-31,4:35.7
-1,-30,4:35.7
-1,-29,4:35.7
-1,-28,4:35.7
-1,-7,4:109.2
-1,-6,4:109.6
-1,-5,4:173
-1,-4,4:173
-1,-3,4:173
-1,-2,4:173
-1,-1,4:173
-1,0,4:173
-1,1,4:173
-1,2,4:109.7
-1,3,4:109.3
-1,24,4:35.7
-1,25,4:35.7
-1,26,4:35.7
-1,27,4:35.7
-1,28,4:35.7
-1,-31,5:35.7
-1,-30,5:35.7
-1,-4,5:54.2
-1,-2,5:54.4
-1,0,5:54.3
-1,26,5:35.7
-1,27,5:35.7
0,-39,1:1
0,-38,1:1
0,-37,1:1
0,-36,1:1
0,-35,1:1
0,-34,1:1
0,-33,1:1
0,-32,1:1
0,-31,1:1
0,-30,1:1
0,-29,1:1
0,-28,1:1
0,-27,1:172
0,-26,1:172
0,-25,1:172
0,-24,1:172
0,-23,1:172
0,-22,1:172
0,-21,1:172
0,-20,1:172
0,-19,1:172
0,-18,1:172
0,-17,1:172
0,-16,1:172
0,-15,1:172
0,-14,1:172
0,-13,1:172
0,-12,1:172
0,-11,1:172
0,-10,1:172
0,-9,1:172
0,-8,1:172
0,-7,1:172
0,-6,1:172
0,-5,1:172
0,-4,1:172
0,-3,1:172
0,-2,1:172
0,-1,1:172
0,0,1:172
0,1,1:172
0,2,1:172
0,3,1:172
0,4,1:172
0,5,1:172
0,6,1:172
0,7,1:172
0,8,1:172
0,9,1:172
0,10,1:172
0,11,1:172
0,12,1:172
0,13,1:172
0,14,1:172
0,15,1:172
0,16,1:172
0,17,1:172
0,18,1:172
0,19,1:172
0,20,1:172
0,21,1:172
0,22,1:172
0,23,1:172
0,24,1:1
0,25,1:1
0,26,1:1
0,27,1:1
0,28,1:1
0,29,1:1
0,30,1:1
0,31,1:1
0,32,1:1
0,33,1:1
0,34,1:1
0,35,1:1
0,-39,2:1
0,-38,2:1
0,-37,2:1
0,-36,2:1
0,-35,2:1
0,-34,2:1
0,-33,2:1
0,-32,2:1
0,-31,2:1
0,-30,2:1
0,-29,2:1
0,-28,2:1
0,-27,2:95.12
0,-26,2:95.12
0,-25,2:95.12
0,-24,2:95.12
0,-23,2:95.12
0,-22,2:95.12
0,-21,2:95.12
0,-20,2:95.12
0,-19,2:95.12
0,-18,2:95.12
0,-17,2:95.12
0,-16,2:95.12
0,-15,2:95.12
0,-14,2:95.12
0,-13,2:95.12
0,-12,2:95.12
0,-11,2:95.12
0,-10,2:95.12
0,-9,2:95.12
0,-8,2:95.12
0,-7,2:95.12
0,-6,2:95.12
0,-5,2:95.12
0,-4,2:95.12
0,-3,2:95.12
0,-2,2:95.12
0,-1,2:95.12
0,0,2:95.12
0,1,2:95.12
0,2,2:95.12
0,3,2:95.12
0,4,2:95.12
0,5,2:95.12
0,6,2:95.12
0,7,2:95.12
0,8,2:95.12
0,9,2:95.12
0,10,2:95.12
0,11,2:95.12
0,12,2:95.12
0,13,2:95.12
0,14,2:95.12
0,15,2:95.12
0,16,2:95.12
0,17,2:95.12
0,18,2:95.12
0,19,2:95.12
0,20,2:95.12
0,21,2:95.12
0,22,2:95.12
0,23,2:95.12
0,24,2:1
0,25,2:1
0,26,2:1
0,27,2:1
0,28,2:1
0,29,2:1
0,30,2:1
0,31,2:1
0,32,2:1
0,33,2:1
0,34,2:1
0,35,2:1
0,-39,3:1
0,-38,3:1
0,-37,3:1
0,-36,3:1
0,-35,3:1
0,-34,3:1
0,-33,3:1
0,-32,3:1
0,-31,3:1
0,-30,3:1
0,-29,3:1
0,-28,3:1
0,-27,3:35.7
0,-26,3:35.7
0,-14,3:159.1
0,-13,3:159.1
0,-12,3:159.1
0,-11,3:159.1
0,-10,3:159.1
0,-9,3:159.1
0,-8,3:159.1
0,-7,3:159.1
0,-6,3:159.1
0,-5,3:159.1
0,-4,3:159.1
0,-3,3:159.1
0,-2,3:159.1
0,-1,3:159.1
0,0,3:159.1
0,1,3:159.1
0,2,3:159.1
0,3,3:159.1
0,4,3:159.1
0,5,3:159.1
0,6,3:159.1
0,7,3:159.1
0,8,3:159.1
0,9,3:159.1
0,10,3:159.1
0,22,3:35.7
0,23,3:35.7
0,24,3:1
0,25,3:1
0,26,3:1
0,27,3:1
0,28,3:1
0,29,3:1
0,30,3:1
0,31,3:1
0,32,3:1
0,33,3:1
0,34,3:1
0,35,3:1
0,-32,4:35.7
0,-31,4:35.7
0,-30,4:35.7
0,-29,4:35.7
0,-28,4:35.7
0,-27,4:35.7
0,-7,4:109.6
0,-6,4:109.6
0,-5,4:109.5
0,-4,4:173
0,-3,4:173
0,-2,4:173
0,-1,4:173
0,0,4:173
0,1,4:109.7
0,2,4:109.7
0,3,4:109.7
0,23,4:35.7
0,24,4:35.7
0,25,4:35.7
0,26,4:35.7
0,27,4:35.7
0,28,4:35.7
0,-32,5:35.7
0,-31,5:35.7
0,-30,5:35.7
0,-29,5:35.7
0,-28,5:35.7
0,-3,5:54.2
0,-2,5:116
0,-1,5:54.3
0,24,5:35.7
0,25,5:35.7
0,26,5:35.7
0,27,5:35.7
0,28,5:35.7
1,-41,1:1
1,-40,1:1
1,-39,1:1
1,-38,1:1
1,-37,1:1
1,-36,1:1
1,-35,1:1
1,-34,1:1
1,-33,1:1
1,-32,1:1
1,-31,1:1
1,-30,1:1
1,-29,1:1
1,-28,1:1
1,-27,1:172
1,-26,1:172
1,-25,1:172
1,-24,1:172
1,-23,1:172
1,-22,1:172
1,-21,1:172
1,-20,1:172
1,-19,1:172
1,-18,1:172
1,-17,1:172
1,-16,1:172
1,-15,1:172
1,-14,1:172
1,-13,1:172
1,-12,1:172
1,-11,1:172
1,-10,1:172
1,-9,1:172
1,-8,1:172
1,-7,1:172
1,-6,1:172
1,-5,1:172
1,-4,1:172
1,-3,1:172
1,-2,1:172
1,-1,1:172
1,0,1:172
1,1,1:172
1,2,1:172
1,3,1:172
1,4,1:172
1,5,1:172
1,6,1:172
1,7,1:172
1,8,1:172
1,9,1:172
1,10,1:172
1,11,1:172
1,12,1:172
1,13,1:172
1,14,1:172
1,15,1:172
1,16,1:172
1,17,1:172
1,18,1:172
1,19,1:172
1,20,1:172
1,21,1:172
1,22,1:172
1,23,1:172
1,24,1:1
1,25,1:1
1,26,1:1
1,27,1:1
1,28,1:1
1,29,1:1
1,30,1:1
1,31,1:1
1,32,1:1
1,33,1:1
1,34,1:1
1,35,1:1
1,36,1:1
1,37,1:1
1,-41,2:1
1,-40,2:1
1,-39,2:1
1,-38,2:1
1,-37,2:1
1,-36,2:1
1,-35,2:1
1,-34,2:1
1,-33,2:1
1,-32,2:1
1,-31,2:1
1,-30,2:1
1,-29,2:1
1,-28,2:1
1,-27,2:95.12
1,-26,2:95.12
1,-25,2:95.12
1,-24,2:95.12
1,-23,2:95.12
1,-22,2:95.12
1,-21,2:95.12
1,-20,2:95.12
1,-19,2:95.12
1,-18,2:95.12
1,-17,2:95.12
1,-16,2:95.12
1,-15,2:95.12
1,-14,2:95.12
1,-13,2:95.12
1,-12,2:95.12
1,-11,2:95.12
1,-10,2:95.12
1,-9,2:95.12
1,-8,2:95.12
1,-7,2:95.12
1,-6,2:95.12
1,-5,2:95.12
1,-4,2:95.12
1,-3,2:95.12
1,-2,2:95.12
1,-1,2:95.12
1,0,2:95.12
1,1,2:95.12
1,2,2:95.12
1,3,2:95.12
1,4,2:95.12
1,5,2:95.12
1,6,2:95.12
1,7,2:95.12
1,8,2:95.12
1,9,2:95.12
1,10,2:95.12
1,11,2:95.12
1,12,2:95.12
1,13,2:95.12
1,14,2:95.12
1,15,2:95.12
1,16,2:95.12
1,17,2:95.12
1,18,2:95.12
1,19,2:95.12
1,20,2:95.12
1,21,2:95.12
1,22,2:95.12
1,23,2:95.12
1,24,2:1
1,25,2:1
1,26,2:1
1,27,2:1
1,28,2:1
1,29,2:1
1,30,2:1
1,31,2:1
1,32,2:1
1,33,2:1
1,34,2:1
1,35,2:1
1,36,2:1
1,37,2:1
1,-41,3:1
1,-40,3:1
1,-39,3:1
1,-38,3:1
1,-37,3:1
1,-36,3:1
1,-35,3:1
1,-34,3:1
1,-33,3:1
1,-32,3:1
1,-31,3:1
1,-30,3:1
1,-29,3:1
1,-28,3:1
1,-27,3:35.7
1,-16,3:159.1
1,-15,3:159.1
1,-14,3:159.1
1,-13,3:159.1
1,-12,3:159.1
1,-11,3:159.1
1,-10,3:159.1
1,-9,3:159.1
1,-8,3:159.1
1,-7,3:159.1
1,-6,3:159.1
1,-5,3:159.1
1,-4,3:159.1
1,-3,3:159.1
1,-2,3:159.1
1,-1,3:159.1
1,0,3:159.1
1,1,3:159.1
1,2,3:159.1
1,3,3:159.1
1,4,3:159.1
1,5,3:159.1
1,6,3:159.1
1,7,3:159.1
1,8,3:159.1
1,9,3:159.1
1,10,3:159.1
1,11,3:159.1
1,12,3:159.1
1,23,3:35.7
1,24,3:1
1,25,3:1
1,26,3:1
1,27,3:1
1,28,3:1
1,29,3:1
1,30,3:1
1,31,3:1
1,32,3:1
1,33,3:1
1,34,3:1
1,35,3:1
1,36,3:1
1,37,3:1
1,-32,4:35.7
1,-31,4:35.7
1,-30,4:35.7
1,-29,4:35.7
1,-28,4:35.7
1,-7,4:109.2
1,-6,4:109.6
1,-5,4:173
1,-4,4:173
1,-3,4:173
1,-2,4:173
1,-1,4:173
1,0,4:173
1,1,4:173
1,2,4:109.7
1,3,4:109.3
1,24,4:35.7
1,25,4:35.7
1,26,4:35.7
1,27,4:35.7
1,28,4:35.7
1,-31,5:35.7
1,-30,5:35.7
1,-4,5:54.2
1,-2,5:54.5
1,0,5:54.3
1,26,5:35.7
1,27,5:35.7
2,-42,0:1
2,-42,1:1
2,-41,1:1
2,-40,1:1
2,-39,1:1
2,-38,1:1
2,-37,1:1
2,-36,1:1
2,-35,1:1
2,-34,1:1
2,-33,1:1
2,-32,1:1
2,-31,1:1
2,-30,1:1
2,-29,1:1
2,-28,1:1
2,-27,1:172
2,-26,1:172
2,-25,1:172
2,-24,1:172
2,-23,1:172
2,-22,1:172
2,-21,1:172
2,-20,1:172
2,-19,1:172
2,-18,1:172
2,-17,1:172
2,-16,1:172
2,-15,1:172
2,-14,1:172
2,-13,1:172
2,-12,1:172
2,-11,1:172
2,-10,1:172
2,-9,1:172
2,-8,1:172
2,-7,1:172
2,-6,1:172
2,-5,1:172
2,-4,1:172
2,-3,1:172
2,-2,1:172
2,-1,1:172
2,0,1:172
2,1,1:172
2,2,1:172
2,3,1:172
2,4,1:172
2,5,1:172
2,6,1:172
2,7,1:172
2,8,1:172
2,9,1:172
2,10,1:172
2,11,1:172
2,12,1:172
2,13,1:172
2,14,1:172
2,15,1:172
2,16,1:172
2,17,1:172
2,18,1:172
2,19,1:172
2,20,1:172
2,21,1:172
2,22,1:172
2,23,1:172
2,24,1:1
2,25,1:1
2,26,1:1
2,27,1:1
2,28,1:1
2,29,1:1
2,30,1:1
2,31,1:1
2,32,1:1
2,33,1:1
2,34,1:1
2,35,1:1
2,36,1:1
2,37,1:1
2,38,1:1
2,-42,2:1
2,-41,2:1
2,-40,2:1
2,-39,2:1
2,-38,2:1
2,-37,2:1
2,-36,2:1
2,-35,2:1
2,-34,2:1
2,-33,2:1
2,-32,2:1
2,-31,2:1
2,-30,2:1
2,-29,2:1
2,-28,2:1
2,-27,2:95.12
2,-26,2:95.12
2,-25,2:95.12
2,-24,2:95.12
2,-23,2:95.12
2,-22,2:95.12
2,-21,2:95.12
2,-20,2:95.12
2,-19,2:95.12
2,-18,2:95.12
2,-17,2:95.12
2,-16,2:95.12
2,-15,2:95.12
2,-14,2:95.12
2,-13,2:95.12
2,-12,2:95.12
2,-11,2:95.12
2,-10,2:95.12
2,-9,2:95.12
2,-8,2:95.12
2,-7,2:95.12
2,-6,2:95.12
2,-5,2:95.12
2,-4,2:95.12
2,-3,2:95.12
2,-2,2:95.12
2,-1,2:95.12
2,0,2:95.12
2,1,2:95.12
2,2,2:95.12
2,3,2:95.12
2,4,2:95.12
2,5,2:95.12
2,6,2:95.12
2,7,2:95.12
2,8,2:95.12
2,9,2:95.12
2,10,2:95.12
2,11,2:95.12
2,12,2:95.12
2,13,2:95.12
2,14,2:95.12
2,15,2:95.12
2,16,2:95.12
2,17,2:95.12
2,18,2:95.12
2,19,2:95.12
2,20,2:95.12
2,21,2:95.12
2,22,2:95.12
2,23,2:95.12
2,24,2:1
2,25,2:1
2,26,2:1
2,27,2:1
2,28,2:1
2,29,2:1
2,30,2:1
2,31,2:1
2,32,2:1
2,33,2:1
2,34,2:1
2,35,2:1
2,36,2:1
2,37,2:1
2,38,2:1
2,-42,3:1
2,-41,3:1
2,-40,3:1
2,-39,3:1
2,-38,3:1
2,-37,3:1
2,-36,3:1
2,-35,3:1
2,-34,3:1
2,-33,3:1
2,-32,3:1
2,-31,3:1
2,-30,3:1
2,-29,3:1
2,-28,3:1
2,-17,3:159.1
2,-16,3:159.1
2,-15,3:159.1
2,-14,3:159.1
2,-13,3:159.1
2,-12,3:159.1
2,-11,3:159.1
2,-10,3:159.1
2,-9,3:159.1
2,-8,3:159.1
2,-7,3:159.1
2,-6,3:159.1
2,-5,3:159.1
2,-4,3:159.1
2,-3,3:159.1
2,-2,3:159.1
2,-1,3:159.1
2,0,3:159.1
2,1,3:159.1
2,2,3:159.1
2,3,3:159.1
2,4,3:159.1
2,5,3:159.1
2,6,3:159.1
2,7,3:159.1
2,8,3:159.1
2,9,3:159.1
2,10,3:159.1
2,11,3:159.1
2,12,3:159.1
2,13,3:159.1
2,24,3:1
2,25,3:1
2,26,3:1
2,27,3:1
2,28,3:1
2,29,3:1
2,30,3:1
2,31,3:1
2,32,3:1
2,33,3:1
2,34,3:1
2,35,3:1
2,36,3:1
2,37,3:1
2,38,3:1
2,-31,4:35.7
2,-30,4:35.7
2,-7,4:109.2
2,-6,4:173
2,-5,4:173
2,-4,4:173
2,-3,4:173
2,-2,4:173
2,-1,4:173
2,0,4:173
2,1,4:173
2,2,4:173
2,3,4:109.3
2,26,4:35.7
2,27,4:35.7
2,-3,5:54.5
2,-1,5:54.5
3,-42,0:1
3,-42,1:1
3,-41,1:1
3,-40,1:1
3,-39,1:1
3,-38,1:1
3,-37,1:1
3,-36,1:1
3,-35,1:1
3,-34,1:1
3,-33,1:1
3,-32,1:1
3,-31,1:1
3,-30,1:1
3,-29,1:1
3,-28,1:1
3,-27,1:172
3,-26,1:172
3,-25,1:172
3,-24,1:172
3,-23,1:172
3,-22,1:172
3,-21,1:172
3,-20,1:172
3,-19,1:172
3,-18,1:172
3,-17,1:172
3,-16,1:172
3,-15,1:172
3,-14,1:172
3,-13,1:172
3,-12,1:172
3,-11,1:172
3,-10,1:172
3,-9,1:172
3,-8,1:172
3,-7,1:172
3,-6,1:172
3,-5,1:172
3,-4,1:172
3,-3,1:172
3,-2,1:172
3,-1,1:172
3,0,1:172
3,1,1:172
3,2,1:172
3,3,1:172
3,4,1:172
3,5,1:172
3,6,1:172
3,7,1:172
3,8,1:172
3,9,1:172
3,10,1:172
3,11,1:172
3,12,1:172
3,13,1:172
3,14,1:172
3,15,1:172
3,16,1:172
3,17,1:172
3,18,1:172
3,19,1:172
3,20,1:172
3,21,1:172
3,22,1:172
3,23,1:172
3,24,1:1
3,25,1:1
3,26,1:1
3,27,1:1
3,28,1:1
3,29,1:1
3,30,1:1
3,31,1:1
3,32,1:1
3,33,1:1
3,34,1:1
3,35,1:1
3,36,1:1
3,37,1:1
3,38,1:1
3,-42,2:1
3,-41,2:1
3,-40,2:1
3,-39,2:1
3,-38,2:1
3,-37,2:1
3,-36,2:1
3,-35,2:1
3,-34,2:1
3,-33,2:1
3,-32,2:1
3,-31,2:1
3,-30,2:1
3,-29,2:1
3,-28,2:1
3,-27,2:95.12
3,-26,2:95.12
3,-25,2:95.12
3,-24,2:95.12
3,-23,2:95.12
3,-22,2:95.12
3,-21,2:95.12
3,-20,2:95.12
3,-19,2:95.12
3,-18,2:95.12
3,-17,2:95.12
3,-16,2:95.12
3,-15,2:95.12
3,-14,2:95.12
3,-13,2:95.12
3,-12,2:95.12
3,-11,2:95.12
3,-10,2:95.12
3,-9,2:95.12
3,-8,2:95.12
3,-7,2:95.12
3,-6,2:95.12
3,-5,2:95.12
3,-4,2:95.12
3,-3,2:95.12
3,-2,2:95.12
3,-1,2:95.12
3,0,2:95.12
3,1,2:95.12
3,2,2:95.12
3,3,2:95.12
3,4,2:95.12
3,5,2:95.12
3,6,2:95.12
3,7,2:95.12
3,8,2:95.12
3,9,2:95.12
3,10,2:95.12
3,11,2:95.12
3,12,2:95.12
3,13,2:95.12
3,14,2:95.12
3,15,2:95.12
3,16,2:95.12
3,17,2:95.12
3,18,2:95.12
3,19,2:95.12
3,20,2:95.12
3,21,2:95.12
3,22,2:95.12
3,23,2:95.12
3,24,2:1
3,25,2:1
3,26,2:1
3,27,2:1
3,28,2:1
3,29,2:1
3,30,2:1
3,31,2:1
3,32,2:1
3,33,2:1
3,34,2:1
3,35,2:1
3,36,2:1
3,37,2:1
3,38,2:1
3,-42,3:1
3,-41,3:1
3,-40,3:1
3,-39,3:1
3,-38,3:1
3,-37,3:1
3,-36,3:1
3,-35,3:1
3,-34,3:1
3,-33,3:1
3,-32,3:1
3,-31,3:1
3,-30,3:1
3,-29,3:1
3,-28,3:1
3,-20,3:159.1
3,-19,3:159.1
3,-18,3:159.1
3,-17,3:159.1
3,-16,3:159.1
3,-15,3:159.1
3,-14,3:159.1
3,-13,3:159.1
3,-12,3:159.1
3,-11,3:159.1
3,-10,3:159.1
3,-9,3:159.1
3,-8,3:159.1
3,-7,3:159.1
3,-6,3:159.1
3,-5,3:159.1
3,-4,3:159.1
3,-3,3:159.1
3,-2,3:159.1
3,-1,3:159.1
3,0,3:159.1
3,1,3:159.1
3,2,3:159.1
3,3,3:159.1
3,4,3:159.1
3,5,3:159.1
3,6,3:159.1
3,7,3:159.1
3,8,3:159.1
3,9,3:159.1
3,10,3:159.1
3,11,3:159.1
3,12,3:159.1
3,13,3:159.1
3,14,3:159.1
3,15,3:159.1
3,16,3:159.1
3,24,3:1
3,25,3:1
3,26,3:1
3,27,3:1
3,28,3:1
3,29,3:1
3,30,3:1
3,31,3:1
3,32,3:1
3,33,3:1
3,34,3:1
3,35,3:1
3,36,3:1
3,37,3:1
3,38,3:1
3,-6,4:109.1
3,-5,4:173
3,-4,4:173
3,-3,4:173
3,-2,4:109.5
3,-1,4:173
3,0,4:173
3,1,4:173
3,2,4:109.1
4,-42,0:1
4,-42,1:1
4,-41,1:1
4,-40,1:1
4,-39,1:1
4,-38,1:1
4,-37,1:1
4,-36,1:1
4,-35,1:1
4,-34,1:1
4,-33,1:1
4,-32,1:1
4,-31,1:1
4,-30,1:1
4,-29,1:1
4,-28,1:1
4,-27,1:172
4,-26,1:172
4,-25,1:172
4,-24,1:172
4,-23,1:172
4,-22,1:172
4,-21,1:172
4,-20,1:172
4,-19,1:172
4,-18,1:172
4,-17,1:172
4,-16,1:172
4,-15,1:172
4,-14,1:172
4,-13,1:172
4,-12,1:172
4,-11,1:172
4,-10,1:172
4,-9,1:172
4,-8,1:172
4,-7,1:172
4,-6,1:172
4,-5,1:172
4,-4,1:172
4,-3,1:172
4,-2,1:172
4,-1,1:172
4,0,1:172
4,1,1:172
4,2,1:172
4,3,1:172
4,4,1:172
4,5,1:172
4,6,1:172
4,7,1:172
4,8,1:172
4,9,1:172
4,10,1:172
4,11,1:172
4,12,1:172
4,13,1:172
4,14,1:172
4,15,1:172
4,16,1:172
4,17,1:172
4,18,1:172
4,19,1:172
4,20,1:172
4,21,1:172
4,22,1:172
4,23,1:172
4,24,1:1
4,25,1:1
4,26,1:1
4,27,1:1
4,28,1:1
4,29,1:1
4,30,1:1
4,31,1:1
4,32,1:1
4,33,1:1
4,34,1:1
4,35,1:1
4,36,1:1
4,37,1:1
4,38,1:1
4,-42,2:1
4,-41,2:1
4,-40,2:1
4,-39,2:1
4,-38,2:1
4,-37,2:1
4,-36,2:1
4,-35,2:1
4,-34,2:1
4,-33,2:1
4,-32,2:1
4,-31,2:1
4,-30,2:1
4,-29,2:1
4,-28,2:1
4,-27,2:95.12
4,-26,2:95.12
4,-25,2:95.12
4,-24,2:95.12
4,-23,2:95.12
4,-22,2:95.12
4,-21,2:95.12
4,-20,2:95.12
4,-19,2:95.12
4,-18,2:95.12
4,-17,2:95.12
4,-16,2:95.12
4,-15,2:95.12
4,-14,2:95.12
4,-13,2:95.12
4,-12,2:95.12
4,-11,2:95.12
4,-10,2:95.12
4,-9,2:95.12
4,-8,2:95.12
4,-7,2:95.12
4,-6,2:95.12
4,-5,2:95.12
4,-4,2:95.12
4,-3,2:95.12
4,-2,2:95.12
4,-1,2:95.12
4,0,2:95.12
4,1,2:95.12
4,2,2:95.12
4,3,2:95.12
4,4,2:95.12
4,5,2:95.12
4,6,2:95.12
4,7,2:95.12
4,8,2:95.12
4,9,2:95.12
4,10,2:95.12
4,11,2:95.12
4,12,2:95.12
4,13,2:95.12
4,14,2:95.12
4,15,2:95.12
4,16,2:95.12
4,17,2:95.12
4,18,2:95.12
4,19,2:95.12
4,20,2:95.12
4,21,2:95.12
4,22,2:95.12
4,23,2:95.12
4,24,2:1
4,25,2:1
4,26,2:1
4,27,2:1
4,28,2:1
4,29,2:1
4,30,2:1
4,31,2:1
4,32,2:1
4,33,2:1
4,34,2:1
4,35,2:1
4,36,2:1
4,37,2:1
4,38,2:1
4,-42,3:1
4,-41,3:1
4,-40,3:1
4,-39,3:1
4,-38,3:1
4,-37,3:1
4,-36,3:1
4,-35,3:1
4,-34,3:1
4,-33,3:1
4,-32,3:1
4,-31,3:1
4,-30,3:1
4,-29,3:1
4,-28,3:1
4,-17,3:159.1
4,-13,3:159.1
4,-12,3:159.1
4,-11,3:159.1
4,-10,3:159.1
4,-9,3:159.1
4,-8,3:159.1
4,-7,3:159.1
4,-6,3:159.1
4,-5,3:159.1
4,-4,3:159.1
4,-3,3:159.1
4,-2,3:159.1
4,-1,3:159.1
4,0,3:159.1
4,1,3:159.1
4,2,3:159.1
4,3,3:159.1
4,4,3:159.1
4,5,3:159.1
4,6,3:159.1
4,7,3:159.1
4,8,3:159.1
4,9,3:159.1
4,13,3:159.1
4,24,3:1
4,25,3:1
4,26,3:1
4,27,3:1
4,28,3:1
4,29,3:1
4,30,3:1
4,31,3:1
4,32,3:1
4,33,3:1
4,34,3:1
4,35,3:1
4,36,3:1
4,37,3:1
4,38,3:1
4,-5,4:109.2
4,-4,4:173
4,-3,4:109.5
4,-2,4:109.4
4,-1,4:109.5
4,0,4:173
4,1,4:109.3
5,-42,0:1
5,-42,1:1
5,-41,1:1
5,-40,1:1
5,-39,1:1
5,-38,1:1
5,-37,1:1
5,-36,1:1
5,-35,1:1
5,-34,1:1
5,-33,1:1
5,-32,1:1
5,-31,1:1
5,-30,1:1
5,-29,1:1
5,-28,1:1
5,-27,1:172
5,-26,1:172
5,-25,1:172
5,-24,1:172
5,-23,1:172
5,-22,1:172
5,-21,1:172
5,-20,1:172
5,-19,1:172
5,-18,1:172
5,-17,1:172
5,-16,1:172
5,-15,1:172
5,-14,1:172
5,-13,1:172
5,-12,1:172
5,-11,1:172
5,-10,1:172
5,-9,1:172
5,-8,1:172
5,-7,1:172
5,-6,1:172
5,-5,1:172
5,-4,1:172
5,-3,1:172
5,-2,1:172
5,-1,1:172
5,0,1:172
5,1,1:172
5,2,1:172
5,3,1:172
5,4,1:172
5,5,1:172
5,6,1:172
5,7,1:172
5,8,1:172
5,9,1:172
5,10,1:172
5,11,1:172
5,12,1:172
5,13,1:172
5,14,1:172
5,15,1:172
5,16,1:172
5,17,1:172
5,18,1:172
5,19,1:172
5,20,1:172
5,21,1:172
5,22,1:172
5,23,1:172
5,24,1:1
5,25,1:1
5,26,1:1
5,27,1:1
5,28,1:1
5,29,1:1
5,30,1:1
5,31,1:1
5,32,1:1
5,33,1:1
5,34,1:1
5,35,1:1
5,36,1:1
5,37,1:1
5,38,1:1
5,-42,2:1
5,-41,2:1
5,-40,2:1
5,-39,2:1
5,-38,2:1
5,-37,2:1
5,-36,2:1
5,-35,2:1
5,-34,2:1
5,-33,2:1
5,-32,2:1
5,-31,2:1
5,-30,2:1
5,-29,2:1
5,-28,2:1
5,-27,2:95.12
5,-26,2:95.12
5,-25,2:95.12
5,-24,2:95.12
5,-23,2:95.12
5,-22,2:95.12
5,-21,2:95.12
5,-20,2:95.12
5,-19,2:95.12
5,-18,2:95.12
5,-17,2:95.12
5,-16,2:95.12
5,-15,2:95.12
5,-14,2:95.12
5,-13,2:95.12
5,-12,2:95.12
5,-11,2:95.12
5,-10,2:95.12
5,-9,2:95.12
5,-8,2:95.12
5,-7,2:95.12
5,-6,2:95.12
5,-5,2:95.12
5,-4,2:95.12
5,-3,2:95.12
5,-2,2:95.12
5,-1,2:95.12
5,0,2:95.12
5,1,2:95.12
5,2,2:95.12
5,3,2:95.12
5,4,2:95.12
5,5,2:95.12
5,6,2:95.12
5,7,2:95.12
5,8,2:95.12
5,9,2:95.12
5,10,2:95.12
5,11,2:95.12
5,12,2:95.12
5,13,2:95.12
5,14,2:95.12
5,15,2:95.12
5,16,2:95.12
5,17,2:95.12
5,18,2:95.12
5,19,2:95.12
5,20,2:95.12
5,21,2:95.12
5,22,2:95.12
5,23,2:95.12
5,24,2:1
5,25,2:1
5,26,2:1
5,27,2:1
5,28,2:1
5,29,2:1
5,30,2:1
5,31,2:1
5,32,2:1
5,33,2:1
5,34,2:1
5,35,2:1
5,36,2:1
5,37,2:1
5,38,2:1
5,-42,3:1
5,-41,3:1
5,-40,3:1
5,-39,3:1
5,-38,3:1
5,-37,3:1
5,-36,3:1
5,-35,3:1
5,-34,3:1
5,-33,3:1
5,-32,3:1
5,-31,3:1
5,-30,3:1
5,-29,3:1
5,-28,3:1
5,-11,3:159.1
5,-10,3:159.1
5,-9,3:159.1
5,-8,3:159.1
5,-7,3:159.1
5,-6,3:159.1
5,-5,3:159.1
5,-4,3:159.1
5,-3,3:159.1
5,-2,3:159.1
5,-1,3:159.1
5,0,3:159.1
5,1,3:159.1
5,2,3:159.1
5,3,3:159.1
5,4,3:159.1
5,5,3:159.1
5,6,3:159.1
5,7,3:159.1
5,24,3:1
5,25,3:1
5,26,3:1
5,27,3:1
5,28,3:1
5,29,3:1
5,30,3:1
5,31,3:1
5,32,3:1
5,33,3:1
5,34,3:1
5,35,3:1
5,36,3:1
5,37,3:1
5,38,3:1
5,-4,4:109.1
5,-3,4:109.1
5,-2,4:109.5
5,-1,4:109.1
5,0,4:109.1
6,-42,0:1
6,-42,1:1
6,-41,1:1
6,-40,1:1
6,-39,1:1
6,-38,1:1
6,-37,1:1
6,-36,1:1
6,-35,1:1
6,-34,1:1
6,-33,1:1
6,-32,1:1
6,-31,1:1
6,-30,1:1
6,-29,1:1
6,-28,1:1
6,-27,1:1
6,-26,1:172
6,-25,1:172
6,-24,1:172
6,-23,1:172
6,-22,1:172
6,-21,1:172
6,-20,1:172
6,-19,1:172
6,-18,1:172
6,-17,1:172
6,-16,1:172
6,-15,1:172
6,-14,1:172
6,-13,1:172
6,-12,1:172
6,-11,1:172
6,-10,1:172
6,-9,1:172
6,-8,1:172
6,-7,1:172
6,-6,1:172
6,-5,1:172
6,-4,1:172
6,-3,1:172
6,-2,1:172
6,-1,1:172
6,0,1:172
6,1,1:172
6,2,1:172
6,3,1:172
6,4,1:172
6,5,1:172
6,6,1:172
6,7,1:172
6,8,1:172
6,9,1:172
6,10,1:172
6,11,1:172
6,12,1:172
6,13,1:172
6,14,1:172
6,15,1:172
6,16,1:172
6,17,1:172
6,18,1:172
6,19,1:172
6,20,1:172
6,21,1:172
6,22,1:172
6,23,1:1
6,24,1:1
6,25,1:1
6,26,1:1
6,27,1:1
6,28,1:1
6,29,1:1
6,30,1:1
6,31,1:1
6,32,1:1
6,33,1:1
6,34,1:1
6,35,1:1
6,36,1:1
6,37,1:1
6,38,1:1
6,-42,2:1
6,-41,2:1
6,-40,2:1
6,-39,2:1
6,-38,2:1
6,-37,2:1
6,-36,2:1
6,-35,2:1
6,-34,2:1
6,-33,2:1
6,-32,2:1
6,-31,2:1
6,-30,2:1
6,-29,2:1
6,-28,2:1
6,-27,2:1
6,-26,2:95.12
6,-25,2:95.12
6,-24,2:95.12
6,-23,2:95.12
6,-22,2:95.12
6,-21,2:95.12
6,-20,2:95.12
6,-19,2:95.12
6,-18,2:95.12
6,-17,2:95.12
6,-16,2:95.12
6,-15,2:95.12
6,-14,2:95.12
6,-13,2:95.12
6,-12,2:95.12
6,-11,2:95.12
6,-10,2:95.12
6,-9,2:95.12
6,-8,2:95.12
6,-7,2:95.12
6,-6,2:95.12
6,-5,2:95.12
6,-4,2:95.12
6,-3,2:95.12
6,-2,2:95.12
6,-1,2:95.12
6,0,2:95.12
6,1,2:95.12
6,2,2:95.12
6,3,2:95.12
6,4,2:95.12
6,5,2:95.12
6,6,2:95.12
6,7,2:95.12
6,8,2:95.12
6,9,2:95.12
6,10,2:95.12
6,11,2:95.12
6,12,2:95.12
6,13,2:95.12
6,14,2:95.12
6,15,2:95.12
6,16,2:95.12
6,17,2:95.12
6,18,2:95.12
6,19,2:95.12
6,20,2:95.12
6,21,2:95.12
6,22,2:95.12
6,23,2:1
6,24,2:1
6,25,2:1
6,26,2:1
6,27,2:1
6,28,2:1
6,29,2:1
6,30,2:1
6,31,2:1
6,32,2:1
6,33,2:1
6,34,2:1
6,35,2:1
6,36,2:1
6,37,2:1
6,38,2:1
6,-42,3:1
6,-41,3:1
6,-40,3:1
6,-39,3:1
6,-38,3:1
6,-37,3:1
6,-36,3:1
6,-35,3:1
6,-34,3:1
6,-33,3:1
6,-32,3:1
6,-31,3:1
6,-30,3:1
6,-29,3:1
6,-28,3:1
6,-27,3:1
6,-11,3:159.1
6,-10,3:159.1
6,-9,3:159.1
6,-8,3:159.1
6,-7,3:159.1
6,-6,3:159.1
6,-5,3:159.1
6,-4,3:159.1
6,-3,3:159.1
6,-2,3:159.1
6,-1,3:159.1
6,0,3:159.1
6,1,3:159.1
6,2,3:159.1
6,3,3:159.1
6,4,3:159.1
6,5,3:159.1
6,6,3:159.1
6,7,3:159.1
6,23,3:1
6,24,3:1
6,25,3:1
6,26,3:1
6,27,3:1
6,28,3:1
6,29,3:1
6,30,3:1
6,31,3:1
6,32,3:1
6,33,3:1
6,34,3:1
6,35,3:1
6,36,3:1
6,37,3:1
6,38,3:1
7,-40,1:1
7,-39,1:1
7,-38,1:1
7,-37,1:1
7,-36,1:1
7,-35,1:1
7,-34,1:1
7,-33,1:1
7,-32,1:1
7,-31,1:1
7,-30,1:1
7,-29,1:1
7,-28,1:1
7,-27,1:1
7,-26,1:172
7,-25,1:172
7,-24,1:172
7,-23,1:172
7,-22,1:172
7,-21,1:172
7,-20,1:172
7,-19,1:172
7,-18,1:172
7,-17,1:172
7,-16,1:172
7,-15,1:172
7,-14,1:172
7,-13,1:172
7,-12,1:172
7,-11,1:172
7,-10,1:172
7,-9,1:172
7,-8,1:172
7,-7,1:172
7,-6,1:172
7,-5,1:172
7,-4,1:172
7,-3,1:172
7,-2,1:172
7,-1,1:172
7,0,1:172
7,1,1:172
7,2,1:172
7,3,1:172
7,4,1:172
7,5,1:172
7,6,1:172
7,7,1:172
7,8,1:172
7,9,1:172
7,10,1:172
7,11,1:172
7,12,1:172
7,13,1:172
7,14,1:172
7,15,1:172
7,16,1:172
7,17,1:172
7,18,1:172
7,19,1:172
7,20,1:172
7,21,1:172
7,22,1:172
7,23,1:1
7,24,1:1
7,25,1:1
7,26,1:1
7,27,1:1
7,28,1:1
7,29,1:1
7,30,1:1
7,31,1:1
7,32,1:1
7,33,1:1
7,34,1:1
7,35,1:1
7,36,1:1
7,-40,2:1
7,-39,2:1
7,-38,2:1
7,-37,2:1
7,-36,2:1
7,-35,2:1
7,-34,2:1
7,-33,2:1
7,-32,2:1
7,-31,2:1
7,-30,2:1
7,-29,2:1
7,-28,2:1
7,-27,2:1
7,-26,2:95.12
7,-25,2:95.12
7,-24,2:95.12
7,-23,2:95.12
7,-22,2:95.12
7,-21,2:95.12
7,-20,2:95.12
7,-19,2:95.12
7,-18,2:95.12
7,-17,2:95.12
7,-16,2:95.12
7,-15,2:95.12
7,-14,2:95.12
7,-13,2:95.12
7,-12,2:95.12
7,-11,2:95.12
7,-10,2:95.12
7,-9,2:95.12
7,-8,2:95.12
7,-7,2:95.12
7,-6,2:95.12
7,-5,2:95.12
7,-4,2:95.12
7,-3,2:95.12
7,-2,2:95.12
7,-1,2:95.12
7,0,2:95.12
7,1,2:95.12
7,2,2:95.12
7,3,2:95.12
7,4,2:95.12
7,5,2:95.12
7,6,2:95.12
7,7,2:95.12
7,8,2:95.12
7,9,2:95.12
7,10,2:95.12
7,11,2:95.12
7,12,2:95.12
7,13,2:95.12
7,14,2:95.12
7,15,2:95.12
7,16,2:95.12
7,17,2:95.12
7,18,2:95.12
7,19,2:95.12
7,20,2:95.12
7,21,2:95.12
7,22,2:95.12
7,23,2:1
7,24,2:1
7,25,2:1
7,26,2:1
7,27,2:1
7,28,2:1
7,29,2:1
7,30,2:1
7,31,2:1
7,32,2:1
7,33,2:1
7,34,2:1
7,35,2:1
7,36,2:1
7,-40,3:1
7,-39,3:1
7,-38,3:1
7,-37,3:1
7,-36,3:1
7,-35,3:1
7,-34,3:1
7,-33,3:1
7,-32,3:1
7,-31,3:1
7,-30,3:1
7,-29,3:1
7,-28,3:1
7,-27,3:1
7,-11,3:159.1
7,-10,3:159.1
7,-9,3:159.1
7,-8,3:159.1
7,-7,3:159.1
7,-6,3:159.1
7,-5,3:159.1
7,-4,3:159.1
7,-3,3:159.1
7,-2,3:159.1
7,-1,3:159.1
7,0,3:159.1
7,1,3:159.1
7,2,3:159.1
7,3,3:159.1
7,4,3:159.1
7,5,3:159.1
7,6,3:159.1
7,7,3:159.1
7,23,3:1
7,24,3:1
7,25,3:1
7,26,3:1
7,27,3:1
7,28,3:1
7,29,3:1
7,30,3:1
7,31,3:1
7,32,3:1
7,33,3:1
7,34,3:1
7,35,3:1
7,36,3:1
8,-38,1:1
8,-37,1:1
8,-36,1:1
8,-34,1:1
8,-33,1:1
8,-32,1:1
8,-31,1:1
8,-30,1:1
8,-29,1:1
8,-28,1:1
8,-27,1:1
8,-26,1:172
8,-25,1:172
8,-24,1:172
8,-23,1:172
8,-22,1:172
8,-21,1:172
8,-20,1:172
8,-19,1:172
8,-18,1:172
8,-17,1:172
8,-16,1:172
8,-15,1:172
8,-14,1:172
8,-13,1:172
8,-12,1:172
8,-11,1:172
8,-10,1:172
8,-9,1:172
8,-8,1:172
8,-7,1:172
8,-6,1:172
8,-5,1:172
8,-4,1:172
8,-3,1:172
8,-2,1:172
8,-1,1:172
8,0,1:172
8,1,1:172
8,2,1:172
8,3,1:172
8,4,1:172
8,5,1:172
8,6,1:172
8,7,1:172
8,8,1:172
8,9,1:172
8,10,1:172
8,11,1:172
8,12,1:172
8,13,1:172
8,14,1:172
8,15,1:172
8,16,1:172
8,17,1:172
8,18,1:172
8,19,1:172
8,20,1:172
8,21,1:172
8,22,1:172
8,23,1:1
8,24,1:1
8,25,1:1
8,26,1:1
8,27,1:1
8,28,1:1
8,29,1:1
8,30,1:1
8,32,1:1
8,33,1:1
8,34,1:1
8,-38,2:1
8,-37,2:1
8,-36,2:1
8,-34,2:1
8,-33,2:1
8,-32,2:1
8,-31,2:1
8,-30,2:1
8,-29,2:1
8,-28,2:1
8,-27,2:1
8,-26,2:95.12
8,-25,2:95.12
8,-24,2:95.12
8,-23,2:95.12
8,-22,2:95.12
8,-21,2:95.12
8,-20,2:95.12
8,-19,2:95.12
8,-18,2:95.12
8,-17,2:95.12
8,-16,2:95.12
8,-15,2:95.12
8,-14,2:95.12
8,-13,2:95.12
8,-12,2:95.12
8,-11,2:95.12
8,-10,2:95.12
8,-9,2:95.12
8,-8,2:95.12
8,-7,2:95.12
8,-6,2:95.12
8,-5,2:95.12
8,-4,2:95.12
8,-3,2:95.12
8,-2,2:95.12
8,-1,2:95.12
8,0,2:95.12
8,1,2:95.12
8,2,2:95.12
8,3,2:95.12
8,4,2:95.12
8,5,2:95.12
8,6,2:95.12
8,7,2:95.12
8,8,2:95.12
8,9,2:95.12
8,10,2:95.12
8,11,2:95.12
8,12,2:95.12
8,13,2:95.12
8,14,2:95.12
8,15,2:95.12
8,16,2:95.12
8,17,2:95.12
8,18,2:95.12
8,19,2:95.12
8,20,2:95.12
8,21,2:95.12
8,22,2:95.12
8,23,2:1
8,24,2:1
8,25,2:1
8,26,2:1
8,27,2:1
8,28,2:1
8,29,2:1
8,30,2:1
8,32,2:1
8,33,2:1
8,34,2:1
8,-38,3:1
8,-37,3:1
8,-36,3:1
8,-34,3:1
8,-33,3:1
8,-32,3:1
8,-31,3:1
8,-30,3:1
8,-29,3:1
8,-28,3:1
8,-27,3:1
8,-11,3:159.1
8,-10,3:159.1
8,-9,3:159.1
8,-8,3:159.1
8,-7,3:159.1
8,-6,3:159.1
8,-5,3:159.1
8,-4,3:159.1
8,-3,3:159.1
8,-2,3:159.1
8,-1,3:159.1
8,0,3:159.1
8,1,3:159.1
8,2,3:159.1
8,3,3:159.1
8,4,3:159.1
8,5,3:159.1
8,6,3:159.1
8,7,3:159.1
8,23,3:1
8,24,3:1
8,25,3:1
8,26,3:1
8,27,3:1
8,28,3:1
8,29,3:1
8,30,3:1
8,32,3:1
8,33,3:1
8,34,3:1
9,-31,1:1
9,-30,1:1
9,-29,1:1
9,-28,1:1
9,-27,1:1
9,-26,1:1
9,-25,1:172
9,-24,1:172
9,-23,1:172
9,-22,1:172
9,-21,1:172
9,-20,1:172
9,-19,1:172
9,-18,1:172
9,-17,1:172
9,-16,1:172
9,-15,1:172
9,-14,1:172
9,-13,1:172
9,-12,1:172
9,-11,1:172
9,-10,1:172
9,-9,1:172
9,-8,1:172
9,-7,1:172
9,-6,1:172
9,-5,1:172
9,-4,1:172
9,-3,1:172
9,-2,1:172
9,-1,1:172
9,0,1:172
9,1,1:172
9,2,1:172
9,3,1:172
9,4,1:172
9,5,1:172
9,6,1:172
9,7,1:172
9,8,1:172
9,9,1:172
9,10,1:172
9,11,1:172
9,12,1:172
9,13,1:172
9,14,1:172
9,15,1:172
9,16,1:172
9,17,1:172
9,18,1:172
9,19,1:172
9,20,1:172
9,21,1:172
9,22,1:1
9,23,1:1
9,24,1:1
9,25,1:1
9,26,1:1
9,27,1:1
9,-31,2:1
9,-30,2:1
9,-29,2:1
9,-28,2:1
9,-27,2:1
9,-26,2:1
9,-25,2:95.12
9,-24,2:95.12
9,-23,2:95.12
9,-22,2:95.12
9,-21,2:95.12
9,-20,2:95.12
9,-19,2:95.12
9,-18,2:95.12
9,-17,2:95.12
9,-16,2:95.12
9,-15,2:95.12
9,-14,2:95.12
9,-13,2:95.12
9,-12,2:95.12
9,-11,2:95.12
9,-10,2:95.12
9,-9,2:95.12
9,-8,2:95.12
9,-7,2:95.12
9,-6,2:95.12
9,-5,2:95.12
9,-4,2:95.12
9,-3,2:95.12
9,-1,2:95.12
9,0,2:95.12
9,1,2:95.12
9,2,2:95.12
9,3,2:95.12
9,4,2:95.12
9,5,2:95.12
9,6,2:95.12
9,7,2:95.12
9,8,2:95.12
9,9,2:95.12
9,10,2:95.12
9,11,2:95.12
9,12,2:95.12
9,13,2:95.12
9,14,2:95.12
9,15,2:95.12
9,16,2:95.12
9,17,2:95.12
9,18,2:95.12
9,19,2:95.12
9,20,2:95.12
9,21,2:95.12
9,22,2:1
9,23,2:1
9,24,2:1
9,25,2:1
9,26,2:1
9,27,2:1
9,-31,3:1
9,-30,3:1
9,-29,3:1
9,-28,3:1
9,-27,3:1
9,-26,3:1
9,-11,3:159.1
9,-10,3:159.1
9,-9,3:159.1
9,-8,3:159.1
9,-7,3:159.1
9,-6,3:159.1
9,-5,3:159.1
9,-4,3:159.1
9,-3,3:159.1
9,-2,3:159.1
9,-1,3:159.1
9,0,3:159.1
9,1,3:159.1
9,2,3:159.1
9,3,3:159.1
9,4,3:159.1
9,5,3:159.1
9,6,3:159.1
9,7,3:159.1
9,22,3:1
9,23,3:1
9,24,3:1
9,25,3:1
9,26,3:1
9,27,3:1
10,-30,1:1
10,-29,1:1
10,-28,1:1
10,-27,1:1
10,-26,1:1
10,-25,1:172
10,-24,1:172
10,-23,1:172
10,-22,1:172
10,-21,1:172
10,-20,1:172
10,-19,1:172
10,-18,1:172
10,-17,1:172
10,-16,1:172
10,-15,1:172
10,-14,1:172
10,-13,1:172
10,-12,1:172
10,-11,1:172
10,-10,1:172
10,-9,1:172
10,-8,1:172
10,-7,1:172
10,-6,1:172
10,-5,1:172
10,-4,1:172
10,-3,1:172
10,-2,1:172
10,-1,1:172
10,0,1:172
10,1,1:172
10,2,1:172
10,3,1:172
10,4,1:172
10,5,1:172
10,6,1:172
10,7,1:172
10,8,1:172
10,9,1:172
10,10,1:172
10,11,1:172
10,12,1:172
10,13,1:172
10,14,1:172
10,15,1:172
10,16,1:172
10,17,1:172
10,18,1:172
10,19,1:172
10,20,1:172
10,21,1:172
10,22,1:1
10,23,1:1
10,24,1:1
10,25,1:1
10,26,1:1
10,-30,2:1
10,-29,2:1
10,-28,2:1
10,-27,2:1
10,-26,2:1
10,-25,2:95.12
10,-24,2:95.12
10,-23,2:95.12
10,-22,2:95.12
10,-21,2:95.12
10,-20,2:95.12
10,-19,2:95.12
10,-18,2:95.12
10,-17,2:95.12
10,-16,2:95.12
10,-15,2:95.12
10,-14,2:95.12
10,-13,2:95.12
10,-12,2:95.12
10,-11,2:95.12
10,-10,2:95.12
10,-9,2:95.12
10,-8,2:95.12
10,-7,2:95.12
10,-6,2:95.12
10,-5,2:95.12
10,-4,2:95.12
10,-3,2:95.12
10,-2,2:95.12
10,-1,2:95.12
10,0,2:95.12
10,1,2:95.12
10,2,2:95.12
10,3,2:95.12
10,4,2:95.12
10,5,2:95.12
10,6,2:95.12
10,7,2:95.12
10,8,2:95.12
10,9,2:95.12
10,10,2:95.12
10,11,2:95.12
10,12,2:95.12
10,13,2:95.12
10,14,2:95.12
10,15,2:95.12
10,16,2:95.12
10,17,2:95.12
10,18,2:95.12
10,19,2:95.12
10,20,2:95.12
10,21,2:95.12
10,22,2:1
10,23,2:1
10,24,2:1
10,25,2:1
10,26,2:1
10,-30,3:1
10,-29,3:1
10,-28,3:1
10,-27,3:1
10,-26,3:1
10,-12,3:159.1
10,-11,3:159.1
10,-10,3:159.1
10,-9,3:159.1
10,-8,3:159.1
10,-6,3:159.1
10,-5,3:159.1
10,-4,3:159.1
10,-3,3:159.1
10,-2,3:159.1
10,-1,3:159.1
10,0,3:159.1
10,1,3:159.1
10,2,3:159.1
10,4,3:159.1
10,5,3:159.1
10,6,3:159.1
10,7,3:159.1
10,8,3:159.1
10,22,3:1
10,23,3:1
10,24,3:1
10,25,3:1
10,26,3:1
11,-32,1:1
11,-31,1:1
11,-30,1:1
11,-29,1:1
11,-28,1:1
11,-27,1:1
11,-26,1:1
11,-25,1:172
11,-24,1:172
11,-23,1:172
11,-22,1:172
11,-21,1:172
11,-20,1:172
11,-19,1:172
11,-18,1:172
11,-17,1:172
11,-16,1:172
11,-15,1:172
11,-14,1:172
11,-13,1:172
11,-12,1:172
11,-11,1:172
11,-10,1:172
11,-9,1:172
11,-8,1:172
11,-7,1:172
11,-6,1:172
11,-5,1:172
11,-4,1:172
11,-3,1:172
11,-2,1:172
11,-1,1:172
11,0,1:172
11,1,1:172
11,2,1:172
11,3,1:172
11,4,1:172
11,5,1:172
11,6,1:172
11,7,1:172
11,8,1:172
11,9,1:172
11,10,1:172
11,11,1:172
11,12,1:172
11,13,1:172
11,14,1:172
11,15,1:172
11,16,1:172
11,17,1:172
11,18,1:172
11,19,1:172
11,20,1:172
11,21,1:172
11,22,1:1
11,23,1:1
11,24,1:1
11,25,1:1
11,26,1:1
11,27,1:1
11,28,1:1
11,-32,2:1
11,-31,2:1
11,-30,2:1
11,-29,2:1
11,-28,2:1
11,-27,2:1
11,-26,2:1
11,-25,2:95.12
11,-24,2:95.12
11,-23,2:95.12
11,-22,2:95.12
11,-21,2:95.12
11,-20,2:95.12
11,-19,2:95.12
11,-18,2:95.12
11,-17,2:95.12
11,-16,2:95.12
11,-15,2:95.12
11,-14,2:95.12
11,-13,2:95.12
11,-12,2:95.12
11,-11,2:95.12
11,-10,2:95.12
11,-9,2:95.12
11,-8,2:95.12
11,-7,2:95.12
11,-6,2:95.12
11,-5,2:95.12
11,-4,2:95.12
11,-3,2:95.12
11,-2,2:95.12
11,-1,2:95.12
11,0,2:95.12
11,1,2:95.12
11,2,2:95.12
11,3,2:95.12
11,4,2:95.12
11,5,2:95.12
11,6,2:95.12
11,7,2:95.12
11,8,2:95.12
11,9,2:95.12
11,10,2:95.12
11,11,2:95.12
11,12,2:95.12
11,13,2:95.12
11,14,2:95.12
11,15,2:95.12
11,16,2:95.12
11,17,2:95.12
11,18,2:95.12
11,19,2:95.12
11,20,2:95.12
11,21,2:95.12
11,22,2:1
11,23,2:1
11,24,2:1
11,25,2:1
11,26,2:1
11,27,2:1
11,28,2:1
11,-32,3:1
11,-31,3:1
11,-30,3:1
11,-29,3:1
11,-28,3:1
11,-27,3:1
11,-26,3:1
11,-13,3:159.1
11,-12,3:159.1
11,-11,3:159.1
11,-10,3:159.1
11,-8,3:159.1
11,-4,3:159.1
11,-3,3:159.1
11,-2,3:159.1
11,-1,3:159.1
11,0,3:159.1
11,4,3:159.1
11,6,3:159.1
11,7,3:159.1
11,8,3:159.1
11,9,3:159.1
11,22,3:1
11,23,3:1
11,24,3:1
11,25,3:1
11,26,3:1
11,27,3:1
11,28,3:1
12,-33,1:1
12,-32,1:1
12,-31,1:1
12,-30,1:1
12,-29,1:1
12,-28,1:1
12,-27,1:1
12,-26,1:1
12,-25,1:1
12,-24,1:172
12,-23,1:172
12,-22,1:172
12,-21,1:172
12,-20,1:172
12,-19,1:172
12,-18,1:172
12,-17,1:172
12,-16,1:172
12,-15,1:172
12,-14,1:172
12,-13,1:172
12,-12,1:172
12,-11,1:172
12,-10,1:172
12,-9,1:172
12,-8,1:172
12,-7,1:172
12,-6,1:172
12,-5,1:172
12,-4,1:172
12,-3,1:172
12,-2,1:172
12,-1,1:172
12,0,1:172
12,1,1:172
12,2,1:172
12,3,1:172
12,4,1:172
12,5,1:172
12,6,1:172
12,7,1:172
12,8,1:172
12,9,1:172
12,10,1:172
12,11,1:172
12,12,1:172
12,13,1:172
12,14,1:172
12,15,1:172
12,16,1:172
12,17,1:172
12,18,1:172
12,19,1:172
12,20,1:172
12,21,1:1
12,22,1:1
12,23,1:1
12,24,1:1
12,25,1:1
12,26,1:1
12,27,1:1
12,28,1:1
12,29,1:1
12,-33,2:1
12,-32,2:1
12,-31,2:1
12,-30,2:1
12,-29,2:1
12,-28,2:1
12,-27,2:1
12,-26,2:1
12,-25,2:1
12,-24,2:95.12
12,-23,2:95.12
12,-22,2:95.12
12,-21,2:95.12
12,-20,2:95.12
12,-19,2:95.12
12,-18,2:95.12
12,-17,2:95.12
12,-16,2:95.12
12,-15,2:95.12
12,-14,2:95.12
12,-13,2:95.12
12,-12,2:95.12
12,-11,2:95.12
12,-10,2:95.12
12,-9,2:95.12
12,-8,2:95.12
12,-7,2:95.12
12,-6,2:95.12
12,-5,2:95.12
12,-4,2:95.12
12,-3,2:95.12
12,-2,2:95.12
12,-1,2:95.12
12,0,2:95.12
12,1,2:95.12
12,2,2:95.12
12,3,2:95.12
12,4,2:95.12
12,5,2:95.12
12,6,2:95.12
12,7,2:95.12
12,8,2:95.12
12,9,2:95.12
12,10,2:95.12
12,11,2:95.12
12,12,2:95.12
12,13,2:95.12
12,14,2:95.12
12,15,2:95.12
12,16,2:95.12
12,17,2:95.12
12,18,2:95.12
12,19,2:95.12
12,20,2:95.12
12,21,2:1
12,22,2:1
12,23,2:1
12,24,2:1
12,25,2:1
12,26,2:1
12,27,2:1
12,28,2:1
12,29,2:1
12,-33,3:1
12,-32,3:1
12,-31,3:1
12,-30,3:1
12,-29,3:1
12,-28,3:1
12,-27,3:1
12,-26,3:1
12,-25,3:1
12,-12,3:159.1
12,-11,3:159.1
12,-4,3:159.1
12,-3,3:159.1
12,-2,3:159.1
12,-1,3:159.1
12,0,3:159.1
12,7,3:159.1
12,8,3:159.1
12,21,3:1
12,22,3:1
12,23,3:1
12,24,3:1
12,25,3:1
12,26,3:1
12,27,3:1
12,28,3:1
12,29,3:1
13,-33,1:1
13,-32,1:1
13,-31,1:1
13,-30,1:1
13,-29,1:1
13,-28,1:1
13,-27,1:1
13,-26,1:1
13,-25,1:1
13,-24,1:1
13,-23,1:172
13,-22,1:172
13,-21,1:172
13,-20,1:172
13,-19,1:172
13,-18,1:172
13,-17,1:172
13,-16,1:172
13,-15,1:172
13,-14,1:172
13,-13,1:172
13,-12,1:172
13,-11,1:172
13,-10,1:172
13,-9,1:172
