[META]
version=2.0
spawnOnBlockType=2
spawnSunlight=True
spawnDarkness=False
spawnWater=False
spawnLava=False
underFill=True
randomRotation=True
dig=True
tree=True
branch=False
needsFoundation=True
rarity=1
collisionPercentage=1
spawnElevationMin=0
spawnElevationMax=256
spawnInBiome=Jungle
[DATA]
-75,-2,29:98.3
-75,4,29:98.3
-75,1,31:98.3
-74,-2,24:98.3
-74,4,24:98.3
-74,-2,27:98.3
-74,4,27:98.3
-74,-2,29:98.3
-74,4,29:98.3
-74,-1,30:98.3
-74,3,30:98.3
-74,1,31:98.3
-73,-2,24:98.3
-73,-1,24:114.2
-73,0,24:112
-73,1,24:114
-73,2,24:112
-73,3,24:114.3
-73,4,24:98.3
-73,-2,25:98.3
-73,4,25:98.3
-73,-2,27:98.3
-73,4,27:98.3
-73,-2,28:98.3
-73,4,28:98.3
-73,-2,29:98.3
-73,-1,29:98.3
-73,3,29:98.3
-73,4,29:98.3
-73,-1,30:98.3
-73,3,30:98.3
-73,0,31:98.3
-73,1,31:98.3
-73,2,31:98.3
-72,1,23:98.3
-72,-3,24:98.3
-72,-2,24:98.3
-72,-1,24:112
-72,0,24:98.3
-72,1,24:98.3
-72,2,24:98.3
-72,3,24:112
-72,4,24:98.3
-72,5,24:98.3
-72,-2,25:98.3
-72,4,25:98.3
-72,-2,26:98.3
-72,4,26:98.3
-72,-3,27:98.3
-72,-2,27:98.3
-72,4,27:98.3
-72,5,27:98.3
-72,-2,28:98.3
-72,4,28:98.3
-72,-2,29:98.3
-72,-1,29:98.3
-72,3,29:98.3
-72,4,29:98.3
-72,-1,30:98.3
-72,0,30:98.3
-72,2,30:98.3
-72,3,30:98.3
-72,0,31:98.3
-72,1,31:98.3
-72,2,31:98.3
-72,1,32:98.3
-71,0,23:98.3
-71,1,23:98.3
-71,2,23:98.3
-71,-3,24:98.3
-71,-2,24:114
-71,-1,24:112
-71,0,24:98.3
-71,1,24:109.1
-71,2,24:98.3
-71,3,24:112
-71,4,24:114
-71,5,24:98.3
-71,-3,25:98.3
-71,-2,25:98
-71,4,25:98
-71,5,25:98.3
-71,-3,26:98.3
-71,-2,26:98
-71,4,26:98
-71,5,26:98.3
-71,-3,27:98.3
-71,-2,27:98
-71,4,27:98
-71,5,27:98.3
-71,-3,28:98.3
-71,-2,28:98
-71,4,28:98
-71,5,28:98.3
-71,-3,29:98.3
-71,-2,29:45
-71,-1,29:98.3
-71,3,29:98.3
-71,4,29:45
-71,5,29:98.3
-71,-2,30:98.3
-71,-1,30:45
-71,0,30:44.14
-71,1,30:98.3
-71,2,30:44.14
-71,3,30:45
-71,4,30:98.3
-71,-1,31:98.3
-71,0,31:45
-71,1,31:45
-71,2,31:45
-71,3,31:98.3
-71,0,32:98.3
-71,1,32:98.3
-71,2,32:98.3
-70,1,22:98.3
-70,0,23:98.3
-70,1,23:98.3
-70,2,23:98.3
-70,-3,24:98.3
-70,-2,24:112
-70,-1,24:98.3
-70,0,24:109.3
-70,1,24:112
-70,2,24:109.2
-70,3,24:98.3
-70,4,24:112
-70,5,24:98.3
-70,-2,25:109.7
-70,4,25:109.6
-70,-2,26:109.3
-70,4,26:109.2
-70,-2,27:98
-70,4,27:98
-70,-2,28:109.7
-70,4,28:109.6
-70,-3,29:98.3
-70,-2,29:45
-70,-1,29:98.3
-70,3,29:98.3
-70,4,29:45
-70,5,29:98.3
-70,-1,30:45
-70,0,30:44.14
-70,1,30:98.3
-70,2,30:44.14
-70,3,30:45
-70,-1,31:98.3
-70,0,31:45
-70,1,31:45
-70,2,31:45
-70,3,31:98.3
-70,1,32:98.3
-69,1,22:98.3
-69,0,23:98.3
-69,1,23:98.3
-69,2,23:98.3
-69,-3,24:98.3
-69,-2,24:112
-69,-1,24:98.3
-69,0,24:109
-69,1,24:109
-69,2,24:109
-69,3,24:98.3
-69,4,24:112
-69,5,24:98.3
-69,-2,25:98.3
-69,4,25:98.3
-69,-2,26:98.3
-69,4,26:98.3
-69,-2,27:98.3
-69,4,27:98.3
-69,-2,28:98.3
-69,-1,28:109.7
-69,3,28:109.6
-69,4,28:98.3
-69,-3,29:98.3
-69,-2,29:45
-69,-1,29:98.3
-69,3,29:98.3
-69,4,29:45
-69,5,29:98.3
-69,-1,30:45
-69,0,30:98.3
-69,1,30:98.3
-69,2,30:98.3
-69,3,30:45
-69,-1,31:98.3
-69,0,31:45
-69,1,31:45
-69,2,31:45
-69,3,31:98.3
-69,1,32:98.3
-68,0,22:98.3
-68,1,22:98.3
-68,2,22:98.3
-68,-1,23:98.3
-68,0,23:98.3
-68,1,23:98.3
-68,2,23:98.3
-68,3,23:98.3
-68,-3,24:98.3
-68,-2,24:112
-68,-1,24:133
-68,0,24:133
-68,1,24:133
-68,2,24:133
-68,3,24:133
-68,4,24:112
-68,5,24:98.3
-68,-2,25:109.7
-68,-1,25:171.7
-68,0,25:171.7
-68,1,25:171.7
-68,2,25:171.7
-68,3,25:171.7
-68,4,25:109.6
-68,-2,26:109.3
-68,4,26:109.2
-68,-2,27:98
-68,4,27:98
-68,-2,28:109.7
-68,4,28:109.6
-68,-3,29:98.3
-68,-2,29:45
-68,-1,29:98.3
-68,3,29:98.3
-68,4,29:45
-68,5,29:98.3
-68,-1,30:45
-68,0,30:44.14
-68,1,30:98.3
-68,2,30:44.14
-68,3,30:45
-68,-1,31:98.3
-68,0,31:45
-68,1,31:45
-68,2,31:45
-68,3,31:98.3
-68,1,32:98.3
-67,0,22:98.3
-67,1,22:98.3
-67,2,22:98.3
-67,-1,23:98.3
-67,0,23:98.3
-67,1,23:98.3
-67,2,23:98.3
-67,3,23:98.3
-67,-3,24:98.3
-67,-2,24:112
-67,-1,24:133
-67,0,24:133
-67,1,24:133
-67,2,24:133
-67,3,24:133
-67,4,24:112
-67,5,24:98.3
-67,-3,25:98.3
-67,-2,25:98
-67,-1,25:171.7
-67,0,25:171.7
-67,1,25:171.7
-67,2,25:171.7
-67,3,25:171.7
-67,4,25:98
-67,5,25:98.3
-67,-3,26:98
-67,-2,26:98
-67,4,26:98
-67,5,26:98.3
-67,-3,27:98
-67,-2,27:98
-67,4,27:98
-67,5,27:98
-67,-3,28:98.3
-67,-2,28:98
-67,4,28:98
-67,5,28:98.3
-67,-3,29:98.3
-67,-2,29:45
-67,-1,29:98.3
-67,3,29:98.3
-67,4,29:45
-67,5,29:98.3
-67,-1,30:45
-67,0,30:44.14
-67,1,30:98.3
-67,2,30:44.14
-67,3,30:45
-67,-1,31:98.3
-67,0,31:45
-67,1,31:45
-67,2,31:45
-67,3,31:98.3
-67,1,32:98.3
-66,0,22:98.3
-66,1,22:98.3
-66,2,22:98.3
-66,-2,23:98.3
-66,-1,23:98.3
-66,0,23:98.3
-66,1,23:98.3
-66,2,23:98.3
-66,3,23:98.3
-66,-3,24:98.3
-66,-2,24:112
-66,-1,24:98.3
-66,0,24:98.3
-66,1,24:98.3
-66,2,24:98.3
-66,3,24:98.3
-66,4,24:112
-66,5,24:98.3
-66,-3,25:98.3
-66,-2,25:45
-66,-1,25:33.5
-66,0,25:33.5
-66,1,25:33.5
-66,2,25:33.5
-66,3,25:33.5
-66,4,25:45
-66,5,25:98.3
-66,-3,26:98.3
-66,-2,26:45
-66,-1,26:33.5
-66,0,26:33.5
-66,1,26:33.5
-66,2,26:33.5
-66,3,26:33.5
-66,4,26:45
-66,5,26:98.3
-66,-3,27:98.3
-66,-2,27:45
-66,-1,27:33.5
-66,0,27:33.5
-66,1,27:33.5
-66,2,27:33.5
-66,3,27:33.5
-66,4,27:45
-66,5,27:98.3
-66,-3,28:98.3
-66,-2,28:45
-66,-1,28:33.5
-66,0,28:33.5
-66,1,28:33.5
-66,2,28:33.5
-66,3,28:33.5
-66,4,28:45
-66,5,28:98.3
-66,-3,29:98.3
-66,-2,29:45
-66,-1,29:98.3
-66,0,29:33.5
-66,1,29:33.5
-66,2,29:33.5
-66,3,29:98.3
-66,4,29:45
-66,5,29:98.3
-66,-2,30:98.3
-66,-1,30:45
-66,0,30:33.5
-66,1,30:98.3
-66,2,30:33.5
-66,3,30:45
-66,4,30:98.3
-66,-1,31:98.3
-66,0,31:45
-66,1,31:45
-66,2,31:45
-66,3,31:98.3
-66,0,32:98.3
-66,1,32:98.3
-66,2,32:98.3
-65,-1,22:98.3
-65,0,22:98.3
-65,1,22:98.3
-65,2,22:98.3
-65,3,22:98.3
-65,-6,23:95.14
-65,-5,23:95.14
-65,-4,23:95.14
-65,-3,23:95.14
-65,-2,23:98.3
-65,-1,23:98.3
-65,0,23:98.3
-65,1,23:98.3
-65,2,23:98.3
-65,3,23:98.3
-65,4,23:98.3
-65,5,23:95.14
-65,6,23:95.14
-65,7,23:95.14
-65,8,23:95.14
-65,-6,24:95.14
-65,-5,24:95.14
-65,-4,24:95.14
-65,-3,24:95.14
-65,-2,24:98.3
-65,-1,24:126.8
-65,0,24:126.8
-65,1,24:53.1
-65,2,24:126.8
-65,3,24:126.8
-65,4,24:98.3
-65,5,24:95.14
-65,6,24:95.14
-65,7,24:95.14
-65,8,24:95.14
-65,-6,25:95.14
-65,-5,25:95.14
-65,-4,25:95.14
-65,-3,25:95.14
-65,-2,25:98.3
-65,4,25:98.3
-65,5,25:95.14
-65,6,25:95.14
-65,7,25:95.14
-65,8,25:95.14
-65,-6,26:95.14
-65,-5,26:95.14
-65,-4,26:95.14
-65,-3,26:95.14
-65,-2,26:98.3
-65,4,26:98.3
-65,5,26:95.14
-65,6,26:95.14
-65,7,26:95.14
-65,8,26:95.14
-65,-6,27:95.14
-65,-5,27:95.14
-65,-4,27:95.14
-65,-3,27:95.14
-65,-2,27:98.3
-65,4,27:98.3
-65,5,27:95.14
-65,6,27:95.14
-65,7,27:95.14
-65,8,27:95.14
-65,-6,28:95.14
-65,-5,28:95.14
-65,-4,28:95.14
-65,-3,28:95.14
-65,-2,28:98.3
-65,4,28:98.3
-65,5,28:95.14
-65,6,28:95.14
-65,7,28:95.14
-65,8,28:95.14
-65,-6,29:95.14
-65,-5,29:95.14
-65,-4,29:95.14
-65,-3,29:95.14
-65,-2,29:98.3
-65,4,29:98.3
-65,5,29:95.14
-65,6,29:95.14
-65,7,29:95.14
-65,8,29:95.14
-65,-6,30:95.14
-65,-5,30:95.14
-65,-4,30:95.14
-65,-3,30:95.14
-65,-2,30:95.14
-65,-1,30:98.3
-65,3,30:98.3
-65,4,30:95.14
-65,5,30:95.14
-65,6,30:95.14
-65,7,30:95.14
-65,8,30:95.14
-65,-6,31:95.14
-65,-5,31:95.14
-65,-4,31:95.14
-65,-3,31:95.14
-65,-2,31:95.14
-65,-1,31:95.14
-65,0,31:98.3
-65,1,31:98.3
-65,2,31:98.3
-65,3,31:95.14
-65,4,31:95.14
-65,5,31:95.14
-65,6,31:95.14
-65,7,31:95.14
-65,8,31:95.14
-65,-6,32:95.14
-65,-5,32:95.14
-65,-4,32:95.14
-65,-3,32:95.14
-65,-2,32:95.14
-65,-1,32:95.14
-65,0,32:95.14
-65,1,32:95.14
-65,2,32:95.14
-65,3,32:95.14
-65,4,32:95.14
-65,5,32:95.14
-65,6,32:95.14
-65,7,32:95.14
-65,8,32:95.14
-65,-6,33:95.14
-65,-5,33:95.14
-65,-4,33:95.14
-65,-3,33:95.14
-65,-2,33:95.14
-65,-1,33:95.14
-65,0,33:95.14
-65,1,33:95.14
-65,2,33:95.14
-65,3,33:95.14
-65,4,33:95.14
-65,5,33:95.14
-65,6,33:95.14
-65,7,33:95.14
-65,8,33:95.14
-65,-6,34:95.14
-65,-5,34:95.14
-65,-4,34:95.14
-65,-3,34:95.14
-65,-2,34:95.14
-65,-1,34:95.14
-65,0,34:95.14
-65,1,34:95.14
-65,2,34:95.14
-65,3,34:95.14
-65,4,34:95.14
-65,5,34:95.14
-65,6,34:95.14
-65,7,34:95.14
-65,8,34:95.14
-65,-6,35:95.14
-65,-5,35:95.14
-65,-4,35:95.14
-65,-3,35:95.14
-65,-2,35:95.14
-65,-1,35:95.14
-65,0,35:95.14
-65,1,35:95.14
-65,2,35:95.14
-65,3,35:95.14
-65,4,35:95.14
-65,5,35:95.14
-65,6,35:95.14
-65,7,35:95.14
-65,8,35:95.14
-65,-6,36:95.14
-65,-5,36:95.14
-65,-4,36:95.14
-65,-3,36:95.14
-65,-2,36:95.14
-65,-1,36:95.14
-65,0,36:95.14
-65,1,36:95.14
-65,2,36:95.14
-65,3,36:95.14
-65,4,36:95.14
-65,5,36:95.14
-65,6,36:95.14
-65,7,36:95.14
-65,8,36:95.14
-65,-6,37:95.14
-65,-5,37:95.14
-65,-4,37:95.14
-65,-3,37:95.14
-65,-2,37:95.14
-65,-1,37:95.14
-65,0,37:95.14
-65,1,37:95.14
-65,2,37:95.14
-65,3,37:95.14
-65,4,37:95.14
-65,5,37:95.14
-65,6,37:95.14
-65,7,37:95.14
-65,8,37:95.14
-65,-6,38:95.14
-65,-5,38:95.14
-65,-4,38:95.14
-65,-3,38:95.14
-65,-2,38:95.14
-65,-1,38:95.14
-65,0,38:95.14
-65,1,38:95.14
-65,2,38:95.14
-65,3,38:95.14
-65,4,38:95.14
-65,5,38:95.14
-65,6,38:95.14
-65,7,38:95.14
-65,8,38:95.14
-65,-6,39:5.1
-65,-5,39:5.1
-65,-4,39:5.1
-65,-3,39:5.1
-65,-2,39:5.1
-65,-1,39:5.1
-65,0,39:5.1
-65,1,39:5.1
-65,2,39:5.1
-65,3,39:5.1
-65,4,39:5.1
-65,5,39:5.1
-65,6,39:5.1
-65,7,39:5.1
-65,8,39:5.1
-65,-6,40:5.1
-65,-5,40:5.1
-65,-4,40:5.1
-65,-3,40:5.1
-65,-2,40:5.1
-65,-1,40:5.1
-65,0,40:5.1
-65,1,40:5.1
-65,2,40:5.1
-65,3,40:5.1
-65,4,40:5.1
-65,5,40:5.1
-65,6,40:5.1
-65,7,40:5.1
-65,8,40:5.1
-65,-6,41:5.1
-65,-5,41:5.1
-65,-4,41:5.1
-65,-3,41:5.1
-65,-2,41:5.1
-65,-1,41:5.1
-65,0,41:5.1
-65,1,41:5.1
-65,2,41:5.1
-65,3,41:5.1
-65,4,41:5.1
-65,5,41:5.1
-65,6,41:5.1
-65,7,41:5.1
-65,8,41:5.1
-65,-6,42:5.1
-65,-5,42:5.1
-65,-4,42:5.1
-65,-3,42:5.1
-65,-2,42:5.1
-65,-1,42:5.1
-65,0,42:5.1
-65,1,42:5.1
-65,2,42:5.1
-65,3,42:5.1
-65,4,42:5.1
-65,5,42:5.1
-65,6,42:5.1
-65,7,42:5.1
-65,8,42:5.1
-64,-1,22:5.2
-64,1,22:5.2
-64,3,22:121
-64,-7,23:95.14
-64,-6,23:109.2
-64,-5,23:109
-64,-3,23:109
-64,-2,23:109
-64,-1,23:5.2
-64,1,23:5.2
-64,3,23:121
-64,4,23:109.2
-64,5,23:109
-64,7,23:109
-64,8,23:109
-64,9,23:95.14
-64,-7,24:95.14
-64,-6,24:139
-64,-5,24:139
-64,-3,24:139
-64,-2,24:139
-64,-1,24:125
-64,0,24:126
-64,1,24:126
-64,2,24:126
-64,3,24:125
-64,4,24:139
-64,5,24:139
-64,7,24:139
-64,8,24:139
-64,9,24:95.14
-64,-7,25:95.14
-64,-6,25:139
-64,-5,25:139
-64,-3,25:139
-64,-2,25:139
-64,4,25:139
-64,5,25:139
-64,7,25:139
-64,8,25:139
-64,9,25:95.14
-64,-7,26:95.14
-64,-6,26:139
-64,-5,26:139
-64,-3,26:139
-64,-2,26:139
-64,4,26:139
-64,5,26:139
-64,7,26:139
-64,8,26:139
-64,9,26:95.14
-64,-7,27:95.14
-64,-5,27:109
-64,-4,27:109.4
-64,-3,27:109
-64,5,27:109
-64,6,27:109.4
-64,7,27:109
-64,9,27:95.14
-64,-7,28:95.14
-64,9,28:95.14
-64,-7,29:95.14
-64,-6,29:109.4
-64,-5,29:109.4
-64,-3,29:109.4
-64,-2,29:109.7
-64,4,29:109.4
-64,5,29:109.4
-64,7,29:109.4
-64,8,29:109.7
-64,9,29:95.14
-64,-7,30:95.14
-64,-2,30:45
-64,4,30:45
-64,9,30:95.14
-64,-7,31:95.14
-64,-1,31:45
-64,3,31:45
-64,9,31:95.14
-64,-7,32:95.14
-64,-6,32:109.6
-64,-5,32:109.4
-64,-3,32:109.4
-64,-2,32:109.4
-64,0,32:45
-64,1,32:45
-64,2,32:45
-64,4,32:109.6
-64,5,32:109.4
-64,7,32:109.4
-64,8,32:109.4
-64,9,32:95.14
-64,-7,33:95.14
-64,-6,33:109.2
-64,-5,33:109
-64,-3,33:109
-64,-2,33:109
-64,0,33:44.5
-64,1,33:109.5
-64,2,33:44.5
-64,4,33:109.2
-64,5,33:109
-64,7,33:109
-64,8,33:109
-64,9,33:95.14
-64,-7,34:95.14
-64,-1,34:44.13
-64,0,34:45
-64,1,34:109.1
-64,2,34:45
-64,3,34:44.13
-64,9,34:95.14
-64,-7,35:95.14
-64,-5,35:109.4
-64,-4,35:109.4
-64,0,35:44.5
-64,2,35:44.5
-64,9,35:95.14
-64,-7,36:95.14
-64,-5,36:109
-64,-4,36:109
-64,-3,36:44.13
-64,-2,36:109.7
-64,4,36:109.6
-64,5,36:44.13
-64,6,36:109.4
-64,7,36:109.7
-64,9,36:95.14
-64,-7,37:95.14
-64,-2,37:44.5
-64,-1,37:109.3
-64,3,37:109.2
-64,4,37:44.5
-64,6,37:109
-64,7,37:109
-64,9,37:95.14
-64,-7,38:95.14
-64,-1,38:44.5
-64,0,38:98
-64,1,38:44.13
-64,2,38:98
-64,3,38:44.5
-64,9,38:95.14
-64,-7,39:5.1
-64,-6,39:5.1
-64,-5,39:109.4
-64,-4,39:109.4
-64,-3,39:44.13
-64,-2,39:44.13
-64,-1,39:109.2
-64,3,39:109.3
-64,4,39:44.13
-64,5,39:44.13
-64,6,39:109.4
-64,7,39:109.7
-64,8,39:5.1
-64,9,39:5.1
-64,-7,40:5.1
-64,-5,40:109
-64,-4,40:109
-64,-1,40:44.5
-64,3,40:44.5
-64,6,40:109
-64,7,40:109
-64,9,40:5.1
-64,-7,41:5.1
-64,-6,41:5.1
-64,-5,41:5.1
-64,-4,41:5.1
-64,-3,41:5.1
-64,-2,41:5.1
-64,-1,41:5.1
-64,0,41:5.1
-64,1,41:5.1
-64,2,41:5.1
-64,3,41:5.1
-64,4,41:5.1
-64,5,41:5.1
-64,6,41:5.1
-64,7,41:5.1
-64,8,41:5.1
-64,9,41:5.1
-64,-7,42:5.1
-64,-6,42:5.1
-64,-5,42:5.1
-64,-4,42:5.1
-64,-3,42:5.1
-64,-2,42:5.1
-64,-1,42:5.1
-64,0,42:5.1
-64,1,42:5.1
-64,2,42:5.1
-64,3,42:5.1
-64,4,42:5.1
-64,5,42:5.1
-64,6,42:5.1
-64,7,42:5.1
-64,8,42:5.1
-64,9,42:5.1
-64,-2,43:109.4
-64,-1,43:109.4
-64,0,43:109.4
-64,2,43:109.4
-64,3,43:109.4
-64,4,43:109.4
-64,-2,44:109
-64,-1,44:109
-64,0,44:109
-64,2,44:109
-64,3,44:109
-64,4,44:109
-63,-7,22:5.1
-63,-6,22:5.1
-63,-5,22:5.1
-63,-4,22:5.1
-63,-3,22:5.1
-63,-2,22:5.1
-63,-1,22:24
-63,0,22:5.2
-63,1,22:5.2
-63,2,22:5.2
-63,3,22:5.2
-63,4,22:5.1
-63,5,22:5.1
-63,6,22:5.1
-63,7,22:5.1
-63,8,22:5.1
-63,9,22:5.1
-63,-12,23:95.14
-63,-11,23:95.14
-63,-10,23:95.14
-63,-9,23:95.14
-63,-8,23:95.14
-63,-6,23:109.2
-63,-5,23:159.14
-63,-4,23:159.14
-63,-3,23:159.14
-63,-2,23:109.3
-63,-1,23:24
-63,0,23:5.2
-63,1,23:5.2
-63,2,23:5.2
-63,3,23:5.2
-63,4,23:109.2
-63,5,23:159.14
-63,6,23:159.14
-63,7,23:159.14
-63,8,23:109.3
-63,10,23:95.14
-63,11,23:95.14
-63,12,23:95.14
-63,13,23:95.14
-63,14,23:95.14
-63,-12,24:95.14
-63,-11,24:95.14
-63,-10,24:95.14
-63,-9,24:95.14
-63,-8,24:95.14
-63,-6,24:139
-63,-5,24:159.14
-63,-4,24:159.14
-63,-3,24:159.14
-63,-2,24:139
-63,-1,24:126
-63,1,24:126
-63,3,24:126
-63,4,24:139
-63,5,24:159.14
-63,6,24:159.14
-63,7,24:159.14
-63,8,24:139
-63,10,24:95.14
-63,11,24:95.14
-63,12,24:95.14
-63,13,24:95.14
-63,14,24:95.14
-63,-12,25:95.14
-63,-11,25:95.14
-63,-10,25:95.14
-63,-9,25:95.14
-63,-8,25:95.14
-63,-6,25:139
-63,-5,25:159.14
-63,-4,25:159.14
-63,-3,25:159.14
-63,-2,25:139
-63,4,25:139
-63,5,25:159.14
-63,6,25:159.14
-63,7,25:159.14
-63,8,25:139
-63,10,25:95.14
-63,11,25:95.14
-63,12,25:95.14
-63,13,25:95.14
-63,14,25:95.14
-63,-12,26:95.14
-63,-11,26:95.14
-63,-10,26:95.14
-63,-9,26:95.14
-63,-8,26:95.14
-63,-6,26:139
-63,-5,26:159.14
-63,-4,26:159.14
-63,-3,26:159.14
-63,-2,26:139
-63,4,26:139
-63,5,26:159.14
-63,6,26:159.14
-63,7,26:159.14
-63,8,26:139
-63,10,26:95.14
-63,11,26:95.14
-63,12,26:95.14
-63,13,26:95.14
-63,14,26:95.14
-63,-12,27:95.14
-63,-11,27:95.14
-63,-10,27:95.14
-63,-9,27:95.14
-63,-8,27:95.14
-63,-6,27:109.2
-63,-5,27:159.14
-63,-4,27:159.14
-63,-3,27:159.14
-63,-2,27:109.3
-63,4,27:109.2
-63,5,27:159.14
-63,6,27:159.14
-63,7,27:159.14
-63,8,27:109.3
-63,10,27:95.14
-63,11,27:95.14
-63,12,27:95.14
-63,13,27:95.14
-63,14,27:95.14
-63,-12,28:95.14
-63,-11,28:95.14
-63,-10,28:95.14
-63,-9,28:95.14
-63,-8,28:95.14
-63,-5,28:45
-63,-4,28:45
-63,-3,28:45
-63,5,28:45
-63,6,28:45
-63,7,28:45
-63,10,28:95.14
-63,11,28:95.14
-63,12,28:95.14
-63,13,28:95.14
-63,14,28:95.14
-63,-12,29:95.14
-63,-11,29:95.14
-63,-10,29:95.14
-63,-9,29:95.14
-63,-8,29:95.14
-63,-6,29:109.6
-63,-5,29:45
-63,-4,29:45
-63,-3,29:45
-63,-2,29:109.7
-63,4,29:109.6
-63,5,29:45
-63,6,29:45
-63,7,29:45
-63,8,29:109.7
-63,10,29:95.14
-63,11,29:95.14
-63,12,29:95.14
-63,13,29:95.14
-63,14,29:95.14
-63,-12,30:95.14
-63,-11,30:95.14
-63,-10,30:95.14
-63,-9,30:95.14
-63,-8,30:95.14
-63,-5,30:45
-63,-4,30:139
-63,-3,30:45
-63,5,30:45
-63,6,30:139
-63,7,30:45
-63,10,30:95.14
-63,11,30:95.14
-63,12,30:95.14
-63,13,30:95.14
-63,14,30:95.14
-63,-12,31:95.14
-63,-11,31:95.14
-63,-10,31:95.14
-63,-9,31:95.14
-63,-8,31:95.14
-63,-5,31:45
-63,-4,31:139
-63,-3,31:45
-63,-2,31:98.3
-63,4,31:98.3
-63,5,31:45
-63,6,31:139
-63,7,31:45
-63,10,31:95.14
-63,11,31:95.14
-63,12,31:95.14
-63,13,31:95.14
-63,14,31:95.14
-63,-12,32:95.14
-63,-11,32:95.14
-63,-10,32:95.14
-63,-9,32:95.14
-63,-8,32:95.14
-63,-6,32:109.6
-63,-5,32:45
-63,-4,32:45
-63,-3,32:45
-63,-2,32:109.7
-63,-1,32:98.3
-63,0,32:109.6
-63,2,32:109.7
-63,3,32:98.3
-63,4,32:109.6
-63,5,32:45
-63,6,32:45
-63,7,32:45
-63,8,32:109.7
-63,10,32:95.14
-63,11,32:95.14
-63,12,32:95.14
-63,13,32:95.14
-63,14,32:95.14
-63,-12,33:95.14
-63,-11,33:95.14
-63,-10,33:95.14
-63,-9,33:95.14
-63,-8,33:95.14
-63,-6,33:109.2
-63,-5,33:45
-63,-4,33:45
-63,-3,33:45
-63,-2,33:109.3
-63,-1,33:109.2
-63,0,33:98.3
-63,1,33:109.5
-63,2,33:98.3
-63,3,33:109.3
-63,4,33:109.2
-63,5,33:45
-63,6,33:45
-63,7,33:45
-63,8,33:109.3
-63,10,33:95.14
-63,11,33:95.14
-63,12,33:95.14
-63,13,33:95.14
-63,14,33:95.14
-63,-12,34:95.14
-63,-11,34:95.14
-63,-10,34:95.14
-63,-9,34:95.14
-63,-8,34:95.14
-63,-5,34:45
-63,-4,34:45
-63,-3,34:45
-63,0,34:44.5
-63,1,34:44.5
-63,2,34:44.5
-63,5,34:45
-63,6,34:45
-63,7,34:45
-63,10,34:95.14
-63,11,34:95.14
-63,12,34:95.14
-63,13,34:95.14
-63,14,34:95.14
-63,-12,35:95.14
-63,-11,35:95.14
-63,-10,35:95.14
-63,-9,35:95.14
-63,-8,35:95.14
-63,-5,35:109.6
-63,-4,35:45
-63,-3,35:45
-63,5,35:45
-63,6,35:45
-63,10,35:95.14
-63,11,35:95.14
-63,12,35:95.14
-63,13,35:95.14
-63,14,35:95.14
-63,-12,36:95.14
-63,-11,36:95.14
-63,-10,36:95.14
-63,-9,36:95.14
-63,-8,36:95.14
-63,-5,36:109.2
-63,-4,36:45
-63,-3,36:45
-63,-2,36:45
-63,-1,36:45
-63,3,36:45
-63,4,36:45
-63,5,36:45
-63,6,36:45
-63,7,36:109.7
-63,10,36:95.14
-63,11,36:95.14
-63,12,36:95.14
-63,13,36:95.14
-63,14,36:95.14
-63,-12,37:95.14
-63,-11,37:95.14
-63,-10,37:95.14
-63,-9,37:95.14
-63,-8,37:95.14
-63,-4,37:45
-63,-3,37:45
-63,-2,37:45
-63,-1,37:45
-63,0,37:45
-63,1,37:45
-63,2,37:45
-63,3,37:45
-63,4,37:45
-63,5,37:45
-63,6,37:45
-63,7,37:109.3
-63,10,37:95.14
-63,11,37:95.14
-63,12,37:95.14
-63,13,37:95.14
-63,14,37:95.14
-63,-12,38:95.14
-63,-11,38:95.14
-63,-10,38:95.14
-63,-9,38:95.14
-63,-8,38:95.14
-63,-4,38:45
-63,-3,38:45
-63,-1,38:45
-63,0,38:45
-63,1,38:45
-63,2,38:45
-63,3,38:45
-63,5,38:45
-63,6,38:45
-63,10,38:95.14
-63,11,38:95.14
-63,12,38:95.14
-63,13,38:95.14
-63,14,38:95.14
-63,-12,39:5.1
-63,-11,39:5.1
-63,-10,39:5.1
-63,-9,39:5.1
-63,-8,39:5.1
-63,-7,39:5.1
-63,-6,39:5.1
-63,-5,39:109.6
-63,-4,39:45
-63,-3,39:45
-63,-2,39:98
-63,-1,39:109.3
-63,3,39:109.2
-63,4,39:98
-63,5,39:45
-63,6,39:45
-63,7,39:109.7
-63,8,39:5.1
-63,9,39:5.1
-63,10,39:5.1
-63,11,39:5.1
-63,12,39:5.1
-63,13,39:5.1
-63,14,39:5.1
-63,-12,40:5.1
-63,-11,40:5.1
-63,-10,40:5.1
-63,-9,40:5.1
-63,-8,40:5.1
-63,-5,40:109.2
-63,-4,40:45
-63,-3,40:45
-63,-2,40:44.5
-63,4,40:44.5
-63,5,40:45
-63,6,40:45
-63,7,40:109.3
-63,10,40:5.1
-63,11,40:5.1
-63,12,40:5.1
-63,13,40:5.1
-63,14,40:5.1
-63,-12,41:5.1
-63,-11,41:5.1
-63,-10,41:5.1
-63,-9,41:5.1
-63,-8,41:5.1
-63,-7,41:5.1
-63,-6,41:5.1
-63,-4,41:45
-63,-3,41:45
-63,5,41:45
-63,6,41:45
-63,8,41:5.1
-63,9,41:5.1
-63,10,41:5.1
-63,11,41:5.1
-63,12,41:5.1
-63,13,41:5.1
-63,14,41:5.1
-63,-12,42:5.1
-63,-11,42:5.1
-63,-10,42:5.1
-63,-9,42:5.1
-63,-8,42:5.1
-63,-7,42:5.1
-63,-6,42:5.1
-63,-4,42:45
-63,-3,42:45
-63,-2,42:45
-63,4,42:45
-63,5,42:45
-63,6,42:45
-63,8,42:5.1
-63,9,42:5.1
-63,10,42:5.1
-63,11,42:5.1
-63,12,42:5.1
-63,13,42:5.1
-63,14,42:5.1
-63,-4,43:45
-63,-3,43:45
-63,-2,43:45
-63,-1,43:45
-63,0,43:45
-63,1,43:45
-63,2,43:45
-63,3,43:45
-63,4,43:45
-63,5,43:45
-63,6,43:45
-63,-2,44:45
-63,-1,44:45
-63,0,44:45
-63,1,44:45
-63,2,44:45
-63,3,44:45
-63,4,44:45
-63,0,45:109.4
-63,1,45:109.4
-63,2,45:109.4
-63,0,46:109
-63,1,46:109
-63,2,46:109
-62,-12,22:5.1
-62,-11,22:5.1
-62,-10,22:5.1
-62,-9,22:5.1
-62,-8,22:5.1
-62,-7,22:5.1
-62,-6,22:5.1
-62,-5,22:5.1
-62,-4,22:5.1
-62,-3,22:5.1
-62,-2,22:5.2
-62,-1,22:5.2
-62,0,22:5.2
-62,1,22:5.2
-62,2,22:24
-62,3,22:5.2
-62,4,22:5.2
-62,5,22:5.1
-62,6,22:5.1
-62,7,22:5.1
-62,8,22:5.1
-62,9,22:5.1
-62,10,22:5.1
-62,11,22:5.1
-62,12,22:5.1
-62,13,22:5.1
-62,14,22:5.1
-62,-16,23:95.14
-62,-15,23:95.14
-62,-14,23:95.14
-62,-13,23:95.14
-62,-12,23:98.3
-62,-11,23:98.3
-62,-10,23:98.3
-62,-9,23:98.3
-62,-8,23:98.3
-62,-7,23:98.3
-62,-5,23:159.14
-62,-4,23:159.14
-62,-3,23:159.14
-62,-2,23:5.2
-62,-1,23:5.2
-62,0,23:5.2
-62,1,23:5.2
-62,2,23:5.2
-62,3,23:5.2
-62,4,23:5.2
-62,5,23:159.14
-62,6,23:159.14
-62,7,23:159.14
-62,9,23:98.3
-62,10,23:98.3
-62,11,23:98.3
-62,12,23:98.3
-62,13,23:98.3
-62,14,23:98.3
-62,15,23:95.14
-62,16,23:95.14
-62,17,23:95.14
-62,18,23:95.14
-62,-16,24:95.14
-62,-15,24:95.14
-62,-14,24:95.14
-62,-13,24:95.14
-62,-5,24:159.14
-62,-4,24:159.14
-62,-3,24:159.14
-62,1,24:126
-62,5,24:159.14
-62,6,24:159.14
-62,7,24:159.14
-62,15,24:95.14
-62,16,24:95.14
-62,17,24:95.14
-62,18,24:95.14
-62,-16,25:95.14
-62,-15,25:95.14
-62,-14,25:95.14
-62,-13,25:95.14
-62,-5,25:159.14
-62,-4,25:159.14
-62,-3,25:159.14
-62,5,25:159.14
-62,6,25:159.14
-62,7,25:159.14
-62,15,25:95.14
-62,16,25:95.14
-62,17,25:95.14
-62,18,25:95.14
-62,-16,26:95.14
-62,-15,26:95.14
-62,-14,26:95.14
-62,-13,26:95.14
-62,-5,26:159.14
-62,-4,26:159.14
-62,-3,26:159.14
-62,5,26:159.14
-62,6,26:159.14
-62,7,26:159.14
-62,15,26:95.14
-62,16,26:95.14
-62,17,26:95.14
-62,18,26:95.14
-62,-16,27:95.14
-62,-15,27:95.14
-62,-14,27:95.14
-62,-13,27:95.14
-62,-6,27:109.6
-62,-5,27:159.14
-62,-4,27:159.14
-62,-3,27:159.14
-62,-2,27:109.7
-62,4,27:109.6
-62,5,27:159.14
-62,6,27:159.14
-62,7,27:159.14
-62,8,27:109.7
-62,15,27:95.14
-62,16,27:95.14
-62,17,27:95.14
-62,18,27:95.14
-62,-16,28:95.14
-62,-15,28:95.14
-62,-14,28:95.14
-62,-13,28:95.14
-62,-5,28:45
-62,-4,28:45
-62,-3,28:45
-62,5,28:45
-62,6,28:45
-62,7,28:45
-62,15,28:95.14
-62,16,28:95.14
-62,17,28:95.14
-62,18,28:95.14
-62,-16,29:95.14
-62,-15,29:95.14
-62,-14,29:95.14
-62,-13,29:95.14
-62,-5,29:45
-62,-4,29:45
-62,-3,29:45
-62,5,29:45
-62,6,29:45
-62,7,29:45
-62,15,29:95.14
-62,16,29:95.14
-62,17,29:95.14
-62,18,29:95.14
-62,-16,30:95.14
-62,-15,30:95.14
-62,-14,30:95.14
-62,-13,30:95.14
-62,-5,30:139
-62,-4,30:45
-62,-3,30:139
-62,5,30:139
-62,6,30:45
-62,7,30:139
-62,15,30:95.14
-62,16,30:95.14
-62,17,30:95.14
-62,18,30:95.14
-62,-16,31:95.14
-62,-15,31:95.14
-62,-14,31:95.14
-62,-13,31:95.14
-62,-5,31:139
-62,-4,31:45
-62,-3,31:139
-62,5,31:139
-62,6,31:45
-62,7,31:139
-62,15,31:95.14
-62,16,31:95.14
-62,17,31:95.14
-62,18,31:95.14
-62,-16,32:95.14
-62,-15,32:95.14
-62,-14,32:95.14
-62,-13,32:95.14
-62,-5,32:45
-62,-4,32:45
-62,-3,32:45
-62,5,32:45
-62,6,32:45
-62,7,32:45
-62,15,32:95.14
-62,16,32:95.14
-62,17,32:95.14
-62,18,32:95.14
-62,-16,33:95.14
-62,-15,33:95.14
-62,-14,33:95.14
-62,-13,33:95.14
-62,-5,33:45
-62,-4,33:45
-62,-3,33:45
-62,5,33:45
-62,6,33:45
-62,7,33:45
-62,15,33:95.14
-62,16,33:95.14
-62,17,33:95.14
-62,18,33:95.14
-62,-16,34:95.14
-62,-15,34:95.14
-62,-14,34:95.14
-62,-13,34:95.14
-62,-5,34:45
-62,-4,34:45
-62,-3,34:45
-62,5,34:45
-62,6,34:45
-62,7,34:45
-62,15,34:95.14
-62,16,34:95.14
-62,17,34:95.14
-62,18,34:95.14
-62,-16,35:95.14
-62,-15,35:95.14
-62,-14,35:95.14
-62,-13,35:95.14
-62,-4,35:45
-62,-3,35:45
-62,-2,35:45
-62,4,35:45
-62,5,35:45
-62,6,35:45
-62,15,35:95.14
-62,16,35:95.14
-62,17,35:95.14
-62,18,35:95.14
-62,-16,36:95.14
-62,-15,36:95.14
-62,-14,36:95.14
-62,-13,36:95.14
-62,-4,36:45
-62,-3,36:45
-62,-2,36:45
-62,-1,36:45
-62,0,36:45
-62,2,36:45
-62,3,36:45
-62,4,36:45
-62,5,36:45
-62,6,36:45
-62,15,36:95.14
-62,16,36:95.14
-62,17,36:95.14
-62,18,36:95.14
-62,-16,37:95.14
-62,-15,37:95.14
-62,-14,37:95.14
-62,-13,37:95.14
-62,-4,37:45
-62,-3,37:45
-62,-2,37:45
-62,-1,37:45
-62,0,37:45
-62,1,37:45
-62,2,37:45
-62,3,37:45
-62,4,37:45
-62,5,37:45
-62,6,37:45
-62,15,37:95.14
-62,16,37:95.14
-62,17,37:95.14
-62,18,37:95.14
-62,-16,38:95.14
-62,-15,38:95.14
-62,-14,38:95.14
-62,-13,38:95.14
-62,-4,38:45
-62,-3,38:45
-62,-1,38:45
-62,0,38:45
-62,1,38:45
-62,2,38:45
-62,3,38:45
-62,5,38:45
-62,6,38:45
-62,15,38:95.14
-62,16,38:95.14
-62,17,38:95.14
-62,18,38:95.14
-62,-16,39:5.1
-62,-15,39:5.1
-62,-14,39:5.1
-62,-13,39:5.1
-62,-12,39:5.1
-62,-11,39:5.1
-62,-10,39:5.1
-62,-9,39:5.1
-62,-8,39:5.1
-62,-7,39:5.1
-62,-4,39:45
-62,-3,39:45
-62,-2,39:44.13
-62,4,39:44.13
-62,5,39:45
-62,6,39:45
-62,9,39:5.1
-62,10,39:5.1
-62,11,39:5.1
-62,12,39:5.1
-62,13,39:5.1
-62,14,39:5.1
-62,15,39:5.1
-62,16,39:5.1
-62,17,39:5.1
-62,18,39:5.1
-62,-16,40:5.1
-62,-15,40:5.1
-62,-14,40:5.1
-62,-13,40:5.1
-62,-4,40:45
-62,-3,40:45
-62,5,40:45
-62,6,40:45
-62,15,40:5.1
-62,16,40:5.1
-62,17,40:5.1
-62,18,40:5.1
-62,-16,41:5.1
-62,-15,41:5.1
-62,-14,41:5.1
-62,-13,41:5.1
-62,-12,41:5.1
-62,-11,41:5.1
-62,-10,41:5.1
-62,-9,41:5.1
-62,-8,41:5.1
-62,-7,41:5.1
-62,-4,41:45
-62,-3,41:45
-62,5,41:45
-62,6,41:45
-62,9,41:5.1
-62,10,41:5.1
-62,11,41:5.1
-62,12,41:5.1
-62,13,41:5.1
-62,14,41:5.1
-62,15,41:5.1
-62,16,41:5.1
-62,17,41:5.1
-62,18,41:5.1
-62,-16,42:5.1
-62,-15,42:5.1
-62,-14,42:5.1
-62,-13,42:5.1
-62,-12,42:5.1
-62,-11,42:5.1
-62,-10,42:5.1
-62,-9,42:5.1
-62,-8,42:5.1
-62,-7,42:5.1
-62,-4,42:45
-62,-3,42:45
-62,-2,42:45
-62,4,42:45
-62,5,42:45
-62,6,42:45
-62,9,42:5.1
-62,10,42:5.1
-62,11,42:5.1
-62,12,42:5.1
-62,13,42:5.1
-62,14,42:5.1
-62,15,42:5.1
-62,16,42:5.1
-62,17,42:5.1
-62,18,42:5.1
-62,-10,43:109
-62,-9,43:109
-62,-8,43:109
-62,-4,43:45
-62,-3,43:45
-62,-2,43:45
-62,4,43:45
-62,5,43:45
-62,6,43:45
-62,11,43:109
-62,12,43:109
-62,-3,44:45
-62,-2,44:45
-62,-1,44:45
-62,0,44:45
-62,1,44:45
-62,2,44:45
-62,3,44:45
-62,4,44:45
-62,5,44:45
-62,0,45:45
-62,1,45:45
-62,2,45:45
-62,0,46:109.1
-62,1,46:109.1
-62,2,46:109.1
-61,-2,5:98.3
-61,-1,5:98.3
-61,0,5:98.3
-61,1,5:98.3
-61,2,5:98.3
-61,3,5:98.3
-61,4,5:98.3
-61,-2,6:133
-61,-1,6:133
-61,0,6:133
-61,1,6:133
-61,2,6:133
-61,3,6:133
-61,4,6:133
-61,-6,7:98
-61,-5,7:98
-61,-4,7:98.3
-61,-3,7:98.3
-61,-2,7:171.7
-61,-1,7:171.7
-61,0,7:171.7
-61,1,7:171.7
-61,2,7:171.7
-61,3,7:171.7
-61,4,7:171.7
-61,5,7:98.3
-61,6,7:98.3
-61,7,7:98
-61,8,7:98
-61,-6,8:98
-61,-5,8:98
-61,-4,8:98.3
-61,6,8:98.3
-61,7,8:98
-61,8,8:98
-61,-6,9:98
-61,-5,9:98
-61,-4,9:98.3
-61,6,9:98.3
-61,7,9:98
-61,8,9:98
-61,-6,10:98
-61,-5,10:98
-61,-4,10:98.3
-61,6,10:98.3
-61,7,10:98
-61,8,10:98
-61,-6,11:98
-61,-5,11:98
-61,-4,11:98.3
-61,-3,11:98.3
-61,5,11:98.3
-61,6,11:98.3
-61,7,11:98
-61,8,11:98
-61,-6,12:98
-61,-5,12:98
-61,-4,12:98.3
-61,-3,12:98.3
-61,5,12:98.3
-61,6,12:98.3
-61,7,12:98
-61,8,12:98
-61,-6,13:98
-61,-5,13:98
-61,-4,13:98.3
-61,-3,13:98.3
-61,-2,13:98.3
-61,-1,13:98.3
-61,3,13:98.3
-61,4,13:98.3
-61,5,13:98.3
-61,6,13:98.3
-61,7,13:98
-61,8,13:98
-61,-6,14:98
-61,-5,14:98
-61,-4,14:98.3
-61,-3,14:98.3
-61,-2,14:98.3
-61,-1,14:98.3
-61,0,14:98.3
-61,1,14:98.3
-61,2,14:98.3
-61,3,14:98.3
-61,4,14:98.3
-61,5,14:98.3
-61,6,14:98.3
-61,7,14:98
-61,8,14:98
-61,-6,15:98
-61,-5,15:98
-61,-4,15:98
-61,-3,15:98
-61,-2,15:98
-61,-1,15:98
-61,0,15:98
-61,1,15:98
-61,2,15:98
-61,3,15:98
-61,4,15:98
-61,5,15:98
-61,6,15:98
-61,7,15:98
-61,8,15:98
-61,-6,16:98
-61,-5,16:98
-61,-4,16:98
-61,-3,16:98
-61,-2,16:98
-61,-1,16:98
-61,0,16:98
-61,1,16:98
-61,2,16:98
-61,3,16:98
-61,4,16:98
-61,5,16:98
-61,6,16:98
-61,7,16:98
-61,8,16:98
-61,-6,17:98
-61,-5,17:98
-61,-4,17:98
-61,-3,17:98
-61,-2,17:98
-61,-1,17:98
-61,0,17:98
-61,1,17:98
-61,2,17:98
-61,3,17:98
-61,4,17:98
-61,5,17:98
-61,6,17:98
-61,7,17:98
-61,8,17:98
-61,-6,18:98
-61,-5,18:98
-61,-4,18:98
-61,-3,18:98
-61,-2,18:98
-61,-1,18:98
-61,0,18:98
-61,1,18:98
-61,2,18:98
-61,3,18:98
-61,4,18:98
-61,5,18:98
-61,6,18:98
-61,7,18:98
-61,8,18:98
-61,-6,19:98
-61,-5,19:98
-61,-4,19:98
-61,-3,19:98
-61,-2,19:98
-61,-1,19:98
-61,0,19:98
-61,1,19:98
-61,2,19:98
-61,3,19:98
-61,4,19:98
-61,5,19:98
-61,6,19:98
-61,7,19:98
-61,8,19:98
-61,-6,20:98
-61,-5,20:98
-61,-4,20:98
-61,-3,20:98
-61,-2,20:98
-61,-1,20:98
-61,0,20:98
-61,1,20:98
-61,2,20:98
-61,3,20:98
-61,4,20:98
-61,5,20:98
-61,6,20:98
-61,7,20:98
-61,8,20:98
-61,-6,21:98
-61,-5,21:98
-61,-4,21:98
-61,-3,21:98
-61,-2,21:98
-61,-1,21:98
-61,0,21:98
-61,1,21:98
-61,2,21:98
-61,3,21:98
-61,4,21:98
-61,5,21:98
-61,6,21:98
-61,7,21:98
-61,8,21:98
-61,-16,22:5.1
-61,-15,22:5.1
-61,-14,22:5.1
-61,-13,22:5.1
-61,-12,22:5.1
-61,-11,22:5.1
-61,-10,22:5.1
-61,-9,22:5.1
-61,-8,22:5.1
-61,-7,22:5.1
-61,-6,22:5.1
-61,-5,22:5.1
-61,-4,22:5.1
-61,-3,22:5.1
-61,-2,22:5.1
-61,-1,22:5.2
-61,0,22:121
-61,1,22:5.2
-61,2,22:5.2
-61,3,22:121
-61,4,22:5.1
-61,5,22:5.1
-61,6,22:5.1
-61,7,22:5.1
-61,8,22:5.1
-61,9,22:5.1
-61,10,22:5.1
-61,11,22:5.1
-61,12,22:5.1
-61,13,22:5.1
-61,14,22:5.1
-61,15,22:5.1
-61,16,22:5.1
-61,17,22:5.1
-61,18,22:5.1
-61,-19,23:95.14
-61,-18,23:95.14
-61,-17,23:95.14
-61,-16,23:98.3
-61,-15,23:98.3
-61,-14,23:98.3
-61,-13,23:98.3
-61,-12,23:2
-61,-11,23:5.1
-61,-10,23:2
-61,-9,23:2
-61,-8,23:2
-61,-7,23:5.1
-61,-6,23:109.2
-61,-5,23:159.14
-61,-4,23:159.14
-61,-3,23:159.14
-61,-2,23:109.3
-61,-1,23:5.2
-61,0,23:5.2
-61,1,23:5.2
-61,2,23:5.2
-61,3,23:5.2
-61,4,23:109.2
-61,5,23:159.14
-61,6,23:159.14
-61,7,23:159.14
-61,8,23:109.3
-61,9,23:159.13
-61,10,23:2
-61,11,23:5.1
-61,12,23:2
-61,13,23:2
-61,14,23:2
-61,15,23:98.3
-61,16,23:98.3
-61,17,23:98.3
-61,18,23:98.3
-61,19,23:95.14
-61,20,23:95.14
-61,21,23:95.14
-61,-19,24:95.14
-61,-18,24:95.14
-61,-17,24:95.14
-61,-10,24:31.2
-61,-9,24:31.1
-61,-6,24:139
-61,-5,24:159.14
-61,-4,24:159.14
-61,-3,24:159.14
-61,-2,24:139
-61,4,24:139
-61,5,24:159.14
-61,6,24:159.14
-61,7,24:159.14
-61,8,24:139
-61,19,24:95.14
-61,20,24:95.14
-61,21,24:95.14
-61,-19,25:95.14
-61,-18,25:95.14
-61,-17,25:95.14
-61,-6,25:139
-61,-5,25:159.14
-61,-4,25:159.14
-61,-3,25:159.14
-61,-2,25:139
-61,4,25:139
-61,5,25:159.14
-61,6,25:159.14
-61,7,25:159.14
-61,8,25:139
-61,19,25:95.14
-61,20,25:95.14
-61,21,25:95.14
-61,-19,26:95.14
-61,-18,26:95.14
-61,-17,26:95.14
-61,-6,26:139
-61,-5,26:159.14
-61,-4,26:159.14
-61,-3,26:159.14
-61,-2,26:139
-61,4,26:139
-61,5,26:159.14
-61,6,26:159.14
-61,7,26:159.14
-61,8,26:139
-61,19,26:95.14
-61,20,26:95.14
-61,21,26:95.14
-61,-19,27:95.14
-61,-18,27:95.14
-61,-17,27:95.14
-61,-6,27:109.2
-61,-5,27:159.14
-61,-4,27:159.14
-61,-3,27:159.14
-61,-2,27:109.3
-61,4,27:109.2
-61,5,27:159.14
-61,6,27:159.14
-61,7,27:159.14
-61,8,27:109.3
-61,19,27:95.14
-61,20,27:95.14
-61,21,27:95.14
-61,-19,28:95.14
-61,-18,28:95.14
-61,-17,28:95.14
-61,-5,28:45
-61,-4,28:45
-61,-3,28:45
-61,5,28:45
-61,6,28:45
-61,7,28:45
-61,19,28:95.14
-61,20,28:95.14
-61,21,28:95.14
-61,-19,29:95.14
-61,-18,29:95.14
-61,-17,29:95.14
-61,-6,29:109.6
-61,-5,29:45
-61,-4,29:45
-61,-3,29:45
-61,-2,29:109.7
-61,4,29:109.6
-61,5,29:45
-61,6,29:45
-61,7,29:45
-61,8,29:109.7
-61,19,29:95.14
-61,20,29:95.14
-61,21,29:95.14
-61,-19,30:95.14
-61,-18,30:95.14
-61,-17,30:95.14
-61,-5,30:45
-61,-4,30:139
-61,-3,30:45
-61,5,30:45
-61,6,30:139
-61,7,30:45
-61,19,30:95.14
-61,20,30:95.14
-61,21,30:95.14
-61,-19,31:95.14
-61,-18,31:95.14
-61,-17,31:95.14
-61,-5,31:45
-61,-4,31:139
-61,-3,31:45
-61,5,31:45
-61,6,31:139
-61,7,31:45
-61,19,31:95.14
-61,20,31:95.14
-61,21,31:95.14
-61,-19,32:95.14
-61,-18,32:95.14
-61,-17,32:95.14
-61,-6,32:109.6
-61,-5,32:45
-61,-4,32:45
-61,-3,32:45
-61,-2,32:109.7
-61,4,32:109.6
-61,5,32:45
-61,6,32:45
-61,7,32:45
-61,8,32:109.7
-61,19,32:95.14
-61,20,32:95.14
-61,21,32:95.14
-61,-19,33:95.14
-61,-18,33:95.14
-61,-17,33:95.14
-61,-6,33:109.2
-61,-5,33:45
-61,-4,33:45
-61,-3,33:45
-61,-2,33:109.3
-61,4,33:109.2
-61,5,33:45
-61,6,33:45
-61,7,33:45
-61,8,33:109.3
-61,19,33:95.14
-61,20,33:95.14
-61,21,33:95.14
-61,-19,34:95.14
-61,-18,34:95.14
-61,-17,34:95.14
-61,-5,34:45
-61,-4,34:45
-61,-3,34:45
-61,5,34:45
-61,6,34:45
-61,7,34:45
-61,19,34:95.14
-61,20,34:95.14
-61,21,34:95.14
-61,-19,35:95.14
-61,-18,35:95.14
-61,-17,35:95.14
-61,-5,35:109.6
-61,-4,35:45
-61,-3,35:45
-61,5,35:45
-61,6,35:45
-61,19,35:95.14
-61,20,35:95.14
-61,21,35:95.14
-61,-19,36:95.14
-61,-18,36:95.14
-61,-17,36:95.14
-61,-5,36:109.2
-61,-4,36:45
-61,-3,36:45
-61,-2,36:45
-61,-1,36:45
-61,3,36:45
-61,4,36:45
-61,5,36:45
-61,6,36:45
-61,7,36:109.7
-61,19,36:95.14
-61,20,36:95.14
-61,21,36:95.14
-61,-19,37:95.14
-61,-18,37:95.14
-61,-17,37:95.14
-61,-4,37:45
-61,-3,37:45
-61,-2,37:45
-61,-1,37:45
-61,0,37:45
-61,1,37:45
-61,2,37:45
-61,3,37:45
-61,4,37:45
-61,5,37:45
-61,6,37:45
-61,7,37:109.3
-61,19,37:95.14
-61,20,37:95.14
-61,21,37:95.14
-61,-19,38:95.14
-61,-18,38:95.14
-61,-17,38:95.14
-61,-4,38:45
-61,-3,38:45
-61,-1,38:45
-61,0,38:45
-61,1,38:45
-61,2,38:45
-61,3,38:45
-61,5,38:45
-61,6,38:45
-61,19,38:95.14
-61,20,38:95.14
-61,21,38:95.14
-61,-19,39:5.1
-61,-18,39:5.1
-61,-17,39:5.1
-61,-16,39:5.1
-61,-15,39:5.1
-61,-14,39:5.1
-61,-13,39:5.1
-61,-12,39:109.7
-61,-5,39:109.6
-61,-4,39:45
-61,-3,39:45
-61,-2,39:98
-61,-1,39:109.3
-61,3,39:109.2
-61,4,39:98
-61,5,39:45
-61,6,39:45
-61,7,39:109.7
-61,14,39:109.6
-61,15,39:5.1
-61,16,39:5.1
-61,17,39:5.1
-61,18,39:5.1
-61,19,39:5.1
-61,20,39:5.1
-61,21,39:5.1
-61,-19,40:5.1
-61,-18,40:5.1
-61,-17,40:5.1
-61,-12,40:109.3
-61,-5,40:109.2
-61,-4,40:45
-61,-3,40:45
-61,-2,40:44.5
-61,4,40:44.5
-61,5,40:45
-61,6,40:45
-61,7,40:109.3
-61,14,40:109.2
-61,19,40:5.1
-61,20,40:5.1
-61,21,40:5.1
-61,-19,41:5.1
-61,-18,41:5.1
-61,-17,41:5.1
-61,-16,41:5.1
-61,-15,41:5.1
-61,-14,41:5.1
-61,-13,41:5.1
-61,-4,41:45
-61,-3,41:45
-61,5,41:45
-61,6,41:45
-61,15,41:5.1
-61,16,41:5.1
-61,17,41:5.1
-61,18,41:5.1
-61,19,41:5.1
-61,20,41:5.1
-61,21,41:5.1
-61,-19,42:5.1
-61,-18,42:5.1
-61,-17,42:5.1
-61,-16,42:5.1
-61,-15,42:5.1
-61,-14,42:5.1
-61,-13,42:5.1
-61,-10,42:109.5
-61,-9,42:109.5
-61,-8,42:109.5
-61,-5,42:109.6
-61,-4,42:45
-61,-3,42:45
-61,-2,42:45
-61,4,42:45
-61,5,42:45
-61,6,42:45
-61,7,42:109.7
-61,11,42:109.5
-61,12,42:109.5
-61,15,42:5.1
-61,16,42:5.1
-61,17,42:5.1
-61,18,42:5.1
-61,19,42:5.1
-61,20,42:5.1
-61,21,42:5.1
-61,-10,43:109.1
-61,-9,43:109.1
-61,-8,43:109.1
-61,-5,43:109.2
-61,-4,43:45
-61,-3,43:45
-61,-2,43:45
-61,4,43:45
-61,5,43:45
-61,6,43:45
-61,7,43:109.3
-61,11,43:109.1
-61,12,43:109.1
-61,-4,44:109.6
-61,-3,44:45
-61,-2,44:45
-61,-1,44:45
-61,0,44:45
-61,1,44:45
-61,2,44:45
-61,3,44:45
-61,4,44:45
-61,5,44:45
-61,6,44:109.7
-61,-4,45:109.2
-61,-3,45:109.3
-61,-1,45:45
-61,0,45:45
-61,1,45:45
-61,2,45:45
-61,3,45:45
-61,5,45:109.2
-61,6,45:109.3
-60,-6,5:1
-60,-5,5:1
-60,-4,5:1
-60,-3,5:1
-60,-2,5:1
-60,-1,5:1
-60,0,5:1
-60,1,5:1
-60,2,5:1
-60,3,5:1
-60,4,5:1
-60,5,5:1
-60,6,5:1
-60,7,5:1
-60,8,5:1
-60,-6,6:12
-60,-5,6:12
-60,-4,6:12
-60,-3,6:12
-60,-2,6:133
-60,-1,6:133
-60,0,6:133
-60,1,6:133
-60,2,6:133
-60,3,6:133
-60,4,6:133
-60,5,6:12
-60,6,6:12
-60,7,6:12
-60,8,6:12
-60,-12,7:98
-60,-11,7:98
-60,-10,7:98
-60,-9,7:98
-60,-8,7:98
-60,-7,7:98
-60,-4,7:98.3
-60,-3,7:98.3
-60,-2,7:171.7
-60,-1,7:171.7
-60,0,7:171.7
-60,1,7:171.7
-60,2,7:171.7
-60,3,7:171.7
-60,4,7:171.7
-60,5,7:98.3
-60,6,7:98.3
-60,9,7:98
-60,10,7:98
-60,11,7:98
-60,12,7:98
-60,13,7:98
-60,14,7:98
-60,-12,8:98
-60,-11,8:98
-60,-10,8:98
-60,-9,8:98
-60,-8,8:98
-60,-7,8:98
-60,-4,8:98.3
-60,-3,8:109.1
-60,5,8:109.1
-60,6,8:98.3
-60,9,8:98
-60,10,8:98
-60,11,8:98
-60,12,8:98
-60,13,8:98
-60,14,8:98
-60,-12,9:98
-60,-11,9:98
-60,-10,9:98
-60,-9,9:98
-60,-8,9:98
-60,-7,9:98
-60,-4,9:98.3
-60,-3,9:44.5
-60,5,9:44.5
-60,6,9:98.3
-60,9,9:98
-60,10,9:98
-60,11,9:98
-60,12,9:98
-60,13,9:98
-60,14,9:98
-60,-12,10:98
-60,-11,10:98
-60,-10,10:98
-60,-9,10:98
-60,-8,10:98
-60,-7,10:98
-60,-4,10:98.3
-60,-3,10:44.13
-60,5,10:44.13
-60,6,10:98.3
-60,9,10:98
-60,10,10:98
-60,11,10:98
-60,12,10:98
-60,13,10:98
-60,14,10:98
-60,-12,11:98
-60,-11,11:98
-60,-10,11:98
-60,-9,11:98
-60,-8,11:98
-60,-7,11:98
-60,-4,11:98.3
-60,-3,11:109.5
-60,5,11:109.5
-60,6,11:98.3
-60,9,11:98
-60,10,11:98
-60,11,11:98
-60,12,11:98
-60,13,11:98
-60,14,11:98
-60,-12,12:98
-60,-11,12:98
-60,-10,12:98
-60,-9,12:98
-60,-8,12:98
-60,-7,12:98
-60,-4,12:98.3
-60,-3,12:98.3
-60,5,12:98.3
-60,6,12:98.3
-60,8,12:17.8
-60,9,12:98
-60,10,12:98
-60,11,12:98
-60,12,12:98
-60,13,12:98
-60,14,12:98
-60,-12,13:98
-60,-11,13:98
-60,-10,13:98
-60,-9,13:98
-60,-8,13:98
-60,-7,13:98
-60,-4,13:98.3
-60,-3,13:98.3
-60,-2,13:5.1
-60,-1,13:5.1
-60,0,13:134.7
-60,1,13:126.9
-60,2,13:134.6
-60,3,13:5.1
-60,4,13:5.1
-60,5,13:98.3
-60,6,13:98.3
-60,9,13:98
-60,10,13:98
-60,11,13:98
-60,12,13:98
-60,13,13:98
-60,14,13:98
-60,-12,14:98
-60,-11,14:98
-60,-10,14:98
-60,-9,14:98
-60,-8,14:98
-60,-7,14:98
-60,-4,14:98.3
-60,-3,14:98.3
-60,-2,14:98.3
-60,-1,14:98.3
-60,0,14:98.3
-60,1,14:98.3
-60,2,14:98.3
-60,3,14:98.3
-60,4,14:98.3
-60,5,14:98.3
-60,6,14:98.3
-60,9,14:98
-60,10,14:98
-60,11,14:98
-60,12,14:98
-60,13,14:98
-60,14,14:98
-60,-12,15:98
-60,-11,15:98
-60,-10,15:98
-60,-9,15:98
-60,-8,15:98
-60,-7,15:98
-60,9,15:98
-60,10,15:98
-60,11,15:98
-60,12,15:98
-60,13,15:98
-60,14,15:98
-60,-12,16:98
-60,-11,16:98
-60,-10,16:98
-60,-9,16:98
-60,-8,16:98
-60,-7,16:98
-60,9,16:98
-60,10,16:98
-60,11,16:98
-60,12,16:98
-60,13,16:98
-60,14,16:98
-60,-12,17:98
-60,-11,17:98
-60,-10,17:98
-60,-9,17:98
-60,-8,17:98
-60,-7,17:98
-60,9,17:98
-60,10,17:98
-60,11,17:98
-60,12,17:98
-60,13,17:98
-60,14,17:98
-60,-12,18:98
-60,-11,18:98
-60,-10,18:98
-60,-9,18:98
-60,-8,18:98
-60,-7,18:98
-60,9,18:98
-60,10,18:98
-60,11,18:98
-60,12,18:98
-60,13,18:98
-60,14,18:98
-60,-12,19:98
-60,-11,19:98
-60,-10,19:98
-60,-9,19:98
-60,-8,19:98
-60,-7,19:98
-60,9,19:98
-60,10,19:98
-60,11,19:98
-60,12,19:98
-60,13,19:98
-60,14,19:98
-60,-12,20:98
-60,-11,20:98
-60,-10,20:98
-60,-9,20:98
-60,-8,20:98
-60,-7,20:98
-60,9,20:98
-60,10,20:98
-60,11,20:98
-60,12,20:98
-60,13,20:98
-60,14,20:98
-60,-12,21:98
-60,-11,21:98
-60,-10,21:98
-60,-9,21:98
-60,-8,21:98
-60,-7,21:98
-60,9,21:98
-60,10,21:98
-60,11,21:98
-60,12,21:98
-60,13,21:98
-60,14,21:98
-60,-19,22:5.1
-60,-18,22:5.1
-60,-17,22:5.1
-60,-16,22:5.1
-60,-15,22:5.1
-60,-14,22:5.1
-60,-13,22:5.1
-60,-12,22:5.1
-60,-11,22:5.1
-60,-10,22:5.1
-60,-9,22:5.1
-60,-8,22:5.1
-60,-7,22:5.1
-60,-6,22:5.1
-60,-5,22:5.1
-60,-4,22:5.1
-60,-3,22:5.1
-60,-2,22:5.1
-60,-1,22:5
-60,0,22:53.2
-60,1,22:5.2
-60,2,22:53.3
-60,3,22:5
-60,4,22:5.1
-60,5,22:5.1
-60,6,22:5.1
-60,7,22:5.1
-60,8,22:5.1
-60,9,22:5.1
-60,10,22:5.1
-60,11,22:5.1
-60,12,22:5.1
-60,13,22:5.1
-60,14,22:5.1
-60,15,22:5.1
-60,16,22:5.1
-60,17,22:5.1
-60,18,22:5.1
-60,19,22:5.1
-60,20,22:5.1
-60,21,22:5.1
-60,-22,23:95.14
-60,-21,23:95.14
-60,-20,23:95.14
-60,-19,23:98.3
-60,-18,23:98.3
-60,-17,23:98.3
-60,-16,23:2
-60,-15,23:2
-60,-14,23:2
-60,-13,23:2
-60,-12,23:2
-60,-11,23:2
-60,-10,23:2
-60,-9,23:2
-60,-8,23:2
-60,-7,23:2
-60,-6,23:109.1
-60,-5,23:109.1
-60,-3,23:109.1
-60,-2,23:98.3
-60,-1,23:126
-60,0,23:126
-60,1,23:5.2
-60,2,23:126
-60,3,23:126
-60,4,23:98.3
-60,5,23:109.1
-60,7,23:109.1
-60,8,23:109.3
-60,9,23:2
-60,10,23:2
-60,11,23:2
-60,12,23:2
-60,13,23:2
-60,14,23:2
-60,15,23:2
-60,16,23:2
-60,17,23:2
-60,18,23:2
-60,19,23:98.3
-60,20,23:98.3
-60,21,23:98.3
-60,22,23:95.14
-60,23,23:95.14
-60,24,23:95.14
-60,-22,24:95.14
-60,-21,24:95.14
-60,-20,24:95.14
-60,-15,24:31.1
-60,-14,24:31.1
-60,-13,24:175.5
-60,-11,24:31.1
-60,-9,24:18.5
-60,-8,24:18.4
-60,-7,24:31.1
-60,-6,24:139
-60,-5,24:139
-60,-3,24:139
-60,-2,24:98.3
-60,4,24:98.3
-60,5,24:139
-60,7,24:139
-60,8,24:139
-60,22,24:95.14
-60,23,24:95.14
-60,24,24:95.14
-60,-22,25:95.14
-60,-21,25:95.14
-60,-20,25:95.14
-60,-13,25:175.8
-60,-8,25:18.5
-60,-6,25:139
-60,-5,25:139
-60,-3,25:139
-60,-2,25:98.3
-60,4,25:98.3
-60,5,25:139
-60,7,25:139
-60,8,25:139
-60,22,25:95.14
-60,23,25:95.14
-60,24,25:95.14
-60,-22,26:95.14
-60,-21,26:95.14
-60,-20,26:95.14
-60,-6,26:139
-60,-5,26:139
-60,-3,26:139
-60,-2,26:98.3
-60,4,26:98.3
-60,5,26:139
-60,7,26:139
-60,8,26:139
-60,22,26:95.14
-60,23,26:95.14
-60,24,26:95.14
-60,-22,27:95.14
-60,-21,27:95.14
-60,-20,27:95.14
-60,-5,27:109.1
-60,-4,27:109.5
-60,-3,27:109.1
-60,-2,27:98.3
-60,4,27:98.3
-60,5,27:109.1
-60,6,27:109.5
-60,7,27:109.1
-60,22,27:95.14
-60,23,27:95.14
-60,24,27:95.14
-60,-22,28:95.14
-60,-21,28:95.14
-60,-20,28:95.14
-60,-2,28:98.3
-60,4,28:98.3
-60,22,28:95.14
-60,23,28:95.14
-60,24,28:95.14
-60,-22,29:95.14
-60,-21,29:95.14
-60,-20,29:95.14
-60,-6,29:109.6
-60,-5,29:109.5
-60,-3,29:109.5
-60,-2,29:98.3
-60,4,29:98.3
-60,5,29:109.5
-60,7,29:109.5
-60,8,29:109.7
-60,22,29:95.14
-60,23,29:95.14
-60,24,29:95.14
-60,-22,30:95.14
-60,-21,30:95.14
-60,-20,30:95.14
-60,-2,30:98.3
-60,4,30:98.3
-60,22,30:95.14
-60,23,30:95.14
-60,24,30:95.14
-60,-22,31:95.14
-60,-21,31:95.14
-60,-20,31:95.14
-60,-2,31:98.3
-60,4,31:98.3
-60,22,31:95.14
-60,23,31:95.14
-60,24,31:95.14
-60,-22,32:95.14
-60,-21,32:95.14
-60,-20,32:95.14
-60,-6,32:109.6
-60,-5,32:109.5
-60,-3,32:109.5
-60,-2,32:98.3
-60,4,32:98.3
-60,5,32:109.5
-60,7,32:109.5
-60,8,32:109.7
-60,22,32:95.14
-60,23,32:95.14
-60,24,32:95.14
-60,-22,33:95.14
-60,-21,33:95.14
-60,-20,33:95.14
-60,-6,33:109.2
-60,-5,33:109.1
-60,-3,33:109.1
-60,-2,33:98.3
-60,4,33:98.3
-60,5,33:109.1
-60,7,33:109.1
-60,8,33:109.3
-60,22,33:95.14
-60,23,33:95.14
-60,24,33:95.14
-60,-22,34:95.14
-60,-21,34:95.14
-60,-20,34:95.14
-60,-2,34:98.3
-60,4,34:98.3
-60,22,34:95.14
-60,23,34:95.14
-60,24,34:95.14
-60,-22,35:95.14
-60,-21,35:95.14
-60,-20,35:95.14
-60,-5,35:109.5
-60,-4,35:109.5
-60,-2,35:98.3
-60,4,35:98.3
-60,22,35:95.14
-60,23,35:95.14
-60,24,35:95.14
-60,-22,36:95.14
-60,-21,36:95.14
-60,-20,36:95.14
-60,-5,36:109.2
-60,-4,36:109.1
-60,-3,36:44.13
-60,-2,36:98.3
-60,-1,36:98.3
-60,3,36:98.3
-60,4,36:98.3
-60,5,36:44.13
-60,6,36:109.5
-60,7,36:109.5
-60,22,36:95.14
-60,23,36:95.14
-60,24,36:95.14
-60,-22,37:95.14
-60,-21,37:95.14
-60,-20,37:95.14
-60,-2,37:44.5
-60,-1,37:109.3
-60,0,37:98.3
-60,1,37:98.3
-60,2,37:98.3
-60,3,37:109.2
-60,4,37:44.5
-60,6,37:109.1
-60,7,37:109.3
-60,22,37:95.14
-60,23,37:95.14
-60,24,37:95.14
-60,-22,38:95.14
-60,-21,38:95.14
-60,-20,38:95.14
-60,-1,38:44.5
-60,0,38:98
-60,1,38:44.13
-60,2,38:98
-60,3,38:44.5
-60,22,38:95.14
-60,23,38:95.14
-60,24,38:95.14
-60,-22,39:5.1
-60,-21,39:5.1
-60,-20,39:5.1
-60,-19,39:5.1
-60,-18,39:5.1
-60,-17,39:5.1
-60,-13,39:109.5
-60,-12,39:109.5
-60,-5,39:109.6
-60,-4,39:109.5
-60,-3,39:44.13
-60,-2,39:44.13
-60,-1,39:109.2
-60,3,39:109.3
-60,4,39:44.13
-60,5,39:44.13
-60,6,39:109.5
-60,7,39:109.7
-60,14,39:109.5
-60,15,39:109.5
-60,19,39:5.1
-60,20,39:5.1
-60,21,39:5.1
-60,22,39:5.1
-60,23,39:5.1
-60,24,39:5.1
-60,-22,40:5.1
-60,-21,40:5.1
-60,-20,40:5.1
-60,-16,40:109.7
-60,-13,40:109.1
-60,-12,40:109.3
-60,-5,40:109.1
-60,-4,40:109.1
-60,6,40:109.1
-60,7,40:109.1
-60,14,40:109.1
-60,15,40:109.1
-60,18,40:109.6
-60,22,40:5.1
-60,23,40:5.1
-60,24,40:5.1
-60,-22,41:5.1
-60,-21,41:5.1
-60,-20,41:5.1
-60,-19,41:5.1
-60,-18,41:5.1
-60,-17,41:5.1
-60,-16,41:109.3
-60,18,41:109.2
-60,19,41:5.1
-60,20,41:5.1
-60,21,41:5.1
-60,22,41:5.1
-60,23,41:5.1
-60,24,41:5.1
-60,-22,42:5.1
-60,-21,42:5.1
-60,-20,42:5.1
-60,-19,42:5.1
-60,-18,42:5.1
-60,-17,42:5.1
-60,-5,42:109.6
-60,-4,42:109.5
-60,6,42:109.5
-60,7,42:109.7
-60,19,42:5.1
-60,20,42:5.1
-60,21,42:5.1
-60,22,42:5.1
-60,23,42:5.1
-60,24,42:5.1
-60,-5,43:109.2
-60,-4,43:109.1
-60,6,43:109.1
-60,7,43:109.1
-60,-4,44:109.6
-60,-3,44:45
-60,-2,44:45
-60,-1,44:45
-60,0,44:45
-60,2,44:45
-60,3,44:45
-60,4,44:45
-60,5,44:45
-60,6,44:109.7
-60,-4,45:109.2
-60,-3,45:109.3
-60,-1,45:45
-60,0,45:45
-60,1,45:45
-60,2,45:45
-60,3,45:45
-60,5,45:109.2
-60,6,45:109.3
-60,0,46:109
-60,1,46:98.3
-60,2,46:109
-59,-12,5:1
-59,-11,5:1
-59,-10,5:1
-59,-9,5:1
-59,-8,5:1
-59,-7,5:1
-59,-6,5:1
-59,-5,5:1
-59,-4,5:1
-59,-3,5:1
-59,-2,5:1
-59,-1,5:1
-59,0,5:1
-59,1,5:1
-59,2,5:1
-59,3,5:1
-59,4,5:1
-59,5,5:1
-59,6,5:1
-59,7,5:1
-59,8,5:1
-59,9,5:1
-59,10,5:1
-59,11,5:1
-59,12,5:1
-59,13,5:1
-59,14,5:1
-59,-12,6:12
-59,-11,6:12
-59,-10,6:12
-59,-9,6:12
-59,-8,6:12
-59,-7,6:12
-59,-6,6:12
-59,-5,6:12
-59,-4,6:12
-59,-3,6:12
-59,-2,6:133
-59,-1,6:133
-59,0,6:133
-59,1,6:133
-59,2,6:133
-59,3,6:133
-59,4,6:133
-59,5,6:12
-59,6,6:12
-59,7,6:12
-59,8,6:12
-59,9,6:12
-59,10,6:12
-59,11,6:12
-59,12,6:12
-59,13,6:12
-59,14,6:12
-59,-16,7:98
-59,-15,7:98
-59,-14,7:98
-59,-13,7:98
-59,-4,7:98.3
-59,-3,7:98.3
-59,-2,7:171.7
-59,-1,7:171.7
-59,0,7:171.7
-59,1,7:171.7
-59,2,7:171.7
-59,3,7:171.7
-59,4,7:171.7
-59,5,7:98.3
-59,6,7:98.3
-59,15,7:98
-59,16,7:98
-59,17,7:98
-59,18,7:98
-59,-16,8:98
-59,-15,8:98
-59,-14,8:98
-59,-13,8:98
-59,-5,8:98.3
-59,-4,8:98.3
-59,6,8:98.3
-59,7,8:98.3
-59,15,8:98
-59,16,8:98
-59,17,8:98
-59,18,8:98
-59,-16,9:98
-59,-15,9:98
-59,-14,9:98
-59,-13,9:98
-59,-5,9:98.3
-59,-4,9:44.13
-59,6,9:44.13
-59,7,9:98.3
-59,15,9:98
-59,16,9:98
-59,17,9:98
-59,18,9:98
-59,-16,10:98
-59,-15,10:98
-59,-14,10:98
-59,-13,10:98
-59,-5,10:98.3
-59,-4,10:44.5
-59,6,10:44.5
-59,7,10:98.3
-59,15,10:98
-59,16,10:98
-59,17,10:98
-59,18,10:98
-59,-16,11:98
-59,-15,11:98
-59,-14,11:98
-59,-13,11:98
-59,-4,11:98.3
-59,6,11:98.3
-59,15,11:98
-59,16,11:98
-59,17,11:98
-59,18,11:98
-59,-16,12:98
-59,-15,12:98
-59,-14,12:98
-59,-13,12:98
-59,-4,12:98.3
-59,-3,12:98.3
-59,5,12:98.3
-59,6,12:98.3
-59,15,12:98
-59,16,12:98
-59,17,12:98
-59,18,12:98
-59,-16,13:98
-59,-15,13:98
-59,-14,13:98
-59,-13,13:98
-59,-4,13:98.3
-59,-3,13:98.3
-59,-2,13:98.3
-59,-1,13:98.3
-59,3,13:98.3
-59,4,13:98.3
-59,5,13:98.3
-59,6,13:98.3
-59,15,13:98
-59,16,13:98
-59,17,13:98
-59,18,13:98
-59,-16,14:98
-59,-15,14:98
-59,-14,14:98
-59,-13,14:98
-59,-4,14:98.3
-59,-3,14:98.3
-59,-2,14:98.3
-59,-1,14:98.3
-59,0,14:98.3
-59,1,14:98.3
-59,2,14:98.3
-59,3,14:98.3
-59,4,14:98.3
-59,5,14:98.3
-59,6,14:98.3
-59,15,14:98
-59,16,14:98
-59,17,14:98
-59,18,14:98
-59,-16,15:98
-59,-15,15:98
-59,-14,15:98
-59,-13,15:98
-59,15,15:98
-59,16,15:98
-59,17,15:98
-59,18,15:98
-59,-16,16:98
-59,-15,16:98
-59,-14,16:98
-59,-13,16:98
-59,15,16:98
-59,16,16:98
-59,17,16:98
-59,18,16:98
-59,-16,17:98
-59,-15,17:98
-59,-14,17:98
-59,-13,17:98
-59,15,17:98
-59,16,17:98
-59,17,17:98
-59,18,17:98
-59,-16,18:98
-59,-15,18:98
-59,-14,18:98
-59,-13,18:98
-59,15,18:98
-59,16,18:98
-59,17,18:98
-59,18,18:98
-59,-16,19:98
-59,-15,19:98
-59,-14,19:98
-59,-13,19:98
-59,15,19:98
-59,16,19:98
-59,17,19:98
-59,18,19:98
-59,-16,20:98
-59,-15,20:98
-59,-14,20:98
-59,-13,20:98
-59,15,20:98
-59,16,20:98
-59,17,20:98
-59,18,20:98
-59,-16,21:98
-59,-15,21:98
-59,-14,21:98
-59,-13,21:98
-59,15,21:98
-59,16,21:98
-59,17,21:98
-59,18,21:98
-59,-22,22:5.1
-59,-21,22:5.1
-59,-20,22:5.1
-59,-19,22:5.1
-59,-18,22:5.1
-59,-17,22:5.1
-59,-16,22:5.1
-59,-15,22:5.1
-59,-14,22:5.1
-59,-13,22:5.1
-59,-12,22:5.1
-59,-11,22:5.1
-59,-10,22:5.1
-59,-9,22:5.1
-59,-8,22:5.1
-59,-7,22:5.1
-59,-6,22:5.1
-59,-5,22:5.1
-59,-4,22:5.1
-59,-3,22:5.1
-59,-2,22:5.1
-59,-1,22:5
-59,0,22:5.2
-59,1,22:5.2
-59,2,22:5.2
-59,3,22:159.1
-59,4,22:5.1
-59,5,22:5.1
-59,6,22:5.1
-59,7,22:5.1
-59,8,22:5.1
-59,9,22:5.1
-59,10,22:5.1
-59,11,22:5.1
-59,12,22:5.1
-59,13,22:5.1
-59,14,22:5.1
-59,15,22:5.1
-59,16,22:5.1
-59,17,22:5.1
-59,18,22:5.1
-59,19,22:5.1
-59,20,22:5.1
-59,21,22:5.1
-59,22,22:5.1
-59,23,22:5.1
-59,24,22:5.1
-59,-25,23:95.14
-59,-24,23:95.14
-59,-23,23:95.14
-59,-22,23:98.3
-59,-21,23:98.3
-59,-20,23:98.3
-59,-19,23:2
-59,-18,23:2
-59,-17,23:2
-59,-16,23:2
-59,-15,23:159.13
-59,-14,23:2
-59,-13,23:2
-59,-12,23:2
-59,-11,23:2
-59,-10,23:2
-59,-9,23:2
-59,-8,23:2
-59,-7,23:2
-59,-6,23:109.2
-59,-5,23:159.14
-59,-4,23:159.14
-59,-3,23:159.14
-59,-2,23:109.3
-59,-1,23:126
-59,0,23:5.2
-59,1,23:5.2
-59,2,23:5.2
-59,3,23:126
-59,4,23:109.2
-59,5,23:159.14
-59,6,23:159.14
-59,7,23:159.14
-59,8,23:109.3
-59,9,23:2
-59,10,23:2
-59,11,23:2
-59,12,23:159.13
-59,13,23:2
-59,14,23:2
-59,15,23:159.13
-59,16,23:2
-59,17,23:2
-59,18,23:2
-59,19,23:159.13
-59,20,23:2
-59,21,23:2
-59,22,23:98.3
-59,23,23:98.3
-59,24,23:98.3
-59,25,23:95.14
-59,26,23:95.14
-59,27,23:95.14
-59,-25,24:95.14
-59,-24,24:95.14
-59,-23,24:95.14
-59,-18,24:31.1
-59,-17,24:31.1
-59,-16,24:31.1
-59,-14,24:31.1
-59,-12,24:31.1
-59,-11,24:31.2
-59,-10,24:18.13
-59,-9,24:18.12
-59,-8,24:18.13
-59,-7,24:38.3
-59,-6,24:139
-59,-5,24:159.14
-59,-4,24:159.14
-59,-3,24:159.14
-59,-2,24:139
-59,4,24:139
-59,5,24:159.14
-59,6,24:159.14
-59,7,24:159.14
-59,8,24:139
-59,10,24:31.1
-59,11,24:18.13
-59,13,24:175.2
-59,16,24:31.1
-59,17,24:31.1
-59,18,24:31.1
-59,20,24:31.2
-59,25,24:95.14
-59,26,24:95.14
-59,27,24:95.14
-59,-25,25:95.14
-59,-24,25:95.14
-59,-23,25:95.14
-59,-9,25:18.12
-59,-6,25:139
-59,-5,25:159.14
-59,-4,25:159.14
-59,-3,25:159.14
-59,-2,25:139
-59,4,25:139
-59,5,25:159.14
-59,6,25:159.14
-59,7,25:159.14
-59,8,25:139
-59,13,25:175.8
-59,25,25:95.14
-59,26,25:95.14
-59,27,25:95.14
-59,-25,26:95.14
-59,-24,26:95.14
-59,-23,26:95.14
-59,-9,26:18.5
-59,-6,26:139
-59,-5,26:159.14
-59,-4,26:159.14
-59,-3,26:159.14
-59,-2,26:139
-59,4,26:139
-59,5,26:159.14
-59,6,26:159.14
-59,7,26:159.14
-59,8,26:139
-59,25,26:95.14
-59,26,26:95.14
-59,27,26:95.14
-59,-25,27:95.14
-59,-24,27:95.14
-59,-23,27:95.14
-59,-6,27:109.2
-59,-5,27:159.14
-59,-4,27:159.14
-59,-3,27:159.14
-59,-2,27:109.3
-59,4,27:109.2
-59,5,27:159.14
-59,6,27:159.14
-59,7,27:159.14
-59,8,27:109.3
-59,25,27:95.14
-59,26,27:95.14
-59,27,27:95.14
-59,-25,28:95.14
-59,-24,28:95.14
-59,-23,28:95.14
-59,-5,28:45
-59,-4,28:45
-59,-3,28:45
-59,5,28:45
-59,6,28:45
-59,7,28:45
-59,25,28:95.14
-59,26,28:95.14
-59,27,28:95.14
-59,-25,29:95.14
-59,-24,29:95.14
-59,-23,29:95.14
-59,-6,29:109.6
-59,-5,29:45
-59,-4,29:45
-59,-3,29:45
-59,-2,29:109.7
-59,4,29:109.6
-59,5,29:45
-59,6,29:45
-59,7,29:45
-59,8,29:109.7
-59,25,29:95.14
-59,26,29:95.14
-59,27,29:95.14
-59,-25,30:95.14
-59,-24,30:95.14
-59,-23,30:95.14
-59,-5,30:45
-59,-4,30:139
-59,-3,30:45
-59,5,30:45
-59,6,30:139
-59,7,30:45
-59,25,30:95.14
-59,26,30:95.14
-59,27,30:95.14
-59,-25,31:95.14
-59,-24,31:95.14
-59,-23,31:95.14
-59,-5,31:45
-59,-4,31:139
-59,-3,31:45
-59,5,31:45
-59,6,31:139
-59,7,31:45
-59,25,31:95.14
-59,26,31:95.14
-59,27,31:95.14
-59,-25,32:95.14
-59,-24,32:95.14
-59,-23,32:95.14
-59,-6,32:109.6
-59,-5,32:45
-59,-4,32:45
-59,-3,32:45
-59,-2,32:109.7
-59,4,32:109.6
-59,5,32:45
-59,6,32:45
-59,7,32:45
-59,8,32:109.7
-59,25,32:95.14
-59,26,32:95.14
-59,27,32:95.14
-59,-25,33:95.14
-59,-24,33:95.14
-59,-23,33:95.14
-59,-6,33:109.2
-59,-5,33:45
-59,-4,33:45
-59,-3,33:45
-59,-2,33:109.3
-59,4,33:109.2
-59,5,33:45
-59,6,33:45
-59,7,33:45
-59,8,33:109.3
-59,25,33:95.14
-59,26,33:95.14
-59,27,33:95.14
-59,-25,34:95.14
-59,-24,34:95.14
-59,-23,34:95.14
-59,-5,34:45
-59,-4,34:45
-59,-3,34:45
-59,5,34:45
-59,6,34:45
-59,7,34:45
-59,25,34:95.14
-59,26,34:95.14
-59,27,34:95.14
-59,-25,35:95.14
-59,-24,35:95.14
-59,-23,35:95.14
-59,-5,35:109.6
-59,-4,35:45
-59,-3,35:45
-59,5,35:45
-59,6,35:45
-59,25,35:95.14
-59,26,35:95.14
-59,27,35:95.14
-59,-25,36:95.14
-59,-24,36:95.14
-59,-23,36:95.14
-59,-5,36:109.2
-59,-4,36:45
-59,-3,36:45
-59,-2,36:45
-59,-1,36:45
-59,3,36:45
-59,4,36:45
-59,5,36:45
-59,6,36:45
-59,7,36:109.7
-59,25,36:95.14
-59,26,36:95.14
-59,27,36:95.14
-59,-25,37:95.14
-59,-24,37:95.14
-59,-23,37:95.14
-59,-4,37:45
-59,-3,37:45
-59,-2,37:45
-59,-1,37:45
-59,0,37:45
-59,1,37:45
-59,2,37:45
-59,3,37:45
-59,4,37:45
-59,5,37:45
-59,6,37:45
-59,7,37:109.3
-59,25,37:95.14
-59,26,37:95.14
-59,27,37:95.14
-59,-25,38:95.14
-59,-24,38:95.14
-59,-23,38:95.14
-59,-4,38:45
-59,-3,38:45
-59,-1,38:45
-59,0,38:45
-59,1,38:45
-59,2,38:45
-59,3,38:45
-59,5,38:45
-59,6,38:45
-59,25,38:95.14
-59,26,38:95.14
-59,27,38:95.14
-59,-25,39:5.1
-59,-24,39:5.1
-59,-23,39:5.1
-59,-22,39:5.1
-59,-21,39:5.1
-59,-20,39:5.1
-59,-5,39:109.6
-59,-4,39:45
-59,-3,39:45
-59,-2,39:98
-59,-1,39:109.3
-59,3,39:109.2
-59,4,39:98
-59,5,39:45
-59,6,39:45
-59,7,39:109.7
-59,22,39:5.1
-59,23,39:5.1
-59,24,39:5.1
-59,25,39:5.1
-59,26,39:5.1
-59,27,39:5.1
-59,-25,40:5.1
-59,-24,40:5.1
-59,-23,40:5.1
-59,-17,40:109.5
-59,-16,40:109.5
-59,-5,40:109.2
-59,-4,40:45
-59,-3,40:45
-59,-2,40:44.5
-59,4,40:44.5
-59,5,40:45
-59,6,40:45
-59,7,40:109.3
-59,18,40:109.5
-59,19,40:109.5
-59,25,40:5.1
-59,26,40:5.1
-59,27,40:5.1
-59,-25,41:5.1
-59,-24,41:5.1
-59,-23,41:5.1
-59,-22,41:5.1
-59,-21,41:5.1
-59,-20,41:5.1
-59,-17,41:109.1
-59,-16,41:109.1
-59,-4,41:45
-59,-3,41:45
-59,5,41:45
-59,6,41:45
-59,18,41:109.1
-59,19,41:109.1
-59,22,41:5.1
-59,23,41:5.1
-59,24,41:5.1
-59,25,41:5.1
-59,26,41:5.1
-59,27,41:5.1
-59,-25,42:5.1
-59,-24,42:5.1
-59,-23,42:5.1
-59,-22,42:5.1
-59,-21,42:5.1
-59,-20,42:5.1
-59,-4,42:45
-59,-3,42:45
-59,-2,42:45
-59,4,42:45
-59,5,42:45
-59,6,42:45
-59,22,42:5.1
-59,23,42:5.1
-59,24,42:5.1
-59,25,42:5.1
-59,26,42:5.1
-59,27,42:5.1
-59,-4,43:45
-59,-3,43:45
-59,-2,43:45
-59,4,43:45
-59,5,43:45
-59,6,43:45
-59,-4,44:109.6
-59,-3,44:45
-59,-2,44:45
-59,-1,44:45
-59,0,44:45
-59,2,44:45
-59,3,44:45
-59,4,44:45
-59,5,44:45
-59,6,44:109.7
-59,-4,45:109.2
-59,-3,45:109.3
-59,-1,45:45
-59,0,45:45
-59,1,45:45
-59,2,45:45
-59,3,45:45
-59,5,45:109.2
-59,6,45:109.3
-59,0,46:109.1
-59,1,46:98.3
-59,2,46:109.1
-58,-16,5:1
-58,-15,5:1
-58,-14,5:1
-58,-13,5:1
-58,-12,5:1
-58,-11,5:1
-58,-10,5:1
-58,-9,5:1
-58,-8,5:1
-58,-7,5:1
-58,-6,5:1
-58,-5,5:1
-58,-4,5:1
-58,-3,5:1
-58,-2,5:1
-58,-1,5:1
-58,0,5:1
-58,1,5:1
-58,2,5:1
-58,3,5:1
-58,4,5:1
-58,5,5:1
-58,6,5:1
-58,7,5:1
-58,8,5:1
-58,9,5:1
-58,10,5:1
-58,11,5:1
-58,12,5:1
-58,13,5:1
-58,14,5:1
-58,15,5:1
-58,16,5:1
-58,17,5:1
-58,18,5:1
-58,-16,6:12
-58,-15,6:12
-58,-14,6:12
-58,-13,6:12
-58,-12,6:12
-58,-11,6:12
-58,-10,6:12
-58,-9,6:12
-58,-8,6:12
-58,-7,6:12
-58,-6,6:12
-58,-5,6:12
-58,-4,6:12
-58,-3,6:12
-58,-2,6:12
-58,-1,6:13
-58,0,6:13
-58,1,6:13
-58,2,6:13
-58,3,6:13
-58,4,6:12
-58,5,6:12
-58,6,6:12
-58,7,6:12
-58,8,6:12
-58,9,6:12
-58,10,6:12
-58,11,6:12
-58,12,6:12
-58,13,6:12
-58,14,6:12
-58,15,6:12
-58,16,6:12
-58,17,6:12
-58,18,6:12
-58,-19,7:98
-58,-18,7:98
-58,-17,7:98
-58,-4,7:98.3
-58,-3,7:44.5
-58,5,7:44.5
-58,6,7:98.3
-58,19,7:98
-58,20,7:98
-58,21,7:98
-58,-19,8:98
-58,-18,8:98
-58,-17,8:98
-58,-5,8:98.3
-58,-4,8:44.5
-58,6,8:44.5
-58,7,8:98.3
-58,19,8:98
-58,20,8:98
-58,21,8:98
-58,-19,9:98
-58,-18,9:98
-58,-17,9:98
-58,-6,9:5.1
-58,-5,9:44.5
-58,7,9:44.5
-58,8,9:5.1
-58,19,9:98
-58,20,9:98
-58,21,9:98
-58,-19,10:98
-58,-18,10:98
-58,-17,10:98
-58,-6,10:5.1
-58,-5,10:44.13
-58,7,10:44.13
-58,8,10:5.1
-58,19,10:98
-58,20,10:98
-58,21,10:98
-58,-19,11:98
-58,-18,11:98
-58,-17,11:98
-58,-5,11:98.3
-58,-4,11:44.13
-58,6,11:44.13
-58,7,11:98.3
-58,19,11:98
-58,20,11:98
-58,21,11:98
-58,-19,12:98
-58,-18,12:98
-58,-17,12:98
-58,-4,12:98.3
-58,-3,12:44.13
-58,5,12:44.13
-58,6,12:98.3
-58,19,12:98
-58,20,12:98
-58,21,12:98
-58,-19,13:98
-58,-18,13:98
-58,-17,13:98
-58,-4,13:98.3
-58,-3,13:98.3
-58,-2,13:98.3
-58,-1,13:98.3
-58,3,13:98.3
-58,4,13:98.3
-58,5,13:98.3
-58,6,13:98.3
-58,19,13:98
-58,20,13:98
-58,21,13:98
-58,-19,14:98
-58,-18,14:98
-58,-17,14:98
-58,-4,14:98.3
-58,-3,14:98.3
-58,-2,14:98.3
-58,-1,14:98.3
-58,0,14:98.3
-58,1,14:98.3
-58,2,14:98.3
-58,3,14:98.3
-58,4,14:98.3
-58,5,14:98.3
-58,6,14:98.3
-58,19,14:98
-58,20,14:98
-58,21,14:98
-58,-19,15:98
-58,-18,15:98
-58,-17,15:98
-58,19,15:98
-58,20,15:98
-58,21,15:98
-58,-19,16:98
-58,-18,16:98
-58,-17,16:98
-58,19,16:98
-58,20,16:98
-58,21,16:98
-58,-19,17:98
-58,-18,17:98
-58,-17,17:98
-58,19,17:98
-58,20,17:98
-58,21,17:98
-58,-19,18:98
-58,-18,18:98
-58,-17,18:98
-58,19,18:98
-58,20,18:98
-58,21,18:98
-58,-19,19:98
-58,-18,19:98
-58,-17,19:98
-58,19,19:98
-58,20,19:98
-58,21,19:98
-58,-19,20:98
-58,-18,20:98
-58,-17,20:98
-58,19,20:98
-58,20,20:98
-58,21,20:98
-58,-19,21:98
-58,-18,21:98
-58,-17,21:98
-58,19,21:98
-58,20,21:98
-58,21,21:98
-58,-25,22:5.1
-58,-24,22:5.1
-58,-23,22:5.1
-58,-22,22:5.1
-58,-21,22:5.1
-58,-20,22:5.1
-58,-19,22:5.1
-58,-18,22:5.1
-58,-17,22:5.1
-58,-16,22:5.1
-58,-15,22:5.1
-58,-14,22:5.1
-58,-13,22:5.1
-58,-12,22:5.1
-58,-11,22:5.1
-58,-10,22:5.1
-58,-9,22:5.1
-58,-8,22:5.1
-58,-7,22:5.1
-58,-6,22:5.1
-58,-5,22:5.1
-58,-4,22:5.1
-58,-3,22:5.1
-58,-2,22:5
-58,-1,22:5
-58,0,22:5
-58,1,22:24
-58,2,22:159.1
-58,3,22:5
-58,4,22:5
-58,5,22:5.1
-58,6,22:5.1
-58,7,22:5.1
-58,8,22:5.1
-58,9,22:5.1
-58,10,22:5.1
-58,11,22:5.1
-58,12,22:5.1
-58,13,22:5.1
-58,14,22:5.1
-58,15,22:5.1
-58,16,22:5.1
-58,17,22:5.1
-58,18,22:5.1
-58,19,22:5.1
-58,20,22:5.1
-58,21,22:5.1
-58,22,22:5.1
-58,23,22:5.1
-58,24,22:5.1
-58,25,22:5.1
-58,26,22:5.1
-58,27,22:5.1
-58,-27,23:95.14
-58,-26,23:95.14
-58,-25,23:98.3
-58,-24,23:98.3
-58,-23,23:98.3
-58,-22,23:2
-58,-21,23:2
-58,-20,23:2
-58,-19,23:2
-58,-18,23:5.1
-58,-17,23:2
-58,-16,23:2
-58,-15,23:2
-58,-14,23:2
-58,-13,23:2
-58,-12,23:5.1
-58,-11,23:2
-58,-10,23:2
-58,-9,23:2
-58,-8,23:2
-58,-7,23:2
-58,-6,23:2
-58,-5,23:159.14
-58,-4,23:159.14
-58,-3,23:159.14
-58,0,23:126
-58,1,23:5.2
-58,2,23:126
-58,5,23:159.14
-58,6,23:159.14
-58,7,23:159.14
-58,8,23:2
-58,9,23:2
-58,10,23:2
-58,11,23:2
-58,12,23:2
-58,13,23:159.13
-58,14,23:2
-58,15,23:2
-58,16,23:2
-58,17,23:2
-58,18,23:2
-58,19,23:2
-58,20,23:2
-58,21,23:2
-58,22,23:5.1
-58,23,23:2
-58,24,23:2
-58,25,23:98.3
-58,26,23:98.3
-58,27,23:98.3
-58,28,23:95.14
-58,29,23:95.14
-58,-27,24:95.14
-58,-26,24:95.14
-58,-20,24:31.1
-58,-19,24:31.1
-58,-17,24:18.4
-58,-16,24:18.13
-58,-15,24:18.4
-58,-14,24:31.1
-58,-13,24:31.1
-58,-11,24:31.1
-58,-10,24:31.1
-58,-9,24:18.12
-58,-8,24:31.2
-58,-7,24:38.3
-58,-6,24:31.1
-58,-5,24:159.14
-58,-4,24:159.14
-58,-3,24:159.14
-58,5,24:159.14
-58,6,24:159.14
-58,7,24:159.14
-58,9,24:18.12
-58,10,24:18.12
-58,11,24:18.12
-58,12,24:31.1
-58,14,24:31.1
-58,15,24:31.1
-58,16,24:18.12
-58,17,24:18.12
-58,18,24:18.12
-58,19,24:31.1
-58,23,24:31.1
-58,28,24:95.14
-58,29,24:95.14
-58,-27,25:95.14
-58,-26,25:95.14
-58,-16,25:18.4
-58,-5,25:159.14
-58,-4,25:159.14
-58,-3,25:159.14
-58,5,25:159.14
-58,6,25:159.14
-58,7,25:159.14
-58,10,25:18.13
-58,17,25:18.13
-58,28,25:95.14
-58,29,25:95.14
-58,-27,26:95.14
-58,-26,26:95.14
-58,-5,26:159.14
-58,-4,26:159.14
-58,-3,26:159.14
-58,5,26:159.14
-58,6,26:159.14
-58,7,26:159.14
-58,28,26:95.14
-58,29,26:95.14
-58,-27,27:95.14
-58,-26,27:95.14
-58,-6,27:109.6
-58,-5,27:159.14
-58,-4,27:159.14
-58,-3,27:159.14
-58,-2,27:109.7
-58,4,27:109.6
-58,5,27:159.14
-58,6,27:159.14
-58,7,27:159.14
-58,8,27:109.7
-58,28,27:95.14
-58,29,27:95.14
-58,-27,28:95.14
-58,-26,28:95.14
-58,-5,28:45
-58,-4,28:45
-58,-3,28:45
-58,5,28:45
-58,6,28:45
-58,7,28:45
-58,28,28:95.14
-58,29,28:95.14
-58,-27,29:95.14
-58,-26,29:95.14
-58,-5,29:45
-58,-4,29:45
-58,-3,29:45
-58,5,29:45
-58,6,29:45
-58,7,29:45
-58,28,29:95.14
-58,29,29:95.14
-58,-27,30:95.14
-58,-26,30:95.14
-58,-5,30:139
-58,-4,30:45
-58,-3,30:139
-58,5,30:139
-58,6,30:45
-58,7,30:139
-58,28,30:95.14
-58,29,30:95.14
-58,-27,31:95.14
-58,-26,31:95.14
-58,-5,31:139
-58,-4,31:45
-58,-3,31:139
-58,5,31:139
-58,6,31:45
-58,7,31:139
-58,28,31:95.14
-58,29,31:95.14
-58,-27,32:95.14
-58,-26,32:95.14
-58,-5,32:45
-58,-4,32:45
-58,-3,32:45
-58,5,32:45
-58,6,32:45
-58,7,32:45
-58,28,32:95.14
-58,29,32:95.14
-58,-27,33:95.14
-58,-26,33:95.14
-58,-5,33:45
-58,-4,33:45
-58,-3,33:45
-58,5,33:45
-58,6,33:45
-58,7,33:45
-58,28,33:95.14
-58,29,33:95.14
-58,-27,34:95.14
-58,-26,34:95.14
-58,-5,34:45
-58,-4,34:45
-58,-3,34:45
-58,5,34:45
-58,6,34:45
-58,7,34:45
-58,28,34:95.14
-58,29,34:95.14
-58,-27,35:95.14
-58,-26,35:95.14
-58,-4,35:45
-58,-3,35:45
-58,-2,35:45
-58,4,35:45
-58,5,35:45
-58,6,35:45
-58,28,35:95.14
-58,29,35:95.14
-58,-27,36:95.14
-58,-26,36:95.14
-58,-4,36:45
-58,-3,36:45
-58,-2,36:45
-58,-1,36:45
-58,0,36:45
-58,2,36:45
-58,3,36:45
-58,4,36:45
-58,5,36:45
-58,6,36:45
-58,28,36:95.14
-58,29,36:95.14
-58,-27,37:95.14
-58,-26,37:95.14
-58,-4,37:45
-58,-3,37:45
-58,-2,37:45
-58,-1,37:45
-58,0,37:45
-58,1,37:45
-58,2,37:45
-58,3,37:45
-58,4,37:45
-58,5,37:45
-58,6,37:45
-58,28,37:95.14
-58,29,37:95.14
-58,-27,38:95.14
-58,-26,38:95.14
-58,-4,38:45
-58,-3,38:45
-58,-1,38:45
-58,0,38:45
-58,1,38:45
-58,2,38:45
-58,3,38:45
-58,5,38:45
-58,6,38:45
-58,28,38:95.14
-58,29,38:95.14
-58,-27,39:5.1
-58,-26,39:5.1
-58,-25,39:5.1
-58,-24,39:5.1
-58,-23,39:5.1
-58,-4,39:45
-58,-3,39:45
-58,-2,39:44.13
-58,4,39:44.13
-58,5,39:45
-58,6,39:45
-58,25,39:5.1
-58,26,39:5.1
-58,27,39:5.1
-58,28,39:5.1
-58,29,39:5.1
-58,-27,40:5.1
-58,-26,40:5.1
-58,-4,40:45
-58,-3,40:45
-58,5,40:45
-58,6,40:45
-58,28,40:5.1
-58,29,40:5.1
-58,-27,41:5.1
-58,-26,41:5.1
-58,-25,41:5.1
-58,-24,41:5.1
-58,-23,41:5.1
-58,-22,41:109.7
-58,-4,41:45
-58,-3,41:45
-58,5,41:45
-58,6,41:45
-58,24,41:109.6
-58,25,41:5.1
-58,26,41:5.1
-58,27,41:5.1
-58,28,41:5.1
-58,29,41:5.1
-58,-27,42:5.1
-58,-26,42:5.1
-58,-25,42:5.1
-58,-24,42:5.1
-58,-23,42:5.1
-58,-22,42:109.3
-58,-4,42:45
-58,-3,42:45
-58,-2,42:45
-58,4,42:45
-58,5,42:45
-58,6,42:45
-58,24,42:109.2
-58,25,42:5.1
-58,26,42:5.1
-58,27,42:5.1
-58,28,42:5.1
-58,29,42:5.1
-58,-4,43:45
-58,-3,43:45
-58,-2,43:45
-58,4,43:45
-58,5,43:45
-58,6,43:45
-58,-3,44:45
-58,-2,44:45
-58,-1,44:45
-58,0,44:45
-58,2,44:45
-58,3,44:45
-58,4,44:45
-58,5,44:45
-58,-1,45:45
-58,0,45:45
-58,1,45:45
-58,2,45:45
-58,3,45:45
-57,-19,5:1
-57,-18,5:1
-57,-17,5:1
-57,-16,5:1
-57,-15,5:1
-57,-14,5:1
-57,-13,5:1
-57,-12,5:1
-57,-11,5:1
-57,-10,5:1
-57,-9,5:1
-57,-8,5:1
-57,-7,5:1
-57,-6,5:1
-57,-5,5:1
-57,-4,5:1
-57,-3,5:1
-57,-2,5:1
-57,-1,5:1
-57,0,5:1
-57,1,5:1
-57,2,5:1
-57,3,5:1
-57,4,5:1
-57,5,5:1
-57,6,5:1
-57,7,5:1
-57,8,5:1
-57,9,5:1
-57,10,5:1
-57,11,5:1
-57,12,5:1
-57,13,5:1
-57,14,5:1
-57,15,5:1
-57,16,5:1
-57,17,5:1
-57,18,5:1
-57,19,5:1
-57,20,5:1
-57,21,5:1
-57,-19,6:12
-57,-18,6:12
-57,-17,6:12
-57,-16,6:12
-57,-15,6:12
-57,-14,6:12
-57,-13,6:12
-57,-12,6:12
-57,-11,6:12
-57,-10,6:12
-57,-9,6:12
-57,-8,6:12
-57,-7,6:12
-57,-6,6:12
-57,-5,6:12
-57,-4,6:12
-57,-3,6:12
-57,-2,6:12
-57,-1,6:12
-57,0,6:13
-57,1,6:13
-57,2,6:13
-57,3,6:12
-57,4,6:12
-57,5,6:12
-57,6,6:12
-57,7,6:12
-57,8,6:12
-57,9,6:12
-57,10,6:12
-57,11,6:12
-57,12,6:12
-57,13,6:12
-57,14,6:12
-57,15,6:12
-57,16,6:12
-57,17,6:12
-57,18,6:12
-57,19,6:12
-57,20,6:12
-57,21,6:12
-57,-22,7:98
-57,-21,7:98
-57,-20,7:98
-57,-5,7:98.3
-57,-4,7:98.3
-57,-3,7:44.5
-57,5,7:44.5
-57,6,7:98.3
-57,7,7:98.3
-57,22,7:98
-57,23,7:98
-57,24,7:98
-57,-22,8:98
-57,-21,8:98
-57,-20,8:98
-57,-5,8:98.3
-57,7,8:98.3
-57,22,8:98
-57,23,8:98
-57,24,8:98
-57,-22,9:98
-57,-21,9:98
-57,-20,9:98
-57,-6,9:5.1
-57,8,9:5.1
-57,22,9:98
-57,23,9:98
-57,24,9:98
-57,-22,10:98
-57,-21,10:98
-57,-20,10:98
-57,-6,10:5.1
-57,8,10:5.1
-57,22,10:98
-57,23,10:98
-57,24,10:98
-57,-22,11:98
-57,-21,11:98
-57,-20,11:98
-57,-5,11:98.3
-57,7,11:98.3
-57,22,11:98
-57,23,11:98
-57,24,11:98
-57,-22,12:98
-57,-21,12:98
-57,-20,12:98
-57,-4,12:98.3
-57,-3,12:44.13
-57,5,12:44.13
-57,6,12:98.3
-57,22,12:98
-57,23,12:98
-57,24,12:98
-57,-22,13:98
-57,-21,13:98
-57,-20,13:98
-57,-4,13:98.3
-57,-3,13:98.3
-57,-2,13:98.3
-57,-1,13:98.3
-57,3,13:98.3
-57,4,13:98.3
-57,5,13:98.3
-57,6,13:98.3
-57,22,13:98
-57,23,13:98
-57,24,13:98
-57,-22,14:98
-57,-21,14:98
-57,-20,14:98
-57,-4,14:98.3
-57,-3,14:98.3
-57,-2,14:98.3
-57,-1,14:98.3
-57,0,14:98.3
-57,1,14:98.3
-57,2,14:98.3
-57,3,14:98.3
-57,4,14:98.3
-57,5,14:98.3
-57,6,14:98.3
-57,22,14:98
-57,23,14:98
-57,24,14:98
-57,-22,15:98
-57,-21,15:98
-57,-20,15:98
-57,22,15:98
-57,23,15:98
-57,24,15:98
-57,-22,16:98
-57,-21,16:98
-57,-20,16:98
-57,22,16:98
-57,23,16:98
-57,24,16:98
-57,-22,17:98
-57,-21,17:98
-57,-20,17:98
-57,22,17:98
-57,23,17:98
-57,24,17:98
-57,-22,18:98
-57,-21,18:98
-57,-20,18:98
-57,22,18:98
-57,23,18:98
-57,24,18:98
-57,-22,19:98
-57,-21,19:98
-57,-20,19:98
-57,22,19:98
-57,23,19:98
-57,24,19:98
-57,-22,20:98
-57,-21,20:98
-57,-20,20:98
-57,22,20:98
-57,23,20:98
-57,24,20:98
-57,-22,21:98
-57,-21,21:98
-57,-20,21:98
-57,22,21:98
-57,23,21:98
-57,24,21:98
-57,-27,22:5.1
-57,-26,22:5.1
-57,-25,22:5.1
-57,-24,22:5.1
-57,-23,22:5.1
-57,-22,22:5.1
-57,-21,22:5.1
-57,-20,22:5.1
-57,-19,22:5.1
-57,-18,22:5.1
-57,-17,22:5.1
-57,-16,22:5.1
-57,-15,22:5.1
-57,-14,22:5.1
-57,-13,22:5.1
-57,-12,22:5.1
-57,-11,22:5.1
-57,-10,22:5.1
-57,-9,22:5.1
-57,-8,22:5.1
-57,-7,22:5.1
-57,-6,22:5.1
-57,-5,22:5.1
-57,-4,22:5.1
-57,-3,22:5.1
-57,-2,22:5.1
-57,-1,22:53.2
-57,0,22:5
-57,1,22:5.2
-57,2,22:5
-57,3,22:53.7
-57,4,22:5.1
-57,5,22:5.1
-57,6,22:5.1
-57,7,22:5.1
-57,8,22:5.1
-57,9,22:5.1
-57,10,22:5.1
-57,11,22:5.1
-57,12,22:5.1
-57,13,22:5.1
-57,14,22:5.1
-57,15,22:5.1
-57,16,22:5.1
-57,17,22:5.1
-57,18,22:5.1
-57,19,22:5.1
-57,20,22:5.1
-57,21,22:5.1
-57,22,22:5.1
-57,23,22:5.1
-57,24,22:5.1
-57,25,22:5.1
-57,26,22:5.1
-57,27,22:5.1
-57,28,22:5.1
-57,29,22:5.1
-57,-29,23:95.14
-57,-28,23:95.14
-57,-27,23:98.3
-57,-26,23:98.3
-57,-25,23:98.3
-57,-24,23:2
-57,-23,23:2
-57,-22,23:2
-57,-21,23:2
-57,-20,23:159.13
-57,-19,23:2
-57,-18,23:2
-57,-17,23:2
-57,-16,23:2
-57,-15,23:2
-57,-14,23:2
-57,-13,23:2
-57,-12,23:2
-57,-11,23:2
-57,-10,23:159.13
-57,-9,23:2
-57,-8,23:2
-57,-7,23:159.13
-57,-6,23:109.2
-57,-5,23:159.14
-57,-4,23:159.14
-57,-3,23:159.14
-57,-2,23:109.3
-57,0,23:126
-57,1,23:5.2
-57,2,23:126
-57,4,23:109.2
-57,5,23:159.14
-57,6,23:159.14
-57,7,23:159.14
-57,8,23:109.3
-57,9,23:5.1
-57,10,23:2
-57,11,23:2
-57,12,23:2
-57,13,23:2
-57,14,23:2
-57,15,23:2
-57,16,23:2
-57,17,23:2
-57,18,23:2
-57,19,23:2
-57,20,23:159.13
-57,21,23:2
-57,22,23:2
-57,23,23:2
-57,24,23:2
-57,25,23:2
-57,26,23:2
-57,27,23:98.3
-57,28,23:98.3
-57,29,23:98.3
-57,30,23:95.14
-57,31,23:95.14
-57,-29,24:95.14
-57,-28,24:95.14
-57,-24,24:31.1
-57,-23,24:31.1
-57,-21,24:18.12
-57,-19,24:31.1
-57,-18,24:38.8
-57,-17,24:18.13
-57,-16,24:18.13
-57,-15,24:18.4
-57,-14,24:31.1
-57,-13,24:31.2
-57,-12,24:31.1
-57,-11,24:175.4
-57,-9,24:31.1
-57,-8,24:31.1
-57,-6,24:139
-57,-5,24:159.14
-57,-4,24:159.14
-57,-3,24:159.14
-57,-2,24:139
-57,4,24:139
-57,5,24:159.14
-57,6,24:159.14
-57,7,24:159.14
-57,8,24:139
-57,10,24:18.4
-57,13,24:31.1
-57,14,24:31.2
-57,15,24:38.3
-57,16,24:18.13
-57,17,24:18.12
-57,18,24:31.1
-57,21,24:31.1
-57,22,24:38.8
-57,23,24:31.2
-57,24,24:31.1
-57,26,24:38.3
-57,30,24:95.14
-57,31,24:95.14
-57,-29,25:95.14
-57,-28,25:95.14
-57,-21,25:18.5
-57,-16,25:18.13
-57,-11,25:175.9
-57,-6,25:139
-57,-5,25:159.14
-57,-4,25:159.14
-57,-3,25:159.14
-57,-2,25:139
-57,4,25:139
-57,5,25:159.14
-57,6,25:159.14
-57,7,25:159.14
-57,8,25:139
-57,30,25:95.14
-57,31,25:95.14
-57,-29,26:95.14
-57,-28,26:95.14
-57,-16,26:18.4
-57,-6,26:139
-57,-5,26:159.14
-57,-4,26:159.14
-57,-3,26:159.14
-57,-2,26:139
-57,4,26:139
-57,5,26:159.14
-57,6,26:159.14
-57,7,26:159.14
-57,8,26:139
-57,30,26:95.14
-57,31,26:95.14
-57,-29,27:95.14
-57,-28,27:95.14
-57,-6,27:109.2
-57,-5,27:159.14
-57,-4,27:159.14
-57,-3,27:159.14
-57,-2,27:109.3
-57,4,27:109.2
-57,5,27:159.14
-57,6,27:159.14
-57,7,27:159.14
-57,8,27:109.3
-57,30,27:95.14
-57,31,27:95.14
-57,-29,28:95.14
-57,-28,28:95.14
-57,-5,28:45
-57,-4,28:45
-57,-3,28:45
-57,5,28:45
-57,6,28:45
-57,7,28:45
-57,30,28:95.14
-57,31,28:95.14
-57,-29,29:95.14
-57,-28,29:95.14
-57,-6,29:109.6
-57,-5,29:45
-57,-4,29:45
-57,-3,29:45
-57,-2,29:109.7
-57,4,29:109.6
-57,5,29:45
-57,6,29:45
-57,7,29:45
-57,8,29:109.7
-57,30,29:95.14
-57,31,29:95.14
-57,-29,30:95.14
-57,-28,30:95.14
-57,-5,30:45
-57,-4,30:139
-57,-3,30:45
-57,5,30:45
-57,6,30:139
-57,7,30:45
-57,30,30:95.14
-57,31,30:95.14
-57,-29,31:95.14
-57,-28,31:95.14
-57,-5,31:45
-57,-4,31:139
-57,-3,31:45
-57,5,31:45
-57,6,31:139
-57,7,31:45
-57,30,31:95.14
-57,31,31:95.14
-57,-29,32:95.14
-57,-28,32:95.14
-57,-6,32:109.6
-57,-5,32:45
-57,-4,32:45
-57,-3,32:45
-57,-2,32:109.7
-57,4,32:109.6
-57,5,32:45
-57,6,32:45
-57,7,32:45
-57,8,32:109.7
-57,30,32:95.14
-57,31,32:95.14
-57,-29,33:95.14
-57,-28,33:95.14
-57,-6,33:109.2
-57,-5,33:45
-57,-4,33:45
-57,-3,33:45
-57,-2,33:109.3
-57,4,33:109.2
-57,5,33:45
-57,6,33:45
-57,7,33:45
-57,8,33:109.3
-57,30,33:95.14
-57,31,33:95.14
-57,-29,34:95.14
-57,-28,34:95.14
-57,-5,34:45
-57,-4,34:45
-57,-3,34:45
-57,5,34:45
-57,6,34:45
-57,7,34:45
-57,30,34:95.14
-57,31,34:95.14
-57,-29,35:95.14
-57,-28,35:95.14
-57,-5,35:109.6
-57,-4,35:45
-57,-3,35:45
-57,5,35:45
-57,6,35:45
-57,30,35:95.14
-57,31,35:95.14
-57,-29,36:95.14
-57,-28,36:95.14
-57,-5,36:109.2
-57,-4,36:45
-57,-3,36:45
-57,-2,36:45
-57,-1,36:45
-57,3,36:45
-57,4,36:45
-57,5,36:45
-57,6,36:45
-57,7,36:109.7
-57,30,36:95.14
-57,31,36:95.14
-57,-29,37:95.14
-57,-28,37:95.14
-57,-4,37:45
-57,-3,37:45
-57,-2,37:45
-57,-1,37:45
-57,0,37:45
-57,1,37:45
-57,2,37:45
-57,3,37:45
-57,4,37:45
-57,5,37:45
-57,6,37:45
-57,7,37:109.3
-57,30,37:95.14
-57,31,37:95.14
-57,-29,38:95.14
-57,-28,38:95.14
-57,-4,38:45
-57,-3,38:45
-57,-1,38:45
-57,0,38:45
-57,1,38:45
-57,2,38:45
-57,3,38:45
-57,5,38:45
-57,6,38:45
-57,30,38:95.14
-57,31,38:95.14
-57,-29,39:5.1
-57,-28,39:5.1
-57,-27,39:5.1
-57,-26,39:5.1
-57,-25,39:5.1
-57,-5,39:109.6
-57,-4,39:45
-57,-3,39:45
-57,-2,39:98
-57,-1,39:109.3
-57,3,39:109.2
-57,4,39:98
-57,5,39:45
-57,6,39:45
-57,7,39:109.7
-57,27,39:5.1
-57,28,39:5.1
-57,29,39:5.1
-57,30,39:5.1
-57,31,39:5.1
-57,-29,40:5.1
-57,-28,40:5.1
-57,-5,40:109.2
-57,-4,40:45
-57,-3,40:45
-57,-2,40:44.5
-57,4,40:44.5
-57,5,40:45
-57,6,40:45
-57,7,40:109.3
-57,30,40:5.1
-57,31,40:5.1
-57,-29,41:5.1
-57,-28,41:5.1
-57,-27,41:5.1
-57,-26,41:5.1
-57,-25,41:5.1
-57,-24,41:109.5
-57,-23,41:109.5
-57,-22,41:109.5
-57,-4,41:45
-57,-3,41:45
-57,5,41:45
-57,6,41:45
-57,24,41:109.6
-57,25,41:109.5
-57,27,41:5.1
-57,28,41:5.1
-57,29,41:5.1
-57,30,41:5.1
-57,31,41:5.1
-57,-29,42:5.1
-57,-28,42:5.1
-57,-27,42:5.1
-57,-26,42:5.1
-57,-25,42:5.1
-57,-24,42:109.1
-57,-23,42:109.1
-57,-22,42:109.1
-57,-5,42:109.6
-57,-4,42:45
-57,-3,42:45
-57,-2,42:45
-57,-1,42:109.7
-57,3,42:109.6
-57,4,42:45
-57,5,42:45
-57,6,42:45
-57,7,42:109.7
-57,24,42:109.2
-57,25,42:109.1
-57,27,42:5.1
-57,28,42:5.1
-57,29,42:5.1
-57,30,42:5.1
-57,31,42:5.1
-57,-5,43:109.2
-57,-4,43:45
-57,-3,43:45
-57,-2,43:45
-57,4,43:45
-57,5,43:45
-57,6,43:45
-57,7,43:109.3
-57,-3,44:45
-57,-2,44:45
-57,-1,44:45
-57,0,44:45
-57,2,44:45
-57,3,44:45
-57,4,44:45
-57,5,44:45
-57,-3,45:109
-57,-2,45:109
-57,-1,45:45
-57,0,45:45
-57,1,45:45
-57,2,45:45
-57,3,45:45
-57,4,45:109
-57,5,45:109
-57,0,46:109
-57,1,46:109
-57,2,46:109
-56,-21,5:1
-56,-20,5:1
-56,-19,5:1
-56,-18,5:1
-56,-17,5:1
-56,-16,5:1
-56,-15,5:1
-56,-14,5:1
-56,-13,5:1
-56,-12,5:1
-56,-11,5:1
-56,-10,5:1
-56,-9,5:1
-56,-8,5:1
-56,-7,5:1
-56,-6,5:1
-56,-5,5:1
-56,-4,5:1
-56,-3,5:1
-56,-2,5:1
-56,-1,5:1
-56,0,5:1
-56,1,5:1
-56,2,5:1
-56,3,5:1
-56,4,5:1
-56,5,5:1
-56,6,5:1
-56,7,5:1
-56,8,5:1
-56,9,5:1
-56,10,5:1
-56,11,5:1
-56,12,5:1
-56,13,5:1
-56,14,5:1
-56,15,5:1
-56,16,5:1
-56,17,5:1
-56,18,5:1
-56,19,5:1
-56,20,5:1
-56,21,5:1
-56,22,5:1
-56,23,5:1
-56,-21,6:12
-56,-20,6:12
-56,-19,6:12
-56,-18,6:12
-56,-17,6:12
-56,-16,6:12
-56,-15,6:12
-56,-14,6:12
-56,-13,6:12
-56,-12,6:12
-56,-11,6:12
-56,-10,6:12
-56,-9,6:12
-56,-8,6:12
-56,-7,6:12
-56,-6,6:12
-56,-5,6:12
-56,-4,6:12
-56,-3,6:12
-56,-2,6:12
-56,-1,6:12
-56,0,6:12
-56,1,6:13
-56,2,6:12
-56,3,6:12
-56,4,6:12
-56,5,6:12
-56,6,6:12
-56,7,6:12
-56,8,6:12
-56,9,6:12
-56,10,6:12
-56,11,6:12
-56,12,6:12
-56,13,6:12
-56,14,6:12
-56,15,6:12
-56,16,6:12
-56,17,6:12
-56,18,6:12
-56,19,6:12
-56,20,6:12
-56,21,6:12
-56,22,6:12
-56,23,6:12
-56,-24,7:98
-56,-23,7:98
-56,-5,7:5.1
-56,-4,7:134
-56,-3,7:134
-56,5,7:134.2
-56,6,7:134
-56,7,7:5.1
-56,25,7:98
-56,26,7:98
-56,-24,8:98
-56,-23,8:98
-56,-5,8:5.1
-56,-4,8:126.1
-56,6,8:126.1
-56,7,8:5.1
-56,25,8:98
-56,26,8:98
-56,-24,9:98
-56,-23,9:98
-56,-6,9:5.1
-56,-5,9:134.3
-56,7,9:134.2
-56,8,9:5.1
-56,25,9:98
-56,26,9:98
-56,-24,10:98
-56,-23,10:98
-56,-6,10:5.1
-56,-5,10:134.7
-56,7,10:134.6
-56,8,10:5.1
-56,25,10:98
-56,26,10:98
-56,-24,11:98
-56,-23,11:98
-56,-5,11:5.1
-56,-4,11:126.9
-56,6,11:126.9
-56,7,11:5.1
-56,25,11:98
-56,26,11:98
-56,-24,12:98
-56,-23,12:98
-56,-4,12:134.4
-56,-3,12:134.7
-56,5,12:134.6
-56,6,12:134.4
-56,7,12:98.3
-56,25,12:98
-56,26,12:98
-56,-24,13:98
-56,-23,13:98
-56,-4,13:98.3
-56,-3,13:98.3
-56,-2,13:5.1
-56,-1,13:134.4
-56,0,13:126.9
-56,2,13:126.9
-56,3,13:134.4
-56,4,13:5.1
-56,5,13:98.3
-56,6,13:98.3
-56,25,13:98
-56,26,13:98
-56,-24,14:98
-56,-23,14:98
-56,-4,14:98.3
-56,-3,14:98.3
-56,-2,14:98.3
-56,-1,14:98.3
-56,0,14:98.3
-56,1,14:5.1
-56,2,14:98.3
-56,3,14:98.3
-56,4,14:98.3
-56,5,14:98.3
-56,6,14:98.3
-56,25,14:98
-56,26,14:98
-56,-24,15:98
-56,-23,15:98
-56,25,15:98
-56,26,15:98
-56,-24,16:98
-56,-23,16:98
-56,25,16:98
-56,26,16:98
-56,-24,17:98
-56,-23,17:98
-56,25,17:98
-56,26,17:98
-56,-24,18:98
-56,-23,18:98
-56,25,18:98
-56,26,18:98
-56,-24,19:98
-56,-23,19:98
-56,25,19:98
-56,26,19:98
-56,-24,20:98
-56,-23,20:98
-56,25,20:98
-56,26,20:98
-56,-24,21:98
-56,-23,21:98
-56,25,21:98
-56,26,21:98
-56,-29,22:5.1
-56,-28,22:5.1
-56,-27,22:5.1
-56,-26,22:5.1
-56,-25,22:5.1
-56,-24,22:5.1
-56,-23,22:5.1
-56,-22,22:5.1
-56,-21,22:5.1
-56,-20,22:5.1
-56,-19,22:5.1
-56,-18,22:5.1
-56,-17,22:5.1
-56,-16,22:5.1
-56,-15,22:5.1
-56,-14,22:5.1
-56,-13,22:5.1
-56,-12,22:5.1
-56,-11,22:5.1
-56,-10,22:5.1
-56,-9,22:5.1
-56,-8,22:5.1
-56,-7,22:5.1
-56,-6,22:5.1
-56,-5,22:5.1
-56,-4,22:98.3
-56,-3,22:5.1
-56,-2,22:5.1
-56,-1,22:5.1
-56,0,22:5
-56,1,22:5
-56,2,22:5
-56,3,22:5.1
-56,4,22:5.1
-56,5,22:5.1
-56,6,22:98.3
-56,7,22:5.1
-56,8,22:5.1
-56,9,22:5.1
-56,10,22:5.1
-56,11,22:5.1
-56,12,22:5.1
-56,13,22:5.1
-56,14,22:5.1
-56,15,22:5.1
-56,16,22:5.1
-56,17,22:5.1
-56,18,22:5.1
-56,19,22:5.1
-56,20,22:5.1
-56,21,22:5.1
-56,22,22:5.1
-56,23,22:5.1
-56,24,22:5.1
-56,25,22:5.1
-56,26,22:5.1
-56,27,22:5.1
-56,28,22:5.1
-56,29,22:5.1
-56,30,22:5.1
-56,31,22:5.1
-56,-31,23:95.14
-56,-30,23:95.14
-56,-29,23:98.3
-56,-28,23:98.3
-56,-27,23:98.3
-56,-26,23:2
-56,-25,23:5.1
-56,-24,23:2
-56,-23,23:2
-56,-22,23:2
-56,-21,23:2
-56,-20,23:2
-56,-19,23:2
-56,-18,23:2
-56,-17,23:2
-56,-16,23:2
-56,-15,23:2
-56,-14,23:2
-56,-13,23:2
-56,-12,23:2
-56,-11,23:126.5
-56,-10,23:164.2
-56,-9,23:126.5
-56,-8,23:5.5
-56,-7,23:126.5
-56,-6,23:109.1
-56,-5,23:109.1
-56,-3,23:109.1
-56,-2,23:109.3
-56,1,23:126
-56,4,23:109.1
-56,5,23:109.1
-56,7,23:109.1
-56,8,23:109.3
-56,9,23:126.5
-56,10,23:5.5
-56,11,23:164.2
-56,12,23:164.3
-56,13,23:126.5
-56,14,23:2
-56,15,23:5.1
-56,16,23:2
-56,17,23:2
-56,18,23:2
-56,19,23:2
-56,20,23:2
-56,21,23:2
-56,22,23:2
-56,23,23:159.13
-56,24,23:2
-56,25,23:2
-56,26,23:2
-56,27,23:2
-56,28,23:159.13
-56,29,23:98.3
-56,30,23:98.3
-56,31,23:98.3
-56,32,23:95.14
-56,33,23:95.14
-56,-31,24:95.14
-56,-30,24:95.14
-56,-23,24:31.1
-56,-22,24:18.12
-56,-21,24:18.12
-56,-20,24:18.5
-56,-19,24:31.1
-56,-17,24:31.1
-56,-16,24:18.4
-56,-13,24:31.1
-56,-6,24:139
-56,-5,24:139
-56,-3,24:139
-56,-2,24:139
-56,4,24:139
-56,5,24:139
-56,7,24:139
-56,8,24:139
-56,14,24:31.1
-56,16,24:31.1
-56,17,24:31.1
-56,18,24:175.5
-56,20,24:31.1
-56,21,24:31.2
-56,22,24:31.1
-56,24,24:18.5
-56,25,24:18.12
-56,26,24:18.4
-56,32,24:95.14
-56,33,24:95.14
-56,-31,25:95.14
-56,-30,25:95.14
-56,-22,25:18.13
-56,-21,25:18.4
-56,-6,25:139
-56,-5,25:139
-56,-3,25:139
-56,-2,25:139
-56,4,25:139
-56,5,25:139
-56,7,25:139
-56,8,25:139
-56,18,25:175.10
-56,26,25:18.12
-56,32,25:95.14
-56,33,25:95.14
-56,-31,26:95.14
-56,-30,26:95.14
-56,-21,26:18.4
-56,-6,26:139
-56,-5,26:139
-56,-3,26:139
-56,-2,26:139
-56,4,26:139
-56,5,26:139
-56,7,26:139
-56,8,26:139
-56,32,26:95.14
-56,33,26:95.14
-56,-31,27:95.14
-56,-30,27:95.14
-56,-5,27:109.1
-56,-4,27:109.5
-56,-3,27:109.1
-56,5,27:109.1
-56,6,27:109.5
-56,7,27:109.1
-56,32,27:95.14
-56,33,27:95.14
-56,-31,28:95.14
-56,-30,28:95.14
-56,32,28:95.14
-56,33,28:95.14
-56,-31,29:95.14
-56,-30,29:95.14
-56,-6,29:109.6
-56,-5,29:109.5
-56,-3,29:109.5
-56,-2,29:109.7
-56,4,29:109.6
-56,5,29:109.5
-56,7,29:109.5
-56,8,29:109.7
-56,32,29:95.14
-56,33,29:95.14
-56,-31,30:95.14
-56,-30,30:95.14
-56,32,30:95.14
-56,33,30:95.14
-56,-31,31:95.14
-56,-30,31:95.14
-56,32,31:95.14
-56,33,31:95.14
-56,-31,32:95.14
-56,-30,32:95.14
-56,-6,32:109.6
-56,-5,32:109.5
-56,-3,32:109.5
-56,-2,32:109.7
-56,4,32:109.6
-56,5,32:109.5
-56,7,32:109.5
-56,8,32:109.7
-56,32,32:95.14
-56,33,32:95.14
-56,-31,33:95.14
-56,-30,33:95.14
-56,-6,33:109.2
-56,-5,33:109.1
-56,-3,33:109.1
-56,-2,33:109.3
-56,4,33:109.2
-56,5,33:109.1
-56,7,33:109.1
-56,8,33:109.3
-56,32,33:95.14
-56,33,33:95.14
-56,-31,34:95.14
-56,-30,34:95.14
-56,32,34:95.14
-56,33,34:95.14
-56,-31,35:95.14
-56,-30,35:95.14
-56,-5,35:109.5
-56,-4,35:109.5
-56,32,35:95.14
-56,33,35:95.14
-56,-31,36:95.14
-56,-30,36:95.14
-56,-5,36:109.2
-56,-4,36:109.1
-56,-3,36:44.13
-56,-2,36:109.7
-56,0,36:109.6
-56,1,36:44.5
-56,2,36:109.7
-56,4,36:109.6
-56,5,36:44.13
-56,6,36:109.5
-56,7,36:109.5
-56,32,36:95.14
-56,33,36:95.14
-56,-31,37:95.14
-56,-30,37:95.14
-56,-2,37:44.5
-56,-1,37:98.3
-56,0,37:109.2
-56,1,37:98.3
-56,2,37:109.3
-56,3,37:98.3
-56,4,37:44.5
-56,6,37:109.1
-56,7,37:109.3
-56,32,37:95.14
-56,33,37:95.14
-56,-31,38:95.14
-56,-30,38:95.14
-56,-3,38:98.3
-56,-2,38:98.3
-56,-1,38:98.3
-56,0,38:109.6
-56,1,38:98.3
-56,2,38:109.7
-56,3,38:98.3
-56,4,38:98.3
-56,5,38:98.3
-56,32,38:95.14
-56,33,38:95.14
-56,-31,39:5.1
-56,-30,39:5.1
-56,-29,39:5.1
-56,-28,39:5.1
-56,-27,39:5.1
-56,-5,39:109.6
-56,-4,39:109.5
-56,-3,39:44.13
-56,-2,39:44.13
-56,-1,39:98.3
-56,0,39:109.2
-56,1,39:44.13
-56,2,39:109.3
-56,3,39:98.3
-56,4,39:44.13
-56,5,39:44.13
-56,6,39:109.5
-56,7,39:109.7
-56,29,39:5.1
-56,30,39:5.1
-56,31,39:5.1
-56,32,39:5.1
-56,33,39:5.1
-56,-31,40:5.1
-56,-30,40:5.1
-56,-5,40:109.1
-56,-4,40:109.1
-56,6,40:109.1
-56,7,40:109.1
-56,32,40:5.1
-56,33,40:5.1
-56,-31,41:5.1
-56,-30,41:5.1
-56,-29,41:5.1
-56,-28,41:5.1
-56,-27,41:5.1
-56,29,41:5.1
-56,30,41:5.1
-56,31,41:5.1
-56,32,41:5.1
-56,33,41:5.1
-56,-31,42:5.1
-56,-30,42:5.1
-56,-29,42:5.1
-56,-28,42:5.1
-56,-27,42:5.1
-56,-26,42:109.7
-56,-5,42:109.6
-56,-4,42:109.5
-56,-2,42:109.5
-56,-1,42:109.5
-56,3,42:109.5
-56,4,42:109.5
-56,6,42:109.5
-56,7,42:109.7
-56,28,42:109.6
-56,29,42:5.1
-56,30,42:5.1
-56,31,42:5.1
-56,32,42:5.1
-56,33,42:5.1
-56,-5,43:109.2
-56,-4,43:109.1
-56,6,43:109.1
-56,7,43:109.1
-56,-3,44:109.5
-56,-2,44:109.5
-56,4,44:109.5
-56,5,44:109.5
-56,-3,45:109.1
-56,-2,45:109.1
-56,0,45:109.5
-56,1,45:109.5
-56,2,45:109.5
-56,4,45:109.1
-56,5,45:109.1
-56,0,46:109.1
-56,1,46:109.1
-56,2,46:109.1
-55,-24,5:1
-55,-23,5:1
-55,-22,5:1
-55,-21,5:1
-55,-20,5:1
-55,-19,5:1
-55,-18,5:1
-55,-17,5:1
-55,-16,5:1
-55,-15,5:1
-55,-14,5:1
-55,-13,5:1
-55,-12,5:1
-55,-11,5:1
-55,-10,5:1
-55,-9,5:1
-55,-8,5:1
-55,-7,5:1
-55,-6,5:1
-55,-5,5:1
-55,-4,5:1
-55,-3,5:1
-55,-2,5:1
-55,-1,5:1
-55,0,5:1
-55,1,5:1
-55,2,5:1
-55,3,5:1
-55,4,5:1
-55,5,5:1
-55,6,5:1
-55,7,5:1
-55,8,5:1
-55,9,5:1
-55,10,5:1
-55,11,5:1
-55,12,5:1
-55,13,5:1
-55,14,5:1
-55,15,5:1
-55,16,5:1
-55,17,5:1
-55,18,5:1
-55,19,5:1
-55,20,5:1
-55,21,5:1
-55,22,5:1
-55,23,5:1
-55,24,5:1
-55,25,5:1
-55,26,5:1
-55,-24,6:12
-55,-23,6:12
-55,-22,6:12
-55,-21,6:12
-55,-20,6:12
-55,-19,6:12
-55,-18,6:12
-55,-17,6:12
-55,-16,6:12
-55,-15,6:12
-55,-14,6:12
-55,-13,6:12
-55,-12,6:12
-55,-11,6:12
-55,-10,6:12
-55,-9,6:12
-55,-8,6:12
-55,-7,6:12
-55,-6,6:12
-55,-5,6:12
-55,-4,6:12
-55,-3,6:12
-55,-2,6:12
-55,-1,6:12
-55,0,6:12
-55,1,6:13
-55,2,6:12
-55,3,6:12
-55,4,6:12
-55,5,6:12
-55,6,6:12
-55,7,6:12
-55,8,6:12
-55,9,6:12
-55,10,6:12
-55,11,6:12
-55,12,6:12
-55,13,6:12
-55,14,6:12
-55,15,6:12
-55,16,6:12
-55,17,6:12
-55,18,6:12
-55,19,6:12
-55,20,6:12
-55,21,6:12
-55,22,6:12
-55,23,6:12
-55,24,6:12
-55,25,6:12
-55,26,6:12
-55,-26,7:98
-55,-25,7:98
-55,-5,7:5.1
-55,-4,7:134.1
-55,-3,7:134.3
-55,5,7:134.1
-55,6,7:134.1
-55,7,7:5.1
-55,27,7:98
-55,28,7:98
-55,-26,8:98
-55,-25,8:98
-55,-5,8:5.1
-55,-4,8:126.1
-55,6,8:126.1
-55,7,8:5.1
-55,27,8:98
-55,28,8:98
-55,-26,9:98
-55,-25,9:98
-55,-6,9:5.1
-55,-5,9:134.3
-55,7,9:134.2
-55,8,9:5.1
-55,27,9:98
-55,28,9:98
-55,-26,10:98
-55,-25,10:98
-55,-6,10:5.1
-55,-5,10:134.7
-55,7,10:134.6
-55,8,10:5.1
-55,27,10:98
-55,28,10:98
-55,-26,11:98
-55,-25,11:98
-55,-5,11:5.1
-55,-4,11:126.9
-55,6,11:126.9
-55,7,11:5.1
-55,27,11:98
-55,28,11:98
-55,-26,12:98
-55,-25,12:98
-55,-4,12:134.5
-55,-3,12:134.7
-55,5,12:134.6
-55,6,12:134.5
-55,7,12:98.3
-55,27,12:98
-55,28,12:98
-55,-26,13:98
-55,-25,13:98
-55,-4,13:98.3
-55,-3,13:98.3
-55,-2,13:5.1
-55,-1,13:134.5
-55,0,13:126.9
-55,2,13:126.9
-55,3,13:134.5
-55,4,13:5.1
-55,5,13:98.3
-55,6,13:98.3
-55,27,13:98
-55,28,13:98
-55,-26,14:98
-55,-25,14:98
-55,-4,14:98.3
-55,-3,14:98.3
-55,-2,14:98.3
-55,-1,14:98.3
-55,0,14:98.3
-55,1,14:5.1
-55,2,14:98.3
-55,3,14:98.3
-55,4,14:98.3
-55,5,14:98.3
-55,6,14:98.3
-55,27,14:98
-55,28,14:98
-55,-26,15:98
-55,-25,15:98
-55,27,15:98
-55,28,15:98
-55,-26,16:98
-55,-25,16:98
-55,27,16:98
-55,28,16:98
-55,-26,17:98
-55,-25,17:98
-55,27,17:98
-55,28,17:98
-55,-26,18:98
-55,-25,18:98
-55,27,18:98
-55,28,18:98
-55,-26,19:98
-55,-25,19:98
-55,27,19:98
-55,28,19:98
-55,-26,20:98
-55,-25,20:98
-55,27,20:98
-55,28,20:98
-55,-26,21:98
-55,-25,21:98
-55,27,21:98
-55,28,21:98
-55,-31,22:5.1
-55,-30,22:5.1
-55,-29,22:5.1
-55,-28,22:5.1
-55,-27,22:5.1
-55,-26,22:5.1
-55,-25,22:5.1
-55,-24,22:5.1
-55,-23,22:5.1
-55,-22,22:5.1
-55,-21,22:5.1
-55,-20,22:5.1
-55,-19,22:5.1
-55,-18,22:5.1
-55,-17,22:5.1
-55,-16,22:5.1
-55,-15,22:5.1
-55,-14,22:5.1
-55,-13,22:5.1
-55,-12,22:5.1
-55,-11,22:5.1
-55,-10,22:5.1
-55,-9,22:5.1
-55,-8,22:5.1
-55,-7,22:5.1
-55,-6,22:5.1
-55,-5,22:5.1
-55,-4,22:5.1
-55,-3,22:98.3
-55,-2,22:98.3
-55,-1,22:5.1
-55,0,22:53.2
-55,1,22:159.1
-55,2,22:53.3
-55,3,22:5.1
-55,4,22:98.3
-55,5,22:98.3
-55,6,22:5.1
-55,7,22:5.1
-55,8,22:5.1
-55,9,22:5.1
-55,10,22:5.1
-55,11,22:5.1
-55,12,22:5.1
-55,13,22:5.1
-55,14,22:5.1
-55,15,22:5.1
-55,16,22:5.1
-55,17,22:5.1
-55,18,22:5.1
-55,19,22:5.1
-55,20,22:5.1
-55,21,22:5.1
-55,22,22:5.1
-55,23,22:5.1
-55,24,22:5.1
-55,25,22:5.1
-55,26,22:5.1
-55,27,22:5.1
-55,28,22:5.1
-55,29,22:5.1
-55,30,22:5.1
-55,31,22:5.1
-55,32,22:5.1
-55,33,22:5.1
-55,-32,23:95.14
-55,-31,23:98.3
-55,-30,23:98.3
-55,-29,23:98.3
-55,-28,23:2
-55,-27,23:2
-55,-26,23:2
-55,-25,23:2
-55,-24,23:2
-55,-23,23:2
-55,-22,23:2
-55,-21,23:2
-55,-20,23:2
-55,-19,23:2
-55,-18,23:2
-55,-17,23:2
-55,-16,23:2
-55,-15,23:126.5
-55,-14,23:164.3
-55,-13,23:5.5
-55,-12,23:126.5
-55,-11,23:126.5
-55,1,23:126
-55,14,23:126.5
-55,15,23:164.2
-55,16,23:126.5
-55,17,23:5.5
-55,18,23:126.5
-55,19,23:2
-55,20,23:2
-55,21,23:2
-55,22,23:2
-55,23,23:2
-55,24,23:2
-55,25,23:2
-55,26,23:2
-55,27,23:2
-55,28,23:2
-55,29,23:2
-55,30,23:2
-55,31,23:98.3
-55,32,23:98.3
-55,33,23:98.3
-55,34,23:95.14
-55,-32,24:95.14
-55,-28,24:37
-55,-27,24:31.1
-55,-26,24:31.2
-55,-25,24:38
-55,-24,24:31.1
-55,-23,24:31.1
-55,-22,24:18.12
-55,-21,24:18.13
-55,-19,24:31.1
-55,-18,24:175.4
-55,-17,24:31.1
-55,19,24:31.2
-55,21,24:31.1
-55,22,24:31.1
-55,24,24:31.1
-55,25,24:18.4
-55,26,24:18.4
-55,27,24:18.5
-55,34,24:95.14
-55,-32,25:95.14
-55,-18,25:175.8
-55,25,25:18.5
-55,26,25:18.12
-55,34,25:95.14
-55,-32,26:95.14
-55,26,26:18.4
-55,34,26:95.14
-55,-32,27:95.14
-55,34,27:95.14
-55,-32,28:95.14
-55,34,28:95.14
-55,-32,29:95.14
-55,34,29:95.14
-55,-32,30:95.14
-55,34,30:95.14
-55,-32,31:95.14
-55,34,31:95.14
-55,-32,32:95.14
-55,34,32:95.14
-55,-32,33:95.14
-55,34,33:95.14
-55,-32,34:95.14
-55,34,34:95.14
-55,-32,35:95.14
-55,-1,35:112
-55,3,35:112
-55,34,35:95.14
-55,-32,36:95.14
-55,-1,36:112
-55,0,36:114.7
-55,2,36:114.6
-55,3,36:112
-55,34,36:95.14
-55,-32,37:95.14
-55,-1,37:112
-55,0,37:112
-55,2,37:112
-55,3,37:112
-55,34,37:95.14
-55,-32,38:95.14
-55,-2,38:112
-55,-1,38:112
-55,0,38:114.2
-55,1,38:112
-55,2,38:114.3
-55,3,38:112
-55,4,38:112
-55,34,38:95.14
-55,-32,39:5.1
-55,-31,39:5.1
-55,-30,39:5.1
-55,-29,39:5.1
-55,-2,39:112
-55,-1,39:112
-55,1,39:112
-55,3,39:112
-55,4,39:112
-55,31,39:5.1
-55,32,39:5.1
-55,33,39:5.1
-55,34,39:5.1
-55,-32,40:5.1
-55,-2,40:112
-55,-1,40:112
-55,3,40:112
-55,4,40:112
-55,34,40:5.1
-55,-32,41:5.1
-55,-31,41:5.1
-55,-30,41:5.1
-55,-29,41:5.1
-55,-2,41:112
-55,-1,41:112
-55,3,41:112
-55,4,41:112
-55,31,41:5.1
-55,32,41:5.1
-55,33,41:5.1
-55,34,41:5.1
-55,-32,42:5.1
-55,-31,42:5.1
-55,-30,42:5.1
-55,-29,42:5.1
-55,-27,42:109.5
-55,-26,42:109.5
-55,-1,42:112
-55,3,42:112
-55,28,42:109.5
-55,29,42:109.5
-55,31,42:5.1
-55,32,42:5.1
-55,33,42:5.1
-55,34,42:5.1
-55,-1,43:112
-55,3,43:112
-54,-26,5:1
-54,-25,5:1
-54,-24,5:1
-54,-23,5:1
-54,-22,5:1
-54,-21,5:1
-54,-20,5:1
-54,-19,5:1
-54,-18,5:1
-54,-17,5:1
-54,-16,5:1
-54,-15,5:1
-54,-14,5:1
-54,-13,5:1
-54,-12,5:1
-54,-11,5:1
-54,-10,5:1
-54,-9,5:1
-54,-8,5:1
-54,-7,5:1
-54,-6,5:1
-54,-5,5:1
-54,-4,5:1
-54,-3,5:1
-54,-2,5:1
-54,-1,5:1
-54,0,5:1
-54,1,5:1
-54,2,5:1
-54,3,5:1
-54,4,5:1
-54,5,5:1
-54,6,5:1
-54,7,5:1
-54,8,5:1
-54,9,5:1
-54,10,5:1
-54,11,5:1
-54,12,5:1
-54,13,5:1
-54,14,5:1
-54,15,5:1
-54,16,5:1
-54,17,5:1
-54,18,5:1
-54,19,5:1
-54,20,5:1
-54,21,5:1
-54,22,5:1
-54,23,5:1
-54,24,5:1
-54,25,5:1
-54,26,5:1
-54,27,5:1
-54,28,5:1
-54,-26,6:12
-54,-25,6:12
-54,-24,6:12
-54,-23,6:12
-54,-22,6:12
-54,-21,6:12
-54,-20,6:12
-54,-19,6:12
-54,-18,6:12
-54,-17,6:12
-54,-16,6:12
-54,-15,6:12
-54,-14,6:12
-54,-13,6:12
-54,-12,6:12
-54,-11,6:12
-54,-10,6:12
-54,-9,6:12
-54,-8,6:12
-54,-7,6:12
-54,-6,6:12
-54,-5,6:12
-54,-4,6:12
-54,-3,6:12
-54,-2,6:12
-54,-1,6:12
-54,0,6:12
-54,1,6:13
-54,2,6:12
-54,3,6:12
-54,4,6:12
-54,5,6:12
-54,6,6:12
-54,7,6:12
-54,8,6:12
-54,9,6:12
-54,10,6:12
-54,11,6:12
-54,12,6:12
-54,13,6:12
-54,14,6:12
-54,15,6:12
-54,16,6:12
-54,17,6:12
-54,18,6:12
-54,19,6:12
-54,20,6:12
-54,21,6:12
-54,22,6:12
-54,23,6:12
-54,24,6:12
-54,25,6:12
-54,26,6:12
-54,27,6:12
-54,28,6:12
-54,-28,7:98
-54,-27,7:98
-54,-5,7:98.3
-54,-4,7:98.3
-54,-3,7:44.5
-54,5,7:44.5
-54,6,7:98.3
-54,7,7:98.3
-54,29,7:98
-54,30,7:98
-54,-28,8:98
-54,-27,8:98
-54,-5,8:98.3
-54,7,8:98.3
-54,29,8:98
-54,30,8:98
-54,-28,9:98
-54,-27,9:98
-54,-6,9:5.1
-54,8,9:5.1
-54,29,9:98
-54,30,9:98
-54,-28,10:98
-54,-27,10:98
-54,-6,10:5.1
-54,8,10:5.1
-54,29,10:98
-54,30,10:98
-54,-28,11:98
-54,-27,11:98
-54,-5,11:98.3
-54,7,11:98.3
-54,29,11:98
-54,30,11:98
-54,-28,12:98
-54,-27,12:98
-54,-4,12:98.3
-54,-3,12:44.13
-54,5,12:44.13
-54,6,12:98.3
-54,29,12:98
-54,30,12:98
-54,-28,13:98
-54,-27,13:98
-54,-4,13:98.3
-54,-3,13:98.3
-54,-2,13:98.3
-54,-1,13:98.3
-54,3,13:98.3
-54,4,13:98.3
-54,5,13:98.3
-54,6,13:98.3
-54,29,13:98
-54,30,13:98
-54,-28,14:98
-54,-27,14:98
-54,-4,14:98.3
-54,-3,14:98.3
-54,-2,14:98.3
-54,-1,14:98.3
-54,0,14:98.3
-54,1,14:98.3
-54,2,14:98.3
-54,3,14:98.3
-54,4,14:98.3
-54,5,14:98.3
-54,6,14:98.3
-54,29,14:98
-54,30,14:98
-54,-28,15:98
-54,-27,15:98
-54,29,15:98
-54,30,15:98
-54,-28,16:98
-54,-27,16:98
-54,29,16:98
-54,30,16:98
-54,-28,17:98
-54,-27,17:98
-54,29,17:98
-54,30,17:98
-54,-28,18:98
-54,-27,18:98
-54,29,18:98
-54,30,18:98
-54,-28,19:98
-54,-27,19:98
-54,29,19:98
-54,30,19:98
-54,-28,20:98
-54,-27,20:98
-54,29,20:98
-54,30,20:98
-54,-28,21:98
-54,-27,21:98
-54,29,21:98
-54,30,21:98
-54,-32,22:5.1
-54,-31,22:5.1
-54,-30,22:5.1
-54,-29,22:5.1
-54,-28,22:5.1
-54,-27,22:5.1
-54,-26,22:5.1
-54,-25,22:5.1
-54,-24,22:5.1
-54,-23,22:5.1
-54,-22,22:5.1
-54,-21,22:5.1
-54,-20,22:5.1
-54,-19,22:5.1
-54,-18,22:5.1
-54,-17,22:5.1
-54,-16,22:5.1
-54,-15,22:5.1
-54,-14,22:5.1
-54,-13,22:5.1
-54,-12,22:5.1
-54,-11,22:5.1
-54,-10,22:5.1
-54,-9,22:5.1
-54,-8,22:5.1
-54,-7,22:5.1
-54,-6,22:5.1
-54,-5,22:5.1
-54,-4,22:5.1
-54,-3,22:5.1
-54,-2,22:98.3
-54,-1,22:5.1
-54,0,22:5.1
-54,1,22:53.1
-54,2,22:5.1
-54,3,22:5.1
-54,4,22:98.3
-54,5,22:5.1
-54,6,22:5.1
-54,7,22:5.1
-54,8,22:5.1
-54,9,22:5.1
-54,10,22:5.1
-54,11,22:5.1
-54,12,22:5.1
-54,13,22:5.1
-54,14,22:5.1
-54,15,22:5.1
-54,16,22:5.1
-54,17,22:5.1
-54,18,22:5.1
-54,19,22:5.1
-54,20,22:5.1
-54,21,22:5.1
-54,22,22:5.1
-54,23,22:5.1
-54,24,22:5.1
-54,25,22:5.1
-54,26,22:5.1
-54,27,22:5.1
-54,28,22:5.1
-54,29,22:5.1
-54,30,22:5.1
-54,31,22:5.1
-54,32,22:5.1
-54,33,22:5.1
-54,34,22:5.1
-54,-34,23:95.14
-54,-33,23:95.14
-54,-32,23:98.3
-54,-31,23:98.3
-54,-30,23:2
-54,-29,23:159.13
-54,-28,23:2
-54,-27,23:2
-54,-26,23:2
-54,-25,23:2
-54,-24,23:2
-54,-23,23:159.13
-54,-22,23:5.1
-54,-21,23:2
-54,-20,23:2
-54,-19,23:164.2
-54,-18,23:164.3
-54,-17,23:5.5
-54,-16,23:126.5
-54,-15,23:126.5
-54,19,23:126.5
-54,20,23:5.5
-54,21,23:126.5
-54,22,23:164.2
-54,23,23:126.5
-54,24,23:2
-54,25,23:2
-54,26,23:2
-54,27,23:2
-54,28,23:2
-54,29,23:2
-54,30,23:2
-54,31,23:2
-54,32,23:159.13
-54,33,23:98.3
-54,34,23:98.3
-54,35,23:95.14
-54,36,23:95.14
-54,-34,24:95.14
-54,-33,24:95.14
-54,-30,24:31.2
-54,-27,24:31.1
-54,-26,24:31.1
-54,-24,24:31.1
-54,-21,24:31.2
-54,24,24:31.2
-54,26,24:18.5
-54,28,24:175.4
-54,29,24:38
-54,30,24:31.1
-54,31,24:31.1
-54,35,24:95.14
-54,36,24:95.14
-54,-34,25:95.14
-54,-33,25:95.14
-54,28,25:175.10
-54,35,25:95.14
-54,36,25:95.14
-54,-34,26:95.14
-54,-33,26:95.14
-54,35,26:95.14
-54,36,26:95.14
-54,-34,27:95.14
-54,-33,27:95.14
-54,35,27:95.14
-54,36,27:95.14
-54,-34,28:95.14
-54,-33,28:95.14
-54,35,28:95.14
-54,36,28:95.14
-54,-34,29:95.14
-54,-33,29:95.14
-54,35,29:95.14
-54,36,29:95.14
-54,-34,30:95.14
-54,-33,30:95.14
-54,35,30:95.14
-54,36,30:95.14
-54,-34,31:95.14
-54,-33,31:95.14
-54,35,31:95.14
-54,36,31:95.14
-54,-34,32:95.14
-54,-33,32:95.14
-54,35,32:95.14
-54,36,32:95.14
-54,-34,33:95.14
-54,-33,33:95.14
-54,35,33:95.14
-54,36,33:95.14
-54,-34,34:95.14
-54,-33,34:95.14
-54,35,34:95.14
-54,36,34:95.14
-54,-34,35:95.14
-54,-33,35:95.14
-54,35,35:95.14
-54,36,35:95.14
-54,-34,36:95.14
-54,-33,36:95.14
-54,35,36:95.14
-54,36,36:95.14
-54,-34,37:95.14
-54,-33,37:95.14
-54,35,37:95.14
-54,36,37:95.14
-54,-34,38:95.14
-54,-33,38:95.14
-54,35,38:95.14
-54,36,38:95.14
-54,-34,39:5.1
-54,-33,39:5.1
-54,-32,39:5.1
-54,-31,39:5.1
-54,33,39:5.1
-54,34,39:5.1
-54,35,39:5.1
-54,36,39:5.1
-54,-34,40:5.1
-54,-33,40:5.1
-54,35,40:5.1
-54,36,40:5.1
-54,-34,41:5.1
-54,-33,41:5.1
-54,-32,41:5.1
-54,-31,41:5.1
-54,-30,41:109.7
-54,32,41:109.6
-54,33,41:5.1
-54,34,41:5.1
-54,35,41:5.1
-54,36,41:5.1
-54,-34,42:5.1
-54,-33,42:5.1
-54,-32,42:5.1
-54,-31,42:5.1
-54,-30,42:109.3
-54,32,42:109.1
-54,33,42:5.1
-54,34,42:5.1
-54,35,42:5.1
-54,36,42:5.1
-53,-28,5:1
-53,-27,5:1
-53,-26,5:1
-53,-25,5:1
-53,-24,5:1
-53,-23,5:1
-53,-22,5:1
-53,-21,5:1
-53,-20,5:1
-53,-19,5:1
-53,-18,5:1
-53,-17,5:1
-53,-16,5:1
-53,-15,5:1
-53,-14,5:1
-53,-13,5:1
-53,-12,5:1
-53,-11,5:1
-53,-10,5:1
-53,-9,5:1
-53,-8,5:1
-53,-7,5:1
-53,-6,5:1
-53,-5,5:1
-53,-4,5:1
-53,-3,5:1
-53,-2,5:1
-53,-1,5:1
-53,0,5:1
-53,1,5:1
-53,2,5:1
-53,3,5:1
-53,4,5:1
-53,5,5:1
-53,6,5:1
-53,7,5:1
-53,8,5:1
-53,9,5:1
-53,10,5:1
-53,11,5:1
-53,12,5:1
-53,13,5:1
-53,14,5:1
-53,15,5:1
-53,16,5:1
-53,17,5:1
-53,18,5:1
-53,19,5:1
-53,20,5:1
-53,21,5:1
-53,22,5:1
-53,23,5:1
-53,24,5:1
-53,25,5:1
-53,26,5:1
-53,27,5:1
-53,28,5:1
-53,29,5:1
-53,30,5:1
-53,-28,6:12
-53,-27,6:12
-53,-26,6:12
-53,-25,6:12
-53,-24,6:12
-53,-23,6:12
-53,-22,6:12
-53,-21,6:12
-53,-20,6:12
-53,-19,6:12
-53,-18,6:12
-53,-17,6:12
-53,-16,6:12
-53,-15,6:12
-53,-14,6:12
-53,-13,6:12
-53,-12,6:12
-53,-11,6:12
-53,-10,6:12
-53,-9,6:12
-53,-8,6:12
-53,-7,6:12
-53,-6,6:12
-53,-5,6:12
-53,-4,6:12
-53,-3,6:12
-53,-2,6:12
-53,-1,6:12
-53,0,6:12
-53,1,6:13
-53,2,6:12
-53,3,6:12
-53,4,6:12
-53,5,6:12
-53,6,6:12
-53,7,6:12
-53,8,6:12
-53,9,6:12
-53,10,6:12
-53,11,6:12
-53,12,6:12
-53,13,6:12
-53,14,6:12
-53,15,6:12
-53,16,6:12
-53,17,6:12
-53,18,6:12
-53,19,6:12
-53,20,6:12
-53,21,6:12
-53,22,6:12
-53,23,6:12
-53,24,6:12
-53,25,6:12
-53,26,6:12
-53,27,6:12
-53,28,6:12
-53,29,6:12
-53,30,6:12
-53,-30,7:98
-53,-29,7:98
-53,-4,7:98.3
-53,-3,7:44.5
-53,5,7:44.5
-53,6,7:98.3
-53,31,7:98
-53,32,7:98
-53,-30,8:98
-53,-29,8:98
-53,-5,8:98.3
-53,-4,8:44.5
-53,6,8:44.5
-53,7,8:98.3
-53,31,8:98
-53,32,8:98
-53,-30,9:98
-53,-29,9:98
-53,-6,9:5.1
-53,-5,9:44.5
-53,7,9:44.5
-53,8,9:5.1
-53,31,9:98
-53,32,9:98
-53,-30,10:98
-53,-29,10:98
-53,-6,10:5.1
-53,-5,10:44.13
-53,7,10:44.13
-53,8,10:5.1
-53,31,10:98
-53,32,10:98
-53,-30,11:98
-53,-29,11:98
-53,-5,11:98.3
-53,-4,11:44.13
-53,6,11:44.13
-53,7,11:98.3
-53,31,11:98
-53,32,11:98
-53,-30,12:98
-53,-29,12:98
-53,-4,12:98.3
-53,-3,12:44.13
-53,5,12:44.13
-53,6,12:98.3
-53,31,12:98
-53,32,12:98
-53,-30,13:98
-53,-29,13:98
-53,-4,13:98.3
-53,-3,13:98.3
-53,-2,13:98.3
-53,-1,13:98.3
-53,3,13:98.3
-53,4,13:98.3
-53,5,13:98.3
-53,6,13:98.3
-53,31,13:98
-53,32,13:98
-53,-30,14:98
-53,-29,14:98
-53,-4,14:98.3
-53,-3,14:98.3
-53,-2,14:98.3
-53,-1,14:98.3
-53,0,14:98.3
-53,1,14:98.3
-53,2,14:98.3
-53,3,14:98.3
-53,4,14:98.3
-53,5,14:98.3
-53,6,14:98.3
-53,31,14:98
-53,32,14:98
-53,-30,15:98
-53,-29,15:98
-53,31,15:98
-53,32,15:98
-53,-30,16:98
-53,-29,16:98
-53,31,16:98
-53,32,16:98
-53,-30,17:98
-53,-29,17:98
-53,31,17:98
-53,32,17:98
-53,-30,18:98
-53,-29,18:98
-53,31,18:98
-53,32,18:98
-53,-30,19:98
-53,-29,19:98
-53,31,19:98
-53,32,19:98
-53,-30,20:98
-53,-29,20:98
-53,31,20:98
-53,32,20:98
-53,-30,21:98
-53,-29,21:98
-53,31,21:98
-53,32,21:98
-53,-34,22:5.1
-53,-33,22:5.1
-53,-32,22:5.1
-53,-31,22:5.1
-53,-30,22:5.1
-53,-29,22:5.1
-53,-28,22:5.1
-53,-27,22:5.1
-53,-26,22:5.1
-53,-25,22:5.1
-53,-24,22:5.1
-53,-23,22:5.1
-53,-22,22:5.1
-53,-21,22:5.1
-53,-20,22:5.1
-53,-19,22:5.1
-53,-18,22:5.1
-53,-17,22:5.1
-53,-16,22:5.1
-53,-15,22:5.1
-53,-14,22:5.1
-53,-13,22:5.1
-53,-12,22:5.1
-53,-11,22:5.1
-53,-10,22:5.1
-53,-9,22:134.3
-53,-8,22:134.1
-53,-7,22:134.1
-53,-6,22:134.1
-53,-5,22:134.1
-53,-4,22:134.1
-53,-3,22:134.1
-53,-2,22:134.1
-53,-1,22:98.3
-53,0,22:5.1
-53,1,22:5.1
-53,2,22:5.1
-53,3,22:98.3
-53,4,22:134.1
-53,5,22:134.1
-53,6,22:134.1
-53,7,22:134.1
-53,8,22:134.1
-53,9,22:134.1
-53,10,22:134.1
-53,11,22:134.2
-53,12,22:5.1
-53,13,22:5.1
-53,14,22:5.1
-53,15,22:5.1
-53,16,22:5.1
-53,17,22:5.1
-53,18,22:5.1
-53,19,22:5.1
-53,20,22:5.1
-53,21,22:5.1
-53,22,22:5.1
-53,23,22:5.1
-53,24,22:5.1
-53,25,22:5.1
-53,26,22:5.1
-53,27,22:5.1
-53,28,22:5.1
-53,29,22:5.1
-53,30,22:5.1
-53,31,22:5.1
-53,32,22:5.1
-53,33,22:5.1
-53,34,22:5.1
-53,35,22:5.1
-53,36,22:5.1
-53,-35,23:95.14
-53,-34,23:98.3
-53,-33,23:98.3
-53,-32,23:2
-53,-31,23:2
-53,-30,23:2
-53,-29,23:5.1
-53,-28,23:2
-53,-27,23:2
-53,-26,23:2
-53,-25,23:2
-53,-24,23:2
-53,-23,23:2
-53,-22,23:2
-53,-21,23:126.5
-53,-20,23:126.5
-53,-19,23:126.5
-53,23,23:126.5
-53,24,23:126.5
-53,25,23:164.3
-53,26,23:5.5
-53,27,23:2
-53,28,23:5.1
-53,29,23:159.13
-53,30,23:2
-53,31,23:2
-53,32,23:2
-53,33,23:2
-53,34,23:2
-53,35,23:98.3
-53,36,23:98.3
-53,37,23:95.14
-53,-35,24:95.14
-53,-32,24:31.1
-53,-30,24:31.1
-53,-28,24:31.2
-53,-27,24:31.1
-53,-26,24:31.2
-53,-25,24:38.8
-53,-24,24:31.1
-53,27,24:31.2
-53,30,24:31.1
-53,31,24:38.8
-53,32,24:38
-53,33,24:31.2
-53,34,24:31.1
-53,37,24:95.14
-53,-35,25:95.14
-53,37,25:95.14
-53,-35,26:95.14
-53,37,26:95.14
-53,-35,27:95.14
-53,37,27:95.14
-53,-35,28:95.14
-53,37,28:95.14
-53,-35,29:95.14
-53,37,29:95.14
-53,-35,30:95.14
-53,37,30:95.14
-53,-35,31:95.14
-53,37,31:95.14
-53,-35,32:95.14
-53,37,32:95.14
-53,-35,33:95.14
-53,37,33:95.14
-53,-35,34:95.14
-53,37,34:95.14
-53,-35,35:95.14
-53,37,35:95.14
-53,-35,36:95.14
-53,37,36:95.14
-53,-35,37:95.14
-53,37,37:95.14
-53,-35,38:95.14
-53,37,38:95.14
-53,-35,39:5.1
-53,-34,39:5.1
-53,-33,39:5.1
-53,35,39:5.1
-53,36,39:5.1
-53,37,39:5.1
-53,-35,40:5.1
-53,37,40:5.1
-53,-35,41:5.1
-53,-34,41:5.1
-53,-33,41:5.1
-53,-31,41:109.5
-53,-30,41:109.5
-53,32,41:109.5
-53,33,41:109.5
-53,35,41:5.1
-53,36,41:5.1
-53,37,41:5.1
-53,-35,42:5.1
-53,-34,42:5.1
-53,-33,42:5.1
-53,-31,42:109.1
-53,-30,42:109.3
-53,32,42:109.2
-53,33,42:109.1
-53,35,42:5.1
-53,36,42:5.1
-53,37,42:5.1
-52,-29,5:1
-52,-28,5:1
-52,-27,5:1
-52,-26,5:1
-52,-25,5:1
-52,-24,5:1
-52,-23,5:1
-52,-22,5:1
-52,-21,5:1
-52,-20,5:1
-52,-19,5:1
-52,-18,5:1
-52,-17,5:1
-52,-16,5:1
-52,-15,5:1
-52,-14,5:1
-52,-13,5:1
-52,-12,5:1
-52,-11,5:1
-52,-10,5:1
-52,-9,5:1
-52,-8,5:1
-52,-7,5:1
-52,-6,5:1
-52,-5,5:1
-52,-4,5:1
-52,-3,5:1
-52,-2,5:1
-52,-1,5:1
-52,0,5:1
-52,1,5:1
-52,2,5:1
-52,3,5:1
-52,4,5:1
-52,5,5:1
-52,6,5:1
-52,7,5:1
-52,8,5:1
-52,9,5:1
-52,10,5:1
-52,11,5:1
-52,12,5:1
-52,13,5:1
-52,14,5:1
-52,15,5:1
-52,16,5:1
-52,17,5:1
-52,18,5:1
-52,19,5:1
-52,20,5:1
-52,21,5:1
-52,22,5:1
-52,23,5:1
-52,24,5:1
-52,25,5:1
-52,26,5:1
-52,27,5:1
-52,28,5:1
-52,29,5:1
-52,30,5:1
-52,31,5:1
-52,-29,6:12
-52,-28,6:12
-52,-27,6:12
-52,-26,6:12
-52,-25,6:12
-52,-24,6:12
-52,-23,6:12
-52,-22,6:12
-52,-21,6:12
-52,-20,6:12
-52,-19,6:12
-52,-18,6:12
-52,-17,6:12
-52,-16,6:12
-52,-15,6:12
-52,-14,6:12
-52,-13,6:12
-52,-12,6:12
-52,-11,6:12
-52,-10,6:12
-52,-9,6:12
-52,-8,6:12
-52,-7,6:12
-52,-6,6:12
-52,-5,6:12
-52,-4,6:12
-52,-3,6:12
-52,-2,6:12
-52,-1,6:12
-52,0,6:13
-52,1,6:13
-52,2,6:13
-52,3,6:12
-52,4,6:12
-52,5,6:12
-52,6,6:12
-52,7,6:12
-52,8,6:12
-52,9,6:12
-52,10,6:12
-52,11,6:12
-52,12,6:12
-52,13,6:12
-52,14,6:12
-52,15,6:12
-52,16,6:12
-52,17,6:12
-52,18,6:12
-52,19,6:12
-52,20,6:12
-52,21,6:12
-52,22,6:12
-52,23,6:12
-52,24,6:12
-52,25,6:12
-52,26,6:12
-52,27,6:12
-52,28,6:12
-52,29,6:12
-52,30,6:12
-52,31,6:12
-52,-31,7:98
-52,-4,7:98.3
-52,-3,7:98.3
-52,5,7:98.3
-52,6,7:98.3
-52,33,7:98
-52,-31,8:98
-52,-5,8:98.3
-52,-4,8:98.3
-52,6,8:98.3
-52,7,8:98.3
-52,33,8:98
-52,-31,9:98
-52,-5,9:98.3
-52,-4,9:44.13
-52,6,9:44.13
-52,7,9:98.3
-52,33,9:98
-52,-31,10:98
-52,-5,10:98.3
-52,-4,10:44.5
-52,6,10:44.5
-52,7,10:98.3
-52,33,10:98
-52,-31,11:98
-52,-4,11:98.3
-52,6,11:98.3
-52,33,11:98
-52,-31,12:98
-52,-4,12:98.3
-52,-3,12:98.3
-52,5,12:98.3
-52,6,12:98.3
-52,33,12:98
-52,-31,13:98
-52,-4,13:98.3
-52,-3,13:98.3
-52,-2,13:98.3
-52,-1,13:98.3
-52,3,13:98.3
-52,4,13:98.3
-52,5,13:98.3
-52,6,13:98.3
-52,33,13:98
-52,-31,14:98
-52,-4,14:98.3
-52,-3,14:98.3
-52,-2,14:98.3
-52,-1,14:98.3
-52,0,14:98.3
-52,1,14:98.3
-52,2,14:98.3
-52,3,14:98.3
-52,4,14:98.3
-52,5,14:98.3
-52,6,14:98.3
-52,33,14:98
-52,-31,15:98
-52,33,15:98
-52,-31,16:98
-52,33,16:98
-52,-31,17:98
-52,33,17:98
-52,-31,18:98
-52,33,18:98
-52,-31,19:98
-52,33,19:98
-52,-31,20:98
-52,33,20:98
-52,-31,21:98
-52,33,21:98
-52,-35,22:5.1
-52,-34,22:5.1
-52,-33,22:5.1
-52,-32,22:5.1
-52,-31,22:5.1
-52,-30,22:5.1
-52,-29,22:5.1
-52,-28,22:5.1
-52,-27,22:5.1
-52,-26,22:5.1
-52,-25,22:5.1
-52,-24,22:5.1
-52,-23,22:5.1
-52,-22,22:5.1
-52,-21,22:5.1
-52,-20,22:5.1
-52,-19,22:5.1
-52,-18,22:5.1
-52,-17,22:5.1
-52,-16,22:5.1
-52,-15,22:5.1
-52,-14,22:134.3
-52,-13,22:134.1
-52,-12,22:134.1
-52,-11,22:134.1
-52,-10,22:134.1
-52,-9,22:134.1
-52,-8,22:35.7
-52,-7,22:35.7
-52,-6,22:35.7
-52,-5,22:35.7
-52,-4,22:35.7
-52,-3,22:35.7
-52,-2,22:35.7
-52,-1,22:98.3
-52,0,22:5.1
-52,1,22:98.3
-52,2,22:5.1
-52,3,22:98.3
-52,4,22:35.7
-52,5,22:35.7
-52,6,22:35.7
-52,7,22:35.7
-52,8,22:35.7
-52,9,22:35.7
-52,10,22:35.7
-52,11,22:134.1
-52,12,22:134.1
-52,13,22:134.1
-52,14,22:134.1
-52,15,22:134.1
-52,16,22:134.1
-52,17,22:5.1
-52,18,22:5.1
-52,19,22:5.1
-52,20,22:5.1
-52,21,22:5.1
-52,22,22:5.1
-52,23,22:5.1
-52,24,22:5.1
-52,25,22:5.1
-52,26,22:5.1
-52,27,22:5.1
-52,28,22:5.1
-52,29,22:5.1
-52,30,22:5.1
-52,31,22:5.1
-52,32,22:5.1
-52,33,22:5.1
-52,34,22:5.1
-52,35,22:5.1
-52,36,22:5.1
-52,37,22:5.1
-52,-37,23:95.14
-52,-36,23:95.14
-52,-35,23:98.3
-52,-34,23:98.3
-52,-33,23:2
-52,-32,23:2
-52,-31,23:2
-52,-30,23:2
-52,-29,23:2
-52,-28,23:2
-52,-27,23:2
-52,-26,23:2
-52,-25,23:2
-52,-24,23:126.5
-52,-23,23:164.2
-52,-22,23:126.5
-52,-21,23:5.5
-52,26,23:126.5
-52,27,23:126.5
-52,28,23:164.3
-52,29,23:126.5
-52,30,23:2
-52,31,23:2
-52,32,23:5.1
-52,33,23:2
-52,34,23:2
-52,35,23:2
-52,36,23:98.3
-52,37,23:98.3
-52,38,23:95.14
-52,39,23:95.14
-52,-37,24:95.14
-52,-36,24:95.14
-52,-31,24:31.1
-52,-30,24:31.2
-52,-29,24:31.1
-52,-26,24:31.1
-52,30,24:31.2
-52,31,24:31.1
-52,33,24:18.4
-52,34,24:18.12
-52,38,24:95.14
-52,39,24:95.14
-52,-37,25:95.14
-52,-36,25:95.14
-52,38,25:95.14
-52,39,25:95.14
-52,-37,26:95.14
-52,-36,26:95.14
-52,38,26:95.14
-52,39,26:95.14
-52,-37,27:95.14
-52,-36,27:95.14
-52,38,27:95.14
-52,39,27:95.14
-52,-37,28:95.14
-52,-36,28:95.14
-52,38,28:95.14
-52,39,28:95.14
-52,-37,29:95.14
-52,-36,29:95.14
-52,38,29:95.14
-52,39,29:95.14
-52,-37,30:95.14
-52,-36,30:95.14
-52,38,30:95.14
-52,39,30:95.14
-52,-37,31:95.14
-52,-36,31:95.14
-52,38,31:95.14
-52,39,31:95.14
-52,-37,32:95.14
-52,-36,32:95.14
-52,38,32:95.14
-52,39,32:95.14
-52,-37,33:95.14
-52,-36,33:95.14
-52,38,33:95.14
-52,39,33:95.14
-52,-37,34:95.14
-52,-36,34:95.14
-52,38,34:95.14
-52,39,34:95.14
-52,-37,35:95.14
-52,-36,35:95.14
-52,38,35:95.14
-52,39,35:95.14
-52,-37,36:95.14
-52,-36,36:95.14
-52,38,36:95.14
-52,39,36:95.14
-52,-37,37:95.14
-52,-36,37:95.14
-52,38,37:95.14
-52,39,37:95.14
-52,-37,38:95.14
-52,-36,38:95.14
-52,38,38:95.14
-52,39,38:95.14
-52,-37,39:5.1
-52,-36,39:5.1
-52,-35,39:5.1
-52,-34,39:5.1
-52,36,39:5.1
-52,37,39:5.1
-52,38,39:5.1
-52,39,39:5.1
-52,-37,40:5.1
-52,-36,40:5.1
-52,38,40:5.1
-52,39,40:5.1
-52,-37,41:5.1
-52,-36,41:5.1
-52,-35,41:5.1
-52,-34,41:5.1
-52,-33,41:109.3
-52,35,41:109.2
-52,36,41:5.1
-52,37,41:5.1
-52,38,41:5.1
-52,39,41:5.1
-52,-37,42:5.1
-52,-36,42:5.1
-52,-35,42:5.1
-52,-34,42:5.1
-52,-33,42:109.7
-52,35,42:109.6
-52,36,42:5.1
-52,37,42:5.1
-52,38,42:5.1
-52,39,42:5.1
-52,-34,43:98.3
-52,-33,43:109.3
-52,35,43:109.2
-52,36,43:98.3
-51,-31,5:1
-51,-30,5:1
-51,-29,5:1
-51,-28,5:1
-51,-27,5:1
-51,-26,5:1
-51,-25,5:1
-51,-24,5:1
-51,-23,5:1
-51,-22,5:1
-51,-21,5:1
-51,-20,5:1
-51,-19,5:1
-51,-18,5:1
-51,-17,5:1
-51,-16,5:1
-51,-15,5:1
-51,-14,5:1
-51,-13,5:1
-51,-12,5:1
-51,-11,5:1
