[META]
version=2.0
spawnOnBlockType=2
spawnSunlight=True
spawnDarkness=False
spawnWater=False
spawnLava=False
underFill=True
randomRotation=True
dig=True
tree=True
branch=False
needsFoundation=True
rarity=1
collisionPercentage=1
spawnElevationMin=0
spawnElevationMax=256
spawnInBiome=Jungle
[DATA]
-7,-8,0:20
-7,-7,0:20
-7,-6,0:20
-7,-5,0:20
-7,-4,0:20
-7,-3,0:20
-7,-2,0:20
-7,-1,0:20
-7,0,0:20
-7,1,0:20
-7,2,0:20
-7,3,0:20
-7,4,0:20
-7,5,0:20
-7,6,0:20
-7,7,0:20
-7,-8,1:20
-7,-7,1:20
-7,-6,1:20
-7,-5,1:20
-7,-4,1:20
-7,-3,1:20
-7,-2,1:20
-7,-1,1:20
-7,0,1:20
-7,1,1:20
-7,2,1:20
-7,3,1:20
-7,4,1:20
-7,5,1:20
-7,6,1:20
-7,7,1:20
-7,-8,2:20
-7,-7,2:20
-7,-6,2:20
-7,-5,2:20
-7,-4,2:20
-7,-3,2:20
-7,-2,2:20
-7,-1,2:20
-7,0,2:20
-7,1,2:20
-7,2,2:20
-7,3,2:20
-7,4,2:20
-7,5,2:20
-7,6,2:20
-7,7,2:20
-7,-8,3:20
-7,-7,3:20
-7,-6,3:20
-7,-5,3:20
-7,-4,3:20
-7,-3,3:20
-7,-2,3:20
-7,-1,3:20
-7,0,3:20
-7,1,3:20
-7,2,3:20
-7,3,3:20
-7,4,3:20
-7,5,3:20
-7,6,3:20
-7,7,3:20
-7,-8,4:20
-7,-7,4:20
-7,-6,4:20
-7,-5,4:20
-7,-4,4:20
-7,-3,4:20
-7,-2,4:20
-7,-1,4:20
-7,0,4:20
-7,1,4:20
-7,2,4:20
-7,3,4:20
-7,4,4:20
-7,5,4:20
-7,6,4:20
-7,7,4:20
-7,-8,5:20
-7,-7,5:20
-7,-6,5:20
-7,-5,5:20
-7,-4,5:20
-7,-3,5:20
-7,-2,5:20
-7,-1,5:20
-7,0,5:20
-7,1,5:20
-7,2,5:20
-7,3,5:20
-7,4,5:20
-7,5,5:20
-7,6,5:20
-7,7,5:20
-7,-8,6:20
-7,-7,6:20
-7,-6,6:20
-7,-5,6:20
-7,-4,6:20
-7,-3,6:20
-7,-2,6:20
-7,-1,6:20
-7,0,6:20
-7,1,6:20
-7,2,6:20
-7,3,6:20
-7,4,6:20
-7,5,6:20
-7,6,6:20
-7,7,6:20
-7,-8,7:20
-7,-7,7:20
-7,-6,7:20
-7,-5,7:20
-7,-4,7:20
-7,-3,7:20
-7,-2,7:20
-7,-1,7:20
-7,0,7:20
-7,1,7:20
-7,2,7:20
-7,3,7:20
-7,4,7:20
-7,5,7:20
-7,6,7:20
-7,7,7:20
-7,-8,8:20
-7,-7,8:20
-7,-6,8:20
-7,-5,8:20
-7,-4,8:20
-7,-3,8:20
-7,-2,8:20
-7,-1,8:20
-7,0,8:20
-7,1,8:20
-7,2,8:20
-7,3,8:20
-7,4,8:20
-7,5,8:20
-7,6,8:20
-7,7,8:20
-7,-8,9:20
-7,-7,9:20
-7,-6,9:20
-7,-5,9:20
-7,-4,9:20
-7,-3,9:20
-7,-2,9:20
-7,-1,9:20
-7,0,9:20
-7,1,9:20
-7,2,9:20
-7,3,9:20
-7,4,9:20
-7,5,9:20
-7,6,9:20
-7,7,9:20
-7,-8,10:20
-7,-7,10:20
-7,-6,10:20
-7,-5,10:20
-7,-4,10:20
-7,-3,10:20
-7,-2,10:20
-7,-1,10:20
-7,0,10:20
-7,1,10:20
-7,2,10:20
-7,3,10:20
-7,4,10:20
-7,5,10:20
-7,6,10:20
-7,7,10:20
-6,-8,0:20
-6,-7,0:20
-6,-6,0:20
-6,-5,0:20
-6,-4,0:20
-6,-3,0:20
-6,-2,0:20
-6,-1,0:20
-6,0,0:20
-6,1,0:20
-6,2,0:20
-6,3,0:20
-6,4,0:20
-6,5,0:20
-6,6,0:20
-6,7,0:20
-6,-8,1:20
-6,7,1:20
-6,-8,2:20
-6,7,2:20
-6,-8,3:20
-6,7,3:20
-6,-8,4:20
-6,7,4:20
-6,-8,5:20
-6,7,5:20
-6,-8,6:20
-6,7,6:20
-6,-8,7:20
-6,7,7:20
-6,-8,8:20
-6,7,8:20
-6,-8,9:20
-6,7,9:20
-6,-8,10:20
-6,7,10:20
-5,-8,0:20
-5,-7,0:20
-5,-6,0:20
-5,-5,0:20
-5,-4,0:20
-5,-3,0:20
-5,-2,0:20
-5,-1,0:20
-5,0,0:20
-5,1,0:20
-5,2,0:20
-5,3,0:20
-5,4,0:20
-5,5,0:20
-5,6,0:20
-5,7,0:20
-5,-8,1:20
-5,7,1:20
-5,-8,2:20
-5,7,2:20
-5,-8,3:20
-5,7,3:20
-5,-8,4:20
-5,7,4:20
-5,-8,5:20
-5,7,5:20
-5,-8,6:20
-5,7,6:20
-5,-8,7:20
-5,7,7:20
-5,-8,8:20
-5,7,8:20
-5,-8,9:20
-5,7,9:20
-5,-8,10:20
-5,7,10:20
-4,-8,0:20
-4,-7,0:20
-4,-6,0:20
-4,-5,0:20
-4,-4,0:20
-4,-3,0:20
-4,-2,0:20
-4,-1,0:20
-4,0,0:20
-4,1,0:20
-4,2,0:20
-4,3,0:20
-4,4,0:20
-4,5,0:20
-4,6,0:20
-4,7,0:20
-4,-8,1:20
-4,7,1:20
-4,-8,2:20
-4,7,2:20
-4,-8,3:20
-4,7,3:20
-4,-8,4:20
-4,7,4:20
-4,-8,5:20
-4,7,5:20
-4,-8,6:20
-4,7,6:20
-4,-8,7:20
-4,7,7:20
-4,-8,8:20
-4,7,8:20
-4,-8,9:20
-4,7,9:20
-4,-8,10:20
-4,7,10:20
-3,-8,0:20
-3,-7,0:20
-3,-6,0:20
-3,-5,0:20
-3,-4,0:20
-3,-3,0:20
-3,-2,0:20
-3,-1,0:20
-3,0,0:20
-3,1,0:20
-3,2,0:20
-3,3,0:20
-3,4,0:20
-3,5,0:20
-3,6,0:20
-3,7,0:20
-3,-8,1:20
-3,7,1:20
-3,-8,2:20
-3,7,2:20
-3,-8,3:20
-3,7,3:20
-3,-8,4:20
-3,7,4:20
-3,-8,5:20
-3,7,5:20
-3,-8,6:20
-3,7,6:20
-3,-8,7:20
-3,7,7:20
-3,-8,8:20
-3,7,8:20
-3,-8,9:20
-3,7,9:20
-3,-8,10:20
-3,7,10:20
-2,-8,0:20
-2,-7,0:20
-2,-6,0:20
-2,-5,0:20
-2,-4,0:20
-2,-3,0:20
-2,-2,0:20
-2,-1,0:20
-2,0,0:20
-2,1,0:20
-2,2,0:20
-2,3,0:20
-2,4,0:20
-2,5,0:20
-2,6,0:20
-2,7,0:20
-2,-8,1:20
-2,7,1:20
-2,-8,2:20
-2,7,2:20
-2,-8,3:20
-2,7,3:20
-2,-8,4:20
-2,7,4:20
-2,-8,5:20
-2,7,5:20
-2,-8,6:20
-2,7,6:20
-2,-8,7:20
-2,7,7:20
-2,-8,8:20
-2,7,8:20
-2,-8,9:20
-2,7,9:20
-2,-8,10:20
-2,7,10:20
-1,-8,0:20
-1,-7,0:20
-1,-6,0:20
-1,-5,0:20
-1,-4,0:20
-1,-3,0:20
-1,-2,0:20
-1,-1,0:20
-1,0,0:20
-1,1,0:20
-1,2,0:20
-1,3,0:20
-1,4,0:20
-1,5,0:20
-1,6,0:20
-1,7,0:20
-1,-8,1:20
-1,7,1:20
-1,-8,2:20
-1,7,2:20
-1,-8,3:20
-1,7,3:20
-1,-8,4:20
-1,7,4:20
-1,-8,5:20
-1,7,5:20
-1,-8,6:20
-1,7,6:20
-1,-8,7:20
-1,7,7:20
-1,-8,8:20
-1,7,8:20
-1,-8,9:20
-1,7,9:20
-1,-8,10:20
-1,7,10:20
0,-8,0:20
0,-7,0:20
0,-6,0:20
0,-5,0:20
0,-4,0:20
0,-3,0:20
0,-2,0:20
0,-1,0:20
0,0,0:20
0,1,0:20
0,2,0:20
0,3,0:20
0,4,0:20
0,5,0:20
0,6,0:20
0,7,0:20
0,-8,1:20
0,7,1:20
0,-8,2:20
0,7,2:20
0,-8,3:20
0,7,3:20
0,-8,4:20
0,7,4:20
0,-8,5:20
0,7,5:20
0,-8,6:20
0,7,6:20
0,-8,7:20
0,7,7:20
0,-8,8:20
0,7,8:20
0,-8,9:20
0,7,9:20
0,-8,10:20
0,7,10:20
1,-8,0:20
1,-7,0:20
1,-6,0:20
1,-5,0:20
1,-4,0:20
1,-3,0:20
1,-2,0:20
1,-1,0:20
1,0,0:20
1,1,0:20
1,2,0:20
1,3,0:20
1,4,0:20
1,5,0:20
1,6,0:20
1,7,0:20
1,-8,1:20
1,7,1:20
1,-8,2:20
1,7,2:20
1,-8,3:20
1,7,3:20
1,-8,4:20
1,7,4:20
1,-8,5:20
1,7,5:20
1,-8,6:20
1,7,6:20
1,-8,7:20
1,7,7:20
1,-8,8:20
1,7,8:20
1,-8,9:20
1,7,9:20
1,-8,10:20
1,7,10:20
2,-8,0:20
2,-7,0:20
2,-6,0:20
2,-5,0:20
2,-4,0:20
2,-3,0:20
2,-2,0:20
2,-1,0:20
2,0,0:20
2,1,0:20
2,2,0:20
2,3,0:20
2,4,0:20
2,5,0:20
2,6,0:20
2,7,0:20
2,-8,1:20
2,7,1:20
2,-8,2:20
2,7,2:20
2,-8,3:20
2,7,3:20
2,-8,4:20
2,7,4:20
2,-8,5:20
2,7,5:20
2,-8,6:20
2,7,6:20
2,-8,7:20
2,7,7:20
2,-8,8:20
2,7,8:20
2,-8,9:20
2,7,9:20
2,-8,10:20
2,7,10:20
3,-8,0:20
3,-7,0:20
3,-6,0:20
3,-5,0:20
3,-4,0:20
3,-3,0:20
3,-2,0:20
3,-1,0:20
3,0,0:20
3,1,0:20
3,2,0:20
3,3,0:20
3,4,0:20
3,5,0:20
3,6,0:20
3,7,0:20
3,-8,1:20
3,7,1:20
3,-8,2:20
3,7,2:20
3,-8,3:20
3,7,3:20
3,-8,4:20
3,7,4:20
3,-8,5:20
3,7,5:20
3,-8,6:20
3,7,6:20
3,-8,7:20
3,7,7:20
3,-8,8:20
3,7,8:20
3,-8,9:20
3,7,9:20
3,-8,10:20
3,7,10:20
4,-8,0:20
4,-7,0:20
4,-6,0:20
4,-5,0:20
4,-4,0:20
4,-3,0:20
4,-2,0:20
4,-1,0:20
4,0,0:20
4,1,0:20
4,2,0:20
4,3,0:20
4,4,0:20
4,5,0:20
4,6,0:20
4,7,0:20
4,-8,1:20
4,7,1:20
4,-8,2:20
4,7,2:20
4,-8,3:20
4,7,3:20
4,-8,4:20
4,7,4:20
4,-8,5:20
4,7,5:20
4,-8,6:20
4,7,6:20
4,-8,7:20
4,7,7:20
4,-8,8:20
4,7,8:20
4,-8,9:20
4,7,9:20
4,-8,10:20
4,7,10:20
5,-8,0:20
5,-7,0:20
5,-6,0:20
5,-5,0:20
5,-4,0:20
5,-3,0:20
5,-2,0:20
5,-1,0:20
5,0,0:20
5,1,0:20
5,2,0:20
5,3,0:20
5,4,0:20
5,5,0:20
5,6,0:20
5,7,0:20
5,-8,1:20
5,7,1:20
5,-8,2:20
5,7,2:20
5,-8,3:20
5,7,3:20
5,-8,4:20
5,7,4:20
5,-8,5:20
5,7,5:20
5,-8,6:20
5,7,6:20
5,-8,7:20
5,7,7:20
5,-8,8:20
5,7,8:20
5,-8,9:20
5,7,9:20
5,-8,10:20
5,7,10:20
6,-8,0:20
6,-7,0:20
6,-6,0:20
6,-5,0:20
6,-4,0:20
6,-3,0:20
6,-2,0:20
6,-1,0:20
6,0,0:20
6,1,0:20
6,2,0:20
6,3,0:20
6,4,0:20
6,5,0:20
6,6,0:20
6,7,0:20
6,-8,1:20
6,7,1:20
6,-8,2:20
6,7,2:20
6,-8,3:20
6,7,3:20
6,-8,4:20
6,7,4:20
6,-8,5:20
6,7,5:20
6,-8,6:20
6,7,6:20
6,-8,7:20
6,7,7:20
6,-8,8:20
6,7,8:20
6,-8,9:20
6,7,9:20
6,-8,10:20
6,7,10:20
7,-8,0:20
7,-7,0:20
7,-6,0:20
7,-5,0:20
7,-4,0:20
7,-3,0:20
7,-2,0:20
7,-1,0:20
7,0,0:20
7,1,0:20
7,2,0:20
7,3,0:20
7,4,0:20
7,5,0:20
7,6,0:20
7,7,0:20
7,-8,1:20
7,-7,1:20
7,-6,1:20
7,-5,1:20
7,-4,1:20
7,-3,1:20
7,-2,1:20
7,-1,1:20
7,0,1:20
7,1,1:20
7,2,1:20
7,3,1:20
7,4,1:20
7,5,1:20
7,6,1:20
7,7,1:20
7,-8,2:20
7,-7,2:20
7,-6,2:20
7,-5,2:20
7,-4,2:20
7,-3,2:20
7,-2,2:20
7,-1,2:20
7,0,2:20
7,1,2:20
7,2,2:20
7,3,2:20
7,4,2:20
7,5,2:20
7,6,2:20
7,7,2:20
7,-8,3:20
7,-7,3:20
7,-6,3:20
7,-5,3:20
7,-4,3:20
7,-3,3:20
7,-2,3:20
7,-1,3:20
7,0,3:20
7,1,3:20
7,2,3:20
7,3,3:20
7,4,3:20
7,5,3:20
7,6,3:20
7,7,3:20
7,-8,4:20
7,-7,4:20
7,-6,4:20
7,-5,4:20
7,-4,4:20
7,-3,4:20
7,-2,4:20
7,-1,4:20
7,0,4:20
7,1,4:20
7,2,4:20
7,3,4:20
7,4,4:20
7,5,4:20
7,6,4:20
7,7,4:20
7,-8,5:20
7,-7,5:20
7,-6,5:20
7,-5,5:20
7,-4,5:20
7,-3,5:20
7,-2,5:20
7,-1,5:20
7,0,5:20
7,1,5:20
7,2,5:20
7,3,5:20
7,4,5:20
7,5,5:20
7,6,5:20
7,7,5:20
7,-8,6:20
7,-7,6:20
7,-6,6:20
7,-5,6:20
7,-4,6:20
7,-3,6:20
7,-2,6:20
7,-1,6:20
7,0,6:20
7,1,6:20
7,2,6:20
7,3,6:20
7,4,6:20
7,5,6:20
7,6,6:20
7,7,6:20
7,-8,7:20
7,-7,7:20
7,-6,7:20
7,-5,7:20
7,-4,7:20
7,-3,7:20
7,-2,7:20
7,-1,7:20
7,0,7:20
7,1,7:20
7,2,7:20
7,3,7:20
7,4,7:20
7,5,7:20
7,6,7:20
7,7,7:20
7,-8,8:20
7,-7,8:20
7,-6,8:20
7,-5,8:20
7,-4,8:20
7,-3,8:20
7,-2,8:20
7,-1,8:20
7,0,8:20
7,1,8:20
7,2,8:20
7,3,8:20
7,4,8:20
7,5,8:20
7,6,8:20
7,7,8:20
7,-8,9:20
7,-7,9:20
7,-6,9:20
7,-5,9:20
7,-4,9:20
7,-3,9:20
7,-2,9:20
7,-1,9:20
7,0,9:20
7,1,9:20
7,2,9:20
7,3,9:20
7,4,9:20
7,5,9:20
7,6,9:20
7,7,9:20
7,-8,10:20
7,-7,10:20
7,-6,10:20
7,-5,10:20
7,-4,10:20
7,-3,10:20
7,-2,10:20
7,-1,10:20
7,0,10:20
7,1,10:20
7,2,10:20
7,3,10:20
7,4,10:20
7,5,10:20
7,6,10:20
7,7,10:20
