[META]
version=2.0
spawnOnBlockType=2
spawnSunlight=True
spawnDarkness=False
spawnWater=False
spawnLava=False
underFill=True
randomRotation=True
dig=True
tree=True
branch=False
needsFoundation=True
rarity=1
collisionPercentage=1
spawnElevationMin=0
spawnElevationMax=256
spawnInBiome=Jungle
[DATA]
-7,-2,0:44
-7,-1,0:44
-7,0,0:44
-7,1,0:44
-7,2,0:44
-6,-4,0:44
-6,-3,0:44
-6,-2,0:98
-6,-1,0:98
-6,0,0:98
-6,1,0:98
-6,2,0:109.4
-6,3,0:44
-6,4,0:44
-5,-5,0:44
-5,-4,0:98
-5,-3,0:98
-5,-2,0:98
-5,-1,0:98
-5,0,0:98
-5,1,0:98
-5,2,0:98
-5,3,0:98
-5,4,0:98
-5,5,0:44
-5,-4,1:109.2
-5,-3,1:109
-5,-2,1:43.8
-5,-1,1:109.2
-5,0,1:109
-5,1,1:109.3
-5,2,1:43.8
-5,3,1:109
-5,4,1:109.3
-5,-4,2:109.6
-5,-3,2:109.4
-5,-2,2:109
-5,-1,2:109.6
-5,0,2:109.4
-5,1,2:109.7
-5,2,2:109
-5,3,2:109.4
-5,4,2:109.7
-5,-1,3:109.2
-5,0,3:109
-5,1,3:109.3
-5,0,4:139
-5,0,5:139
-5,-1,6:109.4
-5,0,6:109.4
-5,1,6:109.7
-5,-3,7:44.8
-5,-1,7:109.2
-5,0,7:109
-5,1,7:109.3
-5,3,7:44.8
-5,-3,8:43
-5,-2,8:43.8
-5,-1,8:43.8
-5,0,8:43.8
-5,1,8:43.8
-5,2,8:43.8
-5,3,8:43
-4,-6,0:44
-4,-5,0:98
-4,-4,0:98
-4,-3,0:98
-4,-2,0:98
-4,-1,0:98
-4,0,0:98
-4,1,0:98
-4,2,0:98
-4,3,0:98
-4,4,0:98
-4,5,0:98
-4,6,0:44
-4,-5,1:109
-4,-4,1:43.8
-4,-3,1:43.8
-4,-2,1:108
-4,-1,1:43.8
-4,0,1:43.8
-4,1,1:43.8
-4,2,1:108
-4,3,1:43.8
-4,4,1:43.8
-4,5,1:109
-4,-5,2:109.4
-4,-4,2:43.8
-4,-3,2:43.8
-4,-2,2:4
-4,-1,2:43.8
-4,0,2:43.8
-4,1,2:43.8
-4,2,2:4
-4,3,2:43.8
-4,4,2:43.8
-4,5,2:109.4
-4,-1,3:109.2
-4,0,3:4
-4,1,3:109.3
-4,-1,4:139
-4,0,4:4
-4,1,4:139
-4,-1,5:139
-4,0,5:4
-4,1,5:139
-4,-1,6:109.6
-4,0,6:4
-4,1,6:109.7
-4,-3,7:44.8
-4,-1,7:109.2
-4,0,7:4
-4,1,7:109.3
-4,3,7:44.8
-4,-4,8:43
-4,-3,8:49
-4,-2,8:43.8
-4,-1,8:43.8
-4,0,8:43.8
-4,1,8:43.8
-4,2,8:43.8
-4,3,8:49
-4,4,8:43
-4,-3,9:44
-4,-2,9:159.9
-4,-1,9:159.9
-4,0,9:159.9
-4,1,9:159.9
-4,2,9:159.9
-4,3,9:44
-4,-2,10:67.4
-4,-1,10:4
-4,0,10:4
-4,1,10:4
-4,2,10:67.4
-4,-3,11:67.4
-4,-2,11:67
-4,2,11:67
-4,3,11:67.4
-4,-3,12:67
-4,3,12:67
-4,-3,15:67.4
-4,3,15:67.4
-4,-3,16:67
-4,-2,16:67.4
-4,2,16:67.4
-4,3,16:67
-4,-2,17:67
-4,2,17:67
-4,-2,18:4
-4,-1,18:4
-4,0,18:4
-4,1,18:4
-4,2,18:4
-4,-2,20:4
-4,-1,20:4
-4,0,20:4
-4,1,20:4
-4,2,20:4
-3,-6,0:44
-3,-5,0:98
-3,-4,0:98
-3,-3,0:98
-3,-2,0:98
-3,-1,0:98
-3,0,0:98
-3,1,0:98
-3,2,0:98
-3,3,0:98
-3,4,0:98
-3,5,0:98
-3,6,0:44
-3,-5,1:109.2
-3,-4,1:43.8
-3,-3,1:43.8
-3,-2,1:108.2
-3,-1,1:43.8
-3,0,1:43.8
-3,1,1:43.8
-3,2,1:108.3
-3,3,1:43.8
-3,4,1:43.8
-3,5,1:109.3
-3,-5,2:109.6
-3,-4,2:43.8
-3,-3,2:43.8
-3,-2,2:4
-3,-1,2:43.8
-3,0,2:43.8
-3,1,2:43.8
-3,2,2:4
-3,3,2:43.8
-3,4,2:43.8
-3,5,2:109.7
-3,-1,3:109.2
-3,0,3:109.1
-3,1,3:109.1
-3,0,4:139
-3,0,5:139
-3,-1,6:109.5
-3,0,6:109.5
-3,1,6:109.5
-3,-5,7:44.8
-3,-4,7:44.8
-3,-3,7:44.8
-3,-1,7:109.1
-3,0,7:109.1
-3,1,7:109.1
-3,3,7:44.8
-3,4,7:44.8
-3,5,7:44.8
-3,-5,8:43
-3,-4,8:49
-3,-3,8:49
-3,-2,8:43.8
-3,-1,8:43.8
-3,0,8:43.8
-3,1,8:43.8
-3,2,8:43.8
-3,3,8:49
-3,4,8:49
-3,5,8:43
-3,-4,9:44
-3,-3,9:159.9
-3,-2,9:159.9
-3,-1,9:159.9
-3,0,9:159.9
-3,1,9:159.9
-3,2,9:159.9
-3,3,9:159.9
-3,4,9:44
-3,-2,10:4
-3,-1,10:159.1
-3,0,10:159.1
-3,1,10:159.1
-3,2,10:4
-3,-4,11:67.6
-3,-2,11:4
-3,-1,11:44.8
-3,0,11:44.8
-3,1,11:44.8
-3,2,11:4
-3,4,11:67.7
-3,-4,12:67.2
-3,-3,12:4
-3,-2,12:44.8
-3,-1,12:44.8
-3,0,12:44.8
-3,1,12:44.8
-3,2,12:44.8
-3,3,12:4
-3,4,12:67.3
-3,-3,13:4
-3,-2,13:44.8
-3,-1,13:44.8
-3,0,13:44.8
-3,1,13:44.8
-3,2,13:44.8
-3,3,13:4
-3,-3,14:4
-3,-2,14:44.8
-3,-1,14:44.8
-3,0,14:44.8
-3,1,14:44.8
-3,2,14:44.8
-3,3,14:4
-3,-4,15:67.6
-3,-3,15:4
-3,-2,15:44.8
-3,-1,15:44.8
-3,0,15:44.8
-3,1,15:44.8
-3,2,15:44.8
-3,3,15:4
-3,4,15:67.7
-3,-4,16:67.2
-3,-3,16:4
-3,-2,16:4
-3,-1,16:44.8
-3,0,16:44.8
-3,1,16:44.8
-3,2,16:4
-3,3,16:4
-3,4,16:67.3
-3,-3,17:4
-3,-1,17:4
-3,0,17:4
-3,1,17:4
-3,3,17:4
-3,-3,18:4
-3,-2,18:4
-3,-1,18:4
-3,0,18:4
-3,1,18:4
-3,2,18:4
-3,3,18:4
-3,-1,19:159.9
-3,0,19:159.9
-3,1,19:159.9
-3,-3,20:4
-3,-2,20:4
-3,-1,20:4
-3,0,20:4
-3,1,20:4
-3,2,20:4
-3,3,20:4
-2,-7,0:44
-2,-6,0:98
-2,-5,0:98
-2,-4,0:98
-2,-3,0:98
-2,-2,0:98
-2,-1,0:98
-2,0,0:98
-2,1,0:98
-2,2,0:98
-2,3,0:98
-2,4,0:98
-2,5,0:98
-2,6,0:98
-2,7,0:44
-2,-5,1:43.8
-2,-4,1:108.2
-2,-3,1:108
-2,-2,1:43.8
-2,-1,1:43.8
-2,0,1:43.8
-2,1,1:43.8
-2,2,1:43.8
-2,3,1:108
-2,4,1:108.3
-2,5,1:43.8
-2,-5,2:109.2
-2,-4,2:4
-2,-3,2:4
-2,-2,2:43.8
-2,-1,2:35.7
-2,0,2:35.7
-2,1,2:35.7
-2,2,2:43.8
-2,3,2:4
-2,4,2:4
-2,5,2:109.3
-2,-5,8:43.8
-2,-4,8:43.8
-2,-3,8:43.8
-2,-2,8:43.8
-2,-1,8:43.8
-2,0,8:43.8
-2,1,8:43.8
-2,2,8:43.8
-2,3,8:43.8
-2,4,8:43.8
-2,5,8:43.8
-2,-4,9:159.9
-2,-3,9:159.9
-2,-2,9:159.9
-2,-1,9:159.9
-2,0,9:159.9
-2,1,9:159.9
-2,2,9:159.9
-2,3,9:159.9
-2,4,9:159.9
-2,-4,10:67.6
-2,-3,10:4
-2,3,10:4
-2,4,10:67.7
-2,-4,11:67.2
-2,-3,11:4
-2,-1,11:159.1
-2,0,11:159.1
-2,1,11:159.1
-2,3,11:4
-2,4,11:67.3
-2,-3,12:44.8
-2,-2,12:159.1
-2,-1,12:159.1
-2,0,12:159.1
-2,1,12:159.1
-2,2,12:159.1
-2,3,12:44.8
-2,-3,13:44.8
-2,-2,13:159.1
-2,-1,13:159.1
-2,0,13:159.1
-2,1,13:159.1
-2,2,13:159.1
-2,3,13:44.8
-2,-3,14:44.8
-2,-2,14:159.1
-2,-1,14:159.1
-2,0,14:159.1
-2,1,14:159.1
-2,2,14:159.1
-2,3,14:44.8
-2,-3,15:44.8
-2,-2,15:159.1
-2,-1,15:159.1
-2,0,15:159.1
-2,1,15:159.1
-2,2,15:159.1
-2,3,15:44.8
-2,-4,16:67.6
-2,-3,16:4
-2,-1,16:159.1
-2,0,16:159.1
-2,1,16:159.1
-2,3,16:4
-2,4,16:67.7
-2,-4,17:67.2
-2,4,17:67.3
-2,-4,18:4
-2,-3,18:4
-2,-2,18:4
-2,-1,18:4
-2,0,18:4
-2,1,18:4
-2,2,18:4
-2,3,18:4
-2,4,18:4
-2,-2,19:159.9
-2,-1,19:159.9
-2,0,19:159.9
-2,1,19:159.9
-2,2,19:159.9
-2,-4,20:4
-2,-3,20:4
-2,-2,20:4
-2,-1,20:4
-2,0,20:4
-2,1,20:4
-2,2,20:4
-2,3,20:4
-2,4,20:4
-1,-7,0:44
-1,-6,0:98
-1,-5,0:98
-1,-4,0:98
-1,-3,0:98
-1,-2,0:98
-1,-1,0:98
-1,0,0:98
-1,1,0:98
-1,2,0:98
-1,3,0:98
-1,4,0:98
-1,5,0:98
-1,6,0:98
-1,7,0:44
-1,-5,1:109
-1,-4,1:43.8
-1,-3,1:43.8
-1,-2,1:43.8
-1,-1,1:43.8
-1,0,1:43.8
-1,1,1:43.8
-1,2,1:43.8
-1,3,1:43.8
-1,4,1:43.8
-1,5,1:109
-1,-5,2:109.4
-1,-4,2:43.8
-1,-3,2:43.8
-1,-2,2:35.7
-1,-1,2:35.7
-1,0,2:43.8
-1,1,2:35.7
-1,2,2:35.7
-1,3,2:43.8
-1,4,2:43.8
-1,5,2:109.4
-1,-5,3:109
-1,-4,3:109
-1,-3,3:109.3
-1,0,3:54.4
-1,3,3:109
-1,4,3:109
-1,5,3:109
-1,-4,4:139
-1,4,4:139
-1,-4,5:139
-1,4,5:139
-1,-5,6:109.4
-1,-4,6:109.4
-1,-3,6:109.7
-1,3,6:109.6
-1,4,6:109.4
-1,5,6:109.7
-1,-5,7:109
-1,-4,7:109
-1,-3,7:109.3
-1,-1,7:44.8
-1,0,7:44.8
-1,1,7:44.8
-1,3,7:109.2
-1,4,7:109
-1,5,7:109
-1,-5,8:43.8
-1,-4,8:43.8
-1,-3,8:43.8
-1,-2,8:43.8
-1,2,8:43.8
-1,3,8:43.8
-1,4,8:43.8
-1,5,8:43.8
-1,-4,9:159.9
-1,-3,9:159.9
-1,-2,9:159.9
-1,-1,9:159.9
-1,0,9:159.9
-1,1,9:159.9
-1,2,9:159.9
-1,3,9:159.9
-1,4,9:159.9
-1,-4,10:4
-1,-3,10:159.1
-1,3,10:159.1
-1,4,10:4
-1,-3,11:44.8
-1,-2,11:159.1
-1,2,11:159.1
-1,3,11:44.8
-1,-3,12:44.8
-1,-2,12:159.1
-1,2,12:159.1
-1,3,12:44.8
-1,-3,13:44.8
-1,-2,13:159.1
-1,2,13:159.1
-1,3,13:44.8
-1,-3,14:44.8
-1,-2,14:159.1
-1,2,14:159.1
-1,3,14:44.8
-1,-3,15:44.8
-1,-2,15:159.1
-1,2,15:159.1
-1,3,15:44.8
-1,-3,16:44.8
-1,-2,16:159.1
-1,2,16:159.1
-1,3,16:44.8
-1,-3,17:4
-1,3,17:4
-1,-4,18:4
-1,-3,18:4
-1,-2,18:4
-1,-1,18:4
-1,0,18:4
-1,1,18:4
-1,2,18:4
-1,3,18:4
-1,4,18:4
-1,-3,19:159.9
-1,-2,19:159.9
-1,-1,19:159.9
-1,0,19:159.9
-1,1,19:159.9
-1,2,19:159.9
-1,3,19:159.9
-1,-4,20:4
-1,-3,20:4
-1,-2,20:4
-1,-1,20:4
-1,0,20:4
-1,1,20:4
-1,2,20:4
-1,3,20:4
-1,4,20:4
0,-7,0:44
0,-6,0:98
0,-5,0:98
0,-4,0:98
0,-3,0:98
0,-2,0:98
0,-1,0:98
0,0,0:98
0,1,0:98
0,2,0:98
0,3,0:98
0,4,0:98
0,5,0:98
0,6,0:98
0,7,0:44
0,-5,1:109.2
0,-4,1:43.8
0,-3,1:43.8
0,-2,1:43.8
0,-1,1:43.8
0,0,1:98
0,1,1:43.8
0,2,1:43.8
0,3,1:43.8
0,4,1:43.8
0,5,1:109.3
0,-5,2:109.6
0,-4,2:43.8
0,-3,2:43.8
0,-2,2:35.7
0,-1,2:43.8
0,0,2:98
0,1,2:43.8
0,2,2:35.7
0,3,2:43.8
0,4,2:43.8
0,5,2:109.7
0,-5,3:109.2
0,-4,3:4
0,-3,3:109.3
0,-1,3:54.2
0,0,3:116
0,1,3:54.3
0,3,3:109.2
0,4,3:4
0,5,3:109.3
0,-5,4:139
0,-4,4:4
0,-3,4:139
0,3,4:139
0,4,4:4
0,5,4:139
0,-5,5:139
0,-4,5:4
0,-3,5:139
0,3,5:139
0,4,5:4
0,5,5:139
0,-5,6:109.6
0,-4,6:4
0,-3,6:109.7
0,3,6:109.6
0,4,6:4
0,5,6:109.7
0,-5,7:109.2
0,-4,7:4
0,-3,7:109.3
0,-1,7:44.8
0,0,7:44.8
0,1,7:44.8
0,3,7:109.2
0,4,7:4
0,5,7:109.3
0,-5,8:43.8
0,-4,8:43.8
0,-3,8:43.8
0,-2,8:43.8
0,0,8:133
0,2,8:43.8
0,3,8:43.8
0,4,8:43.8
0,5,8:43.8
0,-4,9:159.9
0,-3,9:159.9
0,-2,9:159.9
0,-1,9:159.9
0,0,9:159.9
0,1,9:159.9
0,2,9:159.9
0,3,9:159.9
0,4,9:159.9
0,-4,10:4
0,-3,10:159.1
0,0,10:159.1
0,3,10:159.1
0,4,10:4
0,-3,11:44.8
0,-2,11:159.1
0,0,11:159.1
0,2,11:159.1
0,3,11:44.8
0,-3,12:44.8
0,-2,12:159.1
0,0,12:159.1
0,2,12:159.1
0,3,12:44.8
0,-3,13:44.8
0,-2,13:159.1
0,0,13:159.1
0,2,13:159.1
0,3,13:44.8
0,-3,14:44.8
0,-2,14:159.1
0,0,14:159.1
0,2,14:159.1
0,3,14:44.8
0,-3,15:44.8
0,-2,15:159.1
0,0,15:159.1
0,2,15:159.1
0,3,15:44.8
0,-3,16:44.8
0,-2,16:159.1
0,0,16:159.1
0,2,16:159.1
0,3,16:44.8
0,-3,17:4
0,0,17:159.1
0,3,17:4
0,-4,18:4
0,-3,18:4
0,-2,18:4
0,-1,18:4
0,0,18:4
0,1,18:4
0,2,18:4
0,3,18:4
0,4,18:4
0,-3,19:159.9
0,-2,19:159.9
0,-1,19:159.9
0,0,19:159.9
0,1,19:159.9
0,2,19:159.9
0,3,19:159.9
0,-4,20:4
0,-3,20:4
0,-2,20:4
0,-1,20:4
0,0,20:4
0,1,20:4
0,2,20:4
0,3,20:4
0,4,20:4
1,-7,0:44
1,-6,0:98
1,-5,0:98
1,-4,0:98
1,-3,0:98
1,-2,0:98
1,-1,0:98
1,0,0:98
1,1,0:98
1,2,0:98
1,3,0:98
1,4,0:98
1,5,0:98
1,6,0:98
1,7,0:44
1,-5,1:109.1
1,-4,1:43.8
1,-3,1:43.8
1,-2,1:43.8
1,-1,1:43.8
1,0,1:43.8
1,1,1:43.8
1,2,1:43.8
1,3,1:43.8
1,4,1:43.8
1,5,1:109.1
1,-5,2:109.5
1,-4,2:43.8
1,-3,2:43.8
1,-2,2:35.7
1,-1,2:35.7
1,0,2:43.8
1,1,2:35.7
1,2,2:35.7
1,3,2:43.8
1,4,2:43.8
1,5,2:109.5
1,-5,3:109.1
1,-4,3:109.1
1,-3,3:109.1
1,0,3:54.5
1,3,3:109.2
1,4,3:109.1
1,5,3:109.1
1,-4,4:139
1,4,4:139
1,-4,5:139
1,4,5:139
1,-5,6:109.6
1,-4,6:109.5
1,-3,6:109.7
1,3,6:109.6
1,4,6:109.5
1,5,6:109.5
1,-5,7:109.1
1,-4,7:109.1
1,-3,7:109.3
1,-1,7:44.8
1,0,7:44.8
1,1,7:44.8
1,3,7:109.2
1,4,7:109.1
1,5,7:109.1
1,-5,8:43.8
1,-4,8:43.8
1,-3,8:43.8
1,-2,8:43.8
1,2,8:43.8
1,3,8:43.8
1,4,8:43.8
1,5,8:43.8
1,-4,9:159.9
1,-3,9:159.9
1,-2,9:159.9
1,-1,9:159.9
1,0,9:159.9
1,1,9:159.9
1,2,9:159.9
1,3,9:159.9
1,4,9:159.9
1,-4,10:4
1,-3,10:159.1
1,3,10:159.1
1,4,10:4
1,-3,11:44.8
1,-2,11:159.1
1,2,11:159.1
1,3,11:44.8
1,-3,12:44.8
1,-2,12:159.1
1,2,12:159.1
1,3,12:44.8
1,-3,13:44.8
1,-2,13:159.1
1,2,13:159.1
1,3,13:44.8
1,-3,14:44.8
1,-2,14:159.1
1,2,14:159.1
1,3,14:44.8
1,-3,15:44.8
1,-2,15:159.1
1,2,15:159.1
1,3,15:44.8
1,-3,16:44.8
1,-2,16:159.1
1,2,16:159.1
1,3,16:44.8
1,-3,17:4
1,3,17:4
1,-4,18:4
1,-3,18:4
1,-2,18:4
1,-1,18:4
1,0,18:4
1,1,18:4
1,2,18:4
1,3,18:4
1,4,18:4
1,-3,19:159.9
1,-2,19:159.9
1,-1,19:159.9
1,0,19:159.9
1,1,19:159.9
1,2,19:159.9
1,3,19:159.9
1,-4,20:4
1,-3,20:4
1,-2,20:4
1,-1,20:4
1,0,20:4
1,1,20:4
1,2,20:4
1,3,20:4
1,4,20:4
2,-7,0:44
2,-6,0:98
2,-5,0:98
2,-4,0:98
2,-3,0:98
2,-2,0:98
2,-1,0:98
2,0,0:98
2,1,0:98
2,2,0:98
2,3,0:98
2,4,0:98
2,5,0:98
2,6,0:98
2,7,0:44
2,-5,1:43.8
2,-4,1:108.2
2,-3,1:108.1
2,-2,1:43.8
2,-1,1:43.8
2,0,1:43.8
2,1,1:43.8
2,2,1:43.8
2,3,1:108.1
2,4,1:108.3
2,5,1:43.8
2,-5,2:109.2
2,-4,2:4
2,-3,2:4
2,-2,2:43.8
2,-1,2:35.7
2,0,2:35.7
2,1,2:35.7
2,2,2:43.8
2,3,2:4
2,4,2:4
2,5,2:109.3
2,-5,8:43.8
2,-4,8:43.8
2,-3,8:43.8
2,-2,8:43.8
2,-1,8:43.8
2,0,8:43.8
2,1,8:43.8
2,2,8:43.8
2,3,8:43.8
2,4,8:43.8
2,5,8:43.8
2,-4,9:159.9
2,-3,9:159.9
2,-2,9:159.9
2,-1,9:159.9
2,0,9:159.9
2,1,9:159.9
2,2,9:159.9
2,3,9:159.9
2,4,9:159.9
2,-4,10:67.6
2,-3,10:4
2,3,10:4
2,4,10:67.7
2,-4,11:67.2
2,-3,11:4
2,-1,11:159.1
2,0,11:159.1
2,1,11:159.1
2,3,11:4
2,4,11:67.3
2,-3,12:44.8
2,-2,12:159.1
2,-1,12:159.1
2,0,12:159.1
2,1,12:159.1
2,2,12:159.1
2,3,12:44.8
2,-3,13:44.8
2,-2,13:159.1
2,-1,13:159.1
2,0,13:159.1
2,1,13:159.1
2,2,13:159.1
2,3,13:44.8
2,-3,14:44.8
2,-2,14:159.1
2,-1,14:159.1
2,0,14:159.1
2,1,14:159.1
2,2,14:159.1
2,3,14:44.8
2,-3,15:44.8
2,-2,15:159.1
2,-1,15:159.1
2,0,15:159.1
2,1,15:159.1
2,2,15:159.1
2,3,15:44.8
2,-4,16:67.6
2,-3,16:4
2,-1,16:159.1
2,0,16:159.1
2,1,16:159.1
2,3,16:4
2,4,16:67.7
2,-4,17:67.2
2,4,17:67.3
2,-4,18:4
2,-3,18:4
2,-2,18:4
2,-1,18:4
2,0,18:4
2,1,18:4
2,2,18:4
2,3,18:4
2,4,18:4
2,-2,19:159.9
2,-1,19:159.9
2,0,19:159.9
2,1,19:159.9
2,2,19:159.9
2,-4,20:4
2,-3,20:4
2,-2,20:4
2,-1,20:4
2,0,20:4
2,1,20:4
2,2,20:4
2,3,20:4
2,4,20:4
3,-6,0:44
3,-5,0:98
3,-4,0:98
3,-3,0:98
3,-2,0:98
3,-1,0:98
3,0,0:98
3,1,0:98
3,2,0:98
3,3,0:98
3,4,0:98
3,5,0:98
3,6,0:44
3,-5,1:109.2
3,-4,1:43.8
3,-3,1:43.8
3,-2,1:108.2
3,-1,1:43.8
3,0,1:43.8
3,1,1:43.8
3,2,1:108.3
3,3,1:43.8
3,4,1:43.8
3,5,1:109.3
3,-5,2:109.6
3,-4,2:43.8
3,-3,2:43.8
3,-2,2:4
3,-1,2:43.8
3,0,2:43.8
3,1,2:43.8
3,2,2:4
3,3,2:43.8
3,4,2:43.8
3,5,2:109.7
3,-1,3:109
3,0,3:109
3,1,3:109.3
3,0,4:139
3,0,5:139
3,-1,6:109.4
3,0,6:109.4
3,1,6:109.4
3,-5,7:44.8
3,-4,7:44.8
3,-3,7:44.8
3,-1,7:109
3,0,7:109
3,1,7:109
3,3,7:44.8
3,4,7:44.8
3,5,7:44.8
3,-5,8:43
3,-4,8:49
3,-3,8:49
3,-2,8:43.8
3,-1,8:43.8
3,0,8:43.8
3,1,8:43.8
3,2,8:43.8
3,3,8:49
3,4,8:49
3,5,8:43
3,-4,9:44
3,-3,9:159.9
3,-2,9:159.9
3,-1,9:159.9
3,0,9:159.9
3,1,9:159.9
3,2,9:159.9
3,3,9:159.9
3,4,9:44
3,-2,10:4
3,-1,10:159.1
3,0,10:159.1
3,1,10:159.1
3,2,10:4
3,-4,11:67.6
3,-2,11:4
3,-1,11:44.8
3,0,11:44.8
3,1,11:44.8
3,2,11:4
3,4,11:67.7
3,-4,12:67.2
3,-3,12:4
3,-2,12:44.8
3,-1,12:44.8
3,0,12:44.8
3,1,12:44.8
3,2,12:44.8
3,3,12:4
3,4,12:67.3
3,-3,13:4
3,-2,13:44.8
3,-1,13:44.8
3,0,13:44.8
3,1,13:44.8
3,2,13:44.8
3,3,13:4
3,-3,14:4
3,-2,14:44.8
3,-1,14:44.8
3,0,14:44.8
3,1,14:44.8
3,2,14:44.8
3,3,14:4
3,-4,15:67.6
3,-3,15:4
3,-2,15:44.8
3,-1,15:44.8
3,0,15:44.8
3,1,15:44.8
3,2,15:44.8
3,3,15:4
3,4,15:67.7
3,-4,16:67.2
3,-3,16:4
3,-2,16:4
3,-1,16:44.8
3,0,16:44.8
3,1,16:44.8
3,2,16:4
3,3,16:4
3,4,16:67.3
3,-3,17:4
3,-1,17:4
3,0,17:4
3,1,17:4
3,3,17:4
3,-3,18:4
3,-2,18:4
3,-1,18:4
3,0,18:4
3,1,18:4
3,2,18:4
3,3,18:4
3,-1,19:159.9
3,0,19:159.9
3,1,19:159.9
3,-3,20:4
3,-2,20:4
3,-1,20:4
3,0,20:4
3,1,20:4
3,2,20:4
3,3,20:4
4,-6,0:44
4,-5,0:98
4,-4,0:98
4,-3,0:98
4,-2,0:98
4,-1,0:98
4,0,0:98
4,1,0:98
4,2,0:98
4,3,0:98
4,4,0:98
4,5,0:98
4,6,0:44
4,-5,1:109.1
4,-4,1:43.8
4,-3,1:43.8
4,-2,1:108.1
4,-1,1:43.8
4,0,1:43.8
4,1,1:43.8
4,2,1:108.1
4,3,1:43.8
4,4,1:43.8
4,5,1:109.1
4,-5,2:109.5
4,-4,2:43.8
4,-3,2:43.8
4,-2,2:4
4,-1,2:43.8
4,0,2:43.8
4,1,2:43.8
4,2,2:4
4,3,2:43.8
4,4,2:43.8
4,5,2:109.7
4,-1,3:109.2
4,0,3:4
4,1,3:109.3
4,-1,4:139
4,0,4:4
4,1,4:139
4,-1,5:139
4,0,5:4
4,1,5:139
4,-1,6:109.6
4,0,6:4
4,1,6:109.7
4,-3,7:44.8
4,-1,7:109.2
4,0,7:4
4,1,7:109.3
4,3,7:44.8
4,-4,8:43
4,-3,8:49
4,-2,8:43.8
4,-1,8:43.8
4,0,8:43.8
4,1,8:43.8
4,2,8:43.8
4,3,8:49
4,4,8:43
4,-3,9:44
4,-2,9:159.9
4,-1,9:159.9
4,0,9:159.9
4,1,9:159.9
4,2,9:159.9
4,3,9:44
4,-2,10:67.5
4,-1,10:4
4,0,10:4
4,1,10:4
4,2,10:67.5
4,-3,11:67.5
4,-2,11:67.1
4,2,11:67.1
4,3,11:67.5
4,-3,12:67.1
4,3,12:67.1
4,-3,15:67.5
4,3,15:67.5
4,-3,16:67.1
4,-2,16:67.5
4,2,16:67.5
4,3,16:67.1
4,-2,17:67.1
4,2,17:67.1
4,-2,18:4
4,-1,18:4
4,0,18:4
4,1,18:4
4,2,18:4
4,-2,20:4
4,-1,20:4
4,0,20:4
4,1,20:4
4,2,20:4
5,-5,0:44
5,-4,0:98
5,-3,0:98
5,-2,0:98
5,-1,0:98
5,0,0:98
5,1,0:98
5,2,0:98
5,3,0:98
5,4,0:98
5,5,0:44
5,-4,1:109.2
5,-3,1:109.1
5,-2,1:43.8
5,-1,1:109.2
5,0,1:109.1
5,1,1:109.3
5,2,1:43.8
5,3,1:109.1
5,4,1:109.3
5,-4,2:109.6
5,-3,2:109.5
5,-2,2:109.1
5,-1,2:109.6
5,0,2:109.5
5,1,2:109.7
5,2,2:109.1
5,3,2:109.5
5,4,2:109.5
5,-1,3:109.2
5,0,3:109.1
5,1,3:109.3
5,0,4:139
5,0,5:139
5,-1,6:109.6
5,0,6:109.5
5,1,6:109.5
5,-3,7:44.8
5,-1,7:109.2
5,0,7:109.1
5,1,7:109.3
5,3,7:44.8
5,-3,8:43
5,-2,8:43.8
5,-1,8:43.8
5,0,8:43.8
5,1,8:43.8
5,2,8:43.8
5,3,8:43
6,-4,0:44
6,-3,0:44
6,-2,0:98
6,-1,0:98
6,0,0:98
6,1,0:98
6,2,0:98
6,3,0:44
6,4,0:44
7,-2,0:44
7,-1,0:44
7,0,0:44
7,1,0:44
7,2,0:44
